2017-12-15 22:10:49,889-[ERROR]-/ops-data/zp/haha/mysite-11/opsweb/resources/server/__init__.py-[line:34]-("name 'server_aliyun_obj' is not defined",)
2017-12-15 22:14:35,684-[ERROR]-/ops-data/zp/haha/mysite-11/opsweb/resources/server/__init__.py-[line:218]-("'NoneType' object has no attribute 'replace'",)
2017-12-15 22:15:04,519-[ERROR]-/ops-data/zp/haha/mysite-11/opsweb/resources/server/__init__.py-[line:218]-("'NoneType' object has no attribute 'replace'",)
2017-12-15 22:15:09,638-[ERROR]-/ops-data/zp/haha/mysite-11/opsweb/resources/server/__init__.py-[line:22]-("'ResultCallback' object has no attribute 'data'",)
2017-12-15 22:33:49,870-[ERROR]-/ops-data/zp/haha/mysite-11/opsweb/resources/server/__init__.py-[line:218]-("'NoneType' object has no attribute 'replace'",)
2017-12-15 23:11:58,385-[ERROR]-/ops-data/zp/haha/mysite-11/opsweb/resources/server/__init__.py-[line:22]-("'ResultCallback' object has no attribute 'data'",)
2017-12-15 23:15:02,833-[ERROR]-/ops-data/zp/haha/mysite-11/opsweb/resources/server/__init__.py-[line:22]-("'ResultCallback' object has no attribute 'data'",)
2017-12-15 23:15:02,834-[ERROR]-/ops-data/zp/haha/mysite-11/opsweb/resources/cron.py-[line:27]-服务器: 172.17.134.104 自动刷新失败,错误信息: ansible api 调用失败，请查看日志
2017-12-15 23:15:03,977-[ERROR]-/ops-data/zp/haha/mysite-11/opsweb/api/thirdapi/aliyun_describe_instance.py-[line:67]-HTTP Status: 403 Error:ChargeTypeViolation Pay-As-You-Go instances do not support this operation. RequestID: 08549F81-45D0-49E2-87B2-40C6CA9296AF
2017-12-15 23:15:05,611-[ERROR]-/ops-data/zp/haha/mysite-11/opsweb/api/thirdapi/aliyun_describe_instance.py-[line:67]-HTTP Status: 403 Error:ChargeTypeViolation Pay-As-You-Go instances do not support this operation. RequestID: A99D4B35-CBCD-4C51-9870-8C0CF7E7CC11
2017-12-15 23:15:07,187-[ERROR]-/ops-data/zp/haha/mysite-11/opsweb/api/thirdapi/aliyun_describe_instance.py-[line:67]-HTTP Status: 403 Error:ChargeTypeViolation Pay-As-You-Go instances do not support this operation. RequestID: 27910C59-5DD2-4D11-B34A-7C90B28E10B1
2017-12-15 23:15:07,322-[ERROR]-/ops-data/zp/haha/mysite-11/opsweb/resources/server/__init__.py-[line:22]-("'ResultCallback' object has no attribute 'data'",)
2017-12-15 23:15:07,323-[ERROR]-/ops-data/zp/haha/mysite-11/opsweb/resources/cron.py-[line:27]-服务器: 172.17.134.17 自动刷新失败,错误信息: ansible api 调用失败，请查看日志
2017-12-15 23:15:07,602-[ERROR]-/ops-data/zp/haha/mysite-11/opsweb/resources/server/__init__.py-[line:22]-("'ResultCallback' object has no attribute 'data'",)
2017-12-15 23:15:07,602-[ERROR]-/ops-data/zp/haha/mysite-11/opsweb/resources/cron.py-[line:27]-服务器: 172.17.134.19 自动刷新失败,错误信息: ansible api 调用失败，请查看日志
2017-12-15 23:15:07,740-[ERROR]-/ops-data/zp/haha/mysite-11/opsweb/resources/server/__init__.py-[line:22]-("'ResultCallback' object has no attribute 'data'",)
2017-12-15 23:15:07,741-[ERROR]-/ops-data/zp/haha/mysite-11/opsweb/resources/cron.py-[line:27]-服务器: 172.17.134.21 自动刷新失败,错误信息: ansible api 调用失败，请查看日志
2017-12-15 23:15:09,031-[ERROR]-/ops-data/zp/haha/mysite-11/opsweb/resources/server/__init__.py-[line:22]-("'ResultCallback' object has no attribute 'data'",)
2017-12-15 23:15:09,032-[ERROR]-/ops-data/zp/haha/mysite-11/opsweb/resources/cron.py-[line:27]-服务器: 172.17.134.23 自动刷新失败,错误信息: ansible api 调用失败，请查看日志
2017-12-15 23:15:09,191-[ERROR]-/ops-data/zp/haha/mysite-11/opsweb/resources/server/__init__.py-[line:22]-("'ResultCallback' object has no attribute 'data'",)
2017-12-15 23:15:09,191-[ERROR]-/ops-data/zp/haha/mysite-11/opsweb/resources/cron.py-[line:27]-服务器: 172.17.134.24 自动刷新失败,错误信息: ansible api 调用失败，请查看日志
2017-12-15 23:16:03,030-[ERROR]-/ops-data/zp/haha/mysite-11/opsweb/resources/server/__init__.py-[line:22]-("'ResultCallback' object has no attribute 'data'",)
2017-12-15 23:16:03,030-[ERROR]-/ops-data/zp/haha/mysite-11/opsweb/resources/cron.py-[line:27]-服务器: 172.17.134.86 自动刷新失败,错误信息: ansible api 调用失败，请查看日志
2017-12-15 23:16:10,496-[ERROR]-/ops-data/zp/haha/mysite-11/opsweb/resources/server/__init__.py-[line:22]-("'ResultCallback' object has no attribute 'data'",)
2017-12-15 23:16:10,497-[ERROR]-/ops-data/zp/haha/mysite-11/opsweb/resources/cron.py-[line:27]-服务器: 172.17.92.122 自动刷新失败,错误信息: ansible api 调用失败，请查看日志
2017-12-15 23:16:20,796-[ERROR]-/ops-data/zp/haha/mysite-11/opsweb/resources/server/__init__.py-[line:22]-("'ResultCallback' object has no attribute 'data'",)
2017-12-15 23:16:20,796-[ERROR]-/ops-data/zp/haha/mysite-11/opsweb/resources/cron.py-[line:27]-服务器: 172.17.92.123 自动刷新失败,错误信息: ansible api 调用失败，请查看日志
2017-12-15 23:17:29,682-[ERROR]-/ops-data/zp/haha/mysite-11/opsweb/resources/server/__init__.py-[line:22]-("'ResultCallback' object has no attribute 'data'",)
2017-12-15 23:17:33,985-[ERROR]-/ops-data/zp/haha/mysite-11/opsweb/resources/server/__init__.py-[line:22]-("'ResultCallback' object has no attribute 'data'",)
