2017-12-17 16:30:03,461-[ERROR]-/ops-data/zp/haha/mysite-11/opsweb/resources/server/__init__.py-[line:23]-("'ResultCallback' object has no attribute 'data'",)
2017-12-17 16:30:03,462-[ERROR]-/ops-data/zp/haha/mysite-11/opsweb/resources/cron.py-[line:27]-服务器: 172.17.134.104 自动刷新失败,错误信息: ansible api 调用失败，请查看日志
2017-12-17 16:30:04,756-[ERROR]-/ops-data/zp/haha/mysite-11/opsweb/api/thirdapi/aliyun_describe_instance.py-[line:67]-HTTP Status: 403 Error:ChargeTypeViolation Pay-As-You-Go instances do not support this operation. RequestID: 6AD6005F-6312-4D45-8770-5FB57F1A7942
2017-12-17 16:30:06,058-[ERROR]-/ops-data/zp/haha/mysite-11/opsweb/api/thirdapi/aliyun_describe_instance.py-[line:67]-HTTP Status: 403 Error:ChargeTypeViolation Pay-As-You-Go instances do not support this operation. RequestID: 0ADA0847-1A37-4D67-8FB1-1C5DE62799F1
2017-12-17 16:30:08,492-[ERROR]-/ops-data/zp/haha/mysite-11/opsweb/api/thirdapi/aliyun_describe_instance.py-[line:67]-HTTP Status: 403 Error:ChargeTypeViolation Pay-As-You-Go instances do not support this operation. RequestID: 95F5B910-614E-4564-89D8-21D0BD2A8F6A
2017-12-17 16:30:08,761-[ERROR]-/ops-data/zp/haha/mysite-11/opsweb/resources/server/__init__.py-[line:23]-("'ResultCallback' object has no attribute 'data'",)
2017-12-17 16:30:08,762-[ERROR]-/ops-data/zp/haha/mysite-11/opsweb/resources/cron.py-[line:27]-服务器: 172.17.134.17 自动刷新失败,错误信息: ansible api 调用失败，请查看日志
2017-12-17 16:30:09,054-[ERROR]-/ops-data/zp/haha/mysite-11/opsweb/resources/server/__init__.py-[line:23]-("'ResultCallback' object has no attribute 'data'",)
2017-12-17 16:30:09,054-[ERROR]-/ops-data/zp/haha/mysite-11/opsweb/resources/cron.py-[line:27]-服务器: 172.17.134.19 自动刷新失败,错误信息: ansible api 调用失败，请查看日志
2017-12-17 16:30:09,319-[ERROR]-/ops-data/zp/haha/mysite-11/opsweb/resources/server/__init__.py-[line:23]-("'ResultCallback' object has no attribute 'data'",)
2017-12-17 16:30:09,319-[ERROR]-/ops-data/zp/haha/mysite-11/opsweb/resources/cron.py-[line:27]-服务器: 172.17.134.21 自动刷新失败,错误信息: ansible api 调用失败，请查看日志
2017-12-17 16:30:09,449-[ERROR]-/ops-data/zp/haha/mysite-11/opsweb/resources/server/__init__.py-[line:23]-("'ResultCallback' object has no attribute 'data'",)
2017-12-17 16:30:09,449-[ERROR]-/ops-data/zp/haha/mysite-11/opsweb/resources/cron.py-[line:27]-服务器: 172.17.134.22 自动刷新失败,错误信息: ansible api 调用失败，请查看日志
2017-12-17 16:30:09,684-[ERROR]-/ops-data/zp/haha/mysite-11/opsweb/resources/server/__init__.py-[line:23]-("'ResultCallback' object has no attribute 'data'",)
2017-12-17 16:30:09,685-[ERROR]-/ops-data/zp/haha/mysite-11/opsweb/resources/cron.py-[line:27]-服务器: 172.17.134.23 自动刷新失败,错误信息: ansible api 调用失败，请查看日志
2017-12-17 16:30:09,976-[ERROR]-/ops-data/zp/haha/mysite-11/opsweb/resources/server/__init__.py-[line:23]-("'ResultCallback' object has no attribute 'data'",)
2017-12-17 16:30:09,977-[ERROR]-/ops-data/zp/haha/mysite-11/opsweb/resources/cron.py-[line:27]-服务器: 172.17.134.24 自动刷新失败,错误信息: ansible api 调用失败，请查看日志
2017-12-17 16:31:00,367-[ERROR]-/ops-data/zp/haha/mysite-11/opsweb/resources/server/__init__.py-[line:23]-("'ResultCallback' object has no attribute 'data'",)
2017-12-17 16:31:00,368-[ERROR]-/ops-data/zp/haha/mysite-11/opsweb/resources/cron.py-[line:27]-服务器: 172.17.134.86 自动刷新失败,错误信息: ansible api 调用失败，请查看日志
2017-12-17 16:31:07,300-[ERROR]-/ops-data/zp/haha/mysite-11/opsweb/resources/server/__init__.py-[line:23]-("'ResultCallback' object has no attribute 'data'",)
2017-12-17 16:31:07,301-[ERROR]-/ops-data/zp/haha/mysite-11/opsweb/resources/cron.py-[line:27]-服务器: 172.17.92.122 自动刷新失败,错误信息: ansible api 调用失败，请查看日志
2017-12-17 16:31:17,550-[ERROR]-/ops-data/zp/haha/mysite-11/opsweb/resources/server/__init__.py-[line:23]-("'ResultCallback' object has no attribute 'data'",)
2017-12-17 16:31:17,550-[ERROR]-/ops-data/zp/haha/mysite-11/opsweb/resources/cron.py-[line:27]-服务器: 172.17.92.123 自动刷新失败,错误信息: ansible api 调用失败，请查看日志
2017-12-17 17:21:30,528-[ERROR]-/ops-data/zp/haha/mysite-11/opsweb/resources/idc/__init__.py-[line:54]-IDC 模型对象id: 0 不存在
2017-12-17 17:21:47,044-[ERROR]-/ops-data/zp/haha/mysite-11/opsweb/resources/idc/__init__.py-[line:54]-IDC 模型对象id: 0 不存在
2017-12-17 17:29:20,432-[ERROR]-/ops-data/zp/haha/mysite-11/opsweb/resources/idc/__init__.py-[line:98]-IDC: 1 保存修改信息失败,错误信息: ('The following fields do not exist in this model or are m2m fields: last_change_time',)
2017-12-17 17:41:54,328-[ERROR]-/ops-data/zp/haha/mysite-11/opsweb/resources/server/__init__.py-[line:23]-("'ResultCallback' object has no attribute 'data'",)
