2017-12-16 16:30:02,798-[ERROR]-/ops-data/zp/haha/mysite-11/opsweb/resources/server/__init__.py-[line:22]-("'ResultCallback' object has no attribute 'data'",)
2017-12-16 16:30:02,799-[ERROR]-/ops-data/zp/haha/mysite-11/opsweb/resources/cron.py-[line:27]-服务器: 172.17.134.104 自动刷新失败,错误信息: ansible api 调用失败，请查看日志
2017-12-16 16:30:03,918-[ERROR]-/ops-data/zp/haha/mysite-11/opsweb/api/thirdapi/aliyun_describe_instance.py-[line:67]-HTTP Status: 403 Error:ChargeTypeViolation Pay-As-You-Go instances do not support this operation. RequestID: FA227E37-7B90-4071-93C9-9D11D481244D
2017-12-16 16:30:05,198-[ERROR]-/ops-data/zp/haha/mysite-11/opsweb/api/thirdapi/aliyun_describe_instance.py-[line:67]-HTTP Status: 403 Error:ChargeTypeViolation Pay-As-You-Go instances do not support this operation. RequestID: 063157BE-6854-4CA4-AB5D-2E331F575812
2017-12-16 16:30:07,030-[ERROR]-/ops-data/zp/haha/mysite-11/opsweb/api/thirdapi/aliyun_describe_instance.py-[line:67]-HTTP Status: 403 Error:ChargeTypeViolation Pay-As-You-Go instances do not support this operation. RequestID: E9654895-6F95-4217-8040-8642A8E50DFA
2017-12-16 16:30:07,296-[ERROR]-/ops-data/zp/haha/mysite-11/opsweb/resources/server/__init__.py-[line:22]-("'ResultCallback' object has no attribute 'data'",)
2017-12-16 16:30:07,296-[ERROR]-/ops-data/zp/haha/mysite-11/opsweb/resources/cron.py-[line:27]-服务器: 172.17.134.17 自动刷新失败,错误信息: ansible api 调用失败，请查看日志
2017-12-16 16:30:07,598-[ERROR]-/ops-data/zp/haha/mysite-11/opsweb/resources/server/__init__.py-[line:22]-("'ResultCallback' object has no attribute 'data'",)
2017-12-16 16:30:07,598-[ERROR]-/ops-data/zp/haha/mysite-11/opsweb/resources/cron.py-[line:27]-服务器: 172.17.134.19 自动刷新失败,错误信息: ansible api 调用失败，请查看日志
2017-12-16 16:30:07,895-[ERROR]-/ops-data/zp/haha/mysite-11/opsweb/resources/server/__init__.py-[line:22]-("'ResultCallback' object has no attribute 'data'",)
2017-12-16 16:30:07,895-[ERROR]-/ops-data/zp/haha/mysite-11/opsweb/resources/cron.py-[line:27]-服务器: 172.17.134.21 自动刷新失败,错误信息: ansible api 调用失败，请查看日志
2017-12-16 16:30:08,035-[ERROR]-/ops-data/zp/haha/mysite-11/opsweb/resources/server/__init__.py-[line:22]-("'ResultCallback' object has no attribute 'data'",)
2017-12-16 16:30:08,036-[ERROR]-/ops-data/zp/haha/mysite-11/opsweb/resources/cron.py-[line:27]-服务器: 172.17.134.22 自动刷新失败,错误信息: ansible api 调用失败，请查看日志
2017-12-16 16:30:08,241-[ERROR]-/ops-data/zp/haha/mysite-11/opsweb/resources/server/__init__.py-[line:22]-("'ResultCallback' object has no attribute 'data'",)
2017-12-16 16:30:08,241-[ERROR]-/ops-data/zp/haha/mysite-11/opsweb/resources/cron.py-[line:27]-服务器: 172.17.134.23 自动刷新失败,错误信息: ansible api 调用失败，请查看日志
2017-12-16 16:30:08,553-[ERROR]-/ops-data/zp/haha/mysite-11/opsweb/resources/server/__init__.py-[line:22]-("'ResultCallback' object has no attribute 'data'",)
2017-12-16 16:30:08,553-[ERROR]-/ops-data/zp/haha/mysite-11/opsweb/resources/cron.py-[line:27]-服务器: 172.17.134.24 自动刷新失败,错误信息: ansible api 调用失败，请查看日志
2017-12-16 16:30:58,289-[ERROR]-/ops-data/zp/haha/mysite-11/opsweb/resources/server/__init__.py-[line:22]-("'ResultCallback' object has no attribute 'data'",)
2017-12-16 16:30:58,289-[ERROR]-/ops-data/zp/haha/mysite-11/opsweb/resources/cron.py-[line:27]-服务器: 172.17.134.86 自动刷新失败,错误信息: ansible api 调用失败，请查看日志
2017-12-16 16:31:04,998-[ERROR]-/ops-data/zp/haha/mysite-11/opsweb/resources/server/__init__.py-[line:22]-("'ResultCallback' object has no attribute 'data'",)
2017-12-16 16:31:04,998-[ERROR]-/ops-data/zp/haha/mysite-11/opsweb/resources/cron.py-[line:27]-服务器: 172.17.92.122 自动刷新失败,错误信息: ansible api 调用失败，请查看日志
2017-12-16 16:31:15,252-[ERROR]-/ops-data/zp/haha/mysite-11/opsweb/resources/server/__init__.py-[line:22]-("'ResultCallback' object has no attribute 'data'",)
2017-12-16 16:31:15,252-[ERROR]-/ops-data/zp/haha/mysite-11/opsweb/resources/cron.py-[line:27]-服务器: 172.17.92.123 自动刷新失败,错误信息: ansible api 调用失败，请查看日志
2017-12-16 20:49:01,103-[ERROR]-/ops-data/zp/haha/mysite-11/opsweb/resources/server/__init__.py-[line:22]-("'ResultCallback' object has no attribute 'data'",)
2017-12-16 20:49:11,450-[ERROR]-/ops-data/zp/haha/mysite-11/opsweb/resources/server/__init__.py-[line:22]-("'ResultCallback' object has no attribute 'data'",)
2017-12-16 21:22:24,937-[ERROR]-/ops-data/zp/haha/mysite-11/opsweb/resources/server/__init__.py-[line:219]-("'NoneType' object has no attribute 'replace'",)
2017-12-16 21:26:00,976-[ERROR]-/ops-data/zp/haha/mysite-11/opsweb/resources/server/__init__.py-[line:219]-("'NoneType' object has no attribute 'replace'",)
2017-12-16 21:28:47,424-[ERROR]-/ops-data/zp/haha/mysite-11/opsweb/resources/server/__init__.py-[line:219]-("'NoneType' object has no attribute 'replace'",)
2017-12-16 22:00:27,083-[ERROR]-/ops-data/zp/haha/mysite-11/opsweb/api/thirdapi/aliyun_describe_instance.py-[line:67]-HTTP Status: 403 Error:ChargeTypeViolation Pay-As-You-Go instances do not support this operation. RequestID: 29257B9B-3D92-412D-9DB5-60423FC8E2B9
