2017-12-18 16:30:03,325-[ERROR]-/ops-data/zp/haha/mysite-11/opsweb/resources/server/__init__.py-[line:23]-("'ResultCallback' object has no attribute 'data'",)
2017-12-18 16:30:03,325-[ERROR]-/ops-data/zp/haha/mysite-11/opsweb/resources/cron.py-[line:27]-服务器: 172.17.134.104 自动刷新失败,错误信息: ansible api 调用失败，请查看日志
2017-12-18 16:30:04,561-[ERROR]-/ops-data/zp/haha/mysite-11/opsweb/api/thirdapi/aliyun_describe_instance.py-[line:67]-HTTP Status: 403 Error:ChargeTypeViolation Pay-As-You-Go instances do not support this operation. RequestID: A313B256-4EB4-41DC-A483-210710868FBB
2017-12-18 16:30:05,710-[ERROR]-/ops-data/zp/haha/mysite-11/opsweb/api/thirdapi/aliyun_describe_instance.py-[line:67]-HTTP Status: 403 Error:ChargeTypeViolation Pay-As-You-Go instances do not support this operation. RequestID: 31800DAB-B4CC-4E9F-91F7-FDBCBFE44CC3
2017-12-18 16:30:08,626-[ERROR]-/ops-data/zp/haha/mysite-11/opsweb/resources/server/__init__.py-[line:23]-("'ResultCallback' object has no attribute 'data'",)
2017-12-18 16:30:08,626-[ERROR]-/ops-data/zp/haha/mysite-11/opsweb/resources/cron.py-[line:27]-服务器: 172.17.134.17 自动刷新失败,错误信息: ansible api 调用失败，请查看日志
2017-12-18 16:30:08,969-[ERROR]-/ops-data/zp/haha/mysite-11/opsweb/resources/server/__init__.py-[line:23]-("'ResultCallback' object has no attribute 'data'",)
2017-12-18 16:30:08,969-[ERROR]-/ops-data/zp/haha/mysite-11/opsweb/resources/cron.py-[line:27]-服务器: 172.17.134.19 自动刷新失败,错误信息: ansible api 调用失败，请查看日志
2017-12-18 16:30:09,367-[ERROR]-/ops-data/zp/haha/mysite-11/opsweb/resources/server/__init__.py-[line:23]-("'ResultCallback' object has no attribute 'data'",)
2017-12-18 16:30:09,367-[ERROR]-/ops-data/zp/haha/mysite-11/opsweb/resources/cron.py-[line:27]-服务器: 172.17.134.21 自动刷新失败,错误信息: ansible api 调用失败，请查看日志
2017-12-18 16:30:10,732-[ERROR]-/ops-data/zp/haha/mysite-11/opsweb/resources/server/__init__.py-[line:23]-("'ResultCallback' object has no attribute 'data'",)
2017-12-18 16:30:10,732-[ERROR]-/ops-data/zp/haha/mysite-11/opsweb/resources/cron.py-[line:27]-服务器: 172.17.134.23 自动刷新失败,错误信息: ansible api 调用失败，请查看日志
2017-12-18 16:30:11,037-[ERROR]-/ops-data/zp/haha/mysite-11/opsweb/resources/server/__init__.py-[line:23]-("'ResultCallback' object has no attribute 'data'",)
2017-12-18 16:30:11,037-[ERROR]-/ops-data/zp/haha/mysite-11/opsweb/resources/cron.py-[line:27]-服务器: 172.17.134.24 自动刷新失败,错误信息: ansible api 调用失败，请查看日志
2017-12-18 16:31:00,426-[ERROR]-/ops-data/zp/haha/mysite-11/opsweb/resources/server/__init__.py-[line:23]-("'ResultCallback' object has no attribute 'data'",)
2017-12-18 16:31:00,426-[ERROR]-/ops-data/zp/haha/mysite-11/opsweb/resources/cron.py-[line:27]-服务器: 172.17.134.86 自动刷新失败,错误信息: ansible api 调用失败，请查看日志
2017-12-18 16:31:07,335-[ERROR]-/ops-data/zp/haha/mysite-11/opsweb/resources/server/__init__.py-[line:23]-("'ResultCallback' object has no attribute 'data'",)
2017-12-18 16:31:07,335-[ERROR]-/ops-data/zp/haha/mysite-11/opsweb/resources/cron.py-[line:27]-服务器: 172.17.92.122 自动刷新失败,错误信息: ansible api 调用失败，请查看日志
2017-12-18 16:31:17,568-[ERROR]-/ops-data/zp/haha/mysite-11/opsweb/resources/server/__init__.py-[line:23]-("'ResultCallback' object has no attribute 'data'",)
2017-12-18 16:31:17,569-[ERROR]-/ops-data/zp/haha/mysite-11/opsweb/resources/cron.py-[line:27]-服务器: 172.17.92.123 自动刷新失败,错误信息: ansible api 调用失败，请查看日志
2017-12-18 21:14:40,252-[ERROR]-/ops-data/zp/haha/mysite-11/opsweb/resources/server/__init__.py-[line:23]-("'ResultCallback' object has no attribute 'data'",)
2017-12-18 21:14:46,360-[ERROR]-/ops-data/zp/haha/mysite-11/opsweb/resources/server/__init__.py-[line:23]-("'ResultCallback' object has no attribute 'data'",)
2017-12-18 21:14:47,373-[ERROR]-/ops-data/zp/haha/mysite-11/opsweb/resources/server/__init__.py-[line:23]-("'ResultCallback' object has no attribute 'data'",)
