2018-03-22 13:29:01,120-[ERROR]-/ops-data/zp/haha/mysite-11/opsweb/workform/views.py-[line:392]-用户 Lin.Liang 审批失败,WorkFormModel模型对象id: 231 流程进度已不是提交时的进度: process_step_id 为 4
2018-03-22 13:30:05,059-[ERROR]-/ops-data/zp/haha/mysite-11/opsweb/resources/cron.py-[line:94]-该服务器: 172.17.134.86 实例名 mysql1 格式不正确
2018-03-22 13:30:05,411-[ERROR]-/ops-data/zp/haha/mysite-11/opsweb/resources/cron.py-[line:94]-该服务器: 172.17.134.24 实例名 webproxytoidc 格式不正确
2018-03-22 13:30:05,577-[ERROR]-/ops-data/zp/haha/mysite-11/opsweb/resources/cron.py-[line:94]-该服务器: 172.17.134.90 实例名 mysql3 格式不正确
2018-03-22 13:30:05,642-[ERROR]-/ops-data/zp/haha/mysite-11/opsweb/resources/cron.py-[line:94]-该服务器: 172.17.134.89 实例名 mysql2 格式不正确
2018-03-22 13:30:16,341-[ERROR]-/ops-data/zp/haha/mysite-11/opsweb/api/thirdapi/aliyun_describe_instance.py-[line:67]-HTTP Status: 403 Error:ChargeTypeViolation Pay-As-You-Go instances do not support this operation. RequestID: 3CA504DE-897A-4735-94A3-48093A04720D
2018-03-22 13:30:48,662-[ERROR]-/ops-data/zp/haha/mysite-11/opsweb/resources/server/__init__.py-[line:85]-("'ResultCallback' object has no attribute 'data'",)
2018-03-22 13:30:48,663-[ERROR]-/ops-data/zp/haha/mysite-11/opsweb/resources/cron.py-[line:31]-服务器: 172.17.92.122 自动刷新失败,错误信息: ansible api 调用失败，请查看日志
2018-03-22 13:31:28,294-[ERROR]-/ops-data/zp/haha/mysite-11/opsweb/resources/server/__init__.py-[line:85]-("'ResultCallback' object has no attribute 'data'",)
2018-03-22 13:31:28,295-[ERROR]-/ops-data/zp/haha/mysite-11/opsweb/resources/cron.py-[line:31]-服务器: 172.17.92.123 自动刷新失败,错误信息: ansible api 调用失败，请查看日志
2018-03-22 13:40:15,625-[ERROR]-/ops-data/zp/haha/mysite-11/opsweb/api/thirdapi/aliyun_describe_instance.py-[line:67]-HTTP Status: 403 Error:ChargeTypeViolation Pay-As-You-Go instances do not support this operation. RequestID: FEDF61F7-5735-4C9C-9F1A-91F129D31038
2018-03-22 13:40:50,365-[ERROR]-/ops-data/zp/haha/mysite-11/opsweb/resources/server/__init__.py-[line:85]-("'ResultCallback' object has no attribute 'data'",)
2018-03-22 13:40:50,366-[ERROR]-/ops-data/zp/haha/mysite-11/opsweb/resources/cron.py-[line:31]-服务器: 172.17.92.122 自动刷新失败,错误信息: ansible api 调用失败，请查看日志
2018-03-22 13:41:29,457-[ERROR]-/ops-data/zp/haha/mysite-11/opsweb/resources/server/__init__.py-[line:85]-("'ResultCallback' object has no attribute 'data'",)
2018-03-22 13:41:29,457-[ERROR]-/ops-data/zp/haha/mysite-11/opsweb/resources/cron.py-[line:31]-服务器: 172.17.92.123 自动刷新失败,错误信息: ansible api 调用失败，请查看日志
2018-03-22 13:45:03,156-[ERROR]-/ops-data/zp/haha/mysite-11/opsweb/resources/cron.py-[line:94]-该服务器: 172.17.134.86 实例名 mysql1 格式不正确
2018-03-22 13:45:03,333-[ERROR]-/ops-data/zp/haha/mysite-11/opsweb/resources/cron.py-[line:94]-该服务器: 172.17.134.24 实例名 webproxytoidc 格式不正确
2018-03-22 13:45:03,466-[ERROR]-/ops-data/zp/haha/mysite-11/opsweb/resources/cron.py-[line:94]-该服务器: 172.17.134.90 实例名 mysql3 格式不正确
2018-03-22 13:45:03,516-[ERROR]-/ops-data/zp/haha/mysite-11/opsweb/resources/cron.py-[line:94]-该服务器: 172.17.134.89 实例名 mysql2 格式不正确
2018-03-22 13:50:18,166-[ERROR]-/ops-data/zp/haha/mysite-11/opsweb/api/thirdapi/aliyun_describe_instance.py-[line:67]-HTTP Status: 403 Error:ChargeTypeViolation Pay-As-You-Go instances do not support this operation. RequestID: E704A5F8-8EC1-4050-B65E-7F452961C172
2018-03-22 13:50:49,994-[ERROR]-/ops-data/zp/haha/mysite-11/opsweb/resources/server/__init__.py-[line:85]-("'ResultCallback' object has no attribute 'data'",)
2018-03-22 13:50:49,995-[ERROR]-/ops-data/zp/haha/mysite-11/opsweb/resources/cron.py-[line:31]-服务器: 172.17.92.122 自动刷新失败,错误信息: ansible api 调用失败，请查看日志
2018-03-22 13:51:29,336-[ERROR]-/ops-data/zp/haha/mysite-11/opsweb/resources/server/__init__.py-[line:85]-("'ResultCallback' object has no attribute 'data'",)
2018-03-22 13:51:29,336-[ERROR]-/ops-data/zp/haha/mysite-11/opsweb/resources/cron.py-[line:31]-服务器: 172.17.92.123 自动刷新失败,错误信息: ansible api 调用失败，请查看日志
2018-03-22 14:00:03,715-[ERROR]-/ops-data/zp/haha/mysite-11/opsweb/resources/cron.py-[line:94]-该服务器: 172.17.134.86 实例名 mysql1 格式不正确
2018-03-22 14:00:04,055-[ERROR]-/ops-data/zp/haha/mysite-11/opsweb/resources/cron.py-[line:94]-该服务器: 172.17.134.24 实例名 webproxytoidc 格式不正确
2018-03-22 14:00:04,212-[ERROR]-/ops-data/zp/haha/mysite-11/opsweb/resources/cron.py-[line:94]-该服务器: 172.17.134.90 实例名 mysql3 格式不正确
2018-03-22 14:00:04,273-[ERROR]-/ops-data/zp/haha/mysite-11/opsweb/resources/cron.py-[line:94]-该服务器: 172.17.134.89 实例名 mysql2 格式不正确
2018-03-22 14:00:16,649-[ERROR]-/ops-data/zp/haha/mysite-11/opsweb/api/thirdapi/aliyun_describe_instance.py-[line:67]-HTTP Status: 403 Error:ChargeTypeViolation Pay-As-You-Go instances do not support this operation. RequestID: 1AECA091-0655-44D5-AB0F-AE400FA9D8A1
2018-03-22 14:00:52,638-[ERROR]-/ops-data/zp/haha/mysite-11/opsweb/resources/server/__init__.py-[line:85]-("'ResultCallback' object has no attribute 'data'",)
2018-03-22 14:00:52,638-[ERROR]-/ops-data/zp/haha/mysite-11/opsweb/resources/cron.py-[line:31]-服务器: 172.17.92.122 自动刷新失败,错误信息: ansible api 调用失败，请查看日志
2018-03-22 14:01:34,615-[ERROR]-/ops-data/zp/haha/mysite-11/opsweb/resources/server/__init__.py-[line:85]-("'ResultCallback' object has no attribute 'data'",)
2018-03-22 14:01:34,615-[ERROR]-/ops-data/zp/haha/mysite-11/opsweb/resources/cron.py-[line:31]-服务器: 172.17.92.123 自动刷新失败,错误信息: ansible api 调用失败，请查看日志
2018-03-22 14:10:15,653-[ERROR]-/ops-data/zp/haha/mysite-11/opsweb/api/thirdapi/aliyun_describe_instance.py-[line:67]-HTTP Status: 403 Error:ChargeTypeViolation Pay-As-You-Go instances do not support this operation. RequestID: 6E723981-7C5B-49E3-9C00-944DB08F6A40
2018-03-22 14:10:46,791-[ERROR]-/ops-data/zp/haha/mysite-11/opsweb/resources/server/__init__.py-[line:85]-("'ResultCallback' object has no attribute 'data'",)
2018-03-22 14:10:46,792-[ERROR]-/ops-data/zp/haha/mysite-11/opsweb/resources/cron.py-[line:31]-服务器: 172.17.92.122 自动刷新失败,错误信息: ansible api 调用失败，请查看日志
2018-03-22 14:11:26,438-[ERROR]-/ops-data/zp/haha/mysite-11/opsweb/resources/server/__init__.py-[line:85]-("'ResultCallback' object has no attribute 'data'",)
2018-03-22 14:11:26,438-[ERROR]-/ops-data/zp/haha/mysite-11/opsweb/resources/cron.py-[line:31]-服务器: 172.17.92.123 自动刷新失败,错误信息: ansible api 调用失败，请查看日志
2018-03-22 14:15:03,253-[ERROR]-/ops-data/zp/haha/mysite-11/opsweb/resources/cron.py-[line:94]-该服务器: 172.17.134.86 实例名 mysql1 格式不正确
2018-03-22 14:15:03,466-[ERROR]-/ops-data/zp/haha/mysite-11/opsweb/resources/cron.py-[line:94]-该服务器: 172.17.134.24 实例名 webproxytoidc 格式不正确
2018-03-22 14:15:03,636-[ERROR]-/ops-data/zp/haha/mysite-11/opsweb/resources/cron.py-[line:94]-该服务器: 172.17.134.90 实例名 mysql3 格式不正确
2018-03-22 14:15:03,691-[ERROR]-/ops-data/zp/haha/mysite-11/opsweb/resources/cron.py-[line:94]-该服务器: 172.17.134.89 实例名 mysql2 格式不正确
2018-03-22 14:20:14,720-[ERROR]-/ops-data/zp/haha/mysite-11/opsweb/api/thirdapi/aliyun_describe_instance.py-[line:67]-HTTP Status: 403 Error:ChargeTypeViolation Pay-As-You-Go instances do not support this operation. RequestID: A078CEBE-6C2A-4936-A17E-0C93796A7480
2018-03-22 14:20:49,443-[ERROR]-/ops-data/zp/haha/mysite-11/opsweb/resources/server/__init__.py-[line:85]-("'ResultCallback' object has no attribute 'data'",)
2018-03-22 14:20:49,444-[ERROR]-/ops-data/zp/haha/mysite-11/opsweb/resources/cron.py-[line:31]-服务器: 172.17.92.122 自动刷新失败,错误信息: ansible api 调用失败，请查看日志
2018-03-22 14:21:29,814-[ERROR]-/ops-data/zp/haha/mysite-11/opsweb/resources/server/__init__.py-[line:85]-("'ResultCallback' object has no attribute 'data'",)
2018-03-22 14:21:29,814-[ERROR]-/ops-data/zp/haha/mysite-11/opsweb/resources/cron.py-[line:31]-服务器: 172.17.92.123 自动刷新失败,错误信息: ansible api 调用失败，请查看日志
2018-03-22 14:30:04,790-[ERROR]-/ops-data/zp/haha/mysite-11/opsweb/resources/cron.py-[line:94]-该服务器: 172.17.134.86 实例名 mysql1 格式不正确
2018-03-22 14:30:05,142-[ERROR]-/ops-data/zp/haha/mysite-11/opsweb/resources/cron.py-[line:94]-该服务器: 172.17.134.24 实例名 webproxytoidc 格式不正确
2018-03-22 14:30:05,334-[ERROR]-/ops-data/zp/haha/mysite-11/opsweb/resources/cron.py-[line:94]-该服务器: 172.17.134.90 实例名 mysql3 格式不正确
2018-03-22 14:30:05,450-[ERROR]-/ops-data/zp/haha/mysite-11/opsweb/resources/cron.py-[line:94]-该服务器: 172.17.134.89 实例名 mysql2 格式不正确
2018-03-22 14:30:16,015-[ERROR]-/ops-data/zp/haha/mysite-11/opsweb/api/thirdapi/aliyun_describe_instance.py-[line:67]-HTTP Status: 403 Error:ChargeTypeViolation Pay-As-You-Go instances do not support this operation. RequestID: 8B757E01-0A16-4A63-AF5F-9D634D175735
2018-03-22 14:30:47,560-[ERROR]-/ops-data/zp/haha/mysite-11/opsweb/resources/server/__init__.py-[line:85]-("'ResultCallback' object has no attribute 'data'",)
2018-03-22 14:30:47,560-[ERROR]-/ops-data/zp/haha/mysite-11/opsweb/resources/cron.py-[line:31]-服务器: 172.17.92.122 自动刷新失败,错误信息: ansible api 调用失败，请查看日志
2018-03-22 14:31:28,443-[ERROR]-/ops-data/zp/haha/mysite-11/opsweb/resources/server/__init__.py-[line:85]-("'ResultCallback' object has no attribute 'data'",)
2018-03-22 14:31:28,443-[ERROR]-/ops-data/zp/haha/mysite-11/opsweb/resources/cron.py-[line:31]-服务器: 172.17.92.123 自动刷新失败,错误信息: ansible api 调用失败，请查看日志
2018-03-22 14:36:18,693-[ERROR]-/ops-data/zp/haha/mysite-11/opsweb/resources/server/__init__.py-[line:470]-服务器 10.82.40.82 在 zabbix 中不存在
2018-03-22 14:36:18,706-[ERROR]-/ops-data/zp/haha/mysite-11/opsweb/resources/server/__init__.py-[line:470]-服务器 10.82.40.77 在 zabbix 中不存在
2018-03-22 14:36:18,724-[ERROR]-/ops-data/zp/haha/mysite-11/opsweb/resources/server/__init__.py-[line:470]-服务器 10.82.40.81 在 zabbix 中不存在
2018-03-22 14:36:18,745-[ERROR]-/ops-data/zp/haha/mysite-11/opsweb/resources/server/__init__.py-[line:470]-服务器 10.82.40.76 在 zabbix 中不存在
2018-03-22 14:36:18,752-[ERROR]-/ops-data/zp/haha/mysite-11/opsweb/resources/server/__init__.py-[line:470]-服务器 10.82.40.75 在 zabbix 中不存在
2018-03-22 14:36:18,756-[ERROR]-/ops-data/zp/haha/mysite-11/opsweb/resources/server/__init__.py-[line:470]-服务器 10.82.40.79 在 zabbix 中不存在
2018-03-22 14:36:21,583-[ERROR]-/ops-data/zp/haha/mysite-11/opsweb/resources/server/__init__.py-[line:470]-服务器 10.82.40.82 在 zabbix 中不存在
2018-03-22 14:36:21,598-[ERROR]-/ops-data/zp/haha/mysite-11/opsweb/resources/server/__init__.py-[line:470]-服务器 10.82.40.77 在 zabbix 中不存在
2018-03-22 14:36:21,616-[ERROR]-/ops-data/zp/haha/mysite-11/opsweb/resources/server/__init__.py-[line:470]-服务器 10.82.40.81 在 zabbix 中不存在
2018-03-22 14:36:21,634-[ERROR]-/ops-data/zp/haha/mysite-11/opsweb/resources/server/__init__.py-[line:470]-服务器 10.82.40.76 在 zabbix 中不存在
2018-03-22 14:36:21,639-[ERROR]-/ops-data/zp/haha/mysite-11/opsweb/resources/server/__init__.py-[line:470]-服务器 10.82.40.75 在 zabbix 中不存在
2018-03-22 14:36:21,643-[ERROR]-/ops-data/zp/haha/mysite-11/opsweb/resources/server/__init__.py-[line:470]-服务器 10.82.40.79 在 zabbix 中不存在
2018-03-22 14:40:14,903-[ERROR]-/ops-data/zp/haha/mysite-11/opsweb/api/thirdapi/aliyun_describe_instance.py-[line:67]-HTTP Status: 403 Error:ChargeTypeViolation Pay-As-You-Go instances do not support this operation. RequestID: 3816DF6A-2210-4BD6-B5D9-6BA34F507AA5
2018-03-22 14:40:46,370-[ERROR]-/ops-data/zp/haha/mysite-11/opsweb/resources/server/__init__.py-[line:85]-("'ResultCallback' object has no attribute 'data'",)
2018-03-22 14:40:46,370-[ERROR]-/ops-data/zp/haha/mysite-11/opsweb/resources/cron.py-[line:31]-服务器: 172.17.92.122 自动刷新失败,错误信息: ansible api 调用失败，请查看日志
2018-03-22 14:41:26,581-[ERROR]-/ops-data/zp/haha/mysite-11/opsweb/resources/server/__init__.py-[line:85]-("'ResultCallback' object has no attribute 'data'",)
2018-03-22 14:41:26,581-[ERROR]-/ops-data/zp/haha/mysite-11/opsweb/resources/cron.py-[line:31]-服务器: 172.17.92.123 自动刷新失败,错误信息: ansible api 调用失败，请查看日志
2018-03-22 14:45:03,419-[ERROR]-/ops-data/zp/haha/mysite-11/opsweb/resources/cron.py-[line:94]-该服务器: 172.17.134.86 实例名 mysql1 格式不正确
2018-03-22 14:45:03,635-[ERROR]-/ops-data/zp/haha/mysite-11/opsweb/resources/cron.py-[line:94]-该服务器: 172.17.134.24 实例名 webproxytoidc 格式不正确
2018-03-22 14:45:03,775-[ERROR]-/ops-data/zp/haha/mysite-11/opsweb/resources/cron.py-[line:94]-该服务器: 172.17.134.90 实例名 mysql3 格式不正确
2018-03-22 14:45:03,824-[ERROR]-/ops-data/zp/haha/mysite-11/opsweb/resources/cron.py-[line:94]-该服务器: 172.17.134.89 实例名 mysql2 格式不正确
2018-03-22 14:45:51,001-[ERROR]-/ops-data/zp/haha/mysite-11/opsweb/resources/server/__init__.py-[line:470]-服务器 10.82.40.82 在 zabbix 中不存在
2018-03-22 14:45:51,014-[ERROR]-/ops-data/zp/haha/mysite-11/opsweb/resources/server/__init__.py-[line:470]-服务器 10.82.40.77 在 zabbix 中不存在
2018-03-22 14:45:51,032-[ERROR]-/ops-data/zp/haha/mysite-11/opsweb/resources/server/__init__.py-[line:470]-服务器 10.82.40.81 在 zabbix 中不存在
2018-03-22 14:45:51,051-[ERROR]-/ops-data/zp/haha/mysite-11/opsweb/resources/server/__init__.py-[line:470]-服务器 10.82.40.76 在 zabbix 中不存在
2018-03-22 14:45:51,056-[ERROR]-/ops-data/zp/haha/mysite-11/opsweb/resources/server/__init__.py-[line:470]-服务器 10.82.40.75 在 zabbix 中不存在
2018-03-22 14:45:51,060-[ERROR]-/ops-data/zp/haha/mysite-11/opsweb/resources/server/__init__.py-[line:470]-服务器 10.82.40.79 在 zabbix 中不存在
2018-03-22 14:50:15,487-[ERROR]-/ops-data/zp/haha/mysite-11/opsweb/api/thirdapi/aliyun_describe_instance.py-[line:67]-HTTP Status: 403 Error:ChargeTypeViolation Pay-As-You-Go instances do not support this operation. RequestID: FDAB55C1-BC32-41AA-8D27-E7EE6A80CAB4
2018-03-22 14:50:48,162-[ERROR]-/ops-data/zp/haha/mysite-11/opsweb/resources/server/__init__.py-[line:85]-("'ResultCallback' object has no attribute 'data'",)
2018-03-22 14:50:48,162-[ERROR]-/ops-data/zp/haha/mysite-11/opsweb/resources/cron.py-[line:31]-服务器: 172.17.92.122 自动刷新失败,错误信息: ansible api 调用失败，请查看日志
2018-03-22 14:51:28,921-[ERROR]-/ops-data/zp/haha/mysite-11/opsweb/resources/server/__init__.py-[line:85]-("'ResultCallback' object has no attribute 'data'",)
2018-03-22 14:51:28,922-[ERROR]-/ops-data/zp/haha/mysite-11/opsweb/resources/cron.py-[line:31]-服务器: 172.17.92.123 自动刷新失败,错误信息: ansible api 调用失败，请查看日志
2018-03-22 15:00:05,511-[ERROR]-/ops-data/zp/haha/mysite-11/opsweb/resources/cron.py-[line:94]-该服务器: 172.17.134.86 实例名 mysql1 格式不正确
2018-03-22 15:00:05,949-[ERROR]-/ops-data/zp/haha/mysite-11/opsweb/resources/cron.py-[line:94]-该服务器: 172.17.134.24 实例名 webproxytoidc 格式不正确
2018-03-22 15:00:06,152-[ERROR]-/ops-data/zp/haha/mysite-11/opsweb/resources/cron.py-[line:94]-该服务器: 172.17.134.90 实例名 mysql3 格式不正确
2018-03-22 15:00:06,212-[ERROR]-/ops-data/zp/haha/mysite-11/opsweb/resources/cron.py-[line:94]-该服务器: 172.17.134.89 实例名 mysql2 格式不正确
2018-03-22 15:00:17,210-[ERROR]-/ops-data/zp/haha/mysite-11/opsweb/api/thirdapi/aliyun_describe_instance.py-[line:67]-HTTP Status: 403 Error:ChargeTypeViolation Pay-As-You-Go instances do not support this operation. RequestID: C069AF0F-558E-4060-90CA-352A4893CDE6
2018-03-22 15:00:51,025-[ERROR]-/ops-data/zp/haha/mysite-11/opsweb/resources/server/__init__.py-[line:85]-("'ResultCallback' object has no attribute 'data'",)
2018-03-22 15:00:51,025-[ERROR]-/ops-data/zp/haha/mysite-11/opsweb/resources/cron.py-[line:31]-服务器: 172.17.92.122 自动刷新失败,错误信息: ansible api 调用失败，请查看日志
2018-03-22 15:01:34,207-[ERROR]-/ops-data/zp/haha/mysite-11/opsweb/resources/server/__init__.py-[line:85]-("'ResultCallback' object has no attribute 'data'",)
2018-03-22 15:01:34,207-[ERROR]-/ops-data/zp/haha/mysite-11/opsweb/resources/cron.py-[line:31]-服务器: 172.17.92.123 自动刷新失败,错误信息: ansible api 调用失败，请查看日志
2018-03-22 15:10:16,116-[ERROR]-/ops-data/zp/haha/mysite-11/opsweb/api/thirdapi/aliyun_describe_instance.py-[line:67]-HTTP Status: 403 Error:ChargeTypeViolation Pay-As-You-Go instances do not support this operation. RequestID: 303B5744-869F-4612-B123-8BFB4810A866
2018-03-22 15:10:48,568-[ERROR]-/ops-data/zp/haha/mysite-11/opsweb/resources/server/__init__.py-[line:85]-("'ResultCallback' object has no attribute 'data'",)
2018-03-22 15:10:48,569-[ERROR]-/ops-data/zp/haha/mysite-11/opsweb/resources/cron.py-[line:31]-服务器: 172.17.92.122 自动刷新失败,错误信息: ansible api 调用失败，请查看日志
2018-03-22 15:11:30,125-[ERROR]-/ops-data/zp/haha/mysite-11/opsweb/resources/server/__init__.py-[line:85]-("'ResultCallback' object has no attribute 'data'",)
2018-03-22 15:11:30,126-[ERROR]-/ops-data/zp/haha/mysite-11/opsweb/resources/cron.py-[line:31]-服务器: 172.17.92.123 自动刷新失败,错误信息: ansible api 调用失败，请查看日志
2018-03-22 15:15:02,718-[ERROR]-/ops-data/zp/haha/mysite-11/opsweb/resources/cron.py-[line:94]-该服务器: 172.17.134.86 实例名 mysql1 格式不正确
2018-03-22 15:15:02,916-[ERROR]-/ops-data/zp/haha/mysite-11/opsweb/resources/cron.py-[line:94]-该服务器: 172.17.134.24 实例名 webproxytoidc 格式不正确
2018-03-22 15:15:03,063-[ERROR]-/ops-data/zp/haha/mysite-11/opsweb/resources/cron.py-[line:94]-该服务器: 172.17.134.90 实例名 mysql3 格式不正确
2018-03-22 15:15:03,124-[ERROR]-/ops-data/zp/haha/mysite-11/opsweb/resources/cron.py-[line:94]-该服务器: 172.17.134.89 实例名 mysql2 格式不正确
2018-03-22 15:20:15,954-[ERROR]-/ops-data/zp/haha/mysite-11/opsweb/api/thirdapi/aliyun_describe_instance.py-[line:67]-HTTP Status: 403 Error:ChargeTypeViolation Pay-As-You-Go instances do not support this operation. RequestID: CB2DB329-AE59-451E-8B56-A977B01DA0F5
2018-03-22 15:20:48,238-[ERROR]-/ops-data/zp/haha/mysite-11/opsweb/resources/server/__init__.py-[line:85]-("'ResultCallback' object has no attribute 'data'",)
2018-03-22 15:20:48,238-[ERROR]-/ops-data/zp/haha/mysite-11/opsweb/resources/cron.py-[line:31]-服务器: 172.17.92.122 自动刷新失败,错误信息: ansible api 调用失败，请查看日志
2018-03-22 15:21:28,907-[ERROR]-/ops-data/zp/haha/mysite-11/opsweb/resources/server/__init__.py-[line:85]-("'ResultCallback' object has no attribute 'data'",)
2018-03-22 15:21:28,908-[ERROR]-/ops-data/zp/haha/mysite-11/opsweb/resources/cron.py-[line:31]-服务器: 172.17.92.123 自动刷新失败,错误信息: ansible api 调用失败，请查看日志
2018-03-22 15:30:05,723-[ERROR]-/ops-data/zp/haha/mysite-11/opsweb/resources/cron.py-[line:94]-该服务器: 172.17.134.86 实例名 mysql1 格式不正确
2018-03-22 15:30:05,988-[ERROR]-/ops-data/zp/haha/mysite-11/opsweb/resources/cron.py-[line:94]-该服务器: 172.17.134.24 实例名 webproxytoidc 格式不正确
2018-03-22 15:30:06,228-[ERROR]-/ops-data/zp/haha/mysite-11/opsweb/resources/cron.py-[line:94]-该服务器: 172.17.134.90 实例名 mysql3 格式不正确
2018-03-22 15:30:06,320-[ERROR]-/ops-data/zp/haha/mysite-11/opsweb/resources/cron.py-[line:94]-该服务器: 172.17.134.89 实例名 mysql2 格式不正确
2018-03-22 15:30:17,079-[ERROR]-/ops-data/zp/haha/mysite-11/opsweb/api/thirdapi/aliyun_describe_instance.py-[line:67]-HTTP Status: 403 Error:ChargeTypeViolation Pay-As-You-Go instances do not support this operation. RequestID: 35C1C077-153C-4620-AB4C-4A2F832B53D8
2018-03-22 15:30:50,689-[ERROR]-/ops-data/zp/haha/mysite-11/opsweb/resources/server/__init__.py-[line:85]-("'ResultCallback' object has no attribute 'data'",)
2018-03-22 15:30:50,689-[ERROR]-/ops-data/zp/haha/mysite-11/opsweb/resources/cron.py-[line:31]-服务器: 172.17.92.122 自动刷新失败,错误信息: ansible api 调用失败，请查看日志
2018-03-22 15:31:32,954-[ERROR]-/ops-data/zp/haha/mysite-11/opsweb/resources/server/__init__.py-[line:85]-("'ResultCallback' object has no attribute 'data'",)
2018-03-22 15:31:32,955-[ERROR]-/ops-data/zp/haha/mysite-11/opsweb/resources/cron.py-[line:31]-服务器: 172.17.92.123 自动刷新失败,错误信息: ansible api 调用失败，请查看日志
2018-03-22 15:40:14,573-[ERROR]-/ops-data/zp/haha/mysite-11/opsweb/api/thirdapi/aliyun_describe_instance.py-[line:67]-HTTP Status: 403 Error:ChargeTypeViolation Pay-As-You-Go instances do not support this operation. RequestID: 9F6130C4-FB94-46AF-BBAA-C4F38A069E9C
2018-03-22 15:40:46,166-[ERROR]-/ops-data/zp/haha/mysite-11/opsweb/resources/server/__init__.py-[line:85]-("'ResultCallback' object has no attribute 'data'",)
2018-03-22 15:40:46,167-[ERROR]-/ops-data/zp/haha/mysite-11/opsweb/resources/cron.py-[line:31]-服务器: 172.17.92.122 自动刷新失败,错误信息: ansible api 调用失败，请查看日志
2018-03-22 15:41:26,695-[ERROR]-/ops-data/zp/haha/mysite-11/opsweb/resources/server/__init__.py-[line:85]-("'ResultCallback' object has no attribute 'data'",)
2018-03-22 15:41:26,695-[ERROR]-/ops-data/zp/haha/mysite-11/opsweb/resources/cron.py-[line:31]-服务器: 172.17.92.123 自动刷新失败,错误信息: ansible api 调用失败，请查看日志
2018-03-22 15:45:03,312-[ERROR]-/ops-data/zp/haha/mysite-11/opsweb/resources/cron.py-[line:94]-该服务器: 172.17.134.86 实例名 mysql1 格式不正确
2018-03-22 15:45:03,521-[ERROR]-/ops-data/zp/haha/mysite-11/opsweb/resources/cron.py-[line:94]-该服务器: 172.17.134.24 实例名 webproxytoidc 格式不正确
2018-03-22 15:45:03,649-[ERROR]-/ops-data/zp/haha/mysite-11/opsweb/resources/cron.py-[line:94]-该服务器: 172.17.134.90 实例名 mysql3 格式不正确
2018-03-22 15:45:03,700-[ERROR]-/ops-data/zp/haha/mysite-11/opsweb/resources/cron.py-[line:94]-该服务器: 172.17.134.89 实例名 mysql2 格式不正确
2018-03-22 15:50:14,126-[ERROR]-/ops-data/zp/haha/mysite-11/opsweb/api/thirdapi/aliyun_describe_instance.py-[line:67]-HTTP Status: 403 Error:ChargeTypeViolation Pay-As-You-Go instances do not support this operation. RequestID: B057FD90-62C7-47BD-87D5-418DB02078FF
2018-03-22 15:50:45,233-[ERROR]-/ops-data/zp/haha/mysite-11/opsweb/resources/server/__init__.py-[line:85]-("'ResultCallback' object has no attribute 'data'",)
2018-03-22 15:50:45,233-[ERROR]-/ops-data/zp/haha/mysite-11/opsweb/resources/cron.py-[line:31]-服务器: 172.17.92.122 自动刷新失败,错误信息: ansible api 调用失败，请查看日志
2018-03-22 15:51:24,458-[ERROR]-/ops-data/zp/haha/mysite-11/opsweb/resources/server/__init__.py-[line:85]-("'ResultCallback' object has no attribute 'data'",)
2018-03-22 15:51:24,458-[ERROR]-/ops-data/zp/haha/mysite-11/opsweb/resources/cron.py-[line:31]-服务器: 172.17.92.123 自动刷新失败,错误信息: ansible api 调用失败，请查看日志
2018-03-22 16:00:04,903-[ERROR]-/ops-data/zp/haha/mysite-11/opsweb/resources/cron.py-[line:94]-该服务器: 172.17.134.86 实例名 mysql1 格式不正确
2018-03-22 16:00:05,312-[ERROR]-/ops-data/zp/haha/mysite-11/opsweb/resources/cron.py-[line:94]-该服务器: 172.17.134.24 实例名 webproxytoidc 格式不正确
2018-03-22 16:00:05,540-[ERROR]-/ops-data/zp/haha/mysite-11/opsweb/resources/cron.py-[line:94]-该服务器: 172.17.134.90 实例名 mysql3 格式不正确
2018-03-22 16:00:05,625-[ERROR]-/ops-data/zp/haha/mysite-11/opsweb/resources/cron.py-[line:94]-该服务器: 172.17.134.89 实例名 mysql2 格式不正确
2018-03-22 16:00:16,927-[ERROR]-/ops-data/zp/haha/mysite-11/opsweb/api/thirdapi/aliyun_describe_instance.py-[line:67]-HTTP Status: 403 Error:ChargeTypeViolation Pay-As-You-Go instances do not support this operation. RequestID: D30AA492-BBE7-4ED2-B9AB-4092C1E147F2
2018-03-22 16:00:49,467-[ERROR]-/ops-data/zp/haha/mysite-11/opsweb/resources/server/__init__.py-[line:85]-("'ResultCallback' object has no attribute 'data'",)
2018-03-22 16:00:49,468-[ERROR]-/ops-data/zp/haha/mysite-11/opsweb/resources/cron.py-[line:31]-服务器: 172.17.92.122 自动刷新失败,错误信息: ansible api 调用失败，请查看日志
2018-03-22 16:01:29,548-[ERROR]-/ops-data/zp/haha/mysite-11/opsweb/resources/server/__init__.py-[line:85]-("'ResultCallback' object has no attribute 'data'",)
2018-03-22 16:01:29,548-[ERROR]-/ops-data/zp/haha/mysite-11/opsweb/resources/cron.py-[line:31]-服务器: 172.17.92.123 自动刷新失败,错误信息: ansible api 调用失败，请查看日志
2018-03-22 16:10:15,659-[ERROR]-/ops-data/zp/haha/mysite-11/opsweb/api/thirdapi/aliyun_describe_instance.py-[line:67]-HTTP Status: 403 Error:ChargeTypeViolation Pay-As-You-Go instances do not support this operation. RequestID: 5E7E6C67-59B1-475C-9AF6-2CA4765CF724
2018-03-22 16:10:48,585-[ERROR]-/ops-data/zp/haha/mysite-11/opsweb/resources/server/__init__.py-[line:85]-("'ResultCallback' object has no attribute 'data'",)
2018-03-22 16:10:48,586-[ERROR]-/ops-data/zp/haha/mysite-11/opsweb/resources/cron.py-[line:31]-服务器: 172.17.92.122 自动刷新失败,错误信息: ansible api 调用失败，请查看日志
2018-03-22 16:11:28,385-[ERROR]-/ops-data/zp/haha/mysite-11/opsweb/resources/server/__init__.py-[line:85]-("'ResultCallback' object has no attribute 'data'",)
2018-03-22 16:11:28,385-[ERROR]-/ops-data/zp/haha/mysite-11/opsweb/resources/cron.py-[line:31]-服务器: 172.17.92.123 自动刷新失败,错误信息: ansible api 调用失败，请查看日志
2018-03-22 16:15:03,406-[ERROR]-/ops-data/zp/haha/mysite-11/opsweb/resources/cron.py-[line:94]-该服务器: 172.17.134.86 实例名 mysql1 格式不正确
2018-03-22 16:15:03,629-[ERROR]-/ops-data/zp/haha/mysite-11/opsweb/resources/cron.py-[line:94]-该服务器: 172.17.134.24 实例名 webproxytoidc 格式不正确
2018-03-22 16:15:03,787-[ERROR]-/ops-data/zp/haha/mysite-11/opsweb/resources/cron.py-[line:94]-该服务器: 172.17.134.90 实例名 mysql3 格式不正确
2018-03-22 16:15:03,847-[ERROR]-/ops-data/zp/haha/mysite-11/opsweb/resources/cron.py-[line:94]-该服务器: 172.17.134.89 实例名 mysql2 格式不正确
2018-03-22 16:20:14,674-[ERROR]-/ops-data/zp/haha/mysite-11/opsweb/api/thirdapi/aliyun_describe_instance.py-[line:67]-HTTP Status: 403 Error:ChargeTypeViolation Pay-As-You-Go instances do not support this operation. RequestID: 4D80BED1-8411-458E-AE87-4765D87BD055
2018-03-22 16:20:45,753-[ERROR]-/ops-data/zp/haha/mysite-11/opsweb/resources/server/__init__.py-[line:85]-("'ResultCallback' object has no attribute 'data'",)
2018-03-22 16:20:45,754-[ERROR]-/ops-data/zp/haha/mysite-11/opsweb/resources/cron.py-[line:31]-服务器: 172.17.92.122 自动刷新失败,错误信息: ansible api 调用失败，请查看日志
2018-03-22 16:21:25,103-[ERROR]-/ops-data/zp/haha/mysite-11/opsweb/resources/server/__init__.py-[line:85]-("'ResultCallback' object has no attribute 'data'",)
2018-03-22 16:21:25,104-[ERROR]-/ops-data/zp/haha/mysite-11/opsweb/resources/cron.py-[line:31]-服务器: 172.17.92.123 自动刷新失败,错误信息: ansible api 调用失败，请查看日志
2018-03-22 16:30:04,154-[ERROR]-/ops-data/zp/haha/mysite-11/opsweb/resources/cron.py-[line:94]-该服务器: 172.17.134.86 实例名 mysql1 格式不正确
2018-03-22 16:30:04,439-[ERROR]-/ops-data/zp/haha/mysite-11/opsweb/resources/cron.py-[line:94]-该服务器: 172.17.134.24 实例名 webproxytoidc 格式不正确
2018-03-22 16:30:04,596-[ERROR]-/ops-data/zp/haha/mysite-11/opsweb/resources/cron.py-[line:94]-该服务器: 172.17.134.90 实例名 mysql3 格式不正确
2018-03-22 16:30:04,677-[ERROR]-/ops-data/zp/haha/mysite-11/opsweb/resources/cron.py-[line:94]-该服务器: 172.17.134.89 实例名 mysql2 格式不正确
2018-03-22 16:30:15,987-[ERROR]-/ops-data/zp/haha/mysite-11/opsweb/api/thirdapi/aliyun_describe_instance.py-[line:67]-HTTP Status: 403 Error:ChargeTypeViolation Pay-As-You-Go instances do not support this operation. RequestID: DE2EB474-5EE1-4654-835E-68CFF5956DCD
2018-03-22 16:30:48,175-[ERROR]-/ops-data/zp/haha/mysite-11/opsweb/resources/server/__init__.py-[line:85]-("'ResultCallback' object has no attribute 'data'",)
2018-03-22 16:30:48,176-[ERROR]-/ops-data/zp/haha/mysite-11/opsweb/resources/cron.py-[line:31]-服务器: 172.17.92.122 自动刷新失败,错误信息: ansible api 调用失败，请查看日志
2018-03-22 16:31:28,696-[ERROR]-/ops-data/zp/haha/mysite-11/opsweb/resources/server/__init__.py-[line:85]-("'ResultCallback' object has no attribute 'data'",)
2018-03-22 16:31:28,697-[ERROR]-/ops-data/zp/haha/mysite-11/opsweb/resources/cron.py-[line:31]-服务器: 172.17.92.123 自动刷新失败,错误信息: ansible api 调用失败，请查看日志
2018-03-22 16:40:14,803-[ERROR]-/ops-data/zp/haha/mysite-11/opsweb/api/thirdapi/aliyun_describe_instance.py-[line:67]-HTTP Status: 403 Error:ChargeTypeViolation Pay-As-You-Go instances do not support this operation. RequestID: 2488FC89-2A31-4CAA-B41F-3A81B89A9FE8
2018-03-22 16:40:49,002-[ERROR]-/ops-data/zp/haha/mysite-11/opsweb/resources/server/__init__.py-[line:85]-("'ResultCallback' object has no attribute 'data'",)
2018-03-22 16:40:49,003-[ERROR]-/ops-data/zp/haha/mysite-11/opsweb/resources/cron.py-[line:31]-服务器: 172.17.92.122 自动刷新失败,错误信息: ansible api 调用失败，请查看日志
2018-03-22 16:41:31,458-[ERROR]-/ops-data/zp/haha/mysite-11/opsweb/resources/server/__init__.py-[line:85]-("'ResultCallback' object has no attribute 'data'",)
2018-03-22 16:41:31,458-[ERROR]-/ops-data/zp/haha/mysite-11/opsweb/resources/cron.py-[line:31]-服务器: 172.17.92.123 自动刷新失败,错误信息: ansible api 调用失败，请查看日志
2018-03-22 16:45:02,502-[ERROR]-/ops-data/zp/haha/mysite-11/opsweb/resources/cron.py-[line:94]-该服务器: 172.17.134.86 实例名 mysql1 格式不正确
2018-03-22 16:45:02,702-[ERROR]-/ops-data/zp/haha/mysite-11/opsweb/resources/cron.py-[line:94]-该服务器: 172.17.134.24 实例名 webproxytoidc 格式不正确
2018-03-22 16:45:02,852-[ERROR]-/ops-data/zp/haha/mysite-11/opsweb/resources/cron.py-[line:94]-该服务器: 172.17.134.90 实例名 mysql3 格式不正确
2018-03-22 16:45:02,901-[ERROR]-/ops-data/zp/haha/mysite-11/opsweb/resources/cron.py-[line:94]-该服务器: 172.17.134.89 实例名 mysql2 格式不正确
2018-03-22 16:50:14,036-[ERROR]-/ops-data/zp/haha/mysite-11/opsweb/api/thirdapi/aliyun_describe_instance.py-[line:67]-HTTP Status: 403 Error:ChargeTypeViolation Pay-As-You-Go instances do not support this operation. RequestID: 5E46078E-52CB-4C2C-ABC7-A200CF6E67EF
2018-03-22 16:50:45,437-[ERROR]-/ops-data/zp/haha/mysite-11/opsweb/resources/server/__init__.py-[line:85]-("'ResultCallback' object has no attribute 'data'",)
2018-03-22 16:50:45,438-[ERROR]-/ops-data/zp/haha/mysite-11/opsweb/resources/cron.py-[line:31]-服务器: 172.17.92.122 自动刷新失败,错误信息: ansible api 调用失败，请查看日志
2018-03-22 16:51:27,810-[ERROR]-/ops-data/zp/haha/mysite-11/opsweb/resources/server/__init__.py-[line:85]-("'ResultCallback' object has no attribute 'data'",)
2018-03-22 16:51:27,810-[ERROR]-/ops-data/zp/haha/mysite-11/opsweb/resources/cron.py-[line:31]-服务器: 172.17.92.123 自动刷新失败,错误信息: ansible api 调用失败，请查看日志
2018-03-22 17:00:04,039-[ERROR]-/ops-data/zp/haha/mysite-11/opsweb/resources/cron.py-[line:94]-该服务器: 172.17.134.86 实例名 mysql1 格式不正确
2018-03-22 17:00:04,323-[ERROR]-/ops-data/zp/haha/mysite-11/opsweb/resources/cron.py-[line:94]-该服务器: 172.17.134.24 实例名 webproxytoidc 格式不正确
2018-03-22 17:00:04,466-[ERROR]-/ops-data/zp/haha/mysite-11/opsweb/resources/cron.py-[line:94]-该服务器: 172.17.134.90 实例名 mysql3 格式不正确
2018-03-22 17:00:04,515-[ERROR]-/ops-data/zp/haha/mysite-11/opsweb/resources/cron.py-[line:94]-该服务器: 172.17.134.89 实例名 mysql2 格式不正确
2018-03-22 17:00:15,989-[ERROR]-/ops-data/zp/haha/mysite-11/opsweb/api/thirdapi/aliyun_describe_instance.py-[line:67]-HTTP Status: 403 Error:ChargeTypeViolation Pay-As-You-Go instances do not support this operation. RequestID: BA853E9F-5DBC-4DD4-85DD-1E4EDA1F0F1B
2018-03-22 17:00:51,505-[ERROR]-/ops-data/zp/haha/mysite-11/opsweb/resources/server/__init__.py-[line:85]-("'ResultCallback' object has no attribute 'data'",)
2018-03-22 17:00:51,505-[ERROR]-/ops-data/zp/haha/mysite-11/opsweb/resources/cron.py-[line:31]-服务器: 172.17.92.122 自动刷新失败,错误信息: ansible api 调用失败，请查看日志
2018-03-22 17:01:32,285-[ERROR]-/ops-data/zp/haha/mysite-11/opsweb/resources/server/__init__.py-[line:85]-("'ResultCallback' object has no attribute 'data'",)
2018-03-22 17:01:32,285-[ERROR]-/ops-data/zp/haha/mysite-11/opsweb/resources/cron.py-[line:31]-服务器: 172.17.92.123 自动刷新失败,错误信息: ansible api 调用失败，请查看日志
2018-03-22 17:10:15,374-[ERROR]-/ops-data/zp/haha/mysite-11/opsweb/api/thirdapi/aliyun_describe_instance.py-[line:67]-HTTP Status: 403 Error:ChargeTypeViolation Pay-As-You-Go instances do not support this operation. RequestID: 2D88D073-C7B9-42BD-A15E-C112766575F1
2018-03-22 17:10:47,630-[ERROR]-/ops-data/zp/haha/mysite-11/opsweb/resources/server/__init__.py-[line:85]-("'ResultCallback' object has no attribute 'data'",)
2018-03-22 17:10:47,631-[ERROR]-/ops-data/zp/haha/mysite-11/opsweb/resources/cron.py-[line:31]-服务器: 172.17.92.122 自动刷新失败,错误信息: ansible api 调用失败，请查看日志
2018-03-22 17:11:30,181-[ERROR]-/ops-data/zp/haha/mysite-11/opsweb/resources/server/__init__.py-[line:85]-("'ResultCallback' object has no attribute 'data'",)
2018-03-22 17:11:30,181-[ERROR]-/ops-data/zp/haha/mysite-11/opsweb/resources/cron.py-[line:31]-服务器: 172.17.92.123 自动刷新失败,错误信息: ansible api 调用失败，请查看日志
2018-03-22 17:15:03,531-[ERROR]-/ops-data/zp/haha/mysite-11/opsweb/resources/cron.py-[line:94]-该服务器: 172.17.134.86 实例名 mysql1 格式不正确
2018-03-22 17:15:03,738-[ERROR]-/ops-data/zp/haha/mysite-11/opsweb/resources/cron.py-[line:94]-该服务器: 172.17.134.24 实例名 webproxytoidc 格式不正确
2018-03-22 17:15:03,879-[ERROR]-/ops-data/zp/haha/mysite-11/opsweb/resources/cron.py-[line:94]-该服务器: 172.17.134.90 实例名 mysql3 格式不正确
2018-03-22 17:15:03,935-[ERROR]-/ops-data/zp/haha/mysite-11/opsweb/resources/cron.py-[line:94]-该服务器: 172.17.134.89 实例名 mysql2 格式不正确
2018-03-22 17:20:15,594-[ERROR]-/ops-data/zp/haha/mysite-11/opsweb/api/thirdapi/aliyun_describe_instance.py-[line:67]-HTTP Status: 403 Error:ChargeTypeViolation Pay-As-You-Go instances do not support this operation. RequestID: 86C8DCD0-0AA0-4734-8448-3D5677B1FEB0
2018-03-22 17:20:47,574-[ERROR]-/ops-data/zp/haha/mysite-11/opsweb/resources/server/__init__.py-[line:85]-("'ResultCallback' object has no attribute 'data'",)
2018-03-22 17:20:47,574-[ERROR]-/ops-data/zp/haha/mysite-11/opsweb/resources/cron.py-[line:31]-服务器: 172.17.92.122 自动刷新失败,错误信息: ansible api 调用失败，请查看日志
2018-03-22 17:21:27,792-[ERROR]-/ops-data/zp/haha/mysite-11/opsweb/resources/server/__init__.py-[line:85]-("'ResultCallback' object has no attribute 'data'",)
2018-03-22 17:21:27,792-[ERROR]-/ops-data/zp/haha/mysite-11/opsweb/resources/cron.py-[line:31]-服务器: 172.17.92.123 自动刷新失败,错误信息: ansible api 调用失败，请查看日志
2018-03-22 17:30:04,978-[ERROR]-/ops-data/zp/haha/mysite-11/opsweb/resources/cron.py-[line:94]-该服务器: 172.17.134.86 实例名 mysql1 格式不正确
2018-03-22 17:30:05,289-[ERROR]-/ops-data/zp/haha/mysite-11/opsweb/resources/cron.py-[line:94]-该服务器: 172.17.134.24 实例名 webproxytoidc 格式不正确
2018-03-22 17:30:05,526-[ERROR]-/ops-data/zp/haha/mysite-11/opsweb/resources/cron.py-[line:94]-该服务器: 172.17.134.90 实例名 mysql3 格式不正确
2018-03-22 17:30:05,644-[ERROR]-/ops-data/zp/haha/mysite-11/opsweb/resources/cron.py-[line:94]-该服务器: 172.17.134.89 实例名 mysql2 格式不正确
2018-03-22 17:30:16,247-[ERROR]-/ops-data/zp/haha/mysite-11/opsweb/api/thirdapi/aliyun_describe_instance.py-[line:67]-HTTP Status: 403 Error:ChargeTypeViolation Pay-As-You-Go instances do not support this operation. RequestID: 2B0822E3-4F47-49CA-8E21-26252563AD96
2018-03-22 17:30:47,415-[ERROR]-/ops-data/zp/haha/mysite-11/opsweb/resources/server/__init__.py-[line:85]-("'ResultCallback' object has no attribute 'data'",)
2018-03-22 17:30:47,415-[ERROR]-/ops-data/zp/haha/mysite-11/opsweb/resources/cron.py-[line:31]-服务器: 172.17.92.122 自动刷新失败,错误信息: ansible api 调用失败，请查看日志
2018-03-22 17:31:27,676-[ERROR]-/ops-data/zp/haha/mysite-11/opsweb/resources/server/__init__.py-[line:85]-("'ResultCallback' object has no attribute 'data'",)
2018-03-22 17:31:27,676-[ERROR]-/ops-data/zp/haha/mysite-11/opsweb/resources/cron.py-[line:31]-服务器: 172.17.92.123 自动刷新失败,错误信息: ansible api 调用失败，请查看日志
2018-03-22 17:40:14,599-[ERROR]-/ops-data/zp/haha/mysite-11/opsweb/api/thirdapi/aliyun_describe_instance.py-[line:67]-HTTP Status: 403 Error:ChargeTypeViolation Pay-As-You-Go instances do not support this operation. RequestID: C2DAC36C-D919-4FB2-9ADD-94463421AC89
2018-03-22 17:40:45,679-[ERROR]-/ops-data/zp/haha/mysite-11/opsweb/resources/server/__init__.py-[line:85]-("'ResultCallback' object has no attribute 'data'",)
2018-03-22 17:40:45,679-[ERROR]-/ops-data/zp/haha/mysite-11/opsweb/resources/cron.py-[line:31]-服务器: 172.17.92.122 自动刷新失败,错误信息: ansible api 调用失败，请查看日志
2018-03-22 17:41:26,045-[ERROR]-/ops-data/zp/haha/mysite-11/opsweb/resources/server/__init__.py-[line:85]-("'ResultCallback' object has no attribute 'data'",)
2018-03-22 17:41:26,045-[ERROR]-/ops-data/zp/haha/mysite-11/opsweb/resources/cron.py-[line:31]-服务器: 172.17.92.123 自动刷新失败,错误信息: ansible api 调用失败，请查看日志
2018-03-22 17:45:03,278-[ERROR]-/ops-data/zp/haha/mysite-11/opsweb/resources/cron.py-[line:94]-该服务器: 172.17.134.86 实例名 mysql1 格式不正确
2018-03-22 17:45:03,471-[ERROR]-/ops-data/zp/haha/mysite-11/opsweb/resources/cron.py-[line:94]-该服务器: 172.17.134.24 实例名 webproxytoidc 格式不正确
2018-03-22 17:45:03,599-[ERROR]-/ops-data/zp/haha/mysite-11/opsweb/resources/cron.py-[line:94]-该服务器: 172.17.134.90 实例名 mysql3 格式不正确
2018-03-22 17:45:03,651-[ERROR]-/ops-data/zp/haha/mysite-11/opsweb/resources/cron.py-[line:94]-该服务器: 172.17.134.89 实例名 mysql2 格式不正确
2018-03-22 17:50:15,543-[ERROR]-/ops-data/zp/haha/mysite-11/opsweb/api/thirdapi/aliyun_describe_instance.py-[line:67]-HTTP Status: 403 Error:ChargeTypeViolation Pay-As-You-Go instances do not support this operation. RequestID: BC6B05D6-C2D1-47EA-AD94-0931BB88C438
2018-03-22 17:50:46,535-[ERROR]-/ops-data/zp/haha/mysite-11/opsweb/resources/server/__init__.py-[line:85]-("'ResultCallback' object has no attribute 'data'",)
2018-03-22 17:50:46,535-[ERROR]-/ops-data/zp/haha/mysite-11/opsweb/resources/cron.py-[line:31]-服务器: 172.17.92.122 自动刷新失败,错误信息: ansible api 调用失败，请查看日志
2018-03-22 17:51:26,233-[ERROR]-/ops-data/zp/haha/mysite-11/opsweb/resources/server/__init__.py-[line:85]-("'ResultCallback' object has no attribute 'data'",)
2018-03-22 17:51:26,234-[ERROR]-/ops-data/zp/haha/mysite-11/opsweb/resources/cron.py-[line:31]-服务器: 172.17.92.123 自动刷新失败,错误信息: ansible api 调用失败，请查看日志
2018-03-22 18:00:04,455-[ERROR]-/ops-data/zp/haha/mysite-11/opsweb/resources/cron.py-[line:94]-该服务器: 172.17.134.86 实例名 mysql1 格式不正确
2018-03-22 18:00:04,746-[ERROR]-/ops-data/zp/haha/mysite-11/opsweb/resources/cron.py-[line:94]-该服务器: 172.17.134.24 实例名 webproxytoidc 格式不正确
2018-03-22 18:00:04,928-[ERROR]-/ops-data/zp/haha/mysite-11/opsweb/resources/cron.py-[line:94]-该服务器: 172.17.134.90 实例名 mysql3 格式不正确
2018-03-22 18:00:04,984-[ERROR]-/ops-data/zp/haha/mysite-11/opsweb/resources/cron.py-[line:94]-该服务器: 172.17.134.89 实例名 mysql2 格式不正确
2018-03-22 18:00:17,360-[ERROR]-/ops-data/zp/haha/mysite-11/opsweb/api/thirdapi/aliyun_describe_instance.py-[line:67]-HTTP Status: 403 Error:ChargeTypeViolation Pay-As-You-Go instances do not support this operation. RequestID: D7D64879-8F54-4E44-B734-D877BCD76B7B
2018-03-22 18:00:51,499-[ERROR]-/ops-data/zp/haha/mysite-11/opsweb/resources/server/__init__.py-[line:85]-("'ResultCallback' object has no attribute 'data'",)
2018-03-22 18:00:51,499-[ERROR]-/ops-data/zp/haha/mysite-11/opsweb/resources/cron.py-[line:31]-服务器: 172.17.92.122 自动刷新失败,错误信息: ansible api 调用失败，请查看日志
2018-03-22 18:01:31,620-[ERROR]-/ops-data/zp/haha/mysite-11/opsweb/resources/server/__init__.py-[line:85]-("'ResultCallback' object has no attribute 'data'",)
2018-03-22 18:01:31,620-[ERROR]-/ops-data/zp/haha/mysite-11/opsweb/resources/cron.py-[line:31]-服务器: 172.17.92.123 自动刷新失败,错误信息: ansible api 调用失败，请查看日志
2018-03-22 18:10:15,556-[ERROR]-/ops-data/zp/haha/mysite-11/opsweb/api/thirdapi/aliyun_describe_instance.py-[line:67]-HTTP Status: 403 Error:ChargeTypeViolation Pay-As-You-Go instances do not support this operation. RequestID: 9982D29C-8427-4D71-B0AB-AE2CD6B8AD09
2018-03-22 18:10:47,331-[ERROR]-/ops-data/zp/haha/mysite-11/opsweb/resources/server/__init__.py-[line:85]-("'ResultCallback' object has no attribute 'data'",)
2018-03-22 18:10:47,331-[ERROR]-/ops-data/zp/haha/mysite-11/opsweb/resources/cron.py-[line:31]-服务器: 172.17.92.122 自动刷新失败,错误信息: ansible api 调用失败，请查看日志
2018-03-22 18:11:29,423-[ERROR]-/ops-data/zp/haha/mysite-11/opsweb/resources/server/__init__.py-[line:85]-("'ResultCallback' object has no attribute 'data'",)
2018-03-22 18:11:29,424-[ERROR]-/ops-data/zp/haha/mysite-11/opsweb/resources/cron.py-[line:31]-服务器: 172.17.92.123 自动刷新失败,错误信息: ansible api 调用失败，请查看日志
2018-03-22 18:15:03,215-[ERROR]-/ops-data/zp/haha/mysite-11/opsweb/resources/cron.py-[line:94]-该服务器: 172.17.134.86 实例名 mysql1 格式不正确
2018-03-22 18:15:03,431-[ERROR]-/ops-data/zp/haha/mysite-11/opsweb/resources/cron.py-[line:94]-该服务器: 172.17.134.24 实例名 webproxytoidc 格式不正确
2018-03-22 18:15:03,581-[ERROR]-/ops-data/zp/haha/mysite-11/opsweb/resources/cron.py-[line:94]-该服务器: 172.17.134.90 实例名 mysql3 格式不正确
2018-03-22 18:15:03,637-[ERROR]-/ops-data/zp/haha/mysite-11/opsweb/resources/cron.py-[line:94]-该服务器: 172.17.134.89 实例名 mysql2 格式不正确
2018-03-22 18:20:15,098-[ERROR]-/ops-data/zp/haha/mysite-11/opsweb/api/thirdapi/aliyun_describe_instance.py-[line:67]-HTTP Status: 403 Error:ChargeTypeViolation Pay-As-You-Go instances do not support this operation. RequestID: 2F7EB5E7-98DB-4F7F-B462-D87921A5F9E8
2018-03-22 18:20:47,494-[ERROR]-/ops-data/zp/haha/mysite-11/opsweb/resources/server/__init__.py-[line:85]-("'ResultCallback' object has no attribute 'data'",)
2018-03-22 18:20:47,494-[ERROR]-/ops-data/zp/haha/mysite-11/opsweb/resources/cron.py-[line:31]-服务器: 172.17.92.122 自动刷新失败,错误信息: ansible api 调用失败，请查看日志
2018-03-22 18:21:26,854-[ERROR]-/ops-data/zp/haha/mysite-11/opsweb/resources/server/__init__.py-[line:85]-("'ResultCallback' object has no attribute 'data'",)
2018-03-22 18:21:26,854-[ERROR]-/ops-data/zp/haha/mysite-11/opsweb/resources/cron.py-[line:31]-服务器: 172.17.92.123 自动刷新失败,错误信息: ansible api 调用失败，请查看日志
2018-03-22 18:30:04,348-[ERROR]-/ops-data/zp/haha/mysite-11/opsweb/resources/cron.py-[line:94]-该服务器: 172.17.134.86 实例名 mysql1 格式不正确
2018-03-22 18:30:04,566-[ERROR]-/ops-data/zp/haha/mysite-11/opsweb/resources/cron.py-[line:94]-该服务器: 172.17.134.24 实例名 webproxytoidc 格式不正确
2018-03-22 18:30:04,810-[ERROR]-/ops-data/zp/haha/mysite-11/opsweb/resources/cron.py-[line:94]-该服务器: 172.17.134.90 实例名 mysql3 格式不正确
2018-03-22 18:30:04,899-[ERROR]-/ops-data/zp/haha/mysite-11/opsweb/resources/cron.py-[line:94]-该服务器: 172.17.134.89 实例名 mysql2 格式不正确
2018-03-22 18:30:15,977-[ERROR]-/ops-data/zp/haha/mysite-11/opsweb/api/thirdapi/aliyun_describe_instance.py-[line:67]-HTTP Status: 403 Error:ChargeTypeViolation Pay-As-You-Go instances do not support this operation. RequestID: 18660DBA-5FA0-4C4C-BEE4-9A7AAD33A3CF
2018-03-22 18:30:47,053-[ERROR]-/ops-data/zp/haha/mysite-11/opsweb/resources/server/__init__.py-[line:85]-("'ResultCallback' object has no attribute 'data'",)
2018-03-22 18:30:47,054-[ERROR]-/ops-data/zp/haha/mysite-11/opsweb/resources/cron.py-[line:31]-服务器: 172.17.92.122 自动刷新失败,错误信息: ansible api 调用失败，请查看日志
2018-03-22 18:31:26,988-[ERROR]-/ops-data/zp/haha/mysite-11/opsweb/resources/server/__init__.py-[line:85]-("'ResultCallback' object has no attribute 'data'",)
2018-03-22 18:31:26,989-[ERROR]-/ops-data/zp/haha/mysite-11/opsweb/resources/cron.py-[line:31]-服务器: 172.17.92.123 自动刷新失败,错误信息: ansible api 调用失败，请查看日志
2018-03-22 18:40:15,028-[ERROR]-/ops-data/zp/haha/mysite-11/opsweb/api/thirdapi/aliyun_describe_instance.py-[line:67]-HTTP Status: 403 Error:ChargeTypeViolation Pay-As-You-Go instances do not support this operation. RequestID: F99AA728-2987-48EF-9AFF-812CCD525D65
2018-03-22 18:40:46,264-[ERROR]-/ops-data/zp/haha/mysite-11/opsweb/resources/server/__init__.py-[line:85]-("'ResultCallback' object has no attribute 'data'",)
2018-03-22 18:40:46,264-[ERROR]-/ops-data/zp/haha/mysite-11/opsweb/resources/cron.py-[line:31]-服务器: 172.17.92.122 自动刷新失败,错误信息: ansible api 调用失败，请查看日志
2018-03-22 18:41:26,239-[ERROR]-/ops-data/zp/haha/mysite-11/opsweb/resources/server/__init__.py-[line:85]-("'ResultCallback' object has no attribute 'data'",)
2018-03-22 18:41:26,239-[ERROR]-/ops-data/zp/haha/mysite-11/opsweb/resources/cron.py-[line:31]-服务器: 172.17.92.123 自动刷新失败,错误信息: ansible api 调用失败，请查看日志
2018-03-22 18:45:03,097-[ERROR]-/ops-data/zp/haha/mysite-11/opsweb/resources/cron.py-[line:94]-该服务器: 172.17.134.86 实例名 mysql1 格式不正确
2018-03-22 18:45:03,308-[ERROR]-/ops-data/zp/haha/mysite-11/opsweb/resources/cron.py-[line:94]-该服务器: 172.17.134.24 实例名 webproxytoidc 格式不正确
2018-03-22 18:45:03,450-[ERROR]-/ops-data/zp/haha/mysite-11/opsweb/resources/cron.py-[line:94]-该服务器: 172.17.134.90 实例名 mysql3 格式不正确
2018-03-22 18:45:03,502-[ERROR]-/ops-data/zp/haha/mysite-11/opsweb/resources/cron.py-[line:94]-该服务器: 172.17.134.89 实例名 mysql2 格式不正确
2018-03-22 18:50:14,605-[ERROR]-/ops-data/zp/haha/mysite-11/opsweb/api/thirdapi/aliyun_describe_instance.py-[line:67]-HTTP Status: 403 Error:ChargeTypeViolation Pay-As-You-Go instances do not support this operation. RequestID: 250189AC-F03B-493E-B4B0-85C012D34A0A
2018-03-22 18:50:42,219-[ERROR]-/ops-data/zp/haha/mysite-11/opsweb/resources/server/__init__.py-[line:85]-("'ResultCallback' object has no attribute 'data'",)
2018-03-22 18:50:42,219-[ERROR]-/ops-data/zp/haha/mysite-11/opsweb/resources/cron.py-[line:31]-服务器: 172.17.134.142 自动刷新失败,错误信息: ansible api 调用失败，请查看日志
2018-03-22 18:50:45,424-[ERROR]-/ops-data/zp/haha/mysite-11/opsweb/resources/server/__init__.py-[line:85]-("'ResultCallback' object has no attribute 'data'",)
2018-03-22 18:50:45,425-[ERROR]-/ops-data/zp/haha/mysite-11/opsweb/resources/cron.py-[line:31]-服务器: 172.17.92.122 自动刷新失败,错误信息: ansible api 调用失败，请查看日志
2018-03-22 18:51:24,979-[ERROR]-/ops-data/zp/haha/mysite-11/opsweb/resources/server/__init__.py-[line:85]-("'ResultCallback' object has no attribute 'data'",)
2018-03-22 18:51:24,980-[ERROR]-/ops-data/zp/haha/mysite-11/opsweb/resources/cron.py-[line:31]-服务器: 172.17.92.123 自动刷新失败,错误信息: ansible api 调用失败，请查看日志
2018-03-22 19:00:04,583-[ERROR]-/ops-data/zp/haha/mysite-11/opsweb/resources/cron.py-[line:94]-该服务器: 172.17.134.86 实例名 mysql1 格式不正确
2018-03-22 19:00:04,918-[ERROR]-/ops-data/zp/haha/mysite-11/opsweb/resources/cron.py-[line:94]-该服务器: 172.17.134.24 实例名 webproxytoidc 格式不正确
2018-03-22 19:00:05,077-[ERROR]-/ops-data/zp/haha/mysite-11/opsweb/resources/cron.py-[line:94]-该服务器: 172.17.134.90 实例名 mysql3 格式不正确
2018-03-22 19:00:05,123-[ERROR]-/ops-data/zp/haha/mysite-11/opsweb/resources/cron.py-[line:94]-该服务器: 172.17.134.89 实例名 mysql2 格式不正确
2018-03-22 19:00:16,270-[ERROR]-/ops-data/zp/haha/mysite-11/opsweb/api/thirdapi/aliyun_describe_instance.py-[line:67]-HTTP Status: 403 Error:ChargeTypeViolation Pay-As-You-Go instances do not support this operation. RequestID: 0C3E022C-E3F9-4373-B97C-D481FC7918B7
2018-03-22 19:00:49,059-[ERROR]-/ops-data/zp/haha/mysite-11/opsweb/resources/server/__init__.py-[line:85]-("'ResultCallback' object has no attribute 'data'",)
2018-03-22 19:00:49,060-[ERROR]-/ops-data/zp/haha/mysite-11/opsweb/resources/cron.py-[line:31]-服务器: 172.17.92.122 自动刷新失败,错误信息: ansible api 调用失败，请查看日志
2018-03-22 19:01:28,158-[ERROR]-/ops-data/zp/haha/mysite-11/opsweb/resources/server/__init__.py-[line:85]-("'ResultCallback' object has no attribute 'data'",)
2018-03-22 19:01:28,159-[ERROR]-/ops-data/zp/haha/mysite-11/opsweb/resources/cron.py-[line:31]-服务器: 172.17.92.123 自动刷新失败,错误信息: ansible api 调用失败，请查看日志
2018-03-22 19:10:15,536-[ERROR]-/ops-data/zp/haha/mysite-11/opsweb/api/thirdapi/aliyun_describe_instance.py-[line:67]-HTTP Status: 403 Error:ChargeTypeViolation Pay-As-You-Go instances do not support this operation. RequestID: F5D7A7CF-71C5-41EC-83EB-75ED916FF4F1
2018-03-22 19:10:47,524-[ERROR]-/ops-data/zp/haha/mysite-11/opsweb/resources/server/__init__.py-[line:85]-("'ResultCallback' object has no attribute 'data'",)
2018-03-22 19:10:47,524-[ERROR]-/ops-data/zp/haha/mysite-11/opsweb/resources/cron.py-[line:31]-服务器: 172.17.92.122 自动刷新失败,错误信息: ansible api 调用失败，请查看日志
2018-03-22 19:11:26,965-[ERROR]-/ops-data/zp/haha/mysite-11/opsweb/resources/server/__init__.py-[line:85]-("'ResultCallback' object has no attribute 'data'",)
2018-03-22 19:11:26,965-[ERROR]-/ops-data/zp/haha/mysite-11/opsweb/resources/cron.py-[line:31]-服务器: 172.17.92.123 自动刷新失败,错误信息: ansible api 调用失败，请查看日志
2018-03-22 19:15:03,421-[ERROR]-/ops-data/zp/haha/mysite-11/opsweb/resources/cron.py-[line:94]-该服务器: 172.17.134.86 实例名 mysql1 格式不正确
2018-03-22 19:15:03,618-[ERROR]-/ops-data/zp/haha/mysite-11/opsweb/resources/cron.py-[line:94]-该服务器: 172.17.134.24 实例名 webproxytoidc 格式不正确
2018-03-22 19:15:03,748-[ERROR]-/ops-data/zp/haha/mysite-11/opsweb/resources/cron.py-[line:94]-该服务器: 172.17.134.90 实例名 mysql3 格式不正确
2018-03-22 19:15:03,805-[ERROR]-/ops-data/zp/haha/mysite-11/opsweb/resources/cron.py-[line:94]-该服务器: 172.17.134.89 实例名 mysql2 格式不正确
2018-03-22 19:20:15,207-[ERROR]-/ops-data/zp/haha/mysite-11/opsweb/api/thirdapi/aliyun_describe_instance.py-[line:67]-HTTP Status: 403 Error:ChargeTypeViolation Pay-As-You-Go instances do not support this operation. RequestID: 69990560-D912-4C31-88D9-1912AA847F1A
2018-03-22 19:20:47,264-[ERROR]-/ops-data/zp/haha/mysite-11/opsweb/resources/server/__init__.py-[line:85]-("'ResultCallback' object has no attribute 'data'",)
2018-03-22 19:20:47,264-[ERROR]-/ops-data/zp/haha/mysite-11/opsweb/resources/cron.py-[line:31]-服务器: 172.17.92.122 自动刷新失败,错误信息: ansible api 调用失败，请查看日志
2018-03-22 19:21:29,347-[ERROR]-/ops-data/zp/haha/mysite-11/opsweb/resources/server/__init__.py-[line:85]-("'ResultCallback' object has no attribute 'data'",)
2018-03-22 19:21:29,347-[ERROR]-/ops-data/zp/haha/mysite-11/opsweb/resources/cron.py-[line:31]-服务器: 172.17.92.123 自动刷新失败,错误信息: ansible api 调用失败，请查看日志
2018-03-22 19:30:03,579-[ERROR]-/ops-data/zp/haha/mysite-11/opsweb/resources/cron.py-[line:94]-该服务器: 172.17.134.86 实例名 mysql1 格式不正确
2018-03-22 19:30:03,811-[ERROR]-/ops-data/zp/haha/mysite-11/opsweb/resources/cron.py-[line:94]-该服务器: 172.17.134.24 实例名 webproxytoidc 格式不正确
2018-03-22 19:30:04,013-[ERROR]-/ops-data/zp/haha/mysite-11/opsweb/resources/cron.py-[line:94]-该服务器: 172.17.134.90 实例名 mysql3 格式不正确
2018-03-22 19:30:04,085-[ERROR]-/ops-data/zp/haha/mysite-11/opsweb/resources/cron.py-[line:94]-该服务器: 172.17.134.89 实例名 mysql2 格式不正确
2018-03-22 19:30:16,373-[ERROR]-/ops-data/zp/haha/mysite-11/opsweb/api/thirdapi/aliyun_describe_instance.py-[line:67]-HTTP Status: 403 Error:ChargeTypeViolation Pay-As-You-Go instances do not support this operation. RequestID: B0D14ABE-BA10-4530-A873-5750637EA1FE
2018-03-22 19:30:47,684-[ERROR]-/ops-data/zp/haha/mysite-11/opsweb/resources/server/__init__.py-[line:85]-("'ResultCallback' object has no attribute 'data'",)
2018-03-22 19:30:47,684-[ERROR]-/ops-data/zp/haha/mysite-11/opsweb/resources/cron.py-[line:31]-服务器: 172.17.92.122 自动刷新失败,错误信息: ansible api 调用失败，请查看日志
2018-03-22 19:31:29,057-[ERROR]-/ops-data/zp/haha/mysite-11/opsweb/resources/server/__init__.py-[line:85]-("'ResultCallback' object has no attribute 'data'",)
2018-03-22 19:31:29,058-[ERROR]-/ops-data/zp/haha/mysite-11/opsweb/resources/cron.py-[line:31]-服务器: 172.17.92.123 自动刷新失败,错误信息: ansible api 调用失败，请查看日志
2018-03-22 19:40:15,668-[ERROR]-/ops-data/zp/haha/mysite-11/opsweb/api/thirdapi/aliyun_describe_instance.py-[line:67]-HTTP Status: 403 Error:ChargeTypeViolation Pay-As-You-Go instances do not support this operation. RequestID: D288D26D-9BC3-463E-93CF-AA99FD2CEC70
2018-03-22 19:40:48,598-[ERROR]-/ops-data/zp/haha/mysite-11/opsweb/resources/server/__init__.py-[line:85]-("'ResultCallback' object has no attribute 'data'",)
2018-03-22 19:40:48,598-[ERROR]-/ops-data/zp/haha/mysite-11/opsweb/resources/cron.py-[line:31]-服务器: 172.17.92.122 自动刷新失败,错误信息: ansible api 调用失败，请查看日志
2018-03-22 19:41:28,356-[ERROR]-/ops-data/zp/haha/mysite-11/opsweb/resources/server/__init__.py-[line:85]-("'ResultCallback' object has no attribute 'data'",)
2018-03-22 19:41:28,356-[ERROR]-/ops-data/zp/haha/mysite-11/opsweb/resources/cron.py-[line:31]-服务器: 172.17.92.123 自动刷新失败,错误信息: ansible api 调用失败，请查看日志
2018-03-22 19:45:03,534-[ERROR]-/ops-data/zp/haha/mysite-11/opsweb/resources/cron.py-[line:94]-该服务器: 172.17.134.86 实例名 mysql1 格式不正确
2018-03-22 19:45:03,728-[ERROR]-/ops-data/zp/haha/mysite-11/opsweb/resources/cron.py-[line:94]-该服务器: 172.17.134.24 实例名 webproxytoidc 格式不正确
2018-03-22 19:45:03,880-[ERROR]-/ops-data/zp/haha/mysite-11/opsweb/resources/cron.py-[line:94]-该服务器: 172.17.134.90 实例名 mysql3 格式不正确
2018-03-22 19:45:03,929-[ERROR]-/ops-data/zp/haha/mysite-11/opsweb/resources/cron.py-[line:94]-该服务器: 172.17.134.89 实例名 mysql2 格式不正确
2018-03-22 19:50:14,860-[ERROR]-/ops-data/zp/haha/mysite-11/opsweb/api/thirdapi/aliyun_describe_instance.py-[line:67]-HTTP Status: 403 Error:ChargeTypeViolation Pay-As-You-Go instances do not support this operation. RequestID: 5EB1CD21-3685-4B76-9699-D1424E2E3775
2018-03-22 19:50:46,911-[ERROR]-/ops-data/zp/haha/mysite-11/opsweb/resources/server/__init__.py-[line:85]-("'ResultCallback' object has no attribute 'data'",)
2018-03-22 19:50:46,911-[ERROR]-/ops-data/zp/haha/mysite-11/opsweb/resources/cron.py-[line:31]-服务器: 172.17.92.122 自动刷新失败,错误信息: ansible api 调用失败，请查看日志
2018-03-22 19:51:25,900-[ERROR]-/ops-data/zp/haha/mysite-11/opsweb/resources/server/__init__.py-[line:85]-("'ResultCallback' object has no attribute 'data'",)
2018-03-22 19:51:25,900-[ERROR]-/ops-data/zp/haha/mysite-11/opsweb/resources/cron.py-[line:31]-服务器: 172.17.92.123 自动刷新失败,错误信息: ansible api 调用失败，请查看日志
2018-03-22 20:00:04,605-[ERROR]-/ops-data/zp/haha/mysite-11/opsweb/resources/cron.py-[line:94]-该服务器: 172.17.134.86 实例名 mysql1 格式不正确
2018-03-22 20:00:04,877-[ERROR]-/ops-data/zp/haha/mysite-11/opsweb/resources/cron.py-[line:94]-该服务器: 172.17.134.24 实例名 webproxytoidc 格式不正确
2018-03-22 20:00:05,110-[ERROR]-/ops-data/zp/haha/mysite-11/opsweb/resources/cron.py-[line:94]-该服务器: 172.17.134.90 实例名 mysql3 格式不正确
2018-03-22 20:00:05,162-[ERROR]-/ops-data/zp/haha/mysite-11/opsweb/resources/cron.py-[line:94]-该服务器: 172.17.134.89 实例名 mysql2 格式不正确
2018-03-22 20:00:16,171-[ERROR]-/ops-data/zp/haha/mysite-11/opsweb/api/thirdapi/aliyun_describe_instance.py-[line:67]-HTTP Status: 403 Error:ChargeTypeViolation Pay-As-You-Go instances do not support this operation. RequestID: E6522D3D-C44E-45A2-93E0-BE22B466D18B
2018-03-22 20:00:49,806-[ERROR]-/ops-data/zp/haha/mysite-11/opsweb/resources/server/__init__.py-[line:85]-("'ResultCallback' object has no attribute 'data'",)
2018-03-22 20:00:49,807-[ERROR]-/ops-data/zp/haha/mysite-11/opsweb/resources/cron.py-[line:31]-服务器: 172.17.92.122 自动刷新失败,错误信息: ansible api 调用失败，请查看日志
2018-03-22 20:01:31,971-[ERROR]-/ops-data/zp/haha/mysite-11/opsweb/resources/server/__init__.py-[line:85]-("'ResultCallback' object has no attribute 'data'",)
2018-03-22 20:01:31,972-[ERROR]-/ops-data/zp/haha/mysite-11/opsweb/resources/cron.py-[line:31]-服务器: 172.17.92.123 自动刷新失败,错误信息: ansible api 调用失败，请查看日志
2018-03-22 20:10:15,744-[ERROR]-/ops-data/zp/haha/mysite-11/opsweb/api/thirdapi/aliyun_describe_instance.py-[line:67]-HTTP Status: 403 Error:ChargeTypeViolation Pay-As-You-Go instances do not support this operation. RequestID: 91C1D5C4-E69A-463E-AB19-B544F4859FFF
2018-03-22 20:10:47,828-[ERROR]-/ops-data/zp/haha/mysite-11/opsweb/resources/server/__init__.py-[line:85]-("'ResultCallback' object has no attribute 'data'",)
2018-03-22 20:10:47,828-[ERROR]-/ops-data/zp/haha/mysite-11/opsweb/resources/cron.py-[line:31]-服务器: 172.17.92.122 自动刷新失败,错误信息: ansible api 调用失败，请查看日志
2018-03-22 20:11:27,344-[ERROR]-/ops-data/zp/haha/mysite-11/opsweb/resources/server/__init__.py-[line:85]-("'ResultCallback' object has no attribute 'data'",)
2018-03-22 20:11:27,344-[ERROR]-/ops-data/zp/haha/mysite-11/opsweb/resources/cron.py-[line:31]-服务器: 172.17.92.123 自动刷新失败,错误信息: ansible api 调用失败，请查看日志
2018-03-22 20:15:02,589-[ERROR]-/ops-data/zp/haha/mysite-11/opsweb/resources/cron.py-[line:94]-该服务器: 172.17.134.86 实例名 mysql1 格式不正确
2018-03-22 20:15:02,785-[ERROR]-/ops-data/zp/haha/mysite-11/opsweb/resources/cron.py-[line:94]-该服务器: 172.17.134.24 实例名 webproxytoidc 格式不正确
2018-03-22 20:15:02,913-[ERROR]-/ops-data/zp/haha/mysite-11/opsweb/resources/cron.py-[line:94]-该服务器: 172.17.134.90 实例名 mysql3 格式不正确
2018-03-22 20:15:02,965-[ERROR]-/ops-data/zp/haha/mysite-11/opsweb/resources/cron.py-[line:94]-该服务器: 172.17.134.89 实例名 mysql2 格式不正确
2018-03-22 20:20:14,272-[ERROR]-/ops-data/zp/haha/mysite-11/opsweb/api/thirdapi/aliyun_describe_instance.py-[line:67]-HTTP Status: 403 Error:ChargeTypeViolation Pay-As-You-Go instances do not support this operation. RequestID: 2A692BB4-3B19-4BF6-9338-5D5C90DFA247
2018-03-22 20:20:47,821-[ERROR]-/ops-data/zp/haha/mysite-11/opsweb/resources/server/__init__.py-[line:85]-("'ResultCallback' object has no attribute 'data'",)
2018-03-22 20:20:47,821-[ERROR]-/ops-data/zp/haha/mysite-11/opsweb/resources/cron.py-[line:31]-服务器: 172.17.92.122 自动刷新失败,错误信息: ansible api 调用失败，请查看日志
2018-03-22 20:21:28,545-[ERROR]-/ops-data/zp/haha/mysite-11/opsweb/resources/server/__init__.py-[line:85]-("'ResultCallback' object has no attribute 'data'",)
2018-03-22 20:21:28,545-[ERROR]-/ops-data/zp/haha/mysite-11/opsweb/resources/cron.py-[line:31]-服务器: 172.17.92.123 自动刷新失败,错误信息: ansible api 调用失败，请查看日志
2018-03-22 20:30:03,633-[ERROR]-/ops-data/zp/haha/mysite-11/opsweb/resources/cron.py-[line:94]-该服务器: 172.17.134.86 实例名 mysql1 格式不正确
2018-03-22 20:30:03,814-[ERROR]-/ops-data/zp/haha/mysite-11/opsweb/resources/cron.py-[line:94]-该服务器: 172.17.134.24 实例名 webproxytoidc 格式不正确
2018-03-22 20:30:03,935-[ERROR]-/ops-data/zp/haha/mysite-11/opsweb/resources/cron.py-[line:94]-该服务器: 172.17.134.90 实例名 mysql3 格式不正确
2018-03-22 20:30:03,981-[ERROR]-/ops-data/zp/haha/mysite-11/opsweb/resources/cron.py-[line:94]-该服务器: 172.17.134.89 实例名 mysql2 格式不正确
2018-03-22 20:30:15,901-[ERROR]-/ops-data/zp/haha/mysite-11/opsweb/api/thirdapi/aliyun_describe_instance.py-[line:67]-HTTP Status: 403 Error:ChargeTypeViolation Pay-As-You-Go instances do not support this operation. RequestID: B2DD99B5-107C-451D-8247-E6B621ACA1EC
2018-03-22 20:30:47,316-[ERROR]-/ops-data/zp/haha/mysite-11/opsweb/resources/server/__init__.py-[line:85]-("'ResultCallback' object has no attribute 'data'",)
2018-03-22 20:30:47,316-[ERROR]-/ops-data/zp/haha/mysite-11/opsweb/resources/cron.py-[line:31]-服务器: 172.17.92.122 自动刷新失败,错误信息: ansible api 调用失败，请查看日志
2018-03-22 20:31:27,023-[ERROR]-/ops-data/zp/haha/mysite-11/opsweb/resources/server/__init__.py-[line:85]-("'ResultCallback' object has no attribute 'data'",)
2018-03-22 20:31:27,023-[ERROR]-/ops-data/zp/haha/mysite-11/opsweb/resources/cron.py-[line:31]-服务器: 172.17.92.123 自动刷新失败,错误信息: ansible api 调用失败，请查看日志
2018-03-22 20:40:15,869-[ERROR]-/ops-data/zp/haha/mysite-11/opsweb/api/thirdapi/aliyun_describe_instance.py-[line:67]-HTTP Status: 403 Error:ChargeTypeViolation Pay-As-You-Go instances do not support this operation. RequestID: 5F279084-224E-4F40-8521-40930AA68D43
2018-03-22 20:40:47,719-[ERROR]-/ops-data/zp/haha/mysite-11/opsweb/resources/server/__init__.py-[line:85]-("'ResultCallback' object has no attribute 'data'",)
2018-03-22 20:40:47,719-[ERROR]-/ops-data/zp/haha/mysite-11/opsweb/resources/cron.py-[line:31]-服务器: 172.17.92.122 自动刷新失败,错误信息: ansible api 调用失败，请查看日志
2018-03-22 20:41:28,629-[ERROR]-/ops-data/zp/haha/mysite-11/opsweb/resources/server/__init__.py-[line:85]-("'ResultCallback' object has no attribute 'data'",)
2018-03-22 20:41:28,630-[ERROR]-/ops-data/zp/haha/mysite-11/opsweb/resources/cron.py-[line:31]-服务器: 172.17.92.123 自动刷新失败,错误信息: ansible api 调用失败，请查看日志
2018-03-22 20:45:03,086-[ERROR]-/ops-data/zp/haha/mysite-11/opsweb/resources/cron.py-[line:94]-该服务器: 172.17.134.86 实例名 mysql1 格式不正确
2018-03-22 20:45:03,302-[ERROR]-/ops-data/zp/haha/mysite-11/opsweb/resources/cron.py-[line:94]-该服务器: 172.17.134.24 实例名 webproxytoidc 格式不正确
2018-03-22 20:45:03,447-[ERROR]-/ops-data/zp/haha/mysite-11/opsweb/resources/cron.py-[line:94]-该服务器: 172.17.134.90 实例名 mysql3 格式不正确
2018-03-22 20:45:03,502-[ERROR]-/ops-data/zp/haha/mysite-11/opsweb/resources/cron.py-[line:94]-该服务器: 172.17.134.89 实例名 mysql2 格式不正确
2018-03-22 20:50:15,406-[ERROR]-/ops-data/zp/haha/mysite-11/opsweb/api/thirdapi/aliyun_describe_instance.py-[line:67]-HTTP Status: 403 Error:ChargeTypeViolation Pay-As-You-Go instances do not support this operation. RequestID: F22D11AD-AEAF-4BA3-98AD-8E359BD7E788
2018-03-22 20:50:48,522-[ERROR]-/ops-data/zp/haha/mysite-11/opsweb/resources/server/__init__.py-[line:85]-("'ResultCallback' object has no attribute 'data'",)
2018-03-22 20:50:48,522-[ERROR]-/ops-data/zp/haha/mysite-11/opsweb/resources/cron.py-[line:31]-服务器: 172.17.92.122 自动刷新失败,错误信息: ansible api 调用失败，请查看日志
2018-03-22 20:51:29,913-[ERROR]-/ops-data/zp/haha/mysite-11/opsweb/resources/server/__init__.py-[line:85]-("'ResultCallback' object has no attribute 'data'",)
2018-03-22 20:51:29,913-[ERROR]-/ops-data/zp/haha/mysite-11/opsweb/resources/cron.py-[line:31]-服务器: 172.17.92.123 自动刷新失败,错误信息: ansible api 调用失败，请查看日志
2018-03-22 21:00:04,729-[ERROR]-/ops-data/zp/haha/mysite-11/opsweb/resources/cron.py-[line:94]-该服务器: 172.17.134.86 实例名 mysql1 格式不正确
2018-03-22 21:00:05,043-[ERROR]-/ops-data/zp/haha/mysite-11/opsweb/resources/cron.py-[line:94]-该服务器: 172.17.134.24 实例名 webproxytoidc 格式不正确
2018-03-22 21:00:05,209-[ERROR]-/ops-data/zp/haha/mysite-11/opsweb/resources/cron.py-[line:94]-该服务器: 172.17.134.90 实例名 mysql3 格式不正确
2018-03-22 21:00:05,303-[ERROR]-/ops-data/zp/haha/mysite-11/opsweb/resources/cron.py-[line:94]-该服务器: 172.17.134.89 实例名 mysql2 格式不正确
2018-03-22 21:00:17,676-[ERROR]-/ops-data/zp/haha/mysite-11/opsweb/api/thirdapi/aliyun_describe_instance.py-[line:67]-HTTP Status: 403 Error:ChargeTypeViolation Pay-As-You-Go instances do not support this operation. RequestID: DC483DF2-514A-4A6B-B645-BE077BE4C99C
2018-03-22 21:00:49,428-[ERROR]-/ops-data/zp/haha/mysite-11/opsweb/resources/server/__init__.py-[line:85]-("'ResultCallback' object has no attribute 'data'",)
2018-03-22 21:00:49,429-[ERROR]-/ops-data/zp/haha/mysite-11/opsweb/resources/cron.py-[line:31]-服务器: 172.17.92.122 自动刷新失败,错误信息: ansible api 调用失败，请查看日志
2018-03-22 21:01:31,948-[ERROR]-/ops-data/zp/haha/mysite-11/opsweb/resources/server/__init__.py-[line:85]-("'ResultCallback' object has no attribute 'data'",)
2018-03-22 21:01:31,948-[ERROR]-/ops-data/zp/haha/mysite-11/opsweb/resources/cron.py-[line:31]-服务器: 172.17.92.123 自动刷新失败,错误信息: ansible api 调用失败，请查看日志
2018-03-22 21:10:15,382-[ERROR]-/ops-data/zp/haha/mysite-11/opsweb/api/thirdapi/aliyun_describe_instance.py-[line:67]-HTTP Status: 403 Error:ChargeTypeViolation Pay-As-You-Go instances do not support this operation. RequestID: F41D6A95-0CD8-4220-9AD8-7A38868F2BF7
2018-03-22 21:10:46,588-[ERROR]-/ops-data/zp/haha/mysite-11/opsweb/resources/server/__init__.py-[line:85]-("'ResultCallback' object has no attribute 'data'",)
2018-03-22 21:10:46,588-[ERROR]-/ops-data/zp/haha/mysite-11/opsweb/resources/cron.py-[line:31]-服务器: 172.17.92.122 自动刷新失败,错误信息: ansible api 调用失败，请查看日志
2018-03-22 21:11:26,617-[ERROR]-/ops-data/zp/haha/mysite-11/opsweb/resources/server/__init__.py-[line:85]-("'ResultCallback' object has no attribute 'data'",)
2018-03-22 21:11:26,617-[ERROR]-/ops-data/zp/haha/mysite-11/opsweb/resources/cron.py-[line:31]-服务器: 172.17.92.123 自动刷新失败,错误信息: ansible api 调用失败，请查看日志
2018-03-22 21:15:03,470-[ERROR]-/ops-data/zp/haha/mysite-11/opsweb/resources/cron.py-[line:94]-该服务器: 172.17.134.86 实例名 mysql1 格式不正确
2018-03-22 21:15:03,681-[ERROR]-/ops-data/zp/haha/mysite-11/opsweb/resources/cron.py-[line:94]-该服务器: 172.17.134.24 实例名 webproxytoidc 格式不正确
2018-03-22 21:15:03,820-[ERROR]-/ops-data/zp/haha/mysite-11/opsweb/resources/cron.py-[line:94]-该服务器: 172.17.134.90 实例名 mysql3 格式不正确
2018-03-22 21:15:03,874-[ERROR]-/ops-data/zp/haha/mysite-11/opsweb/resources/cron.py-[line:94]-该服务器: 172.17.134.89 实例名 mysql2 格式不正确
2018-03-22 21:20:15,045-[ERROR]-/ops-data/zp/haha/mysite-11/opsweb/api/thirdapi/aliyun_describe_instance.py-[line:67]-HTTP Status: 403 Error:ChargeTypeViolation Pay-As-You-Go instances do not support this operation. RequestID: B4C93914-6E99-4A19-8813-86F08C52343C
2018-03-22 21:20:47,291-[ERROR]-/ops-data/zp/haha/mysite-11/opsweb/resources/server/__init__.py-[line:85]-("'ResultCallback' object has no attribute 'data'",)
2018-03-22 21:20:47,291-[ERROR]-/ops-data/zp/haha/mysite-11/opsweb/resources/cron.py-[line:31]-服务器: 172.17.92.122 自动刷新失败,错误信息: ansible api 调用失败，请查看日志
2018-03-22 21:21:28,475-[ERROR]-/ops-data/zp/haha/mysite-11/opsweb/resources/server/__init__.py-[line:85]-("'ResultCallback' object has no attribute 'data'",)
2018-03-22 21:21:28,476-[ERROR]-/ops-data/zp/haha/mysite-11/opsweb/resources/cron.py-[line:31]-服务器: 172.17.92.123 自动刷新失败,错误信息: ansible api 调用失败，请查看日志
2018-03-22 21:30:03,911-[ERROR]-/ops-data/zp/haha/mysite-11/opsweb/resources/cron.py-[line:94]-该服务器: 172.17.134.86 实例名 mysql1 格式不正确
2018-03-22 21:30:04,132-[ERROR]-/ops-data/zp/haha/mysite-11/opsweb/resources/cron.py-[line:94]-该服务器: 172.17.134.24 实例名 webproxytoidc 格式不正确
2018-03-22 21:30:04,275-[ERROR]-/ops-data/zp/haha/mysite-11/opsweb/resources/cron.py-[line:94]-该服务器: 172.17.134.90 实例名 mysql3 格式不正确
2018-03-22 21:30:04,336-[ERROR]-/ops-data/zp/haha/mysite-11/opsweb/resources/cron.py-[line:94]-该服务器: 172.17.134.89 实例名 mysql2 格式不正确
2018-03-22 21:30:16,093-[ERROR]-/ops-data/zp/haha/mysite-11/opsweb/api/thirdapi/aliyun_describe_instance.py-[line:67]-HTTP Status: 403 Error:ChargeTypeViolation Pay-As-You-Go instances do not support this operation. RequestID: AA4053F4-EE5A-4BC7-9C9E-FED790647A8E
2018-03-22 21:30:48,227-[ERROR]-/ops-data/zp/haha/mysite-11/opsweb/resources/server/__init__.py-[line:85]-("'ResultCallback' object has no attribute 'data'",)
2018-03-22 21:30:48,228-[ERROR]-/ops-data/zp/haha/mysite-11/opsweb/resources/cron.py-[line:31]-服务器: 172.17.92.122 自动刷新失败,错误信息: ansible api 调用失败，请查看日志
2018-03-22 21:31:29,088-[ERROR]-/ops-data/zp/haha/mysite-11/opsweb/resources/server/__init__.py-[line:85]-("'ResultCallback' object has no attribute 'data'",)
2018-03-22 21:31:29,088-[ERROR]-/ops-data/zp/haha/mysite-11/opsweb/resources/cron.py-[line:31]-服务器: 172.17.92.123 自动刷新失败,错误信息: ansible api 调用失败，请查看日志
2018-03-22 21:40:15,172-[ERROR]-/ops-data/zp/haha/mysite-11/opsweb/api/thirdapi/aliyun_describe_instance.py-[line:67]-HTTP Status: 403 Error:ChargeTypeViolation Pay-As-You-Go instances do not support this operation. RequestID: 1C77E33F-07F9-4282-BD75-F5565E51DF60
2018-03-22 21:40:45,938-[ERROR]-/ops-data/zp/haha/mysite-11/opsweb/resources/server/__init__.py-[line:85]-("'ResultCallback' object has no attribute 'data'",)
2018-03-22 21:40:45,938-[ERROR]-/ops-data/zp/haha/mysite-11/opsweb/resources/cron.py-[line:31]-服务器: 172.17.92.122 自动刷新失败,错误信息: ansible api 调用失败，请查看日志
2018-03-22 21:41:30,533-[ERROR]-/ops-data/zp/haha/mysite-11/opsweb/resources/server/__init__.py-[line:85]-("'ResultCallback' object has no attribute 'data'",)
2018-03-22 21:41:30,533-[ERROR]-/ops-data/zp/haha/mysite-11/opsweb/resources/cron.py-[line:31]-服务器: 172.17.92.123 自动刷新失败,错误信息: ansible api 调用失败，请查看日志
2018-03-22 21:45:03,149-[ERROR]-/ops-data/zp/haha/mysite-11/opsweb/resources/cron.py-[line:94]-该服务器: 172.17.134.86 实例名 mysql1 格式不正确
2018-03-22 21:45:03,403-[ERROR]-/ops-data/zp/haha/mysite-11/opsweb/resources/cron.py-[line:94]-该服务器: 172.17.134.24 实例名 webproxytoidc 格式不正确
2018-03-22 21:45:03,561-[ERROR]-/ops-data/zp/haha/mysite-11/opsweb/resources/cron.py-[line:94]-该服务器: 172.17.134.90 实例名 mysql3 格式不正确
2018-03-22 21:45:03,629-[ERROR]-/ops-data/zp/haha/mysite-11/opsweb/resources/cron.py-[line:94]-该服务器: 172.17.134.89 实例名 mysql2 格式不正确
2018-03-22 21:50:14,661-[ERROR]-/ops-data/zp/haha/mysite-11/opsweb/api/thirdapi/aliyun_describe_instance.py-[line:67]-HTTP Status: 403 Error:ChargeTypeViolation Pay-As-You-Go instances do not support this operation. RequestID: CBDEEB33-FBEE-46DB-8115-D6F0B0EA0CF8
2018-03-22 21:50:47,592-[ERROR]-/ops-data/zp/haha/mysite-11/opsweb/resources/server/__init__.py-[line:85]-("'ResultCallback' object has no attribute 'data'",)
2018-03-22 21:50:47,592-[ERROR]-/ops-data/zp/haha/mysite-11/opsweb/resources/cron.py-[line:31]-服务器: 172.17.92.122 自动刷新失败,错误信息: ansible api 调用失败，请查看日志
2018-03-22 21:51:27,363-[ERROR]-/ops-data/zp/haha/mysite-11/opsweb/resources/server/__init__.py-[line:85]-("'ResultCallback' object has no attribute 'data'",)
2018-03-22 21:51:27,363-[ERROR]-/ops-data/zp/haha/mysite-11/opsweb/resources/cron.py-[line:31]-服务器: 172.17.92.123 自动刷新失败,错误信息: ansible api 调用失败，请查看日志
2018-03-22 22:00:04,522-[ERROR]-/ops-data/zp/haha/mysite-11/opsweb/resources/cron.py-[line:94]-该服务器: 172.17.134.86 实例名 mysql1 格式不正确
2018-03-22 22:00:04,783-[ERROR]-/ops-data/zp/haha/mysite-11/opsweb/resources/cron.py-[line:94]-该服务器: 172.17.134.24 实例名 webproxytoidc 格式不正确
2018-03-22 22:00:04,949-[ERROR]-/ops-data/zp/haha/mysite-11/opsweb/resources/cron.py-[line:94]-该服务器: 172.17.134.90 实例名 mysql3 格式不正确
2018-03-22 22:00:05,012-[ERROR]-/ops-data/zp/haha/mysite-11/opsweb/resources/cron.py-[line:94]-该服务器: 172.17.134.89 实例名 mysql2 格式不正确
2018-03-22 22:00:17,104-[ERROR]-/ops-data/zp/haha/mysite-11/opsweb/api/thirdapi/aliyun_describe_instance.py-[line:67]-HTTP Status: 403 Error:ChargeTypeViolation Pay-As-You-Go instances do not support this operation. RequestID: CC306A29-186F-4DF3-AA4A-8A64DD6D1F8C
2018-03-22 22:00:49,638-[ERROR]-/ops-data/zp/haha/mysite-11/opsweb/resources/server/__init__.py-[line:85]-("'ResultCallback' object has no attribute 'data'",)
2018-03-22 22:00:49,639-[ERROR]-/ops-data/zp/haha/mysite-11/opsweb/resources/cron.py-[line:31]-服务器: 172.17.92.122 自动刷新失败,错误信息: ansible api 调用失败，请查看日志
2018-03-22 22:01:30,256-[ERROR]-/ops-data/zp/haha/mysite-11/opsweb/resources/server/__init__.py-[line:85]-("'ResultCallback' object has no attribute 'data'",)
2018-03-22 22:01:30,256-[ERROR]-/ops-data/zp/haha/mysite-11/opsweb/resources/cron.py-[line:31]-服务器: 172.17.92.123 自动刷新失败,错误信息: ansible api 调用失败，请查看日志
2018-03-22 22:10:15,700-[ERROR]-/ops-data/zp/haha/mysite-11/opsweb/api/thirdapi/aliyun_describe_instance.py-[line:67]-HTTP Status: 403 Error:ChargeTypeViolation Pay-As-You-Go instances do not support this operation. RequestID: 393DDCAB-64C7-4435-A852-011E52FCEFC6
2018-03-22 22:10:47,777-[ERROR]-/ops-data/zp/haha/mysite-11/opsweb/resources/server/__init__.py-[line:85]-("'ResultCallback' object has no attribute 'data'",)
2018-03-22 22:10:47,777-[ERROR]-/ops-data/zp/haha/mysite-11/opsweb/resources/cron.py-[line:31]-服务器: 172.17.92.122 自动刷新失败,错误信息: ansible api 调用失败，请查看日志
2018-03-22 22:11:27,607-[ERROR]-/ops-data/zp/haha/mysite-11/opsweb/resources/server/__init__.py-[line:85]-("'ResultCallback' object has no attribute 'data'",)
2018-03-22 22:11:27,608-[ERROR]-/ops-data/zp/haha/mysite-11/opsweb/resources/cron.py-[line:31]-服务器: 172.17.92.123 自动刷新失败,错误信息: ansible api 调用失败，请查看日志
