2017-12-25 16:30:03,649-[ERROR]-/ops-data/zp/haha/mysite-11/opsweb/resources/server/__init__.py-[line:24]-("'ResultCallback' object has no attribute 'data'",)
2017-12-25 16:30:03,650-[ERROR]-/ops-data/zp/haha/mysite-11/opsweb/resources/cron.py-[line:27]-服务器: 172.17.134.104 自动刷新失败,错误信息: ansible api 调用失败，请查看日志
2017-12-25 16:30:33,262-[ERROR]-/ops-data/zp/haha/mysite-11/opsweb/resources/server/__init__.py-[line:24]-("'ResultCallback' object has no attribute 'data'",)
2017-12-25 16:30:33,262-[ERROR]-/ops-data/zp/haha/mysite-11/opsweb/resources/cron.py-[line:27]-服务器: 172.17.134.17 自动刷新失败,错误信息: ansible api 调用失败，请查看日志
2017-12-25 16:30:33,525-[ERROR]-/ops-data/zp/haha/mysite-11/opsweb/resources/server/__init__.py-[line:24]-("'ResultCallback' object has no attribute 'data'",)
2017-12-25 16:30:33,525-[ERROR]-/ops-data/zp/haha/mysite-11/opsweb/resources/cron.py-[line:27]-服务器: 172.17.134.19 自动刷新失败,错误信息: ansible api 调用失败，请查看日志
2017-12-25 16:30:33,793-[ERROR]-/ops-data/zp/haha/mysite-11/opsweb/resources/server/__init__.py-[line:24]-("'ResultCallback' object has no attribute 'data'",)
2017-12-25 16:30:33,793-[ERROR]-/ops-data/zp/haha/mysite-11/opsweb/resources/cron.py-[line:27]-服务器: 172.17.134.21 自动刷新失败,错误信息: ansible api 调用失败，请查看日志
2017-12-25 16:30:35,134-[ERROR]-/ops-data/zp/haha/mysite-11/opsweb/resources/server/__init__.py-[line:24]-("'ResultCallback' object has no attribute 'data'",)
2017-12-25 16:30:35,134-[ERROR]-/ops-data/zp/haha/mysite-11/opsweb/resources/cron.py-[line:27]-服务器: 172.17.134.23 自动刷新失败,错误信息: ansible api 调用失败，请查看日志
2017-12-25 16:30:35,398-[ERROR]-/ops-data/zp/haha/mysite-11/opsweb/resources/server/__init__.py-[line:24]-("'ResultCallback' object has no attribute 'data'",)
2017-12-25 16:30:35,399-[ERROR]-/ops-data/zp/haha/mysite-11/opsweb/resources/cron.py-[line:27]-服务器: 172.17.134.24 自动刷新失败,错误信息: ansible api 调用失败，请查看日志
2017-12-25 16:31:29,151-[ERROR]-/ops-data/zp/haha/mysite-11/opsweb/resources/server/__init__.py-[line:24]-("'ResultCallback' object has no attribute 'data'",)
2017-12-25 16:31:29,151-[ERROR]-/ops-data/zp/haha/mysite-11/opsweb/resources/cron.py-[line:27]-服务器: 172.17.92.122 自动刷新失败,错误信息: ansible api 调用失败，请查看日志
2017-12-25 16:31:39,389-[ERROR]-/ops-data/zp/haha/mysite-11/opsweb/resources/server/__init__.py-[line:24]-("'ResultCallback' object has no attribute 'data'",)
2017-12-25 16:31:39,390-[ERROR]-/ops-data/zp/haha/mysite-11/opsweb/resources/cron.py-[line:27]-服务器: 172.17.92.123 自动刷新失败,错误信息: ansible api 调用失败，请查看日志
2017-12-25 23:08:02,705-[ERROR]-/ops-data/zp/haha/mysite-11/opsweb/resources/cron.py-[line:84]-统计 2017-12-25 的应用总数失败,错误信息: (1062, "Duplicate entry '2017-12-25' for key 'myday'")
