2017-12-21 11:17:38,618-[ERROR]-/ops-data/zp/haha/mysite-11/opsweb/resources/cmdb/__init__.py-[line:15]-CmdbModel 不存在 ID: None 的对象
2017-12-21 16:30:03,242-[ERROR]-/ops-data/zp/haha/mysite-11/opsweb/resources/server/__init__.py-[line:23]-("'ResultCallback' object has no attribute 'data'",)
2017-12-21 16:30:03,242-[ERROR]-/ops-data/zp/haha/mysite-11/opsweb/resources/cron.py-[line:27]-服务器: 172.17.134.104 自动刷新失败,错误信息: ansible api 调用失败，请查看日志
2017-12-21 16:30:06,850-[ERROR]-/ops-data/zp/haha/mysite-11/opsweb/resources/server/__init__.py-[line:23]-("'ResultCallback' object has no attribute 'data'",)
2017-12-21 16:30:06,850-[ERROR]-/ops-data/zp/haha/mysite-11/opsweb/resources/cron.py-[line:27]-服务器: 172.17.134.17 自动刷新失败,错误信息: ansible api 调用失败，请查看日志
2017-12-21 16:30:07,111-[ERROR]-/ops-data/zp/haha/mysite-11/opsweb/resources/server/__init__.py-[line:23]-("'ResultCallback' object has no attribute 'data'",)
2017-12-21 16:30:07,111-[ERROR]-/ops-data/zp/haha/mysite-11/opsweb/resources/cron.py-[line:27]-服务器: 172.17.134.19 自动刷新失败,错误信息: ansible api 调用失败，请查看日志
2017-12-21 16:30:07,436-[ERROR]-/ops-data/zp/haha/mysite-11/opsweb/resources/server/__init__.py-[line:23]-("'ResultCallback' object has no attribute 'data'",)
2017-12-21 16:30:07,436-[ERROR]-/ops-data/zp/haha/mysite-11/opsweb/resources/cron.py-[line:27]-服务器: 172.17.134.21 自动刷新失败,错误信息: ansible api 调用失败，请查看日志
2017-12-21 16:30:08,878-[ERROR]-/ops-data/zp/haha/mysite-11/opsweb/resources/server/__init__.py-[line:23]-("'ResultCallback' object has no attribute 'data'",)
2017-12-21 16:30:08,879-[ERROR]-/ops-data/zp/haha/mysite-11/opsweb/resources/cron.py-[line:27]-服务器: 172.17.134.23 自动刷新失败,错误信息: ansible api 调用失败，请查看日志
2017-12-21 16:30:09,183-[ERROR]-/ops-data/zp/haha/mysite-11/opsweb/resources/server/__init__.py-[line:23]-("'ResultCallback' object has no attribute 'data'",)
2017-12-21 16:30:09,183-[ERROR]-/ops-data/zp/haha/mysite-11/opsweb/resources/cron.py-[line:27]-服务器: 172.17.134.24 自动刷新失败,错误信息: ansible api 调用失败，请查看日志
2017-12-21 16:30:56,281-[ERROR]-/ops-data/zp/haha/mysite-11/opsweb/resources/server/__init__.py-[line:23]-("'ResultCallback' object has no attribute 'data'",)
2017-12-21 16:30:56,282-[ERROR]-/ops-data/zp/haha/mysite-11/opsweb/resources/cron.py-[line:27]-服务器: 172.17.134.86 自动刷新失败,错误信息: ansible api 调用失败，请查看日志
2017-12-21 16:31:02,655-[ERROR]-/ops-data/zp/haha/mysite-11/opsweb/resources/server/__init__.py-[line:23]-("'ResultCallback' object has no attribute 'data'",)
2017-12-21 16:31:02,656-[ERROR]-/ops-data/zp/haha/mysite-11/opsweb/resources/cron.py-[line:27]-服务器: 172.17.92.122 自动刷新失败,错误信息: ansible api 调用失败，请查看日志
2017-12-21 16:31:12,872-[ERROR]-/ops-data/zp/haha/mysite-11/opsweb/resources/server/__init__.py-[line:23]-("'ResultCallback' object has no attribute 'data'",)
2017-12-21 16:31:12,873-[ERROR]-/ops-data/zp/haha/mysite-11/opsweb/resources/cron.py-[line:27]-服务器: 172.17.92.123 自动刷新失败,错误信息: ansible api 调用失败，请查看日志
2017-12-21 17:27:59,828-[ERROR]-/ops-data/zp/haha/mysite-11/opsweb/resources/server/__init__.py-[line:23]-("'ResultCallback' object has no attribute 'data'",)
2017-12-21 17:28:05,997-[ERROR]-/ops-data/zp/haha/mysite-11/opsweb/resources/server/__init__.py-[line:23]-("'ResultCallback' object has no attribute 'data'",)
