2017-12-20 12:14:32,921-[ERROR]-/ops-data/zp/haha/mysite-11/opsweb/resources/server/__init__.py-[line:23]-("'ResultCallback' object has no attribute 'data'",)
2017-12-20 12:16:22,156-[ERROR]-/ops-data/zp/haha/mysite-11/opsweb/resources/server/__init__.py-[line:23]-("'ResultCallback' object has no attribute 'data'",)
2017-12-20 12:16:34,607-[ERROR]-/ops-data/zp/haha/mysite-11/opsweb/resources/server/__init__.py-[line:23]-("'ResultCallback' object has no attribute 'data'",)
2017-12-20 16:30:03,342-[ERROR]-/ops-data/zp/haha/mysite-11/opsweb/resources/server/__init__.py-[line:23]-("'ResultCallback' object has no attribute 'data'",)
2017-12-20 16:30:03,342-[ERROR]-/ops-data/zp/haha/mysite-11/opsweb/resources/cron.py-[line:27]-服务器: 172.17.134.104 自动刷新失败,错误信息: ansible api 调用失败，请查看日志
2017-12-20 16:30:06,092-[ERROR]-/ops-data/zp/haha/mysite-11/opsweb/resources/server/__init__.py-[line:23]-("'ResultCallback' object has no attribute 'data'",)
2017-12-20 16:30:06,093-[ERROR]-/ops-data/zp/haha/mysite-11/opsweb/resources/cron.py-[line:27]-服务器: 172.17.134.17 自动刷新失败,错误信息: ansible api 调用失败，请查看日志
2017-12-20 16:30:06,381-[ERROR]-/ops-data/zp/haha/mysite-11/opsweb/resources/server/__init__.py-[line:23]-("'ResultCallback' object has no attribute 'data'",)
2017-12-20 16:30:06,381-[ERROR]-/ops-data/zp/haha/mysite-11/opsweb/resources/cron.py-[line:27]-服务器: 172.17.134.19 自动刷新失败,错误信息: ansible api 调用失败，请查看日志
2017-12-20 16:30:06,722-[ERROR]-/ops-data/zp/haha/mysite-11/opsweb/resources/server/__init__.py-[line:23]-("'ResultCallback' object has no attribute 'data'",)
2017-12-20 16:30:06,723-[ERROR]-/ops-data/zp/haha/mysite-11/opsweb/resources/cron.py-[line:27]-服务器: 172.17.134.21 自动刷新失败,错误信息: ansible api 调用失败，请查看日志
2017-12-20 16:30:08,845-[ERROR]-/ops-data/zp/haha/mysite-11/opsweb/resources/server/__init__.py-[line:23]-("'ResultCallback' object has no attribute 'data'",)
2017-12-20 16:30:08,846-[ERROR]-/ops-data/zp/haha/mysite-11/opsweb/resources/cron.py-[line:27]-服务器: 172.17.134.23 自动刷新失败,错误信息: ansible api 调用失败，请查看日志
2017-12-20 16:30:09,150-[ERROR]-/ops-data/zp/haha/mysite-11/opsweb/resources/server/__init__.py-[line:23]-("'ResultCallback' object has no attribute 'data'",)
2017-12-20 16:30:09,150-[ERROR]-/ops-data/zp/haha/mysite-11/opsweb/resources/cron.py-[line:27]-服务器: 172.17.134.24 自动刷新失败,错误信息: ansible api 调用失败，请查看日志
2017-12-20 16:30:53,574-[ERROR]-/ops-data/zp/haha/mysite-11/opsweb/resources/server/__init__.py-[line:23]-("'ResultCallback' object has no attribute 'data'",)
2017-12-20 16:30:53,574-[ERROR]-/ops-data/zp/haha/mysite-11/opsweb/resources/cron.py-[line:27]-服务器: 172.17.134.86 自动刷新失败,错误信息: ansible api 调用失败，请查看日志
2017-12-20 16:31:00,174-[ERROR]-/ops-data/zp/haha/mysite-11/opsweb/resources/server/__init__.py-[line:23]-("'ResultCallback' object has no attribute 'data'",)
2017-12-20 16:31:00,174-[ERROR]-/ops-data/zp/haha/mysite-11/opsweb/resources/cron.py-[line:27]-服务器: 172.17.92.122 自动刷新失败,错误信息: ansible api 调用失败，请查看日志
2017-12-20 16:31:10,424-[ERROR]-/ops-data/zp/haha/mysite-11/opsweb/resources/server/__init__.py-[line:23]-("'ResultCallback' object has no attribute 'data'",)
2017-12-20 16:31:10,424-[ERROR]-/ops-data/zp/haha/mysite-11/opsweb/resources/cron.py-[line:27]-服务器: 172.17.92.123 自动刷新失败,错误信息: ansible api 调用失败，请查看日志
2017-12-20 22:44:12,017-[ERROR]-/ops-data/zp/haha/mysite-11/opsweb/resources/cmdb/__init__.py-[line:88]-CmdbModel 不存在 ID: None 的对象
2017-12-20 22:44:26,859-[ERROR]-/ops-data/zp/haha/mysite-11/opsweb/resources/cmdb/__init__.py-[line:88]-CmdbModel 不存在 ID: None 的对象
