2018-04-11 17:01:50,132-[ERROR]-/ops-data/zp/haha/mysite-11/opsweb/resources/server/__init__.py-[line:470]-服务器 10.82.40.82 在 zabbix 中不存在
2018-04-11 17:01:50,146-[ERROR]-/ops-data/zp/haha/mysite-11/opsweb/resources/server/__init__.py-[line:470]-服务器 10.82.40.77 在 zabbix 中不存在
2018-04-11 17:01:50,165-[ERROR]-/ops-data/zp/haha/mysite-11/opsweb/resources/server/__init__.py-[line:470]-服务器 10.82.40.81 在 zabbix 中不存在
2018-04-11 17:01:50,184-[ERROR]-/ops-data/zp/haha/mysite-11/opsweb/resources/server/__init__.py-[line:470]-服务器 10.82.40.76 在 zabbix 中不存在
2018-04-11 17:01:50,189-[ERROR]-/ops-data/zp/haha/mysite-11/opsweb/resources/server/__init__.py-[line:470]-服务器 10.82.40.75 在 zabbix 中不存在
2018-04-11 17:01:50,194-[ERROR]-/ops-data/zp/haha/mysite-11/opsweb/resources/server/__init__.py-[line:470]-服务器 10.82.40.79 在 zabbix 中不存在
2018-04-11 17:02:00,526-[ERROR]-/ops-data/zp/haha/mysite-11/opsweb/resources/server/__init__.py-[line:470]-服务器 10.82.40.82 在 zabbix 中不存在
2018-04-11 17:02:00,545-[ERROR]-/ops-data/zp/haha/mysite-11/opsweb/resources/server/__init__.py-[line:470]-服务器 10.82.40.77 在 zabbix 中不存在
2018-04-11 17:02:00,569-[ERROR]-/ops-data/zp/haha/mysite-11/opsweb/resources/server/__init__.py-[line:470]-服务器 10.82.40.81 在 zabbix 中不存在
2018-04-11 17:02:00,592-[ERROR]-/ops-data/zp/haha/mysite-11/opsweb/resources/server/__init__.py-[line:470]-服务器 10.82.40.76 在 zabbix 中不存在
2018-04-11 17:02:00,598-[ERROR]-/ops-data/zp/haha/mysite-11/opsweb/resources/server/__init__.py-[line:470]-服务器 10.82.40.75 在 zabbix 中不存在
2018-04-11 17:02:00,603-[ERROR]-/ops-data/zp/haha/mysite-11/opsweb/resources/server/__init__.py-[line:470]-服务器 10.82.40.79 在 zabbix 中不存在
2018-04-11 17:09:31,373-[ERROR]-/ops-data/zp/haha/mysite-11/opsweb/resources/server/__init__.py-[line:474]-服务器 10.82.40.82 在 zabbix 中不存在
2018-04-11 17:09:31,394-[ERROR]-/ops-data/zp/haha/mysite-11/opsweb/resources/server/__init__.py-[line:474]-服务器 10.82.40.77 在 zabbix 中不存在
2018-04-11 17:09:31,422-[ERROR]-/ops-data/zp/haha/mysite-11/opsweb/resources/server/__init__.py-[line:474]-服务器 10.82.40.81 在 zabbix 中不存在
2018-04-11 17:09:31,450-[ERROR]-/ops-data/zp/haha/mysite-11/opsweb/resources/server/__init__.py-[line:474]-服务器 10.82.40.76 在 zabbix 中不存在
2018-04-11 17:09:31,456-[ERROR]-/ops-data/zp/haha/mysite-11/opsweb/resources/server/__init__.py-[line:474]-服务器 10.82.40.75 在 zabbix 中不存在
2018-04-11 17:09:31,463-[ERROR]-/ops-data/zp/haha/mysite-11/opsweb/resources/server/__init__.py-[line:474]-服务器 10.82.40.79 在 zabbix 中不存在
2018-04-11 17:09:35,905-[ERROR]-/ops-data/zp/haha/mysite-11/opsweb/resources/server/__init__.py-[line:474]-服务器 10.82.40.82 在 zabbix 中不存在
2018-04-11 17:09:35,922-[ERROR]-/ops-data/zp/haha/mysite-11/opsweb/resources/server/__init__.py-[line:474]-服务器 10.82.40.77 在 zabbix 中不存在
2018-04-11 17:09:35,944-[ERROR]-/ops-data/zp/haha/mysite-11/opsweb/resources/server/__init__.py-[line:474]-服务器 10.82.40.81 在 zabbix 中不存在
2018-04-11 17:09:35,966-[ERROR]-/ops-data/zp/haha/mysite-11/opsweb/resources/server/__init__.py-[line:474]-服务器 10.82.40.76 在 zabbix 中不存在
2018-04-11 17:09:35,972-[ERROR]-/ops-data/zp/haha/mysite-11/opsweb/resources/server/__init__.py-[line:474]-服务器 10.82.40.75 在 zabbix 中不存在
2018-04-11 17:09:35,978-[ERROR]-/ops-data/zp/haha/mysite-11/opsweb/resources/server/__init__.py-[line:474]-服务器 10.82.40.79 在 zabbix 中不存在
2018-04-11 17:09:36,984-[ERROR]-/ops-data/zp/haha/mysite-11/opsweb/resources/server/__init__.py-[line:474]-服务器 10.82.40.82 在 zabbix 中不存在
2018-04-11 17:09:36,998-[ERROR]-/ops-data/zp/haha/mysite-11/opsweb/resources/server/__init__.py-[line:474]-服务器 10.82.40.77 在 zabbix 中不存在
2018-04-11 17:09:37,017-[ERROR]-/ops-data/zp/haha/mysite-11/opsweb/resources/server/__init__.py-[line:474]-服务器 10.82.40.81 在 zabbix 中不存在
2018-04-11 17:09:37,035-[ERROR]-/ops-data/zp/haha/mysite-11/opsweb/resources/server/__init__.py-[line:474]-服务器 10.82.40.76 在 zabbix 中不存在
2018-04-11 17:09:37,040-[ERROR]-/ops-data/zp/haha/mysite-11/opsweb/resources/server/__init__.py-[line:474]-服务器 10.82.40.75 在 zabbix 中不存在
2018-04-11 17:09:37,045-[ERROR]-/ops-data/zp/haha/mysite-11/opsweb/resources/server/__init__.py-[line:474]-服务器 10.82.40.79 在 zabbix 中不存在
2018-04-11 17:09:42,751-[ERROR]-/ops-data/zp/haha/mysite-11/opsweb/resources/server/__init__.py-[line:474]-服务器 10.82.40.82 在 zabbix 中不存在
2018-04-11 17:09:42,767-[ERROR]-/ops-data/zp/haha/mysite-11/opsweb/resources/server/__init__.py-[line:474]-服务器 10.82.40.77 在 zabbix 中不存在
2018-04-11 17:09:42,795-[ERROR]-/ops-data/zp/haha/mysite-11/opsweb/resources/server/__init__.py-[line:474]-服务器 10.82.40.81 在 zabbix 中不存在
2018-04-11 17:09:42,818-[ERROR]-/ops-data/zp/haha/mysite-11/opsweb/resources/server/__init__.py-[line:474]-服务器 10.82.40.76 在 zabbix 中不存在
2018-04-11 17:09:42,823-[ERROR]-/ops-data/zp/haha/mysite-11/opsweb/resources/server/__init__.py-[line:474]-服务器 10.82.40.75 在 zabbix 中不存在
2018-04-11 17:09:42,827-[ERROR]-/ops-data/zp/haha/mysite-11/opsweb/resources/server/__init__.py-[line:474]-服务器 10.82.40.79 在 zabbix 中不存在
2018-04-11 17:10:04,176-[ERROR]-/ops-data/zp/haha/mysite-11/opsweb/api/thirdapi/aliyun_describe_instance.py-[line:67]-HTTP Status: 400 Error:InvalidParameter The instance Id 'i-2zednvbin1s1aicwimg2' does not exist. RequestID: D035FE4D-2B97-4761-93EA-E1F717D33038
2018-04-11 17:10:04,176-[ERROR]-/ops-data/zp/haha/mysite-11/opsweb/resources/cron.py-[line:33]-服务器: 172.17.134.172 自动刷新失败,错误信息: aliyun api 获取续费状态失败，请查看日志
2018-04-11 17:10:09,866-[ERROR]-/ops-data/zp/haha/mysite-11/opsweb/api/thirdapi/aliyun_describe_instance.py-[line:67]-HTTP Status: 400 Error:InvalidParameter The instance Id 'i-2ze2kvdczytchwve66h4' does not exist. RequestID: 045CAB66-E1C2-4A9D-BDE5-BB29F2DDEE6C
2018-04-11 17:10:09,866-[ERROR]-/ops-data/zp/haha/mysite-11/opsweb/resources/cron.py-[line:33]-服务器: 172.17.134.50 自动刷新失败,错误信息: aliyun api 获取续费状态失败，请查看日志
2018-04-11 17:10:41,191-[ERROR]-/ops-data/zp/haha/mysite-11/opsweb/resources/server/__init__.py-[line:89]-("'ResultCallback' object has no attribute 'data'",)
2018-04-11 17:10:41,191-[ERROR]-/ops-data/zp/haha/mysite-11/opsweb/resources/cron.py-[line:33]-服务器: 172.17.92.122 自动刷新失败,错误信息: ansible api 调用失败，请查看日志
2018-04-11 17:11:13,733-[ERROR]-/ops-data/zp/haha/mysite-11/opsweb/resources/server/__init__.py-[line:89]-("'ResultCallback' object has no attribute 'data'",)
2018-04-11 17:11:13,733-[ERROR]-/ops-data/zp/haha/mysite-11/opsweb/resources/cron.py-[line:33]-服务器: 172.17.92.123 自动刷新失败,错误信息: ansible api 调用失败，请查看日志
2018-04-11 17:13:19,012-[ERROR]-/ops-data/zp/haha/mysite-11/opsweb/resources/server/__init__.py-[line:474]-服务器 10.82.40.82 在 zabbix 中不存在
2018-04-11 17:13:19,026-[ERROR]-/ops-data/zp/haha/mysite-11/opsweb/resources/server/__init__.py-[line:474]-服务器 10.82.40.77 在 zabbix 中不存在
2018-04-11 17:13:19,045-[ERROR]-/ops-data/zp/haha/mysite-11/opsweb/resources/server/__init__.py-[line:474]-服务器 10.82.40.81 在 zabbix 中不存在
2018-04-11 17:13:19,063-[ERROR]-/ops-data/zp/haha/mysite-11/opsweb/resources/server/__init__.py-[line:474]-服务器 10.82.40.76 在 zabbix 中不存在
2018-04-11 17:13:19,068-[ERROR]-/ops-data/zp/haha/mysite-11/opsweb/resources/server/__init__.py-[line:474]-服务器 10.82.40.75 在 zabbix 中不存在
2018-04-11 17:13:19,073-[ERROR]-/ops-data/zp/haha/mysite-11/opsweb/resources/server/__init__.py-[line:474]-服务器 10.82.40.79 在 zabbix 中不存在
2018-04-11 17:13:26,643-[ERROR]-/ops-data/zp/haha/mysite-11/opsweb/resources/server/__init__.py-[line:474]-服务器 10.82.40.82 在 zabbix 中不存在
2018-04-11 17:13:26,658-[ERROR]-/ops-data/zp/haha/mysite-11/opsweb/resources/server/__init__.py-[line:474]-服务器 10.82.40.77 在 zabbix 中不存在
2018-04-11 17:13:26,675-[ERROR]-/ops-data/zp/haha/mysite-11/opsweb/resources/server/__init__.py-[line:474]-服务器 10.82.40.81 在 zabbix 中不存在
2018-04-11 17:13:26,694-[ERROR]-/ops-data/zp/haha/mysite-11/opsweb/resources/server/__init__.py-[line:474]-服务器 10.82.40.76 在 zabbix 中不存在
2018-04-11 17:13:26,699-[ERROR]-/ops-data/zp/haha/mysite-11/opsweb/resources/server/__init__.py-[line:474]-服务器 10.82.40.75 在 zabbix 中不存在
2018-04-11 17:13:26,704-[ERROR]-/ops-data/zp/haha/mysite-11/opsweb/resources/server/__init__.py-[line:474]-服务器 10.82.40.79 在 zabbix 中不存在
2018-04-11 17:13:59,358-[ERROR]-/ops-data/zp/haha/mysite-11/opsweb/resources/server/__init__.py-[line:474]-服务器 10.82.40.82 在 zabbix 中不存在
2018-04-11 17:13:59,372-[ERROR]-/ops-data/zp/haha/mysite-11/opsweb/resources/server/__init__.py-[line:474]-服务器 10.82.40.77 在 zabbix 中不存在
2018-04-11 17:13:59,390-[ERROR]-/ops-data/zp/haha/mysite-11/opsweb/resources/server/__init__.py-[line:474]-服务器 10.82.40.81 在 zabbix 中不存在
2018-04-11 17:13:59,410-[ERROR]-/ops-data/zp/haha/mysite-11/opsweb/resources/server/__init__.py-[line:474]-服务器 10.82.40.76 在 zabbix 中不存在
2018-04-11 17:13:59,415-[ERROR]-/ops-data/zp/haha/mysite-11/opsweb/resources/server/__init__.py-[line:474]-服务器 10.82.40.75 在 zabbix 中不存在
2018-04-11 17:13:59,420-[ERROR]-/ops-data/zp/haha/mysite-11/opsweb/resources/server/__init__.py-[line:474]-服务器 10.82.40.79 在 zabbix 中不存在
2018-04-11 17:14:43,458-[ERROR]-/ops-data/zp/haha/mysite-11/opsweb/resources/server/__init__.py-[line:474]-服务器 10.82.40.82 在 zabbix 中不存在
2018-04-11 17:14:43,473-[ERROR]-/ops-data/zp/haha/mysite-11/opsweb/resources/server/__init__.py-[line:474]-服务器 10.82.40.77 在 zabbix 中不存在
2018-04-11 17:14:43,492-[ERROR]-/ops-data/zp/haha/mysite-11/opsweb/resources/server/__init__.py-[line:474]-服务器 10.82.40.81 在 zabbix 中不存在
2018-04-11 17:14:43,511-[ERROR]-/ops-data/zp/haha/mysite-11/opsweb/resources/server/__init__.py-[line:474]-服务器 10.82.40.76 在 zabbix 中不存在
2018-04-11 17:14:43,516-[ERROR]-/ops-data/zp/haha/mysite-11/opsweb/resources/server/__init__.py-[line:474]-服务器 10.82.40.75 在 zabbix 中不存在
2018-04-11 17:14:43,520-[ERROR]-/ops-data/zp/haha/mysite-11/opsweb/resources/server/__init__.py-[line:474]-服务器 10.82.40.79 在 zabbix 中不存在
2018-04-11 17:20:42,189-[ERROR]-/ops-data/zp/haha/mysite-11/opsweb/resources/server/__init__.py-[line:89]-("'ResultCallback' object has no attribute 'data'",)
2018-04-11 17:20:42,190-[ERROR]-/ops-data/zp/haha/mysite-11/opsweb/resources/cron.py-[line:33]-服务器: 172.17.92.122 自动刷新失败,错误信息: ansible api 调用失败，请查看日志
2018-04-11 17:21:16,241-[ERROR]-/ops-data/zp/haha/mysite-11/opsweb/resources/server/__init__.py-[line:89]-("'ResultCallback' object has no attribute 'data'",)
2018-04-11 17:21:16,242-[ERROR]-/ops-data/zp/haha/mysite-11/opsweb/resources/cron.py-[line:33]-服务器: 172.17.92.123 自动刷新失败,错误信息: ansible api 调用失败，请查看日志
2018-04-11 17:30:48,790-[ERROR]-/ops-data/zp/haha/mysite-11/opsweb/resources/server/__init__.py-[line:89]-("'ResultCallback' object has no attribute 'data'",)
2018-04-11 17:30:48,791-[ERROR]-/ops-data/zp/haha/mysite-11/opsweb/resources/cron.py-[line:33]-服务器: 172.17.92.122 自动刷新失败,错误信息: ansible api 调用失败，请查看日志
2018-04-11 17:31:24,949-[ERROR]-/ops-data/zp/haha/mysite-11/opsweb/resources/server/__init__.py-[line:89]-("'ResultCallback' object has no attribute 'data'",)
2018-04-11 17:31:24,949-[ERROR]-/ops-data/zp/haha/mysite-11/opsweb/resources/cron.py-[line:33]-服务器: 172.17.92.123 自动刷新失败,错误信息: ansible api 调用失败，请查看日志
2018-04-11 17:40:40,477-[ERROR]-/ops-data/zp/haha/mysite-11/opsweb/resources/server/__init__.py-[line:89]-("'ResultCallback' object has no attribute 'data'",)
2018-04-11 17:40:40,477-[ERROR]-/ops-data/zp/haha/mysite-11/opsweb/resources/cron.py-[line:33]-服务器: 172.17.92.122 自动刷新失败,错误信息: ansible api 调用失败，请查看日志
2018-04-11 17:41:14,182-[ERROR]-/ops-data/zp/haha/mysite-11/opsweb/resources/server/__init__.py-[line:89]-("'ResultCallback' object has no attribute 'data'",)
2018-04-11 17:41:14,183-[ERROR]-/ops-data/zp/haha/mysite-11/opsweb/resources/cron.py-[line:33]-服务器: 172.17.92.123 自动刷新失败,错误信息: ansible api 调用失败，请查看日志
2018-04-11 17:50:41,215-[ERROR]-/ops-data/zp/haha/mysite-11/opsweb/resources/server/__init__.py-[line:89]-("'ResultCallback' object has no attribute 'data'",)
2018-04-11 17:50:41,215-[ERROR]-/ops-data/zp/haha/mysite-11/opsweb/resources/cron.py-[line:33]-服务器: 172.17.92.122 自动刷新失败,错误信息: ansible api 调用失败，请查看日志
2018-04-11 17:51:13,764-[ERROR]-/ops-data/zp/haha/mysite-11/opsweb/resources/server/__init__.py-[line:89]-("'ResultCallback' object has no attribute 'data'",)
2018-04-11 17:51:13,765-[ERROR]-/ops-data/zp/haha/mysite-11/opsweb/resources/cron.py-[line:33]-服务器: 172.17.92.123 自动刷新失败,错误信息: ansible api 调用失败，请查看日志
2018-04-11 18:00:45,062-[ERROR]-/ops-data/zp/haha/mysite-11/opsweb/resources/server/__init__.py-[line:89]-("'ResultCallback' object has no attribute 'data'",)
2018-04-11 18:00:45,062-[ERROR]-/ops-data/zp/haha/mysite-11/opsweb/resources/cron.py-[line:33]-服务器: 172.17.92.122 自动刷新失败,错误信息: ansible api 调用失败，请查看日志
2018-04-11 18:01:19,655-[ERROR]-/ops-data/zp/haha/mysite-11/opsweb/resources/server/__init__.py-[line:89]-("'ResultCallback' object has no attribute 'data'",)
2018-04-11 18:01:19,655-[ERROR]-/ops-data/zp/haha/mysite-11/opsweb/resources/cron.py-[line:33]-服务器: 172.17.92.123 自动刷新失败,错误信息: ansible api 调用失败，请查看日志
2018-04-11 18:10:44,604-[ERROR]-/ops-data/zp/haha/mysite-11/opsweb/resources/server/__init__.py-[line:89]-("'ResultCallback' object has no attribute 'data'",)
2018-04-11 18:10:44,605-[ERROR]-/ops-data/zp/haha/mysite-11/opsweb/resources/cron.py-[line:33]-服务器: 172.17.92.122 自动刷新失败,错误信息: ansible api 调用失败，请查看日志
2018-04-11 18:11:20,028-[ERROR]-/ops-data/zp/haha/mysite-11/opsweb/resources/server/__init__.py-[line:89]-("'ResultCallback' object has no attribute 'data'",)
2018-04-11 18:11:20,028-[ERROR]-/ops-data/zp/haha/mysite-11/opsweb/resources/cron.py-[line:33]-服务器: 172.17.92.123 自动刷新失败,错误信息: ansible api 调用失败，请查看日志
2018-04-11 18:20:43,401-[ERROR]-/ops-data/zp/haha/mysite-11/opsweb/resources/server/__init__.py-[line:89]-("'ResultCallback' object has no attribute 'data'",)
2018-04-11 18:20:43,401-[ERROR]-/ops-data/zp/haha/mysite-11/opsweb/resources/cron.py-[line:33]-服务器: 172.17.92.122 自动刷新失败,错误信息: ansible api 调用失败，请查看日志
2018-04-11 18:21:19,383-[ERROR]-/ops-data/zp/haha/mysite-11/opsweb/resources/server/__init__.py-[line:89]-("'ResultCallback' object has no attribute 'data'",)
2018-04-11 18:21:19,384-[ERROR]-/ops-data/zp/haha/mysite-11/opsweb/resources/cron.py-[line:33]-服务器: 172.17.92.123 自动刷新失败,错误信息: ansible api 调用失败，请查看日志
2018-04-11 18:30:41,399-[ERROR]-/ops-data/zp/haha/mysite-11/opsweb/resources/server/__init__.py-[line:89]-("'ResultCallback' object has no attribute 'data'",)
2018-04-11 18:30:41,399-[ERROR]-/ops-data/zp/haha/mysite-11/opsweb/resources/cron.py-[line:33]-服务器: 172.17.92.122 自动刷新失败,错误信息: ansible api 调用失败，请查看日志
2018-04-11 18:31:17,277-[ERROR]-/ops-data/zp/haha/mysite-11/opsweb/resources/server/__init__.py-[line:89]-("'ResultCallback' object has no attribute 'data'",)
2018-04-11 18:31:17,277-[ERROR]-/ops-data/zp/haha/mysite-11/opsweb/resources/cron.py-[line:33]-服务器: 172.17.92.123 自动刷新失败,错误信息: ansible api 调用失败，请查看日志
2018-04-11 18:40:40,867-[ERROR]-/ops-data/zp/haha/mysite-11/opsweb/resources/server/__init__.py-[line:89]-("'ResultCallback' object has no attribute 'data'",)
2018-04-11 18:40:40,868-[ERROR]-/ops-data/zp/haha/mysite-11/opsweb/resources/cron.py-[line:33]-服务器: 172.17.92.122 自动刷新失败,错误信息: ansible api 调用失败，请查看日志
2018-04-11 18:41:14,577-[ERROR]-/ops-data/zp/haha/mysite-11/opsweb/resources/server/__init__.py-[line:89]-("'ResultCallback' object has no attribute 'data'",)
2018-04-11 18:41:14,577-[ERROR]-/ops-data/zp/haha/mysite-11/opsweb/resources/cron.py-[line:33]-服务器: 172.17.92.123 自动刷新失败,错误信息: ansible api 调用失败，请查看日志
2018-04-11 18:50:45,170-[ERROR]-/ops-data/zp/haha/mysite-11/opsweb/resources/server/__init__.py-[line:89]-("'ResultCallback' object has no attribute 'data'",)
2018-04-11 18:50:45,171-[ERROR]-/ops-data/zp/haha/mysite-11/opsweb/resources/cron.py-[line:33]-服务器: 172.17.92.122 自动刷新失败,错误信息: ansible api 调用失败，请查看日志
2018-04-11 18:51:17,771-[ERROR]-/ops-data/zp/haha/mysite-11/opsweb/resources/server/__init__.py-[line:89]-("'ResultCallback' object has no attribute 'data'",)
2018-04-11 18:51:17,771-[ERROR]-/ops-data/zp/haha/mysite-11/opsweb/resources/cron.py-[line:33]-服务器: 172.17.92.123 自动刷新失败,错误信息: ansible api 调用失败，请查看日志
2018-04-11 19:00:44,677-[ERROR]-/ops-data/zp/haha/mysite-11/opsweb/resources/server/__init__.py-[line:89]-("'ResultCallback' object has no attribute 'data'",)
2018-04-11 19:00:44,678-[ERROR]-/ops-data/zp/haha/mysite-11/opsweb/resources/cron.py-[line:33]-服务器: 172.17.92.122 自动刷新失败,错误信息: ansible api 调用失败，请查看日志
2018-04-11 19:01:20,825-[ERROR]-/ops-data/zp/haha/mysite-11/opsweb/resources/server/__init__.py-[line:89]-("'ResultCallback' object has no attribute 'data'",)
2018-04-11 19:01:20,826-[ERROR]-/ops-data/zp/haha/mysite-11/opsweb/resources/cron.py-[line:33]-服务器: 172.17.92.123 自动刷新失败,错误信息: ansible api 调用失败，请查看日志
2018-04-11 19:10:41,311-[ERROR]-/ops-data/zp/haha/mysite-11/opsweb/resources/server/__init__.py-[line:89]-("'ResultCallback' object has no attribute 'data'",)
2018-04-11 19:10:41,312-[ERROR]-/ops-data/zp/haha/mysite-11/opsweb/resources/cron.py-[line:33]-服务器: 172.17.92.122 自动刷新失败,错误信息: ansible api 调用失败，请查看日志
2018-04-11 19:11:14,513-[ERROR]-/ops-data/zp/haha/mysite-11/opsweb/resources/server/__init__.py-[line:89]-("'ResultCallback' object has no attribute 'data'",)
2018-04-11 19:11:14,513-[ERROR]-/ops-data/zp/haha/mysite-11/opsweb/resources/cron.py-[line:33]-服务器: 172.17.92.123 自动刷新失败,错误信息: ansible api 调用失败，请查看日志
2018-04-11 19:20:41,043-[ERROR]-/ops-data/zp/haha/mysite-11/opsweb/resources/server/__init__.py-[line:89]-("'ResultCallback' object has no attribute 'data'",)
2018-04-11 19:20:41,044-[ERROR]-/ops-data/zp/haha/mysite-11/opsweb/resources/cron.py-[line:33]-服务器: 172.17.92.122 自动刷新失败,错误信息: ansible api 调用失败，请查看日志
2018-04-11 19:21:13,661-[ERROR]-/ops-data/zp/haha/mysite-11/opsweb/resources/server/__init__.py-[line:89]-("'ResultCallback' object has no attribute 'data'",)
2018-04-11 19:21:13,662-[ERROR]-/ops-data/zp/haha/mysite-11/opsweb/resources/cron.py-[line:33]-服务器: 172.17.92.123 自动刷新失败,错误信息: ansible api 调用失败，请查看日志
2018-04-11 19:30:42,756-[ERROR]-/ops-data/zp/haha/mysite-11/opsweb/resources/server/__init__.py-[line:89]-("'ResultCallback' object has no attribute 'data'",)
2018-04-11 19:30:42,757-[ERROR]-/ops-data/zp/haha/mysite-11/opsweb/resources/cron.py-[line:33]-服务器: 172.17.92.122 自动刷新失败,错误信息: ansible api 调用失败，请查看日志
2018-04-11 19:31:15,899-[ERROR]-/ops-data/zp/haha/mysite-11/opsweb/resources/server/__init__.py-[line:89]-("'ResultCallback' object has no attribute 'data'",)
2018-04-11 19:31:15,899-[ERROR]-/ops-data/zp/haha/mysite-11/opsweb/resources/cron.py-[line:33]-服务器: 172.17.92.123 自动刷新失败,错误信息: ansible api 调用失败，请查看日志
2018-04-11 19:40:40,801-[ERROR]-/ops-data/zp/haha/mysite-11/opsweb/resources/server/__init__.py-[line:89]-("'ResultCallback' object has no attribute 'data'",)
2018-04-11 19:40:40,802-[ERROR]-/ops-data/zp/haha/mysite-11/opsweb/resources/cron.py-[line:33]-服务器: 172.17.92.122 自动刷新失败,错误信息: ansible api 调用失败，请查看日志
2018-04-11 19:41:15,419-[ERROR]-/ops-data/zp/haha/mysite-11/opsweb/resources/server/__init__.py-[line:89]-("'ResultCallback' object has no attribute 'data'",)
2018-04-11 19:41:15,419-[ERROR]-/ops-data/zp/haha/mysite-11/opsweb/resources/cron.py-[line:33]-服务器: 172.17.92.123 自动刷新失败,错误信息: ansible api 调用失败，请查看日志
2018-04-11 19:50:41,753-[ERROR]-/ops-data/zp/haha/mysite-11/opsweb/resources/server/__init__.py-[line:89]-("'ResultCallback' object has no attribute 'data'",)
2018-04-11 19:50:41,754-[ERROR]-/ops-data/zp/haha/mysite-11/opsweb/resources/cron.py-[line:33]-服务器: 172.17.92.122 自动刷新失败,错误信息: ansible api 调用失败，请查看日志
2018-04-11 19:51:15,696-[ERROR]-/ops-data/zp/haha/mysite-11/opsweb/resources/server/__init__.py-[line:89]-("'ResultCallback' object has no attribute 'data'",)
2018-04-11 19:51:15,697-[ERROR]-/ops-data/zp/haha/mysite-11/opsweb/resources/cron.py-[line:33]-服务器: 172.17.92.123 自动刷新失败,错误信息: ansible api 调用失败，请查看日志
2018-04-11 20:00:45,141-[ERROR]-/ops-data/zp/haha/mysite-11/opsweb/resources/server/__init__.py-[line:89]-("'ResultCallback' object has no attribute 'data'",)
2018-04-11 20:00:45,141-[ERROR]-/ops-data/zp/haha/mysite-11/opsweb/resources/cron.py-[line:33]-服务器: 172.17.92.122 自动刷新失败,错误信息: ansible api 调用失败，请查看日志
2018-04-11 20:01:21,015-[ERROR]-/ops-data/zp/haha/mysite-11/opsweb/resources/server/__init__.py-[line:89]-("'ResultCallback' object has no attribute 'data'",)
2018-04-11 20:01:21,016-[ERROR]-/ops-data/zp/haha/mysite-11/opsweb/resources/cron.py-[line:33]-服务器: 172.17.92.123 自动刷新失败,错误信息: ansible api 调用失败，请查看日志
2018-04-11 20:10:43,527-[ERROR]-/ops-data/zp/haha/mysite-11/opsweb/resources/server/__init__.py-[line:89]-("'ResultCallback' object has no attribute 'data'",)
2018-04-11 20:10:43,528-[ERROR]-/ops-data/zp/haha/mysite-11/opsweb/resources/cron.py-[line:33]-服务器: 172.17.92.122 自动刷新失败,错误信息: ansible api 调用失败，请查看日志
2018-04-11 20:11:16,178-[ERROR]-/ops-data/zp/haha/mysite-11/opsweb/resources/server/__init__.py-[line:89]-("'ResultCallback' object has no attribute 'data'",)
2018-04-11 20:11:16,178-[ERROR]-/ops-data/zp/haha/mysite-11/opsweb/resources/cron.py-[line:33]-服务器: 172.17.92.123 自动刷新失败,错误信息: ansible api 调用失败，请查看日志
2018-04-11 20:20:43,283-[ERROR]-/ops-data/zp/haha/mysite-11/opsweb/resources/server/__init__.py-[line:89]-("'ResultCallback' object has no attribute 'data'",)
2018-04-11 20:20:43,283-[ERROR]-/ops-data/zp/haha/mysite-11/opsweb/resources/cron.py-[line:33]-服务器: 172.17.92.122 自动刷新失败,错误信息: ansible api 调用失败，请查看日志
2018-04-11 20:21:15,700-[ERROR]-/ops-data/zp/haha/mysite-11/opsweb/resources/server/__init__.py-[line:89]-("'ResultCallback' object has no attribute 'data'",)
2018-04-11 20:21:15,701-[ERROR]-/ops-data/zp/haha/mysite-11/opsweb/resources/cron.py-[line:33]-服务器: 172.17.92.123 自动刷新失败,错误信息: ansible api 调用失败，请查看日志
2018-04-11 20:30:43,640-[ERROR]-/ops-data/zp/haha/mysite-11/opsweb/resources/server/__init__.py-[line:89]-("'ResultCallback' object has no attribute 'data'",)
2018-04-11 20:30:43,641-[ERROR]-/ops-data/zp/haha/mysite-11/opsweb/resources/cron.py-[line:33]-服务器: 172.17.92.122 自动刷新失败,错误信息: ansible api 调用失败，请查看日志
2018-04-11 20:31:16,253-[ERROR]-/ops-data/zp/haha/mysite-11/opsweb/resources/server/__init__.py-[line:89]-("'ResultCallback' object has no attribute 'data'",)
2018-04-11 20:31:16,254-[ERROR]-/ops-data/zp/haha/mysite-11/opsweb/resources/cron.py-[line:33]-服务器: 172.17.92.123 自动刷新失败,错误信息: ansible api 调用失败，请查看日志
2018-04-11 20:40:40,969-[ERROR]-/ops-data/zp/haha/mysite-11/opsweb/resources/server/__init__.py-[line:89]-("'ResultCallback' object has no attribute 'data'",)
2018-04-11 20:40:40,970-[ERROR]-/ops-data/zp/haha/mysite-11/opsweb/resources/cron.py-[line:33]-服务器: 172.17.92.122 自动刷新失败,错误信息: ansible api 调用失败，请查看日志
2018-04-11 20:41:14,454-[ERROR]-/ops-data/zp/haha/mysite-11/opsweb/resources/server/__init__.py-[line:89]-("'ResultCallback' object has no attribute 'data'",)
2018-04-11 20:41:14,455-[ERROR]-/ops-data/zp/haha/mysite-11/opsweb/resources/cron.py-[line:33]-服务器: 172.17.92.123 自动刷新失败,错误信息: ansible api 调用失败，请查看日志
