[2018-03-01 23:04:58 +0800] [28692] [ERROR] Error handling request /accounts/user/info/
Traceback (most recent call last):
  File "/ops-data/zp/haha/mysite-11/lib/python3.6/site-packages/django/template/utils.py", line 65, in __getitem__
    return self._engines[alias]
KeyError: 'django'

During handling of the above exception, another exception occurred:

Traceback (most recent call last):
  File "/ops-data/zp/haha/mysite-11/lib/python3.6/site-packages/django/core/handlers/exception.py", line 41, in inner
    response = get_response(request)
  File "/ops-data/zp/haha/mysite-11/lib/python3.6/site-packages/django/core/handlers/base.py", line 249, in _legacy_get_response
    response = self._get_response(request)
  File "/ops-data/zp/haha/mysite-11/lib/python3.6/site-packages/django/core/handlers/base.py", line 217, in _get_response
    response = self.process_exception_by_middleware(e, request)
  File "/ops-data/zp/haha/mysite-11/lib/python3.6/site-packages/django/core/handlers/base.py", line 215, in _get_response
    response = response.render()
  File "/ops-data/zp/haha/mysite-11/lib/python3.6/site-packages/django/template/response.py", line 107, in render
    self.content = self.rendered_content
  File "/ops-data/zp/haha/mysite-11/lib/python3.6/site-packages/django/template/response.py", line 82, in rendered_content
    template = self.resolve_template(self.template_name)
  File "/ops-data/zp/haha/mysite-11/lib/python3.6/site-packages/django/template/response.py", line 64, in resolve_template
    return select_template(template, using=self.using)
  File "/ops-data/zp/haha/mysite-11/lib/python3.6/site-packages/django/template/loader.py", line 44, in select_template
    engines = _engine_list(using)
  File "/ops-data/zp/haha/mysite-11/lib/python3.6/site-packages/django/template/loader.py", line 72, in _engine_list
    return engines.all() if using is None else [engines[using]]
  File "/ops-data/zp/haha/mysite-11/lib/python3.6/site-packages/django/template/utils.py", line 89, in all
    return [self[alias] for alias in self]
  File "/ops-data/zp/haha/mysite-11/lib/python3.6/site-packages/django/template/utils.py", line 89, in <listcomp>
    return [self[alias] for alias in self]
  File "/ops-data/zp/haha/mysite-11/lib/python3.6/site-packages/django/template/utils.py", line 80, in __getitem__
    engine = engine_cls(params)
  File "/ops-data/zp/haha/mysite-11/lib/python3.6/site-packages/django/template/backends/django.py", line 32, in __init__
    self.engine = Engine(self.dirs, self.app_dirs, **options)
  File "/ops-data/zp/haha/mysite-11/lib/python3.6/site-packages/django/template/engine.py", line 35, in __init__
    "app_dirs must not be set when loaders is defined.")
django.core.exceptions.ImproperlyConfigured: app_dirs must not be set when loaders is defined.

During handling of the above exception, another exception occurred:

Traceback (most recent call last):
  File "/ops-data/zp/haha/mysite-11/lib/python3.6/site-packages/django/template/utils.py", line 65, in __getitem__
    return self._engines[alias]
KeyError: 'django'

During handling of the above exception, another exception occurred:

Traceback (most recent call last):
  File "/ops-data/zp/haha/mysite-11/lib/python3.6/site-packages/gunicorn/workers/sync.py", line 135, in handle
    self.handle_request(listener, req, client, addr)
  File "/ops-data/zp/haha/mysite-11/lib/python3.6/site-packages/gunicorn/workers/sync.py", line 176, in handle_request
    respiter = self.wsgi(environ, resp.start_response)
  File "/ops-data/zp/haha/mysite-11/lib/python3.6/site-packages/django/core/handlers/wsgi.py", line 157, in __call__
    response = self.get_response(request)
  File "/ops-data/zp/haha/mysite-11/lib/python3.6/site-packages/django/core/handlers/base.py", line 124, in get_response
    response = self._middleware_chain(request)
  File "/ops-data/zp/haha/mysite-11/lib/python3.6/site-packages/django/core/handlers/exception.py", line 43, in inner
    response = response_for_exception(request, exc)
  File "/ops-data/zp/haha/mysite-11/lib/python3.6/site-packages/django/core/handlers/exception.py", line 93, in response_for_exception
    response = handle_uncaught_exception(request, get_resolver(get_urlconf()), sys.exc_info())
  File "/ops-data/zp/haha/mysite-11/lib/python3.6/site-packages/django/core/handlers/exception.py", line 143, in handle_uncaught_exception
    return callback(request, **param_dict)
  File "/ops-data/zp/haha/mysite-11/lib/python3.6/site-packages/django/utils/decorators.py", line 149, in _wrapped_view
    response = view_func(request, *args, **kwargs)
  File "/ops-data/zp/haha/mysite-11/lib/python3.6/site-packages/django/views/defaults.py", line 68, in server_error
    template = loader.get_template(template_name)
  File "/ops-data/zp/haha/mysite-11/lib/python3.6/site-packages/django/template/loader.py", line 18, in get_template
    engines = _engine_list(using)
  File "/ops-data/zp/haha/mysite-11/lib/python3.6/site-packages/django/template/loader.py", line 72, in _engine_list
    return engines.all() if using is None else [engines[using]]
  File "/ops-data/zp/haha/mysite-11/lib/python3.6/site-packages/django/template/utils.py", line 89, in all
    return [self[alias] for alias in self]
  File "/ops-data/zp/haha/mysite-11/lib/python3.6/site-packages/django/template/utils.py", line 89, in <listcomp>
    return [self[alias] for alias in self]
  File "/ops-data/zp/haha/mysite-11/lib/python3.6/site-packages/django/template/utils.py", line 80, in __getitem__
    engine = engine_cls(params)
  File "/ops-data/zp/haha/mysite-11/lib/python3.6/site-packages/django/template/backends/django.py", line 32, in __init__
    self.engine = Engine(self.dirs, self.app_dirs, **options)
  File "/ops-data/zp/haha/mysite-11/lib/python3.6/site-packages/django/template/engine.py", line 35, in __init__
    "app_dirs must not be set when loaders is defined.")
django.core.exceptions.ImproperlyConfigured: app_dirs must not be set when loaders is defined.
[2018-03-06 15:21:32 +0800] [11083] [ERROR] Error handling request /workform/my/list/
Traceback (most recent call last):
  File "/ops-data/zp/haha/mysite-11/lib/python3.6/site-packages/django/core/handlers/exception.py", line 41, in inner
    response = get_response(request)
  File "/ops-data/zp/haha/mysite-11/lib/python3.6/site-packages/django/core/handlers/base.py", line 249, in _legacy_get_response
    response = self._get_response(request)
  File "/ops-data/zp/haha/mysite-11/lib/python3.6/site-packages/django/core/handlers/base.py", line 172, in _get_response
    resolver_match = resolver.resolve(request.path_info)
  File "/ops-data/zp/haha/mysite-11/lib/python3.6/site-packages/django/urls/resolvers.py", line 362, in resolve
    for pattern in self.url_patterns:
  File "/ops-data/zp/haha/mysite-11/lib/python3.6/site-packages/django/utils/functional.py", line 35, in __get__
    res = instance.__dict__[self.name] = self.func(instance)
  File "/ops-data/zp/haha/mysite-11/lib/python3.6/site-packages/django/urls/resolvers.py", line 405, in url_patterns
    patterns = getattr(self.urlconf_module, "urlpatterns", self.urlconf_module)
  File "/ops-data/zp/haha/mysite-11/lib/python3.6/site-packages/django/utils/functional.py", line 35, in __get__
    res = instance.__dict__[self.name] = self.func(instance)
  File "/ops-data/zp/haha/mysite-11/lib/python3.6/site-packages/django/urls/resolvers.py", line 398, in urlconf_module
    return import_module(self.urlconf_name)
  File "/ops-data/zp/haha/mysite-11/lib/python3.6/importlib/__init__.py", line 126, in import_module
    return _bootstrap._gcd_import(name[level:], package, level)
  File "<frozen importlib._bootstrap>", line 994, in _gcd_import
  File "<frozen importlib._bootstrap>", line 971, in _find_and_load
  File "<frozen importlib._bootstrap>", line 955, in _find_and_load_unlocked
  File "<frozen importlib._bootstrap>", line 665, in _load_unlocked
  File "<frozen importlib._bootstrap_external>", line 678, in exec_module
  File "<frozen importlib._bootstrap>", line 219, in _call_with_frames_removed
  File "/ops-data/zp/haha/mysite-11/opsweb/opsweb/urls.py", line 29, in <module>
    url(r'^resources/', include("resources.urls")),
  File "/ops-data/zp/haha/mysite-11/lib/python3.6/site-packages/django/conf/urls/__init__.py", line 50, in include
    urlconf_module = import_module(urlconf_module)
  File "/ops-data/zp/haha/mysite-11/lib/python3.6/importlib/__init__.py", line 126, in import_module
    return _bootstrap._gcd_import(name[level:], package, level)
  File "<frozen importlib._bootstrap>", line 994, in _gcd_import
  File "<frozen importlib._bootstrap>", line 971, in _find_and_load
  File "<frozen importlib._bootstrap>", line 955, in _find_and_load_unlocked
  File "<frozen importlib._bootstrap>", line 665, in _load_unlocked
  File "<frozen importlib._bootstrap_external>", line 678, in exec_module
  File "<frozen importlib._bootstrap>", line 219, in _call_with_frames_removed
  File "/ops-data/zp/haha/mysite-11/opsweb/resources/urls.py", line 4, in <module>
    from . import views,server,idc,cmdb
  File "/ops-data/zp/haha/mysite-11/opsweb/resources/server/__init__.py", line 12, in <module>
    from dashboard.utils.utc_to_local import utc_to_local,utc_to_local_T
ImportError: cannot import name 'utc_to_local_T'

During handling of the above exception, another exception occurred:

Traceback (most recent call last):
  File "/ops-data/zp/haha/mysite-11/lib/python3.6/site-packages/gunicorn/workers/sync.py", line 135, in handle
    self.handle_request(listener, req, client, addr)
  File "/ops-data/zp/haha/mysite-11/lib/python3.6/site-packages/gunicorn/workers/sync.py", line 176, in handle_request
    respiter = self.wsgi(environ, resp.start_response)
  File "/ops-data/zp/haha/mysite-11/lib/python3.6/site-packages/django/core/handlers/wsgi.py", line 157, in __call__
    response = self.get_response(request)
  File "/ops-data/zp/haha/mysite-11/lib/python3.6/site-packages/django/core/handlers/base.py", line 124, in get_response
    response = self._middleware_chain(request)
  File "/ops-data/zp/haha/mysite-11/lib/python3.6/site-packages/django/core/handlers/exception.py", line 43, in inner
    response = response_for_exception(request, exc)
  File "/ops-data/zp/haha/mysite-11/lib/python3.6/site-packages/django/core/handlers/exception.py", line 93, in response_for_exception
    response = handle_uncaught_exception(request, get_resolver(get_urlconf()), sys.exc_info())
  File "/ops-data/zp/haha/mysite-11/lib/python3.6/site-packages/django/core/handlers/exception.py", line 142, in handle_uncaught_exception
    callback, param_dict = resolver.resolve_error_handler(500)
  File "/ops-data/zp/haha/mysite-11/lib/python3.6/site-packages/django/urls/resolvers.py", line 418, in resolve_error_handler
    callback = getattr(self.urlconf_module, 'handler%s' % view_type, None)
  File "/ops-data/zp/haha/mysite-11/lib/python3.6/site-packages/django/utils/functional.py", line 35, in __get__
    res = instance.__dict__[self.name] = self.func(instance)
  File "/ops-data/zp/haha/mysite-11/lib/python3.6/site-packages/django/urls/resolvers.py", line 398, in urlconf_module
    return import_module(self.urlconf_name)
  File "/ops-data/zp/haha/mysite-11/lib/python3.6/importlib/__init__.py", line 126, in import_module
    return _bootstrap._gcd_import(name[level:], package, level)
  File "<frozen importlib._bootstrap>", line 994, in _gcd_import
  File "<frozen importlib._bootstrap>", line 971, in _find_and_load
  File "<frozen importlib._bootstrap>", line 955, in _find_and_load_unlocked
  File "<frozen importlib._bootstrap>", line 665, in _load_unlocked
  File "<frozen importlib._bootstrap_external>", line 678, in exec_module
  File "<frozen importlib._bootstrap>", line 219, in _call_with_frames_removed
  File "/ops-data/zp/haha/mysite-11/opsweb/opsweb/urls.py", line 29, in <module>
    url(r'^resources/', include("resources.urls")),
  File "/ops-data/zp/haha/mysite-11/lib/python3.6/site-packages/django/conf/urls/__init__.py", line 50, in include
    urlconf_module = import_module(urlconf_module)
  File "/ops-data/zp/haha/mysite-11/lib/python3.6/importlib/__init__.py", line 126, in import_module
    return _bootstrap._gcd_import(name[level:], package, level)
  File "<frozen importlib._bootstrap>", line 994, in _gcd_import
  File "<frozen importlib._bootstrap>", line 971, in _find_and_load
  File "<frozen importlib._bootstrap>", line 955, in _find_and_load_unlocked
  File "<frozen importlib._bootstrap>", line 665, in _load_unlocked
  File "<frozen importlib._bootstrap_external>", line 678, in exec_module
  File "<frozen importlib._bootstrap>", line 219, in _call_with_frames_removed
  File "/ops-data/zp/haha/mysite-11/opsweb/resources/urls.py", line 4, in <module>
    from . import views,server,idc,cmdb
  File "/ops-data/zp/haha/mysite-11/opsweb/resources/server/__init__.py", line 12, in <module>
    from dashboard.utils.utc_to_local import utc_to_local,utc_to_local_T
ImportError: cannot import name 'utc_to_local_T'
[2018-03-06 15:21:38 +0800] [11085] [ERROR] Error handling request /workform/my/list/
Traceback (most recent call last):
  File "/ops-data/zp/haha/mysite-11/lib/python3.6/site-packages/django/core/handlers/exception.py", line 41, in inner
    response = get_response(request)
  File "/ops-data/zp/haha/mysite-11/lib/python3.6/site-packages/django/core/handlers/base.py", line 249, in _legacy_get_response
    response = self._get_response(request)
  File "/ops-data/zp/haha/mysite-11/lib/python3.6/site-packages/django/core/handlers/base.py", line 172, in _get_response
    resolver_match = resolver.resolve(request.path_info)
  File "/ops-data/zp/haha/mysite-11/lib/python3.6/site-packages/django/urls/resolvers.py", line 362, in resolve
    for pattern in self.url_patterns:
  File "/ops-data/zp/haha/mysite-11/lib/python3.6/site-packages/django/utils/functional.py", line 35, in __get__
    res = instance.__dict__[self.name] = self.func(instance)
  File "/ops-data/zp/haha/mysite-11/lib/python3.6/site-packages/django/urls/resolvers.py", line 405, in url_patterns
    patterns = getattr(self.urlconf_module, "urlpatterns", self.urlconf_module)
  File "/ops-data/zp/haha/mysite-11/lib/python3.6/site-packages/django/utils/functional.py", line 35, in __get__
    res = instance.__dict__[self.name] = self.func(instance)
  File "/ops-data/zp/haha/mysite-11/lib/python3.6/site-packages/django/urls/resolvers.py", line 398, in urlconf_module
    return import_module(self.urlconf_name)
  File "/ops-data/zp/haha/mysite-11/lib/python3.6/importlib/__init__.py", line 126, in import_module
    return _bootstrap._gcd_import(name[level:], package, level)
  File "<frozen importlib._bootstrap>", line 994, in _gcd_import
  File "<frozen importlib._bootstrap>", line 971, in _find_and_load
  File "<frozen importlib._bootstrap>", line 955, in _find_and_load_unlocked
  File "<frozen importlib._bootstrap>", line 665, in _load_unlocked
  File "<frozen importlib._bootstrap_external>", line 678, in exec_module
  File "<frozen importlib._bootstrap>", line 219, in _call_with_frames_removed
  File "/ops-data/zp/haha/mysite-11/opsweb/opsweb/urls.py", line 29, in <module>
    url(r'^resources/', include("resources.urls")),
  File "/ops-data/zp/haha/mysite-11/lib/python3.6/site-packages/django/conf/urls/__init__.py", line 50, in include
    urlconf_module = import_module(urlconf_module)
  File "/ops-data/zp/haha/mysite-11/lib/python3.6/importlib/__init__.py", line 126, in import_module
    return _bootstrap._gcd_import(name[level:], package, level)
  File "<frozen importlib._bootstrap>", line 994, in _gcd_import
  File "<frozen importlib._bootstrap>", line 971, in _find_and_load
  File "<frozen importlib._bootstrap>", line 955, in _find_and_load_unlocked
  File "<frozen importlib._bootstrap>", line 665, in _load_unlocked
  File "<frozen importlib._bootstrap_external>", line 678, in exec_module
  File "<frozen importlib._bootstrap>", line 219, in _call_with_frames_removed
  File "/ops-data/zp/haha/mysite-11/opsweb/resources/urls.py", line 4, in <module>
    from . import views,server,idc,cmdb
  File "/ops-data/zp/haha/mysite-11/opsweb/resources/server/__init__.py", line 12, in <module>
    from dashboard.utils.utc_to_local import utc_to_local,utc_to_local_T
ImportError: cannot import name 'utc_to_local_T'

During handling of the above exception, another exception occurred:

Traceback (most recent call last):
  File "/ops-data/zp/haha/mysite-11/lib/python3.6/site-packages/gunicorn/workers/sync.py", line 135, in handle
    self.handle_request(listener, req, client, addr)
  File "/ops-data/zp/haha/mysite-11/lib/python3.6/site-packages/gunicorn/workers/sync.py", line 176, in handle_request
    respiter = self.wsgi(environ, resp.start_response)
  File "/ops-data/zp/haha/mysite-11/lib/python3.6/site-packages/django/core/handlers/wsgi.py", line 157, in __call__
    response = self.get_response(request)
  File "/ops-data/zp/haha/mysite-11/lib/python3.6/site-packages/django/core/handlers/base.py", line 124, in get_response
    response = self._middleware_chain(request)
  File "/ops-data/zp/haha/mysite-11/lib/python3.6/site-packages/django/core/handlers/exception.py", line 43, in inner
    response = response_for_exception(request, exc)
  File "/ops-data/zp/haha/mysite-11/lib/python3.6/site-packages/django/core/handlers/exception.py", line 93, in response_for_exception
    response = handle_uncaught_exception(request, get_resolver(get_urlconf()), sys.exc_info())
  File "/ops-data/zp/haha/mysite-11/lib/python3.6/site-packages/django/core/handlers/exception.py", line 142, in handle_uncaught_exception
    callback, param_dict = resolver.resolve_error_handler(500)
  File "/ops-data/zp/haha/mysite-11/lib/python3.6/site-packages/django/urls/resolvers.py", line 418, in resolve_error_handler
    callback = getattr(self.urlconf_module, 'handler%s' % view_type, None)
  File "/ops-data/zp/haha/mysite-11/lib/python3.6/site-packages/django/utils/functional.py", line 35, in __get__
    res = instance.__dict__[self.name] = self.func(instance)
  File "/ops-data/zp/haha/mysite-11/lib/python3.6/site-packages/django/urls/resolvers.py", line 398, in urlconf_module
    return import_module(self.urlconf_name)
  File "/ops-data/zp/haha/mysite-11/lib/python3.6/importlib/__init__.py", line 126, in import_module
    return _bootstrap._gcd_import(name[level:], package, level)
  File "<frozen importlib._bootstrap>", line 994, in _gcd_import
  File "<frozen importlib._bootstrap>", line 971, in _find_and_load
  File "<frozen importlib._bootstrap>", line 955, in _find_and_load_unlocked
  File "<frozen importlib._bootstrap>", line 665, in _load_unlocked
  File "<frozen importlib._bootstrap_external>", line 678, in exec_module
  File "<frozen importlib._bootstrap>", line 219, in _call_with_frames_removed
  File "/ops-data/zp/haha/mysite-11/opsweb/opsweb/urls.py", line 29, in <module>
    url(r'^resources/', include("resources.urls")),
  File "/ops-data/zp/haha/mysite-11/lib/python3.6/site-packages/django/conf/urls/__init__.py", line 50, in include
    urlconf_module = import_module(urlconf_module)
  File "/ops-data/zp/haha/mysite-11/lib/python3.6/importlib/__init__.py", line 126, in import_module
    return _bootstrap._gcd_import(name[level:], package, level)
  File "<frozen importlib._bootstrap>", line 994, in _gcd_import
  File "<frozen importlib._bootstrap>", line 971, in _find_and_load
  File "<frozen importlib._bootstrap>", line 955, in _find_and_load_unlocked
  File "<frozen importlib._bootstrap>", line 665, in _load_unlocked
  File "<frozen importlib._bootstrap_external>", line 678, in exec_module
  File "<frozen importlib._bootstrap>", line 219, in _call_with_frames_removed
  File "/ops-data/zp/haha/mysite-11/opsweb/resources/urls.py", line 4, in <module>
    from . import views,server,idc,cmdb
  File "/ops-data/zp/haha/mysite-11/opsweb/resources/server/__init__.py", line 12, in <module>
    from dashboard.utils.utc_to_local import utc_to_local,utc_to_local_T
ImportError: cannot import name 'utc_to_local_T'
[2018-03-22 14:44:11 +0800] [17971] [ERROR] Error handling request /resources/cmdb/list/
Traceback (most recent call last):
  File "/ops-data/zp/haha/mysite-11/lib/python3.6/site-packages/django/core/handlers/exception.py", line 41, in inner
    response = get_response(request)
  File "/ops-data/zp/haha/mysite-11/lib/python3.6/site-packages/django/core/handlers/base.py", line 249, in _legacy_get_response
    response = self._get_response(request)
  File "/ops-data/zp/haha/mysite-11/lib/python3.6/site-packages/django/core/handlers/base.py", line 172, in _get_response
    resolver_match = resolver.resolve(request.path_info)
  File "/ops-data/zp/haha/mysite-11/lib/python3.6/site-packages/django/urls/resolvers.py", line 362, in resolve
    for pattern in self.url_patterns:
  File "/ops-data/zp/haha/mysite-11/lib/python3.6/site-packages/django/utils/functional.py", line 35, in __get__
    res = instance.__dict__[self.name] = self.func(instance)
  File "/ops-data/zp/haha/mysite-11/lib/python3.6/site-packages/django/urls/resolvers.py", line 405, in url_patterns
    patterns = getattr(self.urlconf_module, "urlpatterns", self.urlconf_module)
  File "/ops-data/zp/haha/mysite-11/lib/python3.6/site-packages/django/utils/functional.py", line 35, in __get__
    res = instance.__dict__[self.name] = self.func(instance)
  File "/ops-data/zp/haha/mysite-11/lib/python3.6/site-packages/django/urls/resolvers.py", line 398, in urlconf_module
    return import_module(self.urlconf_name)
  File "/ops-data/zp/haha/mysite-11/lib/python3.6/importlib/__init__.py", line 126, in import_module
    return _bootstrap._gcd_import(name[level:], package, level)
  File "<frozen importlib._bootstrap>", line 994, in _gcd_import
  File "<frozen importlib._bootstrap>", line 971, in _find_and_load
  File "<frozen importlib._bootstrap>", line 955, in _find_and_load_unlocked
  File "<frozen importlib._bootstrap>", line 665, in _load_unlocked
  File "<frozen importlib._bootstrap_external>", line 678, in exec_module
  File "<frozen importlib._bootstrap>", line 219, in _call_with_frames_removed
  File "/ops-data/zp/haha/mysite-11/opsweb/opsweb/urls.py", line 27, in <module>
    url(r'^accounts/', include("accounts.urls")),
  File "/ops-data/zp/haha/mysite-11/lib/python3.6/site-packages/django/conf/urls/__init__.py", line 50, in include
    urlconf_module = import_module(urlconf_module)
  File "/ops-data/zp/haha/mysite-11/lib/python3.6/importlib/__init__.py", line 126, in import_module
    return _bootstrap._gcd_import(name[level:], package, level)
  File "<frozen importlib._bootstrap>", line 994, in _gcd_import
  File "<frozen importlib._bootstrap>", line 971, in _find_and_load
  File "<frozen importlib._bootstrap>", line 955, in _find_and_load_unlocked
  File "<frozen importlib._bootstrap>", line 665, in _load_unlocked
  File "<frozen importlib._bootstrap_external>", line 678, in exec_module
  File "<frozen importlib._bootstrap>", line 219, in _call_with_frames_removed
  File "/ops-data/zp/haha/mysite-11/opsweb/accounts/urls.py", line 20, in <module>
    from . import views,user,group,permission,api
ImportError: cannot import name 'api'

During handling of the above exception, another exception occurred:

Traceback (most recent call last):
  File "/ops-data/zp/haha/mysite-11/lib/python3.6/site-packages/gunicorn/workers/sync.py", line 135, in handle
    self.handle_request(listener, req, client, addr)
  File "/ops-data/zp/haha/mysite-11/lib/python3.6/site-packages/gunicorn/workers/sync.py", line 176, in handle_request
    respiter = self.wsgi(environ, resp.start_response)
  File "/ops-data/zp/haha/mysite-11/lib/python3.6/site-packages/django/core/handlers/wsgi.py", line 157, in __call__
    response = self.get_response(request)
  File "/ops-data/zp/haha/mysite-11/lib/python3.6/site-packages/django/core/handlers/base.py", line 124, in get_response
    response = self._middleware_chain(request)
  File "/ops-data/zp/haha/mysite-11/lib/python3.6/site-packages/django/core/handlers/exception.py", line 43, in inner
    response = response_for_exception(request, exc)
  File "/ops-data/zp/haha/mysite-11/lib/python3.6/site-packages/django/core/handlers/exception.py", line 93, in response_for_exception
    response = handle_uncaught_exception(request, get_resolver(get_urlconf()), sys.exc_info())
  File "/ops-data/zp/haha/mysite-11/lib/python3.6/site-packages/django/core/handlers/exception.py", line 142, in handle_uncaught_exception
    callback, param_dict = resolver.resolve_error_handler(500)
  File "/ops-data/zp/haha/mysite-11/lib/python3.6/site-packages/django/urls/resolvers.py", line 418, in resolve_error_handler
    callback = getattr(self.urlconf_module, 'handler%s' % view_type, None)
  File "/ops-data/zp/haha/mysite-11/lib/python3.6/site-packages/django/utils/functional.py", line 35, in __get__
    res = instance.__dict__[self.name] = self.func(instance)
  File "/ops-data/zp/haha/mysite-11/lib/python3.6/site-packages/django/urls/resolvers.py", line 398, in urlconf_module
    return import_module(self.urlconf_name)
  File "/ops-data/zp/haha/mysite-11/lib/python3.6/importlib/__init__.py", line 126, in import_module
    return _bootstrap._gcd_import(name[level:], package, level)
  File "<frozen importlib._bootstrap>", line 994, in _gcd_import
  File "<frozen importlib._bootstrap>", line 971, in _find_and_load
  File "<frozen importlib._bootstrap>", line 955, in _find_and_load_unlocked
  File "<frozen importlib._bootstrap>", line 665, in _load_unlocked
  File "<frozen importlib._bootstrap_external>", line 678, in exec_module
  File "<frozen importlib._bootstrap>", line 219, in _call_with_frames_removed
  File "/ops-data/zp/haha/mysite-11/opsweb/opsweb/urls.py", line 27, in <module>
    url(r'^accounts/', include("accounts.urls")),
  File "/ops-data/zp/haha/mysite-11/lib/python3.6/site-packages/django/conf/urls/__init__.py", line 50, in include
    urlconf_module = import_module(urlconf_module)
  File "/ops-data/zp/haha/mysite-11/lib/python3.6/importlib/__init__.py", line 126, in import_module
    return _bootstrap._gcd_import(name[level:], package, level)
  File "<frozen importlib._bootstrap>", line 994, in _gcd_import
  File "<frozen importlib._bootstrap>", line 971, in _find_and_load
  File "<frozen importlib._bootstrap>", line 955, in _find_and_load_unlocked
  File "<frozen importlib._bootstrap>", line 665, in _load_unlocked
  File "<frozen importlib._bootstrap_external>", line 678, in exec_module
  File "<frozen importlib._bootstrap>", line 219, in _call_with_frames_removed
  File "/ops-data/zp/haha/mysite-11/opsweb/accounts/urls.py", line 20, in <module>
    from . import views,user,group,permission,api
ImportError: cannot import name 'api'
[2018-03-22 14:44:13 +0800] [17976] [ERROR] Error handling request /resources/cmdb/list/
Traceback (most recent call last):
  File "/ops-data/zp/haha/mysite-11/lib/python3.6/site-packages/django/core/handlers/exception.py", line 41, in inner
    response = get_response(request)
  File "/ops-data/zp/haha/mysite-11/lib/python3.6/site-packages/django/core/handlers/base.py", line 249, in _legacy_get_response
    response = self._get_response(request)
  File "/ops-data/zp/haha/mysite-11/lib/python3.6/site-packages/django/core/handlers/base.py", line 172, in _get_response
    resolver_match = resolver.resolve(request.path_info)
  File "/ops-data/zp/haha/mysite-11/lib/python3.6/site-packages/django/urls/resolvers.py", line 362, in resolve
    for pattern in self.url_patterns:
  File "/ops-data/zp/haha/mysite-11/lib/python3.6/site-packages/django/utils/functional.py", line 35, in __get__
    res = instance.__dict__[self.name] = self.func(instance)
  File "/ops-data/zp/haha/mysite-11/lib/python3.6/site-packages/django/urls/resolvers.py", line 405, in url_patterns
    patterns = getattr(self.urlconf_module, "urlpatterns", self.urlconf_module)
  File "/ops-data/zp/haha/mysite-11/lib/python3.6/site-packages/django/utils/functional.py", line 35, in __get__
    res = instance.__dict__[self.name] = self.func(instance)
  File "/ops-data/zp/haha/mysite-11/lib/python3.6/site-packages/django/urls/resolvers.py", line 398, in urlconf_module
    return import_module(self.urlconf_name)
  File "/ops-data/zp/haha/mysite-11/lib/python3.6/importlib/__init__.py", line 126, in import_module
    return _bootstrap._gcd_import(name[level:], package, level)
  File "<frozen importlib._bootstrap>", line 994, in _gcd_import
  File "<frozen importlib._bootstrap>", line 971, in _find_and_load
  File "<frozen importlib._bootstrap>", line 955, in _find_and_load_unlocked
  File "<frozen importlib._bootstrap>", line 665, in _load_unlocked
  File "<frozen importlib._bootstrap_external>", line 678, in exec_module
  File "<frozen importlib._bootstrap>", line 219, in _call_with_frames_removed
  File "/ops-data/zp/haha/mysite-11/opsweb/opsweb/urls.py", line 27, in <module>
    url(r'^accounts/', include("accounts.urls")),
  File "/ops-data/zp/haha/mysite-11/lib/python3.6/site-packages/django/conf/urls/__init__.py", line 50, in include
    urlconf_module = import_module(urlconf_module)
  File "/ops-data/zp/haha/mysite-11/lib/python3.6/importlib/__init__.py", line 126, in import_module
    return _bootstrap._gcd_import(name[level:], package, level)
  File "<frozen importlib._bootstrap>", line 994, in _gcd_import
  File "<frozen importlib._bootstrap>", line 971, in _find_and_load
  File "<frozen importlib._bootstrap>", line 955, in _find_and_load_unlocked
  File "<frozen importlib._bootstrap>", line 665, in _load_unlocked
  File "<frozen importlib._bootstrap_external>", line 678, in exec_module
  File "<frozen importlib._bootstrap>", line 219, in _call_with_frames_removed
  File "/ops-data/zp/haha/mysite-11/opsweb/accounts/urls.py", line 20, in <module>
    from . import views,user,group,permission,api
ImportError: cannot import name 'api'

During handling of the above exception, another exception occurred:

Traceback (most recent call last):
  File "/ops-data/zp/haha/mysite-11/lib/python3.6/site-packages/gunicorn/workers/sync.py", line 135, in handle
    self.handle_request(listener, req, client, addr)
  File "/ops-data/zp/haha/mysite-11/lib/python3.6/site-packages/gunicorn/workers/sync.py", line 176, in handle_request
    respiter = self.wsgi(environ, resp.start_response)
  File "/ops-data/zp/haha/mysite-11/lib/python3.6/site-packages/django/core/handlers/wsgi.py", line 157, in __call__
    response = self.get_response(request)
  File "/ops-data/zp/haha/mysite-11/lib/python3.6/site-packages/django/core/handlers/base.py", line 124, in get_response
    response = self._middleware_chain(request)
  File "/ops-data/zp/haha/mysite-11/lib/python3.6/site-packages/django/core/handlers/exception.py", line 43, in inner
    response = response_for_exception(request, exc)
  File "/ops-data/zp/haha/mysite-11/lib/python3.6/site-packages/django/core/handlers/exception.py", line 93, in response_for_exception
    response = handle_uncaught_exception(request, get_resolver(get_urlconf()), sys.exc_info())
  File "/ops-data/zp/haha/mysite-11/lib/python3.6/site-packages/django/core/handlers/exception.py", line 142, in handle_uncaught_exception
    callback, param_dict = resolver.resolve_error_handler(500)
  File "/ops-data/zp/haha/mysite-11/lib/python3.6/site-packages/django/urls/resolvers.py", line 418, in resolve_error_handler
    callback = getattr(self.urlconf_module, 'handler%s' % view_type, None)
  File "/ops-data/zp/haha/mysite-11/lib/python3.6/site-packages/django/utils/functional.py", line 35, in __get__
    res = instance.__dict__[self.name] = self.func(instance)
  File "/ops-data/zp/haha/mysite-11/lib/python3.6/site-packages/django/urls/resolvers.py", line 398, in urlconf_module
    return import_module(self.urlconf_name)
  File "/ops-data/zp/haha/mysite-11/lib/python3.6/importlib/__init__.py", line 126, in import_module
    return _bootstrap._gcd_import(name[level:], package, level)
  File "<frozen importlib._bootstrap>", line 994, in _gcd_import
  File "<frozen importlib._bootstrap>", line 971, in _find_and_load
  File "<frozen importlib._bootstrap>", line 955, in _find_and_load_unlocked
  File "<frozen importlib._bootstrap>", line 665, in _load_unlocked
  File "<frozen importlib._bootstrap_external>", line 678, in exec_module
  File "<frozen importlib._bootstrap>", line 219, in _call_with_frames_removed
  File "/ops-data/zp/haha/mysite-11/opsweb/opsweb/urls.py", line 27, in <module>
    url(r'^accounts/', include("accounts.urls")),
  File "/ops-data/zp/haha/mysite-11/lib/python3.6/site-packages/django/conf/urls/__init__.py", line 50, in include
    urlconf_module = import_module(urlconf_module)
  File "/ops-data/zp/haha/mysite-11/lib/python3.6/importlib/__init__.py", line 126, in import_module
    return _bootstrap._gcd_import(name[level:], package, level)
  File "<frozen importlib._bootstrap>", line 994, in _gcd_import
  File "<frozen importlib._bootstrap>", line 971, in _find_and_load
  File "<frozen importlib._bootstrap>", line 955, in _find_and_load_unlocked
  File "<frozen importlib._bootstrap>", line 665, in _load_unlocked
  File "<frozen importlib._bootstrap_external>", line 678, in exec_module
  File "<frozen importlib._bootstrap>", line 219, in _call_with_frames_removed
  File "/ops-data/zp/haha/mysite-11/opsweb/accounts/urls.py", line 20, in <module>
    from . import views,user,group,permission,api
ImportError: cannot import name 'api'
[2018-03-22 14:44:14 +0800] [19611] [ERROR] Error handling request /resources/cmdb/list/
Traceback (most recent call last):
  File "/ops-data/zp/haha/mysite-11/lib/python3.6/site-packages/django/core/handlers/exception.py", line 41, in inner
    response = get_response(request)
  File "/ops-data/zp/haha/mysite-11/lib/python3.6/site-packages/django/core/handlers/base.py", line 249, in _legacy_get_response
    response = self._get_response(request)
  File "/ops-data/zp/haha/mysite-11/lib/python3.6/site-packages/django/core/handlers/base.py", line 172, in _get_response
    resolver_match = resolver.resolve(request.path_info)
  File "/ops-data/zp/haha/mysite-11/lib/python3.6/site-packages/django/urls/resolvers.py", line 362, in resolve
    for pattern in self.url_patterns:
  File "/ops-data/zp/haha/mysite-11/lib/python3.6/site-packages/django/utils/functional.py", line 35, in __get__
    res = instance.__dict__[self.name] = self.func(instance)
  File "/ops-data/zp/haha/mysite-11/lib/python3.6/site-packages/django/urls/resolvers.py", line 405, in url_patterns
    patterns = getattr(self.urlconf_module, "urlpatterns", self.urlconf_module)
  File "/ops-data/zp/haha/mysite-11/lib/python3.6/site-packages/django/utils/functional.py", line 35, in __get__
    res = instance.__dict__[self.name] = self.func(instance)
  File "/ops-data/zp/haha/mysite-11/lib/python3.6/site-packages/django/urls/resolvers.py", line 398, in urlconf_module
    return import_module(self.urlconf_name)
  File "/ops-data/zp/haha/mysite-11/lib/python3.6/importlib/__init__.py", line 126, in import_module
    return _bootstrap._gcd_import(name[level:], package, level)
  File "<frozen importlib._bootstrap>", line 994, in _gcd_import
  File "<frozen importlib._bootstrap>", line 971, in _find_and_load
  File "<frozen importlib._bootstrap>", line 955, in _find_and_load_unlocked
  File "<frozen importlib._bootstrap>", line 665, in _load_unlocked
  File "<frozen importlib._bootstrap_external>", line 678, in exec_module
  File "<frozen importlib._bootstrap>", line 219, in _call_with_frames_removed
  File "/ops-data/zp/haha/mysite-11/opsweb/opsweb/urls.py", line 27, in <module>
    url(r'^accounts/', include("accounts.urls")),
  File "/ops-data/zp/haha/mysite-11/lib/python3.6/site-packages/django/conf/urls/__init__.py", line 50, in include
    urlconf_module = import_module(urlconf_module)
  File "/ops-data/zp/haha/mysite-11/lib/python3.6/importlib/__init__.py", line 126, in import_module
    return _bootstrap._gcd_import(name[level:], package, level)
  File "<frozen importlib._bootstrap>", line 994, in _gcd_import
  File "<frozen importlib._bootstrap>", line 971, in _find_and_load
  File "<frozen importlib._bootstrap>", line 955, in _find_and_load_unlocked
  File "<frozen importlib._bootstrap>", line 665, in _load_unlocked
  File "<frozen importlib._bootstrap_external>", line 678, in exec_module
  File "<frozen importlib._bootstrap>", line 219, in _call_with_frames_removed
  File "/ops-data/zp/haha/mysite-11/opsweb/accounts/urls.py", line 20, in <module>
    from . import views,user,group,permission,api
ImportError: cannot import name 'api'

During handling of the above exception, another exception occurred:

Traceback (most recent call last):
  File "/ops-data/zp/haha/mysite-11/lib/python3.6/site-packages/gunicorn/workers/sync.py", line 135, in handle
    self.handle_request(listener, req, client, addr)
  File "/ops-data/zp/haha/mysite-11/lib/python3.6/site-packages/gunicorn/workers/sync.py", line 176, in handle_request
    respiter = self.wsgi(environ, resp.start_response)
  File "/ops-data/zp/haha/mysite-11/lib/python3.6/site-packages/django/core/handlers/wsgi.py", line 157, in __call__
    response = self.get_response(request)
  File "/ops-data/zp/haha/mysite-11/lib/python3.6/site-packages/django/core/handlers/base.py", line 124, in get_response
    response = self._middleware_chain(request)
  File "/ops-data/zp/haha/mysite-11/lib/python3.6/site-packages/django/core/handlers/exception.py", line 43, in inner
    response = response_for_exception(request, exc)
  File "/ops-data/zp/haha/mysite-11/lib/python3.6/site-packages/django/core/handlers/exception.py", line 93, in response_for_exception
    response = handle_uncaught_exception(request, get_resolver(get_urlconf()), sys.exc_info())
  File "/ops-data/zp/haha/mysite-11/lib/python3.6/site-packages/django/core/handlers/exception.py", line 142, in handle_uncaught_exception
    callback, param_dict = resolver.resolve_error_handler(500)
  File "/ops-data/zp/haha/mysite-11/lib/python3.6/site-packages/django/urls/resolvers.py", line 418, in resolve_error_handler
    callback = getattr(self.urlconf_module, 'handler%s' % view_type, None)
  File "/ops-data/zp/haha/mysite-11/lib/python3.6/site-packages/django/utils/functional.py", line 35, in __get__
    res = instance.__dict__[self.name] = self.func(instance)
  File "/ops-data/zp/haha/mysite-11/lib/python3.6/site-packages/django/urls/resolvers.py", line 398, in urlconf_module
    return import_module(self.urlconf_name)
  File "/ops-data/zp/haha/mysite-11/lib/python3.6/importlib/__init__.py", line 126, in import_module
    return _bootstrap._gcd_import(name[level:], package, level)
  File "<frozen importlib._bootstrap>", line 994, in _gcd_import
  File "<frozen importlib._bootstrap>", line 971, in _find_and_load
  File "<frozen importlib._bootstrap>", line 955, in _find_and_load_unlocked
  File "<frozen importlib._bootstrap>", line 665, in _load_unlocked
  File "<frozen importlib._bootstrap_external>", line 678, in exec_module
  File "<frozen importlib._bootstrap>", line 219, in _call_with_frames_removed
  File "/ops-data/zp/haha/mysite-11/opsweb/opsweb/urls.py", line 27, in <module>
    url(r'^accounts/', include("accounts.urls")),
  File "/ops-data/zp/haha/mysite-11/lib/python3.6/site-packages/django/conf/urls/__init__.py", line 50, in include
    urlconf_module = import_module(urlconf_module)
  File "/ops-data/zp/haha/mysite-11/lib/python3.6/importlib/__init__.py", line 126, in import_module
    return _bootstrap._gcd_import(name[level:], package, level)
  File "<frozen importlib._bootstrap>", line 994, in _gcd_import
  File "<frozen importlib._bootstrap>", line 971, in _find_and_load
  File "<frozen importlib._bootstrap>", line 955, in _find_and_load_unlocked
  File "<frozen importlib._bootstrap>", line 665, in _load_unlocked
  File "<frozen importlib._bootstrap_external>", line 678, in exec_module
  File "<frozen importlib._bootstrap>", line 219, in _call_with_frames_removed
  File "/ops-data/zp/haha/mysite-11/opsweb/accounts/urls.py", line 20, in <module>
    from . import views,user,group,permission,api
ImportError: cannot import name 'api'
[2018-03-22 14:44:15 +0800] [19417] [ERROR] Error handling request /resources/cmdb/list/
Traceback (most recent call last):
  File "/ops-data/zp/haha/mysite-11/lib/python3.6/site-packages/django/core/handlers/exception.py", line 41, in inner
    response = get_response(request)
  File "/ops-data/zp/haha/mysite-11/lib/python3.6/site-packages/django/core/handlers/base.py", line 249, in _legacy_get_response
    response = self._get_response(request)
  File "/ops-data/zp/haha/mysite-11/lib/python3.6/site-packages/django/core/handlers/base.py", line 172, in _get_response
    resolver_match = resolver.resolve(request.path_info)
  File "/ops-data/zp/haha/mysite-11/lib/python3.6/site-packages/django/urls/resolvers.py", line 362, in resolve
    for pattern in self.url_patterns:
  File "/ops-data/zp/haha/mysite-11/lib/python3.6/site-packages/django/utils/functional.py", line 35, in __get__
    res = instance.__dict__[self.name] = self.func(instance)
  File "/ops-data/zp/haha/mysite-11/lib/python3.6/site-packages/django/urls/resolvers.py", line 405, in url_patterns
    patterns = getattr(self.urlconf_module, "urlpatterns", self.urlconf_module)
  File "/ops-data/zp/haha/mysite-11/lib/python3.6/site-packages/django/utils/functional.py", line 35, in __get__
    res = instance.__dict__[self.name] = self.func(instance)
  File "/ops-data/zp/haha/mysite-11/lib/python3.6/site-packages/django/urls/resolvers.py", line 398, in urlconf_module
    return import_module(self.urlconf_name)
  File "/ops-data/zp/haha/mysite-11/lib/python3.6/importlib/__init__.py", line 126, in import_module
    return _bootstrap._gcd_import(name[level:], package, level)
  File "<frozen importlib._bootstrap>", line 994, in _gcd_import
  File "<frozen importlib._bootstrap>", line 971, in _find_and_load
  File "<frozen importlib._bootstrap>", line 955, in _find_and_load_unlocked
  File "<frozen importlib._bootstrap>", line 665, in _load_unlocked
  File "<frozen importlib._bootstrap_external>", line 678, in exec_module
  File "<frozen importlib._bootstrap>", line 219, in _call_with_frames_removed
  File "/ops-data/zp/haha/mysite-11/opsweb/opsweb/urls.py", line 27, in <module>
    url(r'^accounts/', include("accounts.urls")),
  File "/ops-data/zp/haha/mysite-11/lib/python3.6/site-packages/django/conf/urls/__init__.py", line 50, in include
    urlconf_module = import_module(urlconf_module)
  File "/ops-data/zp/haha/mysite-11/lib/python3.6/importlib/__init__.py", line 126, in import_module
    return _bootstrap._gcd_import(name[level:], package, level)
  File "<frozen importlib._bootstrap>", line 994, in _gcd_import
  File "<frozen importlib._bootstrap>", line 971, in _find_and_load
  File "<frozen importlib._bootstrap>", line 955, in _find_and_load_unlocked
  File "<frozen importlib._bootstrap>", line 665, in _load_unlocked
  File "<frozen importlib._bootstrap_external>", line 678, in exec_module
  File "<frozen importlib._bootstrap>", line 219, in _call_with_frames_removed
  File "/ops-data/zp/haha/mysite-11/opsweb/accounts/urls.py", line 20, in <module>
    from . import views,user,group,permission,api
ImportError: cannot import name 'api'

During handling of the above exception, another exception occurred:

Traceback (most recent call last):
  File "/ops-data/zp/haha/mysite-11/lib/python3.6/site-packages/gunicorn/workers/sync.py", line 135, in handle
    self.handle_request(listener, req, client, addr)
  File "/ops-data/zp/haha/mysite-11/lib/python3.6/site-packages/gunicorn/workers/sync.py", line 176, in handle_request
    respiter = self.wsgi(environ, resp.start_response)
  File "/ops-data/zp/haha/mysite-11/lib/python3.6/site-packages/django/core/handlers/wsgi.py", line 157, in __call__
    response = self.get_response(request)
  File "/ops-data/zp/haha/mysite-11/lib/python3.6/site-packages/django/core/handlers/base.py", line 124, in get_response
    response = self._middleware_chain(request)
  File "/ops-data/zp/haha/mysite-11/lib/python3.6/site-packages/django/core/handlers/exception.py", line 43, in inner
    response = response_for_exception(request, exc)
  File "/ops-data/zp/haha/mysite-11/lib/python3.6/site-packages/django/core/handlers/exception.py", line 93, in response_for_exception
    response = handle_uncaught_exception(request, get_resolver(get_urlconf()), sys.exc_info())
  File "/ops-data/zp/haha/mysite-11/lib/python3.6/site-packages/django/core/handlers/exception.py", line 142, in handle_uncaught_exception
    callback, param_dict = resolver.resolve_error_handler(500)
  File "/ops-data/zp/haha/mysite-11/lib/python3.6/site-packages/django/urls/resolvers.py", line 418, in resolve_error_handler
    callback = getattr(self.urlconf_module, 'handler%s' % view_type, None)
  File "/ops-data/zp/haha/mysite-11/lib/python3.6/site-packages/django/utils/functional.py", line 35, in __get__
    res = instance.__dict__[self.name] = self.func(instance)
  File "/ops-data/zp/haha/mysite-11/lib/python3.6/site-packages/django/urls/resolvers.py", line 398, in urlconf_module
    return import_module(self.urlconf_name)
  File "/ops-data/zp/haha/mysite-11/lib/python3.6/importlib/__init__.py", line 126, in import_module
    return _bootstrap._gcd_import(name[level:], package, level)
  File "<frozen importlib._bootstrap>", line 994, in _gcd_import
  File "<frozen importlib._bootstrap>", line 971, in _find_and_load
  File "<frozen importlib._bootstrap>", line 955, in _find_and_load_unlocked
  File "<frozen importlib._bootstrap>", line 665, in _load_unlocked
  File "<frozen importlib._bootstrap_external>", line 678, in exec_module
  File "<frozen importlib._bootstrap>", line 219, in _call_with_frames_removed
  File "/ops-data/zp/haha/mysite-11/opsweb/opsweb/urls.py", line 27, in <module>
    url(r'^accounts/', include("accounts.urls")),
  File "/ops-data/zp/haha/mysite-11/lib/python3.6/site-packages/django/conf/urls/__init__.py", line 50, in include
    urlconf_module = import_module(urlconf_module)
  File "/ops-data/zp/haha/mysite-11/lib/python3.6/importlib/__init__.py", line 126, in import_module
    return _bootstrap._gcd_import(name[level:], package, level)
  File "<frozen importlib._bootstrap>", line 994, in _gcd_import
  File "<frozen importlib._bootstrap>", line 971, in _find_and_load
  File "<frozen importlib._bootstrap>", line 955, in _find_and_load_unlocked
  File "<frozen importlib._bootstrap>", line 665, in _load_unlocked
  File "<frozen importlib._bootstrap_external>", line 678, in exec_module
  File "<frozen importlib._bootstrap>", line 219, in _call_with_frames_removed
  File "/ops-data/zp/haha/mysite-11/opsweb/accounts/urls.py", line 20, in <module>
    from . import views,user,group,permission,api
ImportError: cannot import name 'api'
[2018-03-28 10:55:08 +0800] [19424] [ERROR] Error handling request /dashboard/
Traceback (most recent call last):
  File "/ops-data/zp/haha/mysite-11/lib/python3.6/site-packages/django/core/handlers/exception.py", line 41, in inner
    response = get_response(request)
  File "/ops-data/zp/haha/mysite-11/lib/python3.6/site-packages/django/core/handlers/base.py", line 249, in _legacy_get_response
    response = self._get_response(request)
  File "/ops-data/zp/haha/mysite-11/lib/python3.6/site-packages/django/core/handlers/base.py", line 172, in _get_response
    resolver_match = resolver.resolve(request.path_info)
  File "/ops-data/zp/haha/mysite-11/lib/python3.6/site-packages/django/urls/resolvers.py", line 362, in resolve
    for pattern in self.url_patterns:
  File "/ops-data/zp/haha/mysite-11/lib/python3.6/site-packages/django/utils/functional.py", line 35, in __get__
    res = instance.__dict__[self.name] = self.func(instance)
  File "/ops-data/zp/haha/mysite-11/lib/python3.6/site-packages/django/urls/resolvers.py", line 405, in url_patterns
    patterns = getattr(self.urlconf_module, "urlpatterns", self.urlconf_module)
  File "/ops-data/zp/haha/mysite-11/lib/python3.6/site-packages/django/utils/functional.py", line 35, in __get__
    res = instance.__dict__[self.name] = self.func(instance)
  File "/ops-data/zp/haha/mysite-11/lib/python3.6/site-packages/django/urls/resolvers.py", line 398, in urlconf_module
    return import_module(self.urlconf_name)
  File "/ops-data/zp/haha/mysite-11/lib/python3.6/importlib/__init__.py", line 126, in import_module
    return _bootstrap._gcd_import(name[level:], package, level)
  File "<frozen importlib._bootstrap>", line 994, in _gcd_import
  File "<frozen importlib._bootstrap>", line 971, in _find_and_load
  File "<frozen importlib._bootstrap>", line 955, in _find_and_load_unlocked
  File "<frozen importlib._bootstrap>", line 665, in _load_unlocked
  File "<frozen importlib._bootstrap_external>", line 678, in exec_module
  File "<frozen importlib._bootstrap>", line 219, in _call_with_frames_removed
  File "/ops-data/zp/haha/mysite-11/opsweb/opsweb/urls.py", line 26, in <module>
    url(r'^helloworld/', include("helloworld.urls")),
  File "/ops-data/zp/haha/mysite-11/lib/python3.6/site-packages/django/conf/urls/__init__.py", line 50, in include
    urlconf_module = import_module(urlconf_module)
  File "/ops-data/zp/haha/mysite-11/lib/python3.6/importlib/__init__.py", line 126, in import_module
    return _bootstrap._gcd_import(name[level:], package, level)
  File "<frozen importlib._bootstrap>", line 994, in _gcd_import
  File "<frozen importlib._bootstrap>", line 971, in _find_and_load
  File "<frozen importlib._bootstrap>", line 941, in _find_and_load_unlocked
  File "<frozen importlib._bootstrap>", line 219, in _call_with_frames_removed
  File "<frozen importlib._bootstrap>", line 994, in _gcd_import
  File "<frozen importlib._bootstrap>", line 971, in _find_and_load
  File "<frozen importlib._bootstrap>", line 953, in _find_and_load_unlocked
ModuleNotFoundError: No module named 'helloworld'

During handling of the above exception, another exception occurred:

Traceback (most recent call last):
  File "/ops-data/zp/haha/mysite-11/lib/python3.6/site-packages/gunicorn/workers/sync.py", line 135, in handle
    self.handle_request(listener, req, client, addr)
  File "/ops-data/zp/haha/mysite-11/lib/python3.6/site-packages/gunicorn/workers/sync.py", line 176, in handle_request
    respiter = self.wsgi(environ, resp.start_response)
  File "/ops-data/zp/haha/mysite-11/lib/python3.6/site-packages/django/core/handlers/wsgi.py", line 157, in __call__
    response = self.get_response(request)
  File "/ops-data/zp/haha/mysite-11/lib/python3.6/site-packages/django/core/handlers/base.py", line 124, in get_response
    response = self._middleware_chain(request)
  File "/ops-data/zp/haha/mysite-11/lib/python3.6/site-packages/django/core/handlers/exception.py", line 43, in inner
    response = response_for_exception(request, exc)
  File "/ops-data/zp/haha/mysite-11/lib/python3.6/site-packages/django/core/handlers/exception.py", line 93, in response_for_exception
    response = handle_uncaught_exception(request, get_resolver(get_urlconf()), sys.exc_info())
  File "/ops-data/zp/haha/mysite-11/lib/python3.6/site-packages/django/core/handlers/exception.py", line 142, in handle_uncaught_exception
    callback, param_dict = resolver.resolve_error_handler(500)
  File "/ops-data/zp/haha/mysite-11/lib/python3.6/site-packages/django/urls/resolvers.py", line 418, in resolve_error_handler
    callback = getattr(self.urlconf_module, 'handler%s' % view_type, None)
  File "/ops-data/zp/haha/mysite-11/lib/python3.6/site-packages/django/utils/functional.py", line 35, in __get__
    res = instance.__dict__[self.name] = self.func(instance)
  File "/ops-data/zp/haha/mysite-11/lib/python3.6/site-packages/django/urls/resolvers.py", line 398, in urlconf_module
    return import_module(self.urlconf_name)
  File "/ops-data/zp/haha/mysite-11/lib/python3.6/importlib/__init__.py", line 126, in import_module
    return _bootstrap._gcd_import(name[level:], package, level)
  File "<frozen importlib._bootstrap>", line 994, in _gcd_import
  File "<frozen importlib._bootstrap>", line 971, in _find_and_load
  File "<frozen importlib._bootstrap>", line 955, in _find_and_load_unlocked
  File "<frozen importlib._bootstrap>", line 665, in _load_unlocked
  File "<frozen importlib._bootstrap_external>", line 678, in exec_module
  File "<frozen importlib._bootstrap>", line 219, in _call_with_frames_removed
  File "/ops-data/zp/haha/mysite-11/opsweb/opsweb/urls.py", line 26, in <module>
    url(r'^helloworld/', include("helloworld.urls")),
  File "/ops-data/zp/haha/mysite-11/lib/python3.6/site-packages/django/conf/urls/__init__.py", line 50, in include
    urlconf_module = import_module(urlconf_module)
  File "/ops-data/zp/haha/mysite-11/lib/python3.6/importlib/__init__.py", line 126, in import_module
    return _bootstrap._gcd_import(name[level:], package, level)
  File "<frozen importlib._bootstrap>", line 994, in _gcd_import
  File "<frozen importlib._bootstrap>", line 971, in _find_and_load
  File "<frozen importlib._bootstrap>", line 941, in _find_and_load_unlocked
  File "<frozen importlib._bootstrap>", line 219, in _call_with_frames_removed
  File "<frozen importlib._bootstrap>", line 994, in _gcd_import
  File "<frozen importlib._bootstrap>", line 971, in _find_and_load
  File "<frozen importlib._bootstrap>", line 953, in _find_and_load_unlocked
ModuleNotFoundError: No module named 'helloworld'
[2018-03-28 10:55:11 +0800] [19422] [ERROR] Error handling request /dashboard/
Traceback (most recent call last):
  File "/ops-data/zp/haha/mysite-11/lib/python3.6/site-packages/django/core/handlers/exception.py", line 41, in inner
    response = get_response(request)
  File "/ops-data/zp/haha/mysite-11/lib/python3.6/site-packages/django/core/handlers/base.py", line 249, in _legacy_get_response
    response = self._get_response(request)
  File "/ops-data/zp/haha/mysite-11/lib/python3.6/site-packages/django/core/handlers/base.py", line 172, in _get_response
    resolver_match = resolver.resolve(request.path_info)
  File "/ops-data/zp/haha/mysite-11/lib/python3.6/site-packages/django/urls/resolvers.py", line 362, in resolve
    for pattern in self.url_patterns:
  File "/ops-data/zp/haha/mysite-11/lib/python3.6/site-packages/django/utils/functional.py", line 35, in __get__
    res = instance.__dict__[self.name] = self.func(instance)
  File "/ops-data/zp/haha/mysite-11/lib/python3.6/site-packages/django/urls/resolvers.py", line 405, in url_patterns
    patterns = getattr(self.urlconf_module, "urlpatterns", self.urlconf_module)
  File "/ops-data/zp/haha/mysite-11/lib/python3.6/site-packages/django/utils/functional.py", line 35, in __get__
    res = instance.__dict__[self.name] = self.func(instance)
  File "/ops-data/zp/haha/mysite-11/lib/python3.6/site-packages/django/urls/resolvers.py", line 398, in urlconf_module
    return import_module(self.urlconf_name)
  File "/ops-data/zp/haha/mysite-11/lib/python3.6/importlib/__init__.py", line 126, in import_module
    return _bootstrap._gcd_import(name[level:], package, level)
  File "<frozen importlib._bootstrap>", line 994, in _gcd_import
  File "<frozen importlib._bootstrap>", line 971, in _find_and_load
  File "<frozen importlib._bootstrap>", line 955, in _find_and_load_unlocked
  File "<frozen importlib._bootstrap>", line 665, in _load_unlocked
  File "<frozen importlib._bootstrap_external>", line 678, in exec_module
  File "<frozen importlib._bootstrap>", line 219, in _call_with_frames_removed
  File "/ops-data/zp/haha/mysite-11/opsweb/opsweb/urls.py", line 26, in <module>
    url(r'^helloworld/', include("helloworld.urls")),
  File "/ops-data/zp/haha/mysite-11/lib/python3.6/site-packages/django/conf/urls/__init__.py", line 50, in include
    urlconf_module = import_module(urlconf_module)
  File "/ops-data/zp/haha/mysite-11/lib/python3.6/importlib/__init__.py", line 126, in import_module
    return _bootstrap._gcd_import(name[level:], package, level)
  File "<frozen importlib._bootstrap>", line 994, in _gcd_import
  File "<frozen importlib._bootstrap>", line 971, in _find_and_load
  File "<frozen importlib._bootstrap>", line 941, in _find_and_load_unlocked
  File "<frozen importlib._bootstrap>", line 219, in _call_with_frames_removed
  File "<frozen importlib._bootstrap>", line 994, in _gcd_import
  File "<frozen importlib._bootstrap>", line 971, in _find_and_load
  File "<frozen importlib._bootstrap>", line 953, in _find_and_load_unlocked
ModuleNotFoundError: No module named 'helloworld'

During handling of the above exception, another exception occurred:

Traceback (most recent call last):
  File "/ops-data/zp/haha/mysite-11/lib/python3.6/site-packages/gunicorn/workers/sync.py", line 135, in handle
    self.handle_request(listener, req, client, addr)
  File "/ops-data/zp/haha/mysite-11/lib/python3.6/site-packages/gunicorn/workers/sync.py", line 176, in handle_request
    respiter = self.wsgi(environ, resp.start_response)
  File "/ops-data/zp/haha/mysite-11/lib/python3.6/site-packages/django/core/handlers/wsgi.py", line 157, in __call__
    response = self.get_response(request)
  File "/ops-data/zp/haha/mysite-11/lib/python3.6/site-packages/django/core/handlers/base.py", line 124, in get_response
    response = self._middleware_chain(request)
  File "/ops-data/zp/haha/mysite-11/lib/python3.6/site-packages/django/core/handlers/exception.py", line 43, in inner
    response = response_for_exception(request, exc)
  File "/ops-data/zp/haha/mysite-11/lib/python3.6/site-packages/django/core/handlers/exception.py", line 93, in response_for_exception
    response = handle_uncaught_exception(request, get_resolver(get_urlconf()), sys.exc_info())
  File "/ops-data/zp/haha/mysite-11/lib/python3.6/site-packages/django/core/handlers/exception.py", line 142, in handle_uncaught_exception
    callback, param_dict = resolver.resolve_error_handler(500)
  File "/ops-data/zp/haha/mysite-11/lib/python3.6/site-packages/django/urls/resolvers.py", line 418, in resolve_error_handler
    callback = getattr(self.urlconf_module, 'handler%s' % view_type, None)
  File "/ops-data/zp/haha/mysite-11/lib/python3.6/site-packages/django/utils/functional.py", line 35, in __get__
    res = instance.__dict__[self.name] = self.func(instance)
  File "/ops-data/zp/haha/mysite-11/lib/python3.6/site-packages/django/urls/resolvers.py", line 398, in urlconf_module
    return import_module(self.urlconf_name)
  File "/ops-data/zp/haha/mysite-11/lib/python3.6/importlib/__init__.py", line 126, in import_module
    return _bootstrap._gcd_import(name[level:], package, level)
  File "<frozen importlib._bootstrap>", line 994, in _gcd_import
  File "<frozen importlib._bootstrap>", line 971, in _find_and_load
  File "<frozen importlib._bootstrap>", line 955, in _find_and_load_unlocked
  File "<frozen importlib._bootstrap>", line 665, in _load_unlocked
  File "<frozen importlib._bootstrap_external>", line 678, in exec_module
  File "<frozen importlib._bootstrap>", line 219, in _call_with_frames_removed
  File "/ops-data/zp/haha/mysite-11/opsweb/opsweb/urls.py", line 26, in <module>
    url(r'^helloworld/', include("helloworld.urls")),
  File "/ops-data/zp/haha/mysite-11/lib/python3.6/site-packages/django/conf/urls/__init__.py", line 50, in include
    urlconf_module = import_module(urlconf_module)
  File "/ops-data/zp/haha/mysite-11/lib/python3.6/importlib/__init__.py", line 126, in import_module
    return _bootstrap._gcd_import(name[level:], package, level)
  File "<frozen importlib._bootstrap>", line 994, in _gcd_import
  File "<frozen importlib._bootstrap>", line 971, in _find_and_load
  File "<frozen importlib._bootstrap>", line 941, in _find_and_load_unlocked
  File "<frozen importlib._bootstrap>", line 219, in _call_with_frames_removed
  File "<frozen importlib._bootstrap>", line 994, in _gcd_import
  File "<frozen importlib._bootstrap>", line 971, in _find_and_load
  File "<frozen importlib._bootstrap>", line 953, in _find_and_load_unlocked
ModuleNotFoundError: No module named 'helloworld'
[2018-03-28 10:55:12 +0800] [19422] [ERROR] Error handling request /dashboard/
Traceback (most recent call last):
  File "/ops-data/zp/haha/mysite-11/lib/python3.6/site-packages/django/core/handlers/exception.py", line 41, in inner
    response = get_response(request)
  File "/ops-data/zp/haha/mysite-11/lib/python3.6/site-packages/django/core/handlers/base.py", line 249, in _legacy_get_response
    response = self._get_response(request)
  File "/ops-data/zp/haha/mysite-11/lib/python3.6/site-packages/django/core/handlers/base.py", line 172, in _get_response
    resolver_match = resolver.resolve(request.path_info)
  File "/ops-data/zp/haha/mysite-11/lib/python3.6/site-packages/django/urls/resolvers.py", line 362, in resolve
    for pattern in self.url_patterns:
  File "/ops-data/zp/haha/mysite-11/lib/python3.6/site-packages/django/utils/functional.py", line 35, in __get__
    res = instance.__dict__[self.name] = self.func(instance)
  File "/ops-data/zp/haha/mysite-11/lib/python3.6/site-packages/django/urls/resolvers.py", line 405, in url_patterns
    patterns = getattr(self.urlconf_module, "urlpatterns", self.urlconf_module)
  File "/ops-data/zp/haha/mysite-11/lib/python3.6/site-packages/django/utils/functional.py", line 35, in __get__
    res = instance.__dict__[self.name] = self.func(instance)
  File "/ops-data/zp/haha/mysite-11/lib/python3.6/site-packages/django/urls/resolvers.py", line 398, in urlconf_module
    return import_module(self.urlconf_name)
  File "/ops-data/zp/haha/mysite-11/lib/python3.6/importlib/__init__.py", line 126, in import_module
    return _bootstrap._gcd_import(name[level:], package, level)
  File "<frozen importlib._bootstrap>", line 994, in _gcd_import
  File "<frozen importlib._bootstrap>", line 971, in _find_and_load
  File "<frozen importlib._bootstrap>", line 955, in _find_and_load_unlocked
  File "<frozen importlib._bootstrap>", line 665, in _load_unlocked
  File "<frozen importlib._bootstrap_external>", line 678, in exec_module
  File "<frozen importlib._bootstrap>", line 219, in _call_with_frames_removed
  File "/ops-data/zp/haha/mysite-11/opsweb/opsweb/urls.py", line 26, in <module>
    url(r'^helloworld/', include("helloworld.urls")),
  File "/ops-data/zp/haha/mysite-11/lib/python3.6/site-packages/django/conf/urls/__init__.py", line 50, in include
    urlconf_module = import_module(urlconf_module)
  File "/ops-data/zp/haha/mysite-11/lib/python3.6/importlib/__init__.py", line 126, in import_module
    return _bootstrap._gcd_import(name[level:], package, level)
  File "<frozen importlib._bootstrap>", line 994, in _gcd_import
  File "<frozen importlib._bootstrap>", line 971, in _find_and_load
  File "<frozen importlib._bootstrap>", line 941, in _find_and_load_unlocked
  File "<frozen importlib._bootstrap>", line 219, in _call_with_frames_removed
  File "<frozen importlib._bootstrap>", line 994, in _gcd_import
  File "<frozen importlib._bootstrap>", line 971, in _find_and_load
  File "<frozen importlib._bootstrap>", line 953, in _find_and_load_unlocked
ModuleNotFoundError: No module named 'helloworld'

During handling of the above exception, another exception occurred:

Traceback (most recent call last):
  File "/ops-data/zp/haha/mysite-11/lib/python3.6/site-packages/gunicorn/workers/sync.py", line 135, in handle
    self.handle_request(listener, req, client, addr)
  File "/ops-data/zp/haha/mysite-11/lib/python3.6/site-packages/gunicorn/workers/sync.py", line 176, in handle_request
    respiter = self.wsgi(environ, resp.start_response)
  File "/ops-data/zp/haha/mysite-11/lib/python3.6/site-packages/django/core/handlers/wsgi.py", line 157, in __call__
    response = self.get_response(request)
  File "/ops-data/zp/haha/mysite-11/lib/python3.6/site-packages/django/core/handlers/base.py", line 124, in get_response
    response = self._middleware_chain(request)
  File "/ops-data/zp/haha/mysite-11/lib/python3.6/site-packages/django/core/handlers/exception.py", line 43, in inner
    response = response_for_exception(request, exc)
  File "/ops-data/zp/haha/mysite-11/lib/python3.6/site-packages/django/core/handlers/exception.py", line 93, in response_for_exception
    response = handle_uncaught_exception(request, get_resolver(get_urlconf()), sys.exc_info())
  File "/ops-data/zp/haha/mysite-11/lib/python3.6/site-packages/django/core/handlers/exception.py", line 142, in handle_uncaught_exception
    callback, param_dict = resolver.resolve_error_handler(500)
  File "/ops-data/zp/haha/mysite-11/lib/python3.6/site-packages/django/urls/resolvers.py", line 418, in resolve_error_handler
    callback = getattr(self.urlconf_module, 'handler%s' % view_type, None)
  File "/ops-data/zp/haha/mysite-11/lib/python3.6/site-packages/django/utils/functional.py", line 35, in __get__
    res = instance.__dict__[self.name] = self.func(instance)
  File "/ops-data/zp/haha/mysite-11/lib/python3.6/site-packages/django/urls/resolvers.py", line 398, in urlconf_module
    return import_module(self.urlconf_name)
  File "/ops-data/zp/haha/mysite-11/lib/python3.6/importlib/__init__.py", line 126, in import_module
    return _bootstrap._gcd_import(name[level:], package, level)
  File "<frozen importlib._bootstrap>", line 994, in _gcd_import
  File "<frozen importlib._bootstrap>", line 971, in _find_and_load
  File "<frozen importlib._bootstrap>", line 955, in _find_and_load_unlocked
  File "<frozen importlib._bootstrap>", line 665, in _load_unlocked
  File "<frozen importlib._bootstrap_external>", line 678, in exec_module
  File "<frozen importlib._bootstrap>", line 219, in _call_with_frames_removed
  File "/ops-data/zp/haha/mysite-11/opsweb/opsweb/urls.py", line 26, in <module>
    url(r'^helloworld/', include("helloworld.urls")),
  File "/ops-data/zp/haha/mysite-11/lib/python3.6/site-packages/django/conf/urls/__init__.py", line 50, in include
    urlconf_module = import_module(urlconf_module)
  File "/ops-data/zp/haha/mysite-11/lib/python3.6/importlib/__init__.py", line 126, in import_module
    return _bootstrap._gcd_import(name[level:], package, level)
  File "<frozen importlib._bootstrap>", line 994, in _gcd_import
  File "<frozen importlib._bootstrap>", line 971, in _find_and_load
  File "<frozen importlib._bootstrap>", line 941, in _find_and_load_unlocked
  File "<frozen importlib._bootstrap>", line 219, in _call_with_frames_removed
  File "<frozen importlib._bootstrap>", line 994, in _gcd_import
  File "<frozen importlib._bootstrap>", line 971, in _find_and_load
  File "<frozen importlib._bootstrap>", line 953, in _find_and_load_unlocked
ModuleNotFoundError: No module named 'helloworld'
[2018-03-28 10:55:13 +0800] [19429] [ERROR] Error handling request /dashboard/
Traceback (most recent call last):
  File "/ops-data/zp/haha/mysite-11/lib/python3.6/site-packages/django/core/handlers/exception.py", line 41, in inner
    response = get_response(request)
  File "/ops-data/zp/haha/mysite-11/lib/python3.6/site-packages/django/core/handlers/base.py", line 249, in _legacy_get_response
    response = self._get_response(request)
  File "/ops-data/zp/haha/mysite-11/lib/python3.6/site-packages/django/core/handlers/base.py", line 172, in _get_response
    resolver_match = resolver.resolve(request.path_info)
  File "/ops-data/zp/haha/mysite-11/lib/python3.6/site-packages/django/urls/resolvers.py", line 362, in resolve
    for pattern in self.url_patterns:
  File "/ops-data/zp/haha/mysite-11/lib/python3.6/site-packages/django/utils/functional.py", line 35, in __get__
    res = instance.__dict__[self.name] = self.func(instance)
  File "/ops-data/zp/haha/mysite-11/lib/python3.6/site-packages/django/urls/resolvers.py", line 405, in url_patterns
    patterns = getattr(self.urlconf_module, "urlpatterns", self.urlconf_module)
  File "/ops-data/zp/haha/mysite-11/lib/python3.6/site-packages/django/utils/functional.py", line 35, in __get__
    res = instance.__dict__[self.name] = self.func(instance)
  File "/ops-data/zp/haha/mysite-11/lib/python3.6/site-packages/django/urls/resolvers.py", line 398, in urlconf_module
    return import_module(self.urlconf_name)
  File "/ops-data/zp/haha/mysite-11/lib/python3.6/importlib/__init__.py", line 126, in import_module
    return _bootstrap._gcd_import(name[level:], package, level)
  File "<frozen importlib._bootstrap>", line 994, in _gcd_import
  File "<frozen importlib._bootstrap>", line 971, in _find_and_load
  File "<frozen importlib._bootstrap>", line 955, in _find_and_load_unlocked
  File "<frozen importlib._bootstrap>", line 665, in _load_unlocked
  File "<frozen importlib._bootstrap_external>", line 678, in exec_module
  File "<frozen importlib._bootstrap>", line 219, in _call_with_frames_removed
  File "/ops-data/zp/haha/mysite-11/opsweb/opsweb/urls.py", line 26, in <module>
    url(r'^helloworld/', include("helloworld.urls")),
  File "/ops-data/zp/haha/mysite-11/lib/python3.6/site-packages/django/conf/urls/__init__.py", line 50, in include
    urlconf_module = import_module(urlconf_module)
  File "/ops-data/zp/haha/mysite-11/lib/python3.6/importlib/__init__.py", line 126, in import_module
    return _bootstrap._gcd_import(name[level:], package, level)
  File "<frozen importlib._bootstrap>", line 994, in _gcd_import
  File "<frozen importlib._bootstrap>", line 971, in _find_and_load
  File "<frozen importlib._bootstrap>", line 941, in _find_and_load_unlocked
  File "<frozen importlib._bootstrap>", line 219, in _call_with_frames_removed
  File "<frozen importlib._bootstrap>", line 994, in _gcd_import
  File "<frozen importlib._bootstrap>", line 971, in _find_and_load
  File "<frozen importlib._bootstrap>", line 953, in _find_and_load_unlocked
ModuleNotFoundError: No module named 'helloworld'

During handling of the above exception, another exception occurred:

Traceback (most recent call last):
  File "/ops-data/zp/haha/mysite-11/lib/python3.6/site-packages/gunicorn/workers/sync.py", line 135, in handle
    self.handle_request(listener, req, client, addr)
  File "/ops-data/zp/haha/mysite-11/lib/python3.6/site-packages/gunicorn/workers/sync.py", line 176, in handle_request
    respiter = self.wsgi(environ, resp.start_response)
  File "/ops-data/zp/haha/mysite-11/lib/python3.6/site-packages/django/core/handlers/wsgi.py", line 157, in __call__
    response = self.get_response(request)
  File "/ops-data/zp/haha/mysite-11/lib/python3.6/site-packages/django/core/handlers/base.py", line 124, in get_response
    response = self._middleware_chain(request)
  File "/ops-data/zp/haha/mysite-11/lib/python3.6/site-packages/django/core/handlers/exception.py", line 43, in inner
    response = response_for_exception(request, exc)
  File "/ops-data/zp/haha/mysite-11/lib/python3.6/site-packages/django/core/handlers/exception.py", line 93, in response_for_exception
    response = handle_uncaught_exception(request, get_resolver(get_urlconf()), sys.exc_info())
  File "/ops-data/zp/haha/mysite-11/lib/python3.6/site-packages/django/core/handlers/exception.py", line 142, in handle_uncaught_exception
    callback, param_dict = resolver.resolve_error_handler(500)
  File "/ops-data/zp/haha/mysite-11/lib/python3.6/site-packages/django/urls/resolvers.py", line 418, in resolve_error_handler
    callback = getattr(self.urlconf_module, 'handler%s' % view_type, None)
  File "/ops-data/zp/haha/mysite-11/lib/python3.6/site-packages/django/utils/functional.py", line 35, in __get__
    res = instance.__dict__[self.name] = self.func(instance)
  File "/ops-data/zp/haha/mysite-11/lib/python3.6/site-packages/django/urls/resolvers.py", line 398, in urlconf_module
    return import_module(self.urlconf_name)
  File "/ops-data/zp/haha/mysite-11/lib/python3.6/importlib/__init__.py", line 126, in import_module
    return _bootstrap._gcd_import(name[level:], package, level)
  File "<frozen importlib._bootstrap>", line 994, in _gcd_import
  File "<frozen importlib._bootstrap>", line 971, in _find_and_load
  File "<frozen importlib._bootstrap>", line 955, in _find_and_load_unlocked
  File "<frozen importlib._bootstrap>", line 665, in _load_unlocked
  File "<frozen importlib._bootstrap_external>", line 678, in exec_module
  File "<frozen importlib._bootstrap>", line 219, in _call_with_frames_removed
  File "/ops-data/zp/haha/mysite-11/opsweb/opsweb/urls.py", line 26, in <module>
    url(r'^helloworld/', include("helloworld.urls")),
  File "/ops-data/zp/haha/mysite-11/lib/python3.6/site-packages/django/conf/urls/__init__.py", line 50, in include
    urlconf_module = import_module(urlconf_module)
  File "/ops-data/zp/haha/mysite-11/lib/python3.6/importlib/__init__.py", line 126, in import_module
    return _bootstrap._gcd_import(name[level:], package, level)
  File "<frozen importlib._bootstrap>", line 994, in _gcd_import
  File "<frozen importlib._bootstrap>", line 971, in _find_and_load
  File "<frozen importlib._bootstrap>", line 941, in _find_and_load_unlocked
  File "<frozen importlib._bootstrap>", line 219, in _call_with_frames_removed
  File "<frozen importlib._bootstrap>", line 994, in _gcd_import
  File "<frozen importlib._bootstrap>", line 971, in _find_and_load
  File "<frozen importlib._bootstrap>", line 953, in _find_and_load_unlocked
ModuleNotFoundError: No module named 'helloworld'
[2018-03-28 10:55:13 +0800] [19427] [ERROR] Error handling request /dashboard/
Traceback (most recent call last):
  File "/ops-data/zp/haha/mysite-11/lib/python3.6/site-packages/django/core/handlers/exception.py", line 41, in inner
    response = get_response(request)
  File "/ops-data/zp/haha/mysite-11/lib/python3.6/site-packages/django/core/handlers/base.py", line 249, in _legacy_get_response
    response = self._get_response(request)
  File "/ops-data/zp/haha/mysite-11/lib/python3.6/site-packages/django/core/handlers/base.py", line 172, in _get_response
    resolver_match = resolver.resolve(request.path_info)
  File "/ops-data/zp/haha/mysite-11/lib/python3.6/site-packages/django/urls/resolvers.py", line 362, in resolve
    for pattern in self.url_patterns:
  File "/ops-data/zp/haha/mysite-11/lib/python3.6/site-packages/django/utils/functional.py", line 35, in __get__
    res = instance.__dict__[self.name] = self.func(instance)
  File "/ops-data/zp/haha/mysite-11/lib/python3.6/site-packages/django/urls/resolvers.py", line 405, in url_patterns
    patterns = getattr(self.urlconf_module, "urlpatterns", self.urlconf_module)
  File "/ops-data/zp/haha/mysite-11/lib/python3.6/site-packages/django/utils/functional.py", line 35, in __get__
    res = instance.__dict__[self.name] = self.func(instance)
  File "/ops-data/zp/haha/mysite-11/lib/python3.6/site-packages/django/urls/resolvers.py", line 398, in urlconf_module
    return import_module(self.urlconf_name)
  File "/ops-data/zp/haha/mysite-11/lib/python3.6/importlib/__init__.py", line 126, in import_module
    return _bootstrap._gcd_import(name[level:], package, level)
  File "<frozen importlib._bootstrap>", line 994, in _gcd_import
  File "<frozen importlib._bootstrap>", line 971, in _find_and_load
  File "<frozen importlib._bootstrap>", line 955, in _find_and_load_unlocked
  File "<frozen importlib._bootstrap>", line 665, in _load_unlocked
  File "<frozen importlib._bootstrap_external>", line 678, in exec_module
  File "<frozen importlib._bootstrap>", line 219, in _call_with_frames_removed
  File "/ops-data/zp/haha/mysite-11/opsweb/opsweb/urls.py", line 26, in <module>
    url(r'^helloworld/', include("helloworld.urls")),
  File "/ops-data/zp/haha/mysite-11/lib/python3.6/site-packages/django/conf/urls/__init__.py", line 50, in include
    urlconf_module = import_module(urlconf_module)
  File "/ops-data/zp/haha/mysite-11/lib/python3.6/importlib/__init__.py", line 126, in import_module
    return _bootstrap._gcd_import(name[level:], package, level)
  File "<frozen importlib._bootstrap>", line 994, in _gcd_import
  File "<frozen importlib._bootstrap>", line 971, in _find_and_load
  File "<frozen importlib._bootstrap>", line 941, in _find_and_load_unlocked
  File "<frozen importlib._bootstrap>", line 219, in _call_with_frames_removed
  File "<frozen importlib._bootstrap>", line 994, in _gcd_import
  File "<frozen importlib._bootstrap>", line 971, in _find_and_load
  File "<frozen importlib._bootstrap>", line 953, in _find_and_load_unlocked
ModuleNotFoundError: No module named 'helloworld'

During handling of the above exception, another exception occurred:

Traceback (most recent call last):
  File "/ops-data/zp/haha/mysite-11/lib/python3.6/site-packages/gunicorn/workers/sync.py", line 135, in handle
    self.handle_request(listener, req, client, addr)
  File "/ops-data/zp/haha/mysite-11/lib/python3.6/site-packages/gunicorn/workers/sync.py", line 176, in handle_request
    respiter = self.wsgi(environ, resp.start_response)
  File "/ops-data/zp/haha/mysite-11/lib/python3.6/site-packages/django/core/handlers/wsgi.py", line 157, in __call__
    response = self.get_response(request)
  File "/ops-data/zp/haha/mysite-11/lib/python3.6/site-packages/django/core/handlers/base.py", line 124, in get_response
    response = self._middleware_chain(request)
  File "/ops-data/zp/haha/mysite-11/lib/python3.6/site-packages/django/core/handlers/exception.py", line 43, in inner
    response = response_for_exception(request, exc)
  File "/ops-data/zp/haha/mysite-11/lib/python3.6/site-packages/django/core/handlers/exception.py", line 93, in response_for_exception
    response = handle_uncaught_exception(request, get_resolver(get_urlconf()), sys.exc_info())
  File "/ops-data/zp/haha/mysite-11/lib/python3.6/site-packages/django/core/handlers/exception.py", line 142, in handle_uncaught_exception
    callback, param_dict = resolver.resolve_error_handler(500)
  File "/ops-data/zp/haha/mysite-11/lib/python3.6/site-packages/django/urls/resolvers.py", line 418, in resolve_error_handler
    callback = getattr(self.urlconf_module, 'handler%s' % view_type, None)
  File "/ops-data/zp/haha/mysite-11/lib/python3.6/site-packages/django/utils/functional.py", line 35, in __get__
    res = instance.__dict__[self.name] = self.func(instance)
  File "/ops-data/zp/haha/mysite-11/lib/python3.6/site-packages/django/urls/resolvers.py", line 398, in urlconf_module
    return import_module(self.urlconf_name)
  File "/ops-data/zp/haha/mysite-11/lib/python3.6/importlib/__init__.py", line 126, in import_module
    return _bootstrap._gcd_import(name[level:], package, level)
  File "<frozen importlib._bootstrap>", line 994, in _gcd_import
  File "<frozen importlib._bootstrap>", line 971, in _find_and_load
  File "<frozen importlib._bootstrap>", line 955, in _find_and_load_unlocked
  File "<frozen importlib._bootstrap>", line 665, in _load_unlocked
  File "<frozen importlib._bootstrap_external>", line 678, in exec_module
  File "<frozen importlib._bootstrap>", line 219, in _call_with_frames_removed
  File "/ops-data/zp/haha/mysite-11/opsweb/opsweb/urls.py", line 26, in <module>
    url(r'^helloworld/', include("helloworld.urls")),
  File "/ops-data/zp/haha/mysite-11/lib/python3.6/site-packages/django/conf/urls/__init__.py", line 50, in include
    urlconf_module = import_module(urlconf_module)
  File "/ops-data/zp/haha/mysite-11/lib/python3.6/importlib/__init__.py", line 126, in import_module
    return _bootstrap._gcd_import(name[level:], package, level)
  File "<frozen importlib._bootstrap>", line 994, in _gcd_import
  File "<frozen importlib._bootstrap>", line 971, in _find_and_load
  File "<frozen importlib._bootstrap>", line 941, in _find_and_load_unlocked
  File "<frozen importlib._bootstrap>", line 219, in _call_with_frames_removed
  File "<frozen importlib._bootstrap>", line 994, in _gcd_import
  File "<frozen importlib._bootstrap>", line 971, in _find_and_load
  File "<frozen importlib._bootstrap>", line 953, in _find_and_load_unlocked
ModuleNotFoundError: No module named 'helloworld'
[2018-03-28 10:55:13 +0800] [19422] [ERROR] Error handling request /dashboard/
Traceback (most recent call last):
  File "/ops-data/zp/haha/mysite-11/lib/python3.6/site-packages/django/core/handlers/exception.py", line 41, in inner
    response = get_response(request)
  File "/ops-data/zp/haha/mysite-11/lib/python3.6/site-packages/django/core/handlers/base.py", line 249, in _legacy_get_response
    response = self._get_response(request)
  File "/ops-data/zp/haha/mysite-11/lib/python3.6/site-packages/django/core/handlers/base.py", line 172, in _get_response
    resolver_match = resolver.resolve(request.path_info)
  File "/ops-data/zp/haha/mysite-11/lib/python3.6/site-packages/django/urls/resolvers.py", line 362, in resolve
    for pattern in self.url_patterns:
  File "/ops-data/zp/haha/mysite-11/lib/python3.6/site-packages/django/utils/functional.py", line 35, in __get__
    res = instance.__dict__[self.name] = self.func(instance)
  File "/ops-data/zp/haha/mysite-11/lib/python3.6/site-packages/django/urls/resolvers.py", line 405, in url_patterns
    patterns = getattr(self.urlconf_module, "urlpatterns", self.urlconf_module)
  File "/ops-data/zp/haha/mysite-11/lib/python3.6/site-packages/django/utils/functional.py", line 35, in __get__
    res = instance.__dict__[self.name] = self.func(instance)
  File "/ops-data/zp/haha/mysite-11/lib/python3.6/site-packages/django/urls/resolvers.py", line 398, in urlconf_module
    return import_module(self.urlconf_name)
  File "/ops-data/zp/haha/mysite-11/lib/python3.6/importlib/__init__.py", line 126, in import_module
    return _bootstrap._gcd_import(name[level:], package, level)
  File "<frozen importlib._bootstrap>", line 994, in _gcd_import
  File "<frozen importlib._bootstrap>", line 971, in _find_and_load
  File "<frozen importlib._bootstrap>", line 955, in _find_and_load_unlocked
  File "<frozen importlib._bootstrap>", line 665, in _load_unlocked
  File "<frozen importlib._bootstrap_external>", line 678, in exec_module
  File "<frozen importlib._bootstrap>", line 219, in _call_with_frames_removed
  File "/ops-data/zp/haha/mysite-11/opsweb/opsweb/urls.py", line 26, in <module>
    url(r'^helloworld/', include("helloworld.urls")),
  File "/ops-data/zp/haha/mysite-11/lib/python3.6/site-packages/django/conf/urls/__init__.py", line 50, in include
    urlconf_module = import_module(urlconf_module)
  File "/ops-data/zp/haha/mysite-11/lib/python3.6/importlib/__init__.py", line 126, in import_module
    return _bootstrap._gcd_import(name[level:], package, level)
  File "<frozen importlib._bootstrap>", line 994, in _gcd_import
  File "<frozen importlib._bootstrap>", line 971, in _find_and_load
  File "<frozen importlib._bootstrap>", line 941, in _find_and_load_unlocked
  File "<frozen importlib._bootstrap>", line 219, in _call_with_frames_removed
  File "<frozen importlib._bootstrap>", line 994, in _gcd_import
  File "<frozen importlib._bootstrap>", line 971, in _find_and_load
  File "<frozen importlib._bootstrap>", line 953, in _find_and_load_unlocked
ModuleNotFoundError: No module named 'helloworld'

During handling of the above exception, another exception occurred:

Traceback (most recent call last):
  File "/ops-data/zp/haha/mysite-11/lib/python3.6/site-packages/gunicorn/workers/sync.py", line 135, in handle
    self.handle_request(listener, req, client, addr)
  File "/ops-data/zp/haha/mysite-11/lib/python3.6/site-packages/gunicorn/workers/sync.py", line 176, in handle_request
    respiter = self.wsgi(environ, resp.start_response)
  File "/ops-data/zp/haha/mysite-11/lib/python3.6/site-packages/django/core/handlers/wsgi.py", line 157, in __call__
    response = self.get_response(request)
  File "/ops-data/zp/haha/mysite-11/lib/python3.6/site-packages/django/core/handlers/base.py", line 124, in get_response
    response = self._middleware_chain(request)
  File "/ops-data/zp/haha/mysite-11/lib/python3.6/site-packages/django/core/handlers/exception.py", line 43, in inner
    response = response_for_exception(request, exc)
  File "/ops-data/zp/haha/mysite-11/lib/python3.6/site-packages/django/core/handlers/exception.py", line 93, in response_for_exception
    response = handle_uncaught_exception(request, get_resolver(get_urlconf()), sys.exc_info())
  File "/ops-data/zp/haha/mysite-11/lib/python3.6/site-packages/django/core/handlers/exception.py", line 142, in handle_uncaught_exception
    callback, param_dict = resolver.resolve_error_handler(500)
  File "/ops-data/zp/haha/mysite-11/lib/python3.6/site-packages/django/urls/resolvers.py", line 418, in resolve_error_handler
    callback = getattr(self.urlconf_module, 'handler%s' % view_type, None)
  File "/ops-data/zp/haha/mysite-11/lib/python3.6/site-packages/django/utils/functional.py", line 35, in __get__
    res = instance.__dict__[self.name] = self.func(instance)
  File "/ops-data/zp/haha/mysite-11/lib/python3.6/site-packages/django/urls/resolvers.py", line 398, in urlconf_module
    return import_module(self.urlconf_name)
  File "/ops-data/zp/haha/mysite-11/lib/python3.6/importlib/__init__.py", line 126, in import_module
    return _bootstrap._gcd_import(name[level:], package, level)
  File "<frozen importlib._bootstrap>", line 994, in _gcd_import
  File "<frozen importlib._bootstrap>", line 971, in _find_and_load
  File "<frozen importlib._bootstrap>", line 955, in _find_and_load_unlocked
  File "<frozen importlib._bootstrap>", line 665, in _load_unlocked
  File "<frozen importlib._bootstrap_external>", line 678, in exec_module
  File "<frozen importlib._bootstrap>", line 219, in _call_with_frames_removed
  File "/ops-data/zp/haha/mysite-11/opsweb/opsweb/urls.py", line 26, in <module>
    url(r'^helloworld/', include("helloworld.urls")),
  File "/ops-data/zp/haha/mysite-11/lib/python3.6/site-packages/django/conf/urls/__init__.py", line 50, in include
    urlconf_module = import_module(urlconf_module)
  File "/ops-data/zp/haha/mysite-11/lib/python3.6/importlib/__init__.py", line 126, in import_module
    return _bootstrap._gcd_import(name[level:], package, level)
  File "<frozen importlib._bootstrap>", line 994, in _gcd_import
  File "<frozen importlib._bootstrap>", line 971, in _find_and_load
  File "<frozen importlib._bootstrap>", line 941, in _find_and_load_unlocked
  File "<frozen importlib._bootstrap>", line 219, in _call_with_frames_removed
  File "<frozen importlib._bootstrap>", line 994, in _gcd_import
  File "<frozen importlib._bootstrap>", line 971, in _find_and_load
  File "<frozen importlib._bootstrap>", line 953, in _find_and_load_unlocked
ModuleNotFoundError: No module named 'helloworld'
[2018-03-28 10:55:13 +0800] [19427] [ERROR] Error handling request /dashboard/
Traceback (most recent call last):
  File "/ops-data/zp/haha/mysite-11/lib/python3.6/site-packages/django/core/handlers/exception.py", line 41, in inner
    response = get_response(request)
  File "/ops-data/zp/haha/mysite-11/lib/python3.6/site-packages/django/core/handlers/base.py", line 249, in _legacy_get_response
    response = self._get_response(request)
  File "/ops-data/zp/haha/mysite-11/lib/python3.6/site-packages/django/core/handlers/base.py", line 172, in _get_response
    resolver_match = resolver.resolve(request.path_info)
  File "/ops-data/zp/haha/mysite-11/lib/python3.6/site-packages/django/urls/resolvers.py", line 362, in resolve
    for pattern in self.url_patterns:
  File "/ops-data/zp/haha/mysite-11/lib/python3.6/site-packages/django/utils/functional.py", line 35, in __get__
    res = instance.__dict__[self.name] = self.func(instance)
  File "/ops-data/zp/haha/mysite-11/lib/python3.6/site-packages/django/urls/resolvers.py", line 405, in url_patterns
    patterns = getattr(self.urlconf_module, "urlpatterns", self.urlconf_module)
  File "/ops-data/zp/haha/mysite-11/lib/python3.6/site-packages/django/utils/functional.py", line 35, in __get__
    res = instance.__dict__[self.name] = self.func(instance)
  File "/ops-data/zp/haha/mysite-11/lib/python3.6/site-packages/django/urls/resolvers.py", line 398, in urlconf_module
    return import_module(self.urlconf_name)
  File "/ops-data/zp/haha/mysite-11/lib/python3.6/importlib/__init__.py", line 126, in import_module
    return _bootstrap._gcd_import(name[level:], package, level)
  File "<frozen importlib._bootstrap>", line 994, in _gcd_import
  File "<frozen importlib._bootstrap>", line 971, in _find_and_load
  File "<frozen importlib._bootstrap>", line 955, in _find_and_load_unlocked
  File "<frozen importlib._bootstrap>", line 665, in _load_unlocked
  File "<frozen importlib._bootstrap_external>", line 678, in exec_module
  File "<frozen importlib._bootstrap>", line 219, in _call_with_frames_removed
  File "/ops-data/zp/haha/mysite-11/opsweb/opsweb/urls.py", line 26, in <module>
    url(r'^helloworld/', include("helloworld.urls")),
  File "/ops-data/zp/haha/mysite-11/lib/python3.6/site-packages/django/conf/urls/__init__.py", line 50, in include
    urlconf_module = import_module(urlconf_module)
  File "/ops-data/zp/haha/mysite-11/lib/python3.6/importlib/__init__.py", line 126, in import_module
    return _bootstrap._gcd_import(name[level:], package, level)
  File "<frozen importlib._bootstrap>", line 994, in _gcd_import
  File "<frozen importlib._bootstrap>", line 971, in _find_and_load
  File "<frozen importlib._bootstrap>", line 941, in _find_and_load_unlocked
  File "<frozen importlib._bootstrap>", line 219, in _call_with_frames_removed
  File "<frozen importlib._bootstrap>", line 994, in _gcd_import
  File "<frozen importlib._bootstrap>", line 971, in _find_and_load
  File "<frozen importlib._bootstrap>", line 953, in _find_and_load_unlocked
ModuleNotFoundError: No module named 'helloworld'

During handling of the above exception, another exception occurred:

Traceback (most recent call last):
  File "/ops-data/zp/haha/mysite-11/lib/python3.6/site-packages/gunicorn/workers/sync.py", line 135, in handle
    self.handle_request(listener, req, client, addr)
  File "/ops-data/zp/haha/mysite-11/lib/python3.6/site-packages/gunicorn/workers/sync.py", line 176, in handle_request
    respiter = self.wsgi(environ, resp.start_response)
  File "/ops-data/zp/haha/mysite-11/lib/python3.6/site-packages/django/core/handlers/wsgi.py", line 157, in __call__
    response = self.get_response(request)
  File "/ops-data/zp/haha/mysite-11/lib/python3.6/site-packages/django/core/handlers/base.py", line 124, in get_response
    response = self._middleware_chain(request)
  File "/ops-data/zp/haha/mysite-11/lib/python3.6/site-packages/django/core/handlers/exception.py", line 43, in inner
    response = response_for_exception(request, exc)
  File "/ops-data/zp/haha/mysite-11/lib/python3.6/site-packages/django/core/handlers/exception.py", line 93, in response_for_exception
    response = handle_uncaught_exception(request, get_resolver(get_urlconf()), sys.exc_info())
  File "/ops-data/zp/haha/mysite-11/lib/python3.6/site-packages/django/core/handlers/exception.py", line 142, in handle_uncaught_exception
    callback, param_dict = resolver.resolve_error_handler(500)
  File "/ops-data/zp/haha/mysite-11/lib/python3.6/site-packages/django/urls/resolvers.py", line 418, in resolve_error_handler
    callback = getattr(self.urlconf_module, 'handler%s' % view_type, None)
  File "/ops-data/zp/haha/mysite-11/lib/python3.6/site-packages/django/utils/functional.py", line 35, in __get__
    res = instance.__dict__[self.name] = self.func(instance)
  File "/ops-data/zp/haha/mysite-11/lib/python3.6/site-packages/django/urls/resolvers.py", line 398, in urlconf_module
    return import_module(self.urlconf_name)
  File "/ops-data/zp/haha/mysite-11/lib/python3.6/importlib/__init__.py", line 126, in import_module
    return _bootstrap._gcd_import(name[level:], package, level)
  File "<frozen importlib._bootstrap>", line 994, in _gcd_import
  File "<frozen importlib._bootstrap>", line 971, in _find_and_load
  File "<frozen importlib._bootstrap>", line 955, in _find_and_load_unlocked
  File "<frozen importlib._bootstrap>", line 665, in _load_unlocked
  File "<frozen importlib._bootstrap_external>", line 678, in exec_module
  File "<frozen importlib._bootstrap>", line 219, in _call_with_frames_removed
  File "/ops-data/zp/haha/mysite-11/opsweb/opsweb/urls.py", line 26, in <module>
    url(r'^helloworld/', include("helloworld.urls")),
  File "/ops-data/zp/haha/mysite-11/lib/python3.6/site-packages/django/conf/urls/__init__.py", line 50, in include
    urlconf_module = import_module(urlconf_module)
  File "/ops-data/zp/haha/mysite-11/lib/python3.6/importlib/__init__.py", line 126, in import_module
    return _bootstrap._gcd_import(name[level:], package, level)
  File "<frozen importlib._bootstrap>", line 994, in _gcd_import
  File "<frozen importlib._bootstrap>", line 971, in _find_and_load
  File "<frozen importlib._bootstrap>", line 941, in _find_and_load_unlocked
  File "<frozen importlib._bootstrap>", line 219, in _call_with_frames_removed
  File "<frozen importlib._bootstrap>", line 994, in _gcd_import
  File "<frozen importlib._bootstrap>", line 971, in _find_and_load
  File "<frozen importlib._bootstrap>", line 953, in _find_and_load_unlocked
ModuleNotFoundError: No module named 'helloworld'
[2018-04-12 10:18:54 +0800] [22663] [ERROR] Exception in worker process
Traceback (most recent call last):
  File "/ops-data/zp/haha/mysite-11/lib/python3.6/site-packages/gunicorn/arbiter.py", line 578, in spawn_worker
    worker.init_process()
  File "/ops-data/zp/haha/mysite-11/lib/python3.6/site-packages/gunicorn/workers/base.py", line 126, in init_process
    self.load_wsgi()
  File "/ops-data/zp/haha/mysite-11/lib/python3.6/site-packages/gunicorn/workers/base.py", line 135, in load_wsgi
    self.wsgi = self.app.wsgi()
  File "/ops-data/zp/haha/mysite-11/lib/python3.6/site-packages/gunicorn/app/base.py", line 67, in wsgi
    self.callable = self.load()
  File "/ops-data/zp/haha/mysite-11/lib/python3.6/site-packages/gunicorn/app/wsgiapp.py", line 65, in load
    return self.load_wsgiapp()
  File "/ops-data/zp/haha/mysite-11/lib/python3.6/site-packages/gunicorn/app/wsgiapp.py", line 52, in load_wsgiapp
    return util.import_app(self.app_uri)
  File "/ops-data/zp/haha/mysite-11/lib/python3.6/site-packages/gunicorn/util.py", line 352, in import_app
    __import__(module)
  File "/ops-data/zp/haha/mysite-11/opsweb/opsweb/wsgi.py", line 16, in <module>
    application = get_wsgi_application()
  File "/ops-data/zp/haha/mysite-11/lib/python3.6/site-packages/django/core/wsgi.py", line 13, in get_wsgi_application
    django.setup(set_prefix=False)
  File "/ops-data/zp/haha/mysite-11/lib/python3.6/site-packages/django/__init__.py", line 22, in setup
    configure_logging(settings.LOGGING_CONFIG, settings.LOGGING)
  File "/ops-data/zp/haha/mysite-11/lib/python3.6/site-packages/django/conf/__init__.py", line 56, in __getattr__
    self._setup(name)
  File "/ops-data/zp/haha/mysite-11/lib/python3.6/site-packages/django/conf/__init__.py", line 41, in _setup
    self._wrapped = Settings(settings_module)
  File "/ops-data/zp/haha/mysite-11/lib/python3.6/site-packages/django/conf/__init__.py", line 110, in __init__
    mod = importlib.import_module(self.SETTINGS_MODULE)
  File "/ops-data/zp/haha/mysite-11/lib/python3.6/importlib/__init__.py", line 126, in import_module
    return _bootstrap._gcd_import(name[level:], package, level)
  File "/ops-data/zp/haha/mysite-11/opsweb/opsweb/settings.py", line 272, in <module>
    import  djcelery
  File "/ops-data/zp/haha/mysite-11/lib/python3.6/site-packages/djcelery/__init__.py", line 34, in <module>
    from celery import current_app as celery  # noqa
ImportError: cannot import name 'current_app'
[2018-04-18 16:49:02 +0800] [12658] [ERROR] Exception in worker process
Traceback (most recent call last):
  File "/ops-data/zp/haha/mysite-11/lib/python3.6/site-packages/gunicorn/arbiter.py", line 578, in spawn_worker
    worker.init_process()
  File "/ops-data/zp/haha/mysite-11/lib/python3.6/site-packages/gunicorn/workers/base.py", line 126, in init_process
    self.load_wsgi()
  File "/ops-data/zp/haha/mysite-11/lib/python3.6/site-packages/gunicorn/workers/base.py", line 135, in load_wsgi
    self.wsgi = self.app.wsgi()
  File "/ops-data/zp/haha/mysite-11/lib/python3.6/site-packages/gunicorn/app/base.py", line 67, in wsgi
    self.callable = self.load()
  File "/ops-data/zp/haha/mysite-11/lib/python3.6/site-packages/gunicorn/app/wsgiapp.py", line 65, in load
    return self.load_wsgiapp()
  File "/ops-data/zp/haha/mysite-11/lib/python3.6/site-packages/gunicorn/app/wsgiapp.py", line 52, in load_wsgiapp
    return util.import_app(self.app_uri)
  File "/ops-data/zp/haha/mysite-11/lib/python3.6/site-packages/gunicorn/util.py", line 352, in import_app
    __import__(module)
  File "/ops-data/zp/haha/mysite-11/opsweb/opsweb/wsgi.py", line 16, in <module>
    application = get_wsgi_application()
  File "/ops-data/zp/haha/mysite-11/lib/python3.6/site-packages/django/core/wsgi.py", line 13, in get_wsgi_application
    django.setup(set_prefix=False)
  File "/ops-data/zp/haha/mysite-11/lib/python3.6/site-packages/django/__init__.py", line 27, in setup
    apps.populate(settings.INSTALLED_APPS)
  File "/ops-data/zp/haha/mysite-11/lib/python3.6/site-packages/django/apps/registry.py", line 116, in populate
    app_config.ready()
  File "/ops-data/zp/haha/mysite-11/lib/python3.6/site-packages/django/contrib/admin/apps.py", line 23, in ready
    self.module.autodiscover()
  File "/ops-data/zp/haha/mysite-11/lib/python3.6/site-packages/django/contrib/admin/__init__.py", line 26, in autodiscover
    autodiscover_modules('admin', register_to=site)
  File "/ops-data/zp/haha/mysite-11/lib/python3.6/site-packages/django/utils/module_loading.py", line 50, in autodiscover_modules
    import_module('%s.%s' % (app_config.name, module_to_search))
  File "/ops-data/zp/haha/mysite-11/lib/python3.6/importlib/__init__.py", line 126, in import_module
    return _bootstrap._gcd_import(name[level:], package, level)
  File "/ops-data/zp/haha/mysite-11/opsweb/dbmanager/admin.py", line 8, in <module>
    from .models import Instance, Database, Cluster,IncControl
ImportError: cannot import name 'IncControl'
[2018-04-18 16:49:03 +0800] [12660] [ERROR] Exception in worker process
Traceback (most recent call last):
  File "/ops-data/zp/haha/mysite-11/lib/python3.6/site-packages/gunicorn/arbiter.py", line 578, in spawn_worker
    worker.init_process()
  File "/ops-data/zp/haha/mysite-11/lib/python3.6/site-packages/gunicorn/workers/base.py", line 126, in init_process
    self.load_wsgi()
  File "/ops-data/zp/haha/mysite-11/lib/python3.6/site-packages/gunicorn/workers/base.py", line 135, in load_wsgi
    self.wsgi = self.app.wsgi()
  File "/ops-data/zp/haha/mysite-11/lib/python3.6/site-packages/gunicorn/app/base.py", line 67, in wsgi
    self.callable = self.load()
  File "/ops-data/zp/haha/mysite-11/lib/python3.6/site-packages/gunicorn/app/wsgiapp.py", line 65, in load
    return self.load_wsgiapp()
  File "/ops-data/zp/haha/mysite-11/lib/python3.6/site-packages/gunicorn/app/wsgiapp.py", line 52, in load_wsgiapp
    return util.import_app(self.app_uri)
  File "/ops-data/zp/haha/mysite-11/lib/python3.6/site-packages/gunicorn/util.py", line 352, in import_app
    __import__(module)
  File "/ops-data/zp/haha/mysite-11/opsweb/opsweb/wsgi.py", line 16, in <module>
    application = get_wsgi_application()
  File "/ops-data/zp/haha/mysite-11/lib/python3.6/site-packages/django/core/wsgi.py", line 13, in get_wsgi_application
    django.setup(set_prefix=False)
  File "/ops-data/zp/haha/mysite-11/lib/python3.6/site-packages/django/__init__.py", line 27, in setup
    apps.populate(settings.INSTALLED_APPS)
  File "/ops-data/zp/haha/mysite-11/lib/python3.6/site-packages/django/apps/registry.py", line 116, in populate
    app_config.ready()
  File "/ops-data/zp/haha/mysite-11/lib/python3.6/site-packages/django/contrib/admin/apps.py", line 23, in ready
    self.module.autodiscover()
  File "/ops-data/zp/haha/mysite-11/lib/python3.6/site-packages/django/contrib/admin/__init__.py", line 26, in autodiscover
    autodiscover_modules('admin', register_to=site)
  File "/ops-data/zp/haha/mysite-11/lib/python3.6/site-packages/django/utils/module_loading.py", line 50, in autodiscover_modules
    import_module('%s.%s' % (app_config.name, module_to_search))
  File "/ops-data/zp/haha/mysite-11/lib/python3.6/importlib/__init__.py", line 126, in import_module
    return _bootstrap._gcd_import(name[level:], package, level)
  File "/ops-data/zp/haha/mysite-11/opsweb/dbmanager/admin.py", line 8, in <module>
    from .models import Instance, Database, Cluster,IncControl
ImportError: cannot import name 'IncControl'
[2018-04-18 17:16:43 +0800] [22655] [ERROR] Error handling request /workform/pub/add/
Traceback (most recent call last):
  File "/ops-data/zp/haha/mysite-11/lib/python3.6/site-packages/django/core/handlers/exception.py", line 41, in inner
    response = get_response(request)
  File "/ops-data/zp/haha/mysite-11/lib/python3.6/site-packages/django/core/handlers/base.py", line 249, in _legacy_get_response
    response = self._get_response(request)
  File "/ops-data/zp/haha/mysite-11/lib/python3.6/site-packages/django/core/handlers/base.py", line 172, in _get_response
    resolver_match = resolver.resolve(request.path_info)
  File "/ops-data/zp/haha/mysite-11/lib/python3.6/site-packages/django/urls/resolvers.py", line 362, in resolve
    for pattern in self.url_patterns:
  File "/ops-data/zp/haha/mysite-11/lib/python3.6/site-packages/django/utils/functional.py", line 35, in __get__
    res = instance.__dict__[self.name] = self.func(instance)
  File "/ops-data/zp/haha/mysite-11/lib/python3.6/site-packages/django/urls/resolvers.py", line 405, in url_patterns
    patterns = getattr(self.urlconf_module, "urlpatterns", self.urlconf_module)
  File "/ops-data/zp/haha/mysite-11/lib/python3.6/site-packages/django/utils/functional.py", line 35, in __get__
    res = instance.__dict__[self.name] = self.func(instance)
  File "/ops-data/zp/haha/mysite-11/lib/python3.6/site-packages/django/urls/resolvers.py", line 398, in urlconf_module
    return import_module(self.urlconf_name)
  File "/ops-data/zp/haha/mysite-11/lib/python3.6/importlib/__init__.py", line 126, in import_module
    return _bootstrap._gcd_import(name[level:], package, level)
  File "<frozen importlib._bootstrap>", line 994, in _gcd_import
  File "<frozen importlib._bootstrap>", line 971, in _find_and_load
  File "<frozen importlib._bootstrap>", line 955, in _find_and_load_unlocked
  File "<frozen importlib._bootstrap>", line 665, in _load_unlocked
  File "<frozen importlib._bootstrap_external>", line 678, in exec_module
  File "<frozen importlib._bootstrap>", line 219, in _call_with_frames_removed
  File "/ops-data/zp/haha/mysite-11/opsweb/opsweb/urls.py", line 31, in <module>
    url(r'^workform/', include("workform.urls")),
  File "/ops-data/zp/haha/mysite-11/lib/python3.6/site-packages/django/conf/urls/__init__.py", line 50, in include
    urlconf_module = import_module(urlconf_module)
  File "/ops-data/zp/haha/mysite-11/lib/python3.6/importlib/__init__.py", line 126, in import_module
    return _bootstrap._gcd_import(name[level:], package, level)
  File "<frozen importlib._bootstrap>", line 994, in _gcd_import
  File "<frozen importlib._bootstrap>", line 971, in _find_and_load
  File "<frozen importlib._bootstrap>", line 955, in _find_and_load_unlocked
  File "<frozen importlib._bootstrap>", line 665, in _load_unlocked
  File "<frozen importlib._bootstrap_external>", line 678, in exec_module
  File "<frozen importlib._bootstrap>", line 219, in _call_with_frames_removed
  File "/ops-data/zp/haha/mysite-11/opsweb/workform/urls.py", line 4, in <module>
    from . import views,workform_type,workform_process
  File "/ops-data/zp/haha/mysite-11/opsweb/workform/views.py", line 22, in <module>
    from dbmanager.tasks import sync_workform_sql
  File "/ops-data/zp/haha/mysite-11/opsweb/dbmanager/tasks.py", line 21, in <module>
    from opsweb_dev.settings import BASE_DIR
ModuleNotFoundError: No module named 'opsweb_dev'

During handling of the above exception, another exception occurred:

Traceback (most recent call last):
  File "/ops-data/zp/haha/mysite-11/lib/python3.6/site-packages/gunicorn/workers/sync.py", line 135, in handle
    self.handle_request(listener, req, client, addr)
  File "/ops-data/zp/haha/mysite-11/lib/python3.6/site-packages/gunicorn/workers/sync.py", line 176, in handle_request
    respiter = self.wsgi(environ, resp.start_response)
  File "/ops-data/zp/haha/mysite-11/lib/python3.6/site-packages/django/core/handlers/wsgi.py", line 157, in __call__
    response = self.get_response(request)
  File "/ops-data/zp/haha/mysite-11/lib/python3.6/site-packages/django/core/handlers/base.py", line 124, in get_response
    response = self._middleware_chain(request)
  File "/ops-data/zp/haha/mysite-11/lib/python3.6/site-packages/django/core/handlers/exception.py", line 43, in inner
    response = response_for_exception(request, exc)
  File "/ops-data/zp/haha/mysite-11/lib/python3.6/site-packages/django/core/handlers/exception.py", line 93, in response_for_exception
    response = handle_uncaught_exception(request, get_resolver(get_urlconf()), sys.exc_info())
  File "/ops-data/zp/haha/mysite-11/lib/python3.6/site-packages/django/core/handlers/exception.py", line 142, in handle_uncaught_exception
    callback, param_dict = resolver.resolve_error_handler(500)
  File "/ops-data/zp/haha/mysite-11/lib/python3.6/site-packages/django/urls/resolvers.py", line 418, in resolve_error_handler
    callback = getattr(self.urlconf_module, 'handler%s' % view_type, None)
  File "/ops-data/zp/haha/mysite-11/lib/python3.6/site-packages/django/utils/functional.py", line 35, in __get__
    res = instance.__dict__[self.name] = self.func(instance)
  File "/ops-data/zp/haha/mysite-11/lib/python3.6/site-packages/django/urls/resolvers.py", line 398, in urlconf_module
    return import_module(self.urlconf_name)
  File "/ops-data/zp/haha/mysite-11/lib/python3.6/importlib/__init__.py", line 126, in import_module
    return _bootstrap._gcd_import(name[level:], package, level)
  File "<frozen importlib._bootstrap>", line 994, in _gcd_import
  File "<frozen importlib._bootstrap>", line 971, in _find_and_load
  File "<frozen importlib._bootstrap>", line 955, in _find_and_load_unlocked
  File "<frozen importlib._bootstrap>", line 665, in _load_unlocked
  File "<frozen importlib._bootstrap_external>", line 678, in exec_module
  File "<frozen importlib._bootstrap>", line 219, in _call_with_frames_removed
  File "/ops-data/zp/haha/mysite-11/opsweb/opsweb/urls.py", line 31, in <module>
    url(r'^workform/', include("workform.urls")),
  File "/ops-data/zp/haha/mysite-11/lib/python3.6/site-packages/django/conf/urls/__init__.py", line 50, in include
    urlconf_module = import_module(urlconf_module)
  File "/ops-data/zp/haha/mysite-11/lib/python3.6/importlib/__init__.py", line 126, in import_module
    return _bootstrap._gcd_import(name[level:], package, level)
  File "<frozen importlib._bootstrap>", line 994, in _gcd_import
  File "<frozen importlib._bootstrap>", line 971, in _find_and_load
  File "<frozen importlib._bootstrap>", line 955, in _find_and_load_unlocked
  File "<frozen importlib._bootstrap>", line 665, in _load_unlocked
  File "<frozen importlib._bootstrap_external>", line 678, in exec_module
  File "<frozen importlib._bootstrap>", line 219, in _call_with_frames_removed
  File "/ops-data/zp/haha/mysite-11/opsweb/workform/urls.py", line 4, in <module>
    from . import views,workform_type,workform_process
  File "/ops-data/zp/haha/mysite-11/opsweb/workform/views.py", line 22, in <module>
    from dbmanager.tasks import sync_workform_sql
  File "/ops-data/zp/haha/mysite-11/opsweb/dbmanager/tasks.py", line 21, in <module>
    from opsweb_dev.settings import BASE_DIR
ModuleNotFoundError: No module named 'opsweb_dev'
[2018-04-18 17:16:45 +0800] [22655] [ERROR] Error handling request /workform/pub/add/
Traceback (most recent call last):
  File "/ops-data/zp/haha/mysite-11/lib/python3.6/site-packages/django/core/handlers/exception.py", line 41, in inner
    response = get_response(request)
  File "/ops-data/zp/haha/mysite-11/lib/python3.6/site-packages/django/core/handlers/base.py", line 249, in _legacy_get_response
    response = self._get_response(request)
  File "/ops-data/zp/haha/mysite-11/lib/python3.6/site-packages/django/core/handlers/base.py", line 172, in _get_response
    resolver_match = resolver.resolve(request.path_info)
  File "/ops-data/zp/haha/mysite-11/lib/python3.6/site-packages/django/urls/resolvers.py", line 362, in resolve
    for pattern in self.url_patterns:
  File "/ops-data/zp/haha/mysite-11/lib/python3.6/site-packages/django/utils/functional.py", line 35, in __get__
    res = instance.__dict__[self.name] = self.func(instance)
  File "/ops-data/zp/haha/mysite-11/lib/python3.6/site-packages/django/urls/resolvers.py", line 405, in url_patterns
    patterns = getattr(self.urlconf_module, "urlpatterns", self.urlconf_module)
  File "/ops-data/zp/haha/mysite-11/lib/python3.6/site-packages/django/utils/functional.py", line 35, in __get__
    res = instance.__dict__[self.name] = self.func(instance)
  File "/ops-data/zp/haha/mysite-11/lib/python3.6/site-packages/django/urls/resolvers.py", line 398, in urlconf_module
    return import_module(self.urlconf_name)
  File "/ops-data/zp/haha/mysite-11/lib/python3.6/importlib/__init__.py", line 126, in import_module
    return _bootstrap._gcd_import(name[level:], package, level)
  File "<frozen importlib._bootstrap>", line 994, in _gcd_import
  File "<frozen importlib._bootstrap>", line 971, in _find_and_load
  File "<frozen importlib._bootstrap>", line 955, in _find_and_load_unlocked
  File "<frozen importlib._bootstrap>", line 665, in _load_unlocked
  File "<frozen importlib._bootstrap_external>", line 678, in exec_module
  File "<frozen importlib._bootstrap>", line 219, in _call_with_frames_removed
  File "/ops-data/zp/haha/mysite-11/opsweb/opsweb/urls.py", line 31, in <module>
    url(r'^workform/', include("workform.urls")),
  File "/ops-data/zp/haha/mysite-11/lib/python3.6/site-packages/django/conf/urls/__init__.py", line 50, in include
    urlconf_module = import_module(urlconf_module)
  File "/ops-data/zp/haha/mysite-11/lib/python3.6/importlib/__init__.py", line 126, in import_module
    return _bootstrap._gcd_import(name[level:], package, level)
  File "<frozen importlib._bootstrap>", line 994, in _gcd_import
  File "<frozen importlib._bootstrap>", line 971, in _find_and_load
  File "<frozen importlib._bootstrap>", line 955, in _find_and_load_unlocked
  File "<frozen importlib._bootstrap>", line 665, in _load_unlocked
  File "<frozen importlib._bootstrap_external>", line 678, in exec_module
  File "<frozen importlib._bootstrap>", line 219, in _call_with_frames_removed
  File "/ops-data/zp/haha/mysite-11/opsweb/workform/urls.py", line 4, in <module>
    from . import views,workform_type,workform_process
  File "/ops-data/zp/haha/mysite-11/opsweb/workform/views.py", line 22, in <module>
    from dbmanager.tasks import sync_workform_sql
  File "/ops-data/zp/haha/mysite-11/opsweb/dbmanager/tasks.py", line 21, in <module>
    from opsweb_dev.settings import BASE_DIR
ModuleNotFoundError: No module named 'opsweb_dev'

During handling of the above exception, another exception occurred:

Traceback (most recent call last):
  File "/ops-data/zp/haha/mysite-11/lib/python3.6/site-packages/gunicorn/workers/sync.py", line 135, in handle
    self.handle_request(listener, req, client, addr)
  File "/ops-data/zp/haha/mysite-11/lib/python3.6/site-packages/gunicorn/workers/sync.py", line 176, in handle_request
    respiter = self.wsgi(environ, resp.start_response)
  File "/ops-data/zp/haha/mysite-11/lib/python3.6/site-packages/django/core/handlers/wsgi.py", line 157, in __call__
    response = self.get_response(request)
  File "/ops-data/zp/haha/mysite-11/lib/python3.6/site-packages/django/core/handlers/base.py", line 124, in get_response
    response = self._middleware_chain(request)
  File "/ops-data/zp/haha/mysite-11/lib/python3.6/site-packages/django/core/handlers/exception.py", line 43, in inner
    response = response_for_exception(request, exc)
  File "/ops-data/zp/haha/mysite-11/lib/python3.6/site-packages/django/core/handlers/exception.py", line 93, in response_for_exception
    response = handle_uncaught_exception(request, get_resolver(get_urlconf()), sys.exc_info())
  File "/ops-data/zp/haha/mysite-11/lib/python3.6/site-packages/django/core/handlers/exception.py", line 142, in handle_uncaught_exception
    callback, param_dict = resolver.resolve_error_handler(500)
  File "/ops-data/zp/haha/mysite-11/lib/python3.6/site-packages/django/urls/resolvers.py", line 418, in resolve_error_handler
    callback = getattr(self.urlconf_module, 'handler%s' % view_type, None)
  File "/ops-data/zp/haha/mysite-11/lib/python3.6/site-packages/django/utils/functional.py", line 35, in __get__
    res = instance.__dict__[self.name] = self.func(instance)
  File "/ops-data/zp/haha/mysite-11/lib/python3.6/site-packages/django/urls/resolvers.py", line 398, in urlconf_module
    return import_module(self.urlconf_name)
  File "/ops-data/zp/haha/mysite-11/lib/python3.6/importlib/__init__.py", line 126, in import_module
    return _bootstrap._gcd_import(name[level:], package, level)
  File "<frozen importlib._bootstrap>", line 994, in _gcd_import
  File "<frozen importlib._bootstrap>", line 971, in _find_and_load
  File "<frozen importlib._bootstrap>", line 955, in _find_and_load_unlocked
  File "<frozen importlib._bootstrap>", line 665, in _load_unlocked
  File "<frozen importlib._bootstrap_external>", line 678, in exec_module
  File "<frozen importlib._bootstrap>", line 219, in _call_with_frames_removed
  File "/ops-data/zp/haha/mysite-11/opsweb/opsweb/urls.py", line 31, in <module>
    url(r'^workform/', include("workform.urls")),
  File "/ops-data/zp/haha/mysite-11/lib/python3.6/site-packages/django/conf/urls/__init__.py", line 50, in include
    urlconf_module = import_module(urlconf_module)
  File "/ops-data/zp/haha/mysite-11/lib/python3.6/importlib/__init__.py", line 126, in import_module
    return _bootstrap._gcd_import(name[level:], package, level)
  File "<frozen importlib._bootstrap>", line 994, in _gcd_import
  File "<frozen importlib._bootstrap>", line 971, in _find_and_load
  File "<frozen importlib._bootstrap>", line 955, in _find_and_load_unlocked
  File "<frozen importlib._bootstrap>", line 665, in _load_unlocked
  File "<frozen importlib._bootstrap_external>", line 678, in exec_module
  File "<frozen importlib._bootstrap>", line 219, in _call_with_frames_removed
  File "/ops-data/zp/haha/mysite-11/opsweb/workform/urls.py", line 4, in <module>
    from . import views,workform_type,workform_process
  File "/ops-data/zp/haha/mysite-11/opsweb/workform/views.py", line 22, in <module>
    from dbmanager.tasks import sync_workform_sql
  File "/ops-data/zp/haha/mysite-11/opsweb/dbmanager/tasks.py", line 21, in <module>
    from opsweb_dev.settings import BASE_DIR
ModuleNotFoundError: No module named 'opsweb_dev'
[2018-04-18 17:19:41 +0800] [25000] [ERROR] Error handling request /workform/pub/add/
Traceback (most recent call last):
  File "/ops-data/zp/haha/mysite-11/lib/python3.6/site-packages/django/core/handlers/exception.py", line 41, in inner
    response = get_response(request)
  File "/ops-data/zp/haha/mysite-11/lib/python3.6/site-packages/django/core/handlers/base.py", line 249, in _legacy_get_response
    response = self._get_response(request)
  File "/ops-data/zp/haha/mysite-11/lib/python3.6/site-packages/django/core/handlers/base.py", line 172, in _get_response
    resolver_match = resolver.resolve(request.path_info)
  File "/ops-data/zp/haha/mysite-11/lib/python3.6/site-packages/django/urls/resolvers.py", line 362, in resolve
    for pattern in self.url_patterns:
  File "/ops-data/zp/haha/mysite-11/lib/python3.6/site-packages/django/utils/functional.py", line 35, in __get__
    res = instance.__dict__[self.name] = self.func(instance)
  File "/ops-data/zp/haha/mysite-11/lib/python3.6/site-packages/django/urls/resolvers.py", line 405, in url_patterns
    patterns = getattr(self.urlconf_module, "urlpatterns", self.urlconf_module)
  File "/ops-data/zp/haha/mysite-11/lib/python3.6/site-packages/django/utils/functional.py", line 35, in __get__
    res = instance.__dict__[self.name] = self.func(instance)
  File "/ops-data/zp/haha/mysite-11/lib/python3.6/site-packages/django/urls/resolvers.py", line 398, in urlconf_module
    return import_module(self.urlconf_name)
  File "/ops-data/zp/haha/mysite-11/lib/python3.6/importlib/__init__.py", line 126, in import_module
    return _bootstrap._gcd_import(name[level:], package, level)
  File "<frozen importlib._bootstrap>", line 994, in _gcd_import
  File "<frozen importlib._bootstrap>", line 971, in _find_and_load
  File "<frozen importlib._bootstrap>", line 955, in _find_and_load_unlocked
  File "<frozen importlib._bootstrap>", line 665, in _load_unlocked
  File "<frozen importlib._bootstrap_external>", line 678, in exec_module
  File "<frozen importlib._bootstrap>", line 219, in _call_with_frames_removed
  File "/ops-data/zp/haha/mysite-11/opsweb/opsweb/urls.py", line 31, in <module>
    url(r'^workform/', include("workform.urls")),
  File "/ops-data/zp/haha/mysite-11/lib/python3.6/site-packages/django/conf/urls/__init__.py", line 50, in include
    urlconf_module = import_module(urlconf_module)
  File "/ops-data/zp/haha/mysite-11/lib/python3.6/importlib/__init__.py", line 126, in import_module
    return _bootstrap._gcd_import(name[level:], package, level)
  File "<frozen importlib._bootstrap>", line 994, in _gcd_import
  File "<frozen importlib._bootstrap>", line 971, in _find_and_load
  File "<frozen importlib._bootstrap>", line 955, in _find_and_load_unlocked
  File "<frozen importlib._bootstrap>", line 665, in _load_unlocked
  File "<frozen importlib._bootstrap_external>", line 678, in exec_module
  File "<frozen importlib._bootstrap>", line 219, in _call_with_frames_removed
  File "/ops-data/zp/haha/mysite-11/opsweb/workform/urls.py", line 4, in <module>
    from . import views,workform_type,workform_process
  File "/ops-data/zp/haha/mysite-11/opsweb/workform/views.py", line 746, in <module>
    class WorkFormDetailView(LoginRequiredMixin,DetailView):
NameError: name 'DetailView' is not defined

During handling of the above exception, another exception occurred:

Traceback (most recent call last):
  File "/ops-data/zp/haha/mysite-11/lib/python3.6/site-packages/gunicorn/workers/sync.py", line 135, in handle
    self.handle_request(listener, req, client, addr)
  File "/ops-data/zp/haha/mysite-11/lib/python3.6/site-packages/gunicorn/workers/sync.py", line 176, in handle_request
    respiter = self.wsgi(environ, resp.start_response)
  File "/ops-data/zp/haha/mysite-11/lib/python3.6/site-packages/django/core/handlers/wsgi.py", line 157, in __call__
    response = self.get_response(request)
  File "/ops-data/zp/haha/mysite-11/lib/python3.6/site-packages/django/core/handlers/base.py", line 124, in get_response
    response = self._middleware_chain(request)
  File "/ops-data/zp/haha/mysite-11/lib/python3.6/site-packages/django/core/handlers/exception.py", line 43, in inner
    response = response_for_exception(request, exc)
  File "/ops-data/zp/haha/mysite-11/lib/python3.6/site-packages/django/core/handlers/exception.py", line 93, in response_for_exception
    response = handle_uncaught_exception(request, get_resolver(get_urlconf()), sys.exc_info())
  File "/ops-data/zp/haha/mysite-11/lib/python3.6/site-packages/django/core/handlers/exception.py", line 142, in handle_uncaught_exception
    callback, param_dict = resolver.resolve_error_handler(500)
  File "/ops-data/zp/haha/mysite-11/lib/python3.6/site-packages/django/urls/resolvers.py", line 418, in resolve_error_handler
    callback = getattr(self.urlconf_module, 'handler%s' % view_type, None)
  File "/ops-data/zp/haha/mysite-11/lib/python3.6/site-packages/django/utils/functional.py", line 35, in __get__
    res = instance.__dict__[self.name] = self.func(instance)
  File "/ops-data/zp/haha/mysite-11/lib/python3.6/site-packages/django/urls/resolvers.py", line 398, in urlconf_module
    return import_module(self.urlconf_name)
  File "/ops-data/zp/haha/mysite-11/lib/python3.6/importlib/__init__.py", line 126, in import_module
    return _bootstrap._gcd_import(name[level:], package, level)
  File "<frozen importlib._bootstrap>", line 994, in _gcd_import
  File "<frozen importlib._bootstrap>", line 971, in _find_and_load
  File "<frozen importlib._bootstrap>", line 955, in _find_and_load_unlocked
  File "<frozen importlib._bootstrap>", line 665, in _load_unlocked
  File "<frozen importlib._bootstrap_external>", line 678, in exec_module
  File "<frozen importlib._bootstrap>", line 219, in _call_with_frames_removed
  File "/ops-data/zp/haha/mysite-11/opsweb/opsweb/urls.py", line 31, in <module>
    url(r'^workform/', include("workform.urls")),
  File "/ops-data/zp/haha/mysite-11/lib/python3.6/site-packages/django/conf/urls/__init__.py", line 50, in include
    urlconf_module = import_module(urlconf_module)
  File "/ops-data/zp/haha/mysite-11/lib/python3.6/importlib/__init__.py", line 126, in import_module
    return _bootstrap._gcd_import(name[level:], package, level)
  File "<frozen importlib._bootstrap>", line 994, in _gcd_import
  File "<frozen importlib._bootstrap>", line 971, in _find_and_load
  File "<frozen importlib._bootstrap>", line 955, in _find_and_load_unlocked
  File "<frozen importlib._bootstrap>", line 665, in _load_unlocked
  File "<frozen importlib._bootstrap_external>", line 678, in exec_module
  File "<frozen importlib._bootstrap>", line 219, in _call_with_frames_removed
  File "/ops-data/zp/haha/mysite-11/opsweb/workform/urls.py", line 4, in <module>
    from . import views,workform_type,workform_process
  File "/ops-data/zp/haha/mysite-11/opsweb/workform/views.py", line 746, in <module>
    class WorkFormDetailView(LoginRequiredMixin,DetailView):
NameError: name 'DetailView' is not defined
[2018-04-18 17:49:51 +0800] [2564] [ERROR] Error handling request /admin
Traceback (most recent call last):
  File "/ops-data/zp/haha/mysite-11/lib/python3.6/site-packages/django/core/handlers/exception.py", line 41, in inner
    response = get_response(request)
  File "/ops-data/zp/haha/mysite-11/lib/python3.6/site-packages/django/core/handlers/base.py", line 244, in _legacy_get_response
    response = middleware_method(request)
  File "/ops-data/zp/haha/mysite-11/lib/python3.6/site-packages/django/middleware/common.py", line 62, in process_request
    if self.should_redirect_with_slash(request):
  File "/ops-data/zp/haha/mysite-11/lib/python3.6/site-packages/django/middleware/common.py", line 80, in should_redirect_with_slash
    not is_valid_path(request.path_info, urlconf) and
  File "/ops-data/zp/haha/mysite-11/lib/python3.6/site-packages/django/urls/base.py", line 158, in is_valid_path
    resolve(path, urlconf)
  File "/ops-data/zp/haha/mysite-11/lib/python3.6/site-packages/django/urls/base.py", line 27, in resolve
    return get_resolver(urlconf).resolve(path)
  File "/ops-data/zp/haha/mysite-11/lib/python3.6/site-packages/django/urls/resolvers.py", line 362, in resolve
    for pattern in self.url_patterns:
  File "/ops-data/zp/haha/mysite-11/lib/python3.6/site-packages/django/utils/functional.py", line 35, in __get__
    res = instance.__dict__[self.name] = self.func(instance)
  File "/ops-data/zp/haha/mysite-11/lib/python3.6/site-packages/django/urls/resolvers.py", line 405, in url_patterns
    patterns = getattr(self.urlconf_module, "urlpatterns", self.urlconf_module)
  File "/ops-data/zp/haha/mysite-11/lib/python3.6/site-packages/django/utils/functional.py", line 35, in __get__
    res = instance.__dict__[self.name] = self.func(instance)
  File "/ops-data/zp/haha/mysite-11/lib/python3.6/site-packages/django/urls/resolvers.py", line 398, in urlconf_module
    return import_module(self.urlconf_name)
  File "/ops-data/zp/haha/mysite-11/lib/python3.6/importlib/__init__.py", line 126, in import_module
    return _bootstrap._gcd_import(name[level:], package, level)
  File "<frozen importlib._bootstrap>", line 994, in _gcd_import
  File "<frozen importlib._bootstrap>", line 971, in _find_and_load
  File "<frozen importlib._bootstrap>", line 955, in _find_and_load_unlocked
  File "<frozen importlib._bootstrap>", line 665, in _load_unlocked
  File "<frozen importlib._bootstrap_external>", line 678, in exec_module
  File "<frozen importlib._bootstrap>", line 219, in _call_with_frames_removed
  File "/ops-data/zp/haha/mysite-11/opsweb/opsweb/urls.py", line 31, in <module>
    url(r'^workform/', include("workform.urls")),
  File "/ops-data/zp/haha/mysite-11/lib/python3.6/site-packages/django/conf/urls/__init__.py", line 50, in include
    urlconf_module = import_module(urlconf_module)
  File "/ops-data/zp/haha/mysite-11/lib/python3.6/importlib/__init__.py", line 126, in import_module
    return _bootstrap._gcd_import(name[level:], package, level)
  File "<frozen importlib._bootstrap>", line 994, in _gcd_import
  File "<frozen importlib._bootstrap>", line 971, in _find_and_load
  File "<frozen importlib._bootstrap>", line 955, in _find_and_load_unlocked
  File "<frozen importlib._bootstrap>", line 665, in _load_unlocked
  File "<frozen importlib._bootstrap_external>", line 678, in exec_module
  File "<frozen importlib._bootstrap>", line 219, in _call_with_frames_removed
  File "/ops-data/zp/haha/mysite-11/opsweb/workform/urls.py", line 4, in <module>
    from . import views,workform_type,workform_process
  File "/ops-data/zp/haha/mysite-11/opsweb/workform/views.py", line 17, in <module>
    from workform.tasks import workform_mail_send
  File "/ops-data/zp/haha/mysite-11/opsweb/workform/tasks.py", line 1, in <module>
    from opsweb.celery import app
  File "/ops-data/zp/haha/mysite-11/opsweb/opsweb/celery.py", line 10, in <module>
    app.config_from_object('django.conf:settings', namespace='CELERY')
TypeError: config_from_object() got an unexpected keyword argument 'namespace'

During handling of the above exception, another exception occurred:

Traceback (most recent call last):
  File "/ops-data/zp/haha/mysite-11/lib/python3.6/site-packages/gunicorn/workers/sync.py", line 135, in handle
    self.handle_request(listener, req, client, addr)
  File "/ops-data/zp/haha/mysite-11/lib/python3.6/site-packages/gunicorn/workers/sync.py", line 176, in handle_request
    respiter = self.wsgi(environ, resp.start_response)
  File "/ops-data/zp/haha/mysite-11/lib/python3.6/site-packages/django/core/handlers/wsgi.py", line 157, in __call__
    response = self.get_response(request)
  File "/ops-data/zp/haha/mysite-11/lib/python3.6/site-packages/django/core/handlers/base.py", line 124, in get_response
    response = self._middleware_chain(request)
  File "/ops-data/zp/haha/mysite-11/lib/python3.6/site-packages/django/core/handlers/exception.py", line 43, in inner
    response = response_for_exception(request, exc)
  File "/ops-data/zp/haha/mysite-11/lib/python3.6/site-packages/django/core/handlers/exception.py", line 93, in response_for_exception
    response = handle_uncaught_exception(request, get_resolver(get_urlconf()), sys.exc_info())
  File "/ops-data/zp/haha/mysite-11/lib/python3.6/site-packages/django/core/handlers/exception.py", line 142, in handle_uncaught_exception
    callback, param_dict = resolver.resolve_error_handler(500)
  File "/ops-data/zp/haha/mysite-11/lib/python3.6/site-packages/django/urls/resolvers.py", line 418, in resolve_error_handler
    callback = getattr(self.urlconf_module, 'handler%s' % view_type, None)
  File "/ops-data/zp/haha/mysite-11/lib/python3.6/site-packages/django/utils/functional.py", line 35, in __get__
    res = instance.__dict__[self.name] = self.func(instance)
  File "/ops-data/zp/haha/mysite-11/lib/python3.6/site-packages/django/urls/resolvers.py", line 398, in urlconf_module
    return import_module(self.urlconf_name)
  File "/ops-data/zp/haha/mysite-11/lib/python3.6/importlib/__init__.py", line 126, in import_module
    return _bootstrap._gcd_import(name[level:], package, level)
  File "<frozen importlib._bootstrap>", line 994, in _gcd_import
  File "<frozen importlib._bootstrap>", line 971, in _find_and_load
  File "<frozen importlib._bootstrap>", line 955, in _find_and_load_unlocked
  File "<frozen importlib._bootstrap>", line 665, in _load_unlocked
  File "<frozen importlib._bootstrap_external>", line 678, in exec_module
  File "<frozen importlib._bootstrap>", line 219, in _call_with_frames_removed
  File "/ops-data/zp/haha/mysite-11/opsweb/opsweb/urls.py", line 31, in <module>
    url(r'^workform/', include("workform.urls")),
  File "/ops-data/zp/haha/mysite-11/lib/python3.6/site-packages/django/conf/urls/__init__.py", line 50, in include
    urlconf_module = import_module(urlconf_module)
  File "/ops-data/zp/haha/mysite-11/lib/python3.6/importlib/__init__.py", line 126, in import_module
    return _bootstrap._gcd_import(name[level:], package, level)
  File "<frozen importlib._bootstrap>", line 994, in _gcd_import
  File "<frozen importlib._bootstrap>", line 971, in _find_and_load
  File "<frozen importlib._bootstrap>", line 955, in _find_and_load_unlocked
  File "<frozen importlib._bootstrap>", line 665, in _load_unlocked
  File "<frozen importlib._bootstrap_external>", line 678, in exec_module
  File "<frozen importlib._bootstrap>", line 219, in _call_with_frames_removed
  File "/ops-data/zp/haha/mysite-11/opsweb/workform/urls.py", line 4, in <module>
    from . import views,workform_type,workform_process
  File "/ops-data/zp/haha/mysite-11/opsweb/workform/views.py", line 17, in <module>
    from workform.tasks import workform_mail_send
  File "/ops-data/zp/haha/mysite-11/opsweb/workform/tasks.py", line 1, in <module>
    from opsweb.celery import app
  File "/ops-data/zp/haha/mysite-11/opsweb/opsweb/celery.py", line 10, in <module>
    app.config_from_object('django.conf:settings', namespace='CELERY')
TypeError: config_from_object() got an unexpected keyword argument 'namespace'
[2018-04-18 17:49:53 +0800] [2562] [ERROR] Error handling request /admin
Traceback (most recent call last):
  File "/ops-data/zp/haha/mysite-11/lib/python3.6/site-packages/django/core/handlers/exception.py", line 41, in inner
    response = get_response(request)
  File "/ops-data/zp/haha/mysite-11/lib/python3.6/site-packages/django/core/handlers/base.py", line 244, in _legacy_get_response
    response = middleware_method(request)
  File "/ops-data/zp/haha/mysite-11/lib/python3.6/site-packages/django/middleware/common.py", line 62, in process_request
    if self.should_redirect_with_slash(request):
  File "/ops-data/zp/haha/mysite-11/lib/python3.6/site-packages/django/middleware/common.py", line 80, in should_redirect_with_slash
    not is_valid_path(request.path_info, urlconf) and
  File "/ops-data/zp/haha/mysite-11/lib/python3.6/site-packages/django/urls/base.py", line 158, in is_valid_path
    resolve(path, urlconf)
  File "/ops-data/zp/haha/mysite-11/lib/python3.6/site-packages/django/urls/base.py", line 27, in resolve
    return get_resolver(urlconf).resolve(path)
  File "/ops-data/zp/haha/mysite-11/lib/python3.6/site-packages/django/urls/resolvers.py", line 362, in resolve
    for pattern in self.url_patterns:
  File "/ops-data/zp/haha/mysite-11/lib/python3.6/site-packages/django/utils/functional.py", line 35, in __get__
    res = instance.__dict__[self.name] = self.func(instance)
  File "/ops-data/zp/haha/mysite-11/lib/python3.6/site-packages/django/urls/resolvers.py", line 405, in url_patterns
    patterns = getattr(self.urlconf_module, "urlpatterns", self.urlconf_module)
  File "/ops-data/zp/haha/mysite-11/lib/python3.6/site-packages/django/utils/functional.py", line 35, in __get__
    res = instance.__dict__[self.name] = self.func(instance)
  File "/ops-data/zp/haha/mysite-11/lib/python3.6/site-packages/django/urls/resolvers.py", line 398, in urlconf_module
    return import_module(self.urlconf_name)
  File "/ops-data/zp/haha/mysite-11/lib/python3.6/importlib/__init__.py", line 126, in import_module
    return _bootstrap._gcd_import(name[level:], package, level)
  File "<frozen importlib._bootstrap>", line 994, in _gcd_import
  File "<frozen importlib._bootstrap>", line 971, in _find_and_load
  File "<frozen importlib._bootstrap>", line 955, in _find_and_load_unlocked
  File "<frozen importlib._bootstrap>", line 665, in _load_unlocked
  File "<frozen importlib._bootstrap_external>", line 678, in exec_module
  File "<frozen importlib._bootstrap>", line 219, in _call_with_frames_removed
  File "/ops-data/zp/haha/mysite-11/opsweb/opsweb/urls.py", line 31, in <module>
    url(r'^workform/', include("workform.urls")),
  File "/ops-data/zp/haha/mysite-11/lib/python3.6/site-packages/django/conf/urls/__init__.py", line 50, in include
    urlconf_module = import_module(urlconf_module)
  File "/ops-data/zp/haha/mysite-11/lib/python3.6/importlib/__init__.py", line 126, in import_module
    return _bootstrap._gcd_import(name[level:], package, level)
  File "<frozen importlib._bootstrap>", line 994, in _gcd_import
  File "<frozen importlib._bootstrap>", line 971, in _find_and_load
  File "<frozen importlib._bootstrap>", line 955, in _find_and_load_unlocked
  File "<frozen importlib._bootstrap>", line 665, in _load_unlocked
  File "<frozen importlib._bootstrap_external>", line 678, in exec_module
  File "<frozen importlib._bootstrap>", line 219, in _call_with_frames_removed
  File "/ops-data/zp/haha/mysite-11/opsweb/workform/urls.py", line 4, in <module>
    from . import views,workform_type,workform_process
  File "/ops-data/zp/haha/mysite-11/opsweb/workform/views.py", line 17, in <module>
    from workform.tasks import workform_mail_send
  File "/ops-data/zp/haha/mysite-11/opsweb/workform/tasks.py", line 1, in <module>
    from opsweb.celery import app
  File "/ops-data/zp/haha/mysite-11/opsweb/opsweb/celery.py", line 10, in <module>
    app.config_from_object('django.conf:settings', namespace='CELERY')
TypeError: config_from_object() got an unexpected keyword argument 'namespace'

During handling of the above exception, another exception occurred:

Traceback (most recent call last):
  File "/ops-data/zp/haha/mysite-11/lib/python3.6/site-packages/gunicorn/workers/sync.py", line 135, in handle
    self.handle_request(listener, req, client, addr)
  File "/ops-data/zp/haha/mysite-11/lib/python3.6/site-packages/gunicorn/workers/sync.py", line 176, in handle_request
    respiter = self.wsgi(environ, resp.start_response)
  File "/ops-data/zp/haha/mysite-11/lib/python3.6/site-packages/django/core/handlers/wsgi.py", line 157, in __call__
    response = self.get_response(request)
  File "/ops-data/zp/haha/mysite-11/lib/python3.6/site-packages/django/core/handlers/base.py", line 124, in get_response
    response = self._middleware_chain(request)
  File "/ops-data/zp/haha/mysite-11/lib/python3.6/site-packages/django/core/handlers/exception.py", line 43, in inner
    response = response_for_exception(request, exc)
  File "/ops-data/zp/haha/mysite-11/lib/python3.6/site-packages/django/core/handlers/exception.py", line 93, in response_for_exception
    response = handle_uncaught_exception(request, get_resolver(get_urlconf()), sys.exc_info())
  File "/ops-data/zp/haha/mysite-11/lib/python3.6/site-packages/django/core/handlers/exception.py", line 142, in handle_uncaught_exception
    callback, param_dict = resolver.resolve_error_handler(500)
  File "/ops-data/zp/haha/mysite-11/lib/python3.6/site-packages/django/urls/resolvers.py", line 418, in resolve_error_handler
    callback = getattr(self.urlconf_module, 'handler%s' % view_type, None)
  File "/ops-data/zp/haha/mysite-11/lib/python3.6/site-packages/django/utils/functional.py", line 35, in __get__
    res = instance.__dict__[self.name] = self.func(instance)
  File "/ops-data/zp/haha/mysite-11/lib/python3.6/site-packages/django/urls/resolvers.py", line 398, in urlconf_module
    return import_module(self.urlconf_name)
  File "/ops-data/zp/haha/mysite-11/lib/python3.6/importlib/__init__.py", line 126, in import_module
    return _bootstrap._gcd_import(name[level:], package, level)
  File "<frozen importlib._bootstrap>", line 994, in _gcd_import
  File "<frozen importlib._bootstrap>", line 971, in _find_and_load
  File "<frozen importlib._bootstrap>", line 955, in _find_and_load_unlocked
  File "<frozen importlib._bootstrap>", line 665, in _load_unlocked
  File "<frozen importlib._bootstrap_external>", line 678, in exec_module
  File "<frozen importlib._bootstrap>", line 219, in _call_with_frames_removed
  File "/ops-data/zp/haha/mysite-11/opsweb/opsweb/urls.py", line 31, in <module>
    url(r'^workform/', include("workform.urls")),
  File "/ops-data/zp/haha/mysite-11/lib/python3.6/site-packages/django/conf/urls/__init__.py", line 50, in include
    urlconf_module = import_module(urlconf_module)
  File "/ops-data/zp/haha/mysite-11/lib/python3.6/importlib/__init__.py", line 126, in import_module
    return _bootstrap._gcd_import(name[level:], package, level)
  File "<frozen importlib._bootstrap>", line 994, in _gcd_import
  File "<frozen importlib._bootstrap>", line 971, in _find_and_load
  File "<frozen importlib._bootstrap>", line 955, in _find_and_load_unlocked
  File "<frozen importlib._bootstrap>", line 665, in _load_unlocked
  File "<frozen importlib._bootstrap_external>", line 678, in exec_module
  File "<frozen importlib._bootstrap>", line 219, in _call_with_frames_removed
  File "/ops-data/zp/haha/mysite-11/opsweb/workform/urls.py", line 4, in <module>
    from . import views,workform_type,workform_process
  File "/ops-data/zp/haha/mysite-11/opsweb/workform/views.py", line 17, in <module>
    from workform.tasks import workform_mail_send
  File "/ops-data/zp/haha/mysite-11/opsweb/workform/tasks.py", line 1, in <module>
    from opsweb.celery import app
  File "/ops-data/zp/haha/mysite-11/opsweb/opsweb/celery.py", line 10, in <module>
    app.config_from_object('django.conf:settings', namespace='CELERY')
TypeError: config_from_object() got an unexpected keyword argument 'namespace'
