2017-12-17 11:03:18,228-[WARNING]-/ops-data/zp/haha/mysite-11/lib/python3.6/site-packages/django/core/handlers/base.py-[line:152]-Not Found: /favicon.ico
2017-12-17 11:14:40,168-[WARNING]-/ops-data/zp/haha/mysite-11/lib/python3.6/site-packages/django/core/handlers/base.py-[line:152]-Not Found: /static/img/logo.png
2017-12-17 11:15:09,511-[WARNING]-/ops-data/zp/haha/mysite-11/lib/python3.6/site-packages/django/core/handlers/base.py-[line:152]-Not Found: /static/img/logo.png
2017-12-17 11:21:22,631-[WARNING]-/ops-data/zp/haha/mysite-11/lib/python3.6/site-packages/django/core/handlers/base.py-[line:152]-Not Found: /static/img/logo.png
2017-12-17 11:27:55,629-[WARNING]-/ops-data/zp/haha/mysite-11/lib/python3.6/site-packages/django/core/handlers/base.py-[line:152]-Not Found: /static/img/logo.png
2017-12-17 11:28:23,601-[WARNING]-/ops-data/zp/haha/mysite-11/lib/python3.6/site-packages/django/core/handlers/base.py-[line:152]-Not Found: /static/img/logo.png
2017-12-17 11:28:49,458-[WARNING]-/ops-data/zp/haha/mysite-11/lib/python3.6/site-packages/django/core/handlers/base.py-[line:152]-Not Found: /static/img/logo.png
2017-12-17 11:33:21,588-[WARNING]-/ops-data/zp/haha/mysite-11/lib/python3.6/site-packages/django/core/handlers/base.py-[line:152]-Not Found: /static/img/logo.png
2017-12-17 11:34:37,137-[WARNING]-/ops-data/zp/haha/mysite-11/lib/python3.6/site-packages/django/core/handlers/base.py-[line:152]-Not Found: /static/img/logo.png
2017-12-17 11:41:22,468-[WARNING]-/ops-data/zp/haha/mysite-11/lib/python3.6/site-packages/django/core/handlers/base.py-[line:152]-Not Found: /static/img/logo.png
2017-12-17 12:42:23,040-[WARNING]-/ops-data/zp/haha/mysite-11/lib/python3.6/site-packages/django/core/handlers/base.py-[line:152]-Not Found: /static/img/logo.png
2017-12-17 12:42:26,037-[WARNING]-/ops-data/zp/haha/mysite-11/lib/python3.6/site-packages/django/core/handlers/base.py-[line:152]-Not Found: /static/img/logo.png
2017-12-17 12:42:28,760-[WARNING]-/ops-data/zp/haha/mysite-11/lib/python3.6/site-packages/django/core/handlers/base.py-[line:152]-Not Found: /static/img/logo.png
2017-12-17 12:42:30,003-[WARNING]-/ops-data/zp/haha/mysite-11/lib/python3.6/site-packages/django/core/handlers/base.py-[line:152]-Not Found: /static/img/logo.png
2017-12-17 12:42:30,582-[WARNING]-/ops-data/zp/haha/mysite-11/lib/python3.6/site-packages/django/core/handlers/base.py-[line:152]-Not Found: /static/img/logo.png
2017-12-17 12:42:31,476-[WARNING]-/ops-data/zp/haha/mysite-11/lib/python3.6/site-packages/django/core/handlers/base.py-[line:152]-Not Found: /static/img/logo.png
2017-12-17 12:45:30,673-[WARNING]-/ops-data/zp/haha/mysite-11/lib/python3.6/site-packages/django/core/handlers/base.py-[line:152]-Not Found: /static/img/logo.png
2017-12-17 16:30:04,762-[INFO]-/ops-data/zp/haha/mysite-11/opsweb/resources/cron.py-[line:30]-服务器: 172.17.134.113 自动刷新成功
2017-12-17 16:30:06,064-[INFO]-/ops-data/zp/haha/mysite-11/opsweb/resources/cron.py-[line:30]-服务器: 172.17.134.114 自动刷新成功
2017-12-17 16:30:08,497-[INFO]-/ops-data/zp/haha/mysite-11/opsweb/resources/cron.py-[line:30]-服务器: 172.17.134.115 自动刷新成功
2017-12-17 16:30:11,323-[INFO]-/ops-data/zp/haha/mysite-11/opsweb/resources/cron.py-[line:30]-服务器: 172.17.134.25 自动刷新成功
2017-12-17 16:30:12,693-[INFO]-/ops-data/zp/haha/mysite-11/opsweb/resources/cron.py-[line:30]-服务器: 172.17.134.26 自动刷新成功
2017-12-17 16:30:13,908-[INFO]-/ops-data/zp/haha/mysite-11/opsweb/resources/cron.py-[line:30]-服务器: 172.17.134.27 自动刷新成功
2017-12-17 16:30:15,277-[INFO]-/ops-data/zp/haha/mysite-11/opsweb/resources/cron.py-[line:30]-服务器: 172.17.134.28 自动刷新成功
2017-12-17 16:30:16,573-[INFO]-/ops-data/zp/haha/mysite-11/opsweb/resources/cron.py-[line:30]-服务器: 172.17.134.29 自动刷新成功
2017-12-17 16:30:17,768-[INFO]-/ops-data/zp/haha/mysite-11/opsweb/resources/cron.py-[line:30]-服务器: 172.17.134.30 自动刷新成功
2017-12-17 16:30:18,905-[INFO]-/ops-data/zp/haha/mysite-11/opsweb/resources/cron.py-[line:30]-服务器: 172.17.134.31 自动刷新成功
2017-12-17 16:30:20,158-[INFO]-/ops-data/zp/haha/mysite-11/opsweb/resources/cron.py-[line:30]-服务器: 172.17.134.32 自动刷新成功
2017-12-17 16:30:21,488-[INFO]-/ops-data/zp/haha/mysite-11/opsweb/resources/cron.py-[line:30]-服务器: 172.17.134.33 自动刷新成功
2017-12-17 16:30:22,694-[INFO]-/ops-data/zp/haha/mysite-11/opsweb/resources/cron.py-[line:30]-服务器: 172.17.134.34 自动刷新成功
2017-12-17 16:30:23,906-[INFO]-/ops-data/zp/haha/mysite-11/opsweb/resources/cron.py-[line:30]-服务器: 172.17.134.35 自动刷新成功
2017-12-17 16:30:25,098-[INFO]-/ops-data/zp/haha/mysite-11/opsweb/resources/cron.py-[line:30]-服务器: 172.17.134.36 自动刷新成功
2017-12-17 16:30:26,452-[INFO]-/ops-data/zp/haha/mysite-11/opsweb/resources/cron.py-[line:30]-服务器: 172.17.134.37 自动刷新成功
2017-12-17 16:30:27,599-[INFO]-/ops-data/zp/haha/mysite-11/opsweb/resources/cron.py-[line:30]-服务器: 172.17.134.48 自动刷新成功
2017-12-17 16:30:28,857-[INFO]-/ops-data/zp/haha/mysite-11/opsweb/resources/cron.py-[line:30]-服务器: 172.17.134.49 自动刷新成功
2017-12-17 16:30:30,007-[INFO]-/ops-data/zp/haha/mysite-11/opsweb/resources/cron.py-[line:30]-服务器: 172.17.134.50 自动刷新成功
2017-12-17 16:30:31,392-[INFO]-/ops-data/zp/haha/mysite-11/opsweb/resources/cron.py-[line:30]-服务器: 172.17.134.51 自动刷新成功
2017-12-17 16:30:32,856-[INFO]-/ops-data/zp/haha/mysite-11/opsweb/resources/cron.py-[line:30]-服务器: 172.17.134.52 自动刷新成功
2017-12-17 16:30:34,123-[INFO]-/ops-data/zp/haha/mysite-11/opsweb/resources/cron.py-[line:30]-服务器: 172.17.134.53 自动刷新成功
2017-12-17 16:30:35,565-[INFO]-/ops-data/zp/haha/mysite-11/opsweb/resources/cron.py-[line:30]-服务器: 172.17.134.54 自动刷新成功
2017-12-17 16:30:36,893-[INFO]-/ops-data/zp/haha/mysite-11/opsweb/resources/cron.py-[line:30]-服务器: 172.17.134.55 自动刷新成功
2017-12-17 16:30:38,235-[INFO]-/ops-data/zp/haha/mysite-11/opsweb/resources/cron.py-[line:30]-服务器: 172.17.134.56 自动刷新成功
2017-12-17 16:30:40,146-[INFO]-/ops-data/zp/haha/mysite-11/opsweb/resources/cron.py-[line:30]-服务器: 172.17.134.58 自动刷新成功
2017-12-17 16:30:41,317-[INFO]-/ops-data/zp/haha/mysite-11/opsweb/resources/cron.py-[line:30]-服务器: 172.17.134.59 自动刷新成功
2017-12-17 16:30:42,459-[INFO]-/ops-data/zp/haha/mysite-11/opsweb/resources/cron.py-[line:30]-服务器: 172.17.134.65 自动刷新成功
2017-12-17 16:30:43,716-[INFO]-/ops-data/zp/haha/mysite-11/opsweb/resources/cron.py-[line:30]-服务器: 172.17.134.70 自动刷新成功
2017-12-17 16:30:45,114-[INFO]-/ops-data/zp/haha/mysite-11/opsweb/resources/cron.py-[line:30]-服务器: 172.17.134.71 自动刷新成功
2017-12-17 16:30:46,284-[INFO]-/ops-data/zp/haha/mysite-11/opsweb/resources/cron.py-[line:30]-服务器: 172.17.134.72 自动刷新成功
2017-12-17 16:30:47,496-[INFO]-/ops-data/zp/haha/mysite-11/opsweb/resources/cron.py-[line:30]-服务器: 172.17.134.73 自动刷新成功
2017-12-17 16:30:48,791-[INFO]-/ops-data/zp/haha/mysite-11/opsweb/resources/cron.py-[line:30]-服务器: 172.17.134.74 自动刷新成功
2017-12-17 16:30:50,442-[INFO]-/ops-data/zp/haha/mysite-11/opsweb/resources/cron.py-[line:30]-服务器: 172.17.134.75 自动刷新成功
2017-12-17 16:30:52,264-[INFO]-/ops-data/zp/haha/mysite-11/opsweb/resources/cron.py-[line:30]-服务器: 172.17.134.76 自动刷新成功
2017-12-17 16:30:53,647-[INFO]-/ops-data/zp/haha/mysite-11/opsweb/resources/cron.py-[line:30]-服务器: 172.17.134.77 自动刷新成功
2017-12-17 16:30:54,928-[INFO]-/ops-data/zp/haha/mysite-11/opsweb/resources/cron.py-[line:30]-服务器: 172.17.134.78 自动刷新成功
2017-12-17 16:30:56,206-[INFO]-/ops-data/zp/haha/mysite-11/opsweb/resources/cron.py-[line:30]-服务器: 172.17.134.79 自动刷新成功
2017-12-17 16:30:57,415-[INFO]-/ops-data/zp/haha/mysite-11/opsweb/resources/cron.py-[line:30]-服务器: 172.17.134.80 自动刷新成功
2017-12-17 16:30:58,542-[INFO]-/ops-data/zp/haha/mysite-11/opsweb/resources/cron.py-[line:30]-服务器: 172.17.134.81 自动刷新成功
2017-12-17 16:31:00,104-[INFO]-/ops-data/zp/haha/mysite-11/opsweb/resources/cron.py-[line:30]-服务器: 172.17.134.82 自动刷新成功
2017-12-17 16:31:01,554-[INFO]-/ops-data/zp/haha/mysite-11/opsweb/resources/cron.py-[line:30]-服务器: 172.17.134.87 自动刷新成功
2017-12-17 16:31:02,859-[INFO]-/ops-data/zp/haha/mysite-11/opsweb/resources/cron.py-[line:30]-服务器: 172.17.134.89 自动刷新成功
2017-12-17 16:31:04,284-[INFO]-/ops-data/zp/haha/mysite-11/opsweb/resources/cron.py-[line:30]-服务器: 172.17.134.90 自动刷新成功
2017-12-17 16:31:06,941-[INFO]-/ops-data/zp/haha/mysite-11/opsweb/resources/cron.py-[line:30]-服务器: 172.17.134.99 自动刷新成功
2017-12-17 16:44:13,034-[ERROR]-/ops-data/zp/haha/mysite-11/lib/python3.6/site-packages/django/core/handlers/exception.py-[line:135]-Internal Server Error: /resources/idc/list/
Traceback (most recent call last):
  File "/ops-data/zp/haha/mysite-11/lib/python3.6/site-packages/django/core/handlers/exception.py", line 41, in inner
    response = get_response(request)
  File "/ops-data/zp/haha/mysite-11/lib/python3.6/site-packages/django/core/handlers/base.py", line 249, in _legacy_get_response
    response = self._get_response(request)
  File "/ops-data/zp/haha/mysite-11/lib/python3.6/site-packages/django/core/handlers/base.py", line 172, in _get_response
    resolver_match = resolver.resolve(request.path_info)
  File "/ops-data/zp/haha/mysite-11/lib/python3.6/site-packages/django/urls/resolvers.py", line 362, in resolve
    for pattern in self.url_patterns:
  File "/ops-data/zp/haha/mysite-11/lib/python3.6/site-packages/django/utils/functional.py", line 35, in __get__
    res = instance.__dict__[self.name] = self.func(instance)
  File "/ops-data/zp/haha/mysite-11/lib/python3.6/site-packages/django/urls/resolvers.py", line 405, in url_patterns
    patterns = getattr(self.urlconf_module, "urlpatterns", self.urlconf_module)
  File "/ops-data/zp/haha/mysite-11/lib/python3.6/site-packages/django/utils/functional.py", line 35, in __get__
    res = instance.__dict__[self.name] = self.func(instance)
  File "/ops-data/zp/haha/mysite-11/lib/python3.6/site-packages/django/urls/resolvers.py", line 398, in urlconf_module
    return import_module(self.urlconf_name)
  File "/ops-data/zp/haha/mysite-11/lib/python3.6/importlib/__init__.py", line 126, in import_module
    return _bootstrap._gcd_import(name[level:], package, level)
  File "<frozen importlib._bootstrap>", line 994, in _gcd_import
  File "<frozen importlib._bootstrap>", line 971, in _find_and_load
  File "<frozen importlib._bootstrap>", line 955, in _find_and_load_unlocked
  File "<frozen importlib._bootstrap>", line 665, in _load_unlocked
  File "<frozen importlib._bootstrap_external>", line 678, in exec_module
  File "<frozen importlib._bootstrap>", line 219, in _call_with_frames_removed
  File "/ops-data/zp/haha/mysite-11/opsweb/opsweb/urls.py", line 29, in <module>
    url(r'^resources/', include("resources.urls")),
  File "/ops-data/zp/haha/mysite-11/lib/python3.6/site-packages/django/conf/urls/__init__.py", line 50, in include
    urlconf_module = import_module(urlconf_module)
  File "/ops-data/zp/haha/mysite-11/lib/python3.6/importlib/__init__.py", line 126, in import_module
    return _bootstrap._gcd_import(name[level:], package, level)
  File "<frozen importlib._bootstrap>", line 994, in _gcd_import
  File "<frozen importlib._bootstrap>", line 971, in _find_and_load
  File "<frozen importlib._bootstrap>", line 955, in _find_and_load_unlocked
  File "<frozen importlib._bootstrap>", line 665, in _load_unlocked
  File "<frozen importlib._bootstrap_external>", line 678, in exec_module
  File "<frozen importlib._bootstrap>", line 219, in _call_with_frames_removed
  File "/ops-data/zp/haha/mysite-11/opsweb/resources/urls.py", line 4, in <module>
    from . import views,server,idc
  File "/ops-data/zp/haha/mysite-11/opsweb/resources/idc/__init__.py", line 11, in <module>
    from dajngo.forms.models import model_to_dict
ModuleNotFoundError: No module named 'dajngo'
2017-12-17 16:44:52,178-[ERROR]-/ops-data/zp/haha/mysite-11/lib/python3.6/site-packages/django/core/handlers/exception.py-[line:135]-Internal Server Error: /resources/idc/list/
Traceback (most recent call last):
  File "/ops-data/zp/haha/mysite-11/lib/python3.6/site-packages/django/core/handlers/exception.py", line 41, in inner
    response = get_response(request)
  File "/ops-data/zp/haha/mysite-11/lib/python3.6/site-packages/django/core/handlers/base.py", line 249, in _legacy_get_response
    response = self._get_response(request)
  File "/ops-data/zp/haha/mysite-11/lib/python3.6/site-packages/django/core/handlers/base.py", line 217, in _get_response
    response = self.process_exception_by_middleware(e, request)
  File "/ops-data/zp/haha/mysite-11/lib/python3.6/site-packages/django/core/handlers/base.py", line 215, in _get_response
    response = response.render()
  File "/ops-data/zp/haha/mysite-11/lib/python3.6/site-packages/django/template/response.py", line 107, in render
    self.content = self.rendered_content
  File "/ops-data/zp/haha/mysite-11/lib/python3.6/site-packages/django/template/response.py", line 84, in rendered_content
    content = template.render(context, self._request)
  File "/ops-data/zp/haha/mysite-11/lib/python3.6/site-packages/django/template/backends/django.py", line 66, in render
    return self.template.render(context)
  File "/ops-data/zp/haha/mysite-11/lib/python3.6/site-packages/django/template/base.py", line 207, in render
    return self._render(context)
  File "/ops-data/zp/haha/mysite-11/lib/python3.6/site-packages/django/template/base.py", line 199, in _render
    return self.nodelist.render(context)
  File "/ops-data/zp/haha/mysite-11/lib/python3.6/site-packages/django/template/base.py", line 990, in render
    bit = node.render_annotated(context)
  File "/ops-data/zp/haha/mysite-11/lib/python3.6/site-packages/django/template/base.py", line 957, in render_annotated
    return self.render(context)
  File "/ops-data/zp/haha/mysite-11/lib/python3.6/site-packages/django/template/loader_tags.py", line 177, in render
    return compiled_parent._render(context)
  File "/ops-data/zp/haha/mysite-11/lib/python3.6/site-packages/django/template/base.py", line 199, in _render
    return self.nodelist.render(context)
  File "/ops-data/zp/haha/mysite-11/lib/python3.6/site-packages/django/template/base.py", line 990, in render
    bit = node.render_annotated(context)
  File "/ops-data/zp/haha/mysite-11/lib/python3.6/site-packages/django/template/base.py", line 957, in render_annotated
    return self.render(context)
  File "/ops-data/zp/haha/mysite-11/lib/python3.6/site-packages/django/template/loader_tags.py", line 72, in render
    result = block.nodelist.render(context)
  File "/ops-data/zp/haha/mysite-11/lib/python3.6/site-packages/django/template/base.py", line 990, in render
    bit = node.render_annotated(context)
  File "/ops-data/zp/haha/mysite-11/lib/python3.6/site-packages/django/template/base.py", line 957, in render_annotated
    return self.render(context)
  File "/ops-data/zp/haha/mysite-11/lib/python3.6/site-packages/django/template/defaulttags.py", line 458, in render
    url = reverse(view_name, args=args, kwargs=kwargs, current_app=current_app)
  File "/ops-data/zp/haha/mysite-11/lib/python3.6/site-packages/django/urls/base.py", line 91, in reverse
    return force_text(iri_to_uri(resolver._reverse_with_prefix(view, prefix, *args, **kwargs)))
  File "/ops-data/zp/haha/mysite-11/lib/python3.6/site-packages/django/urls/resolvers.py", line 497, in _reverse_with_prefix
    raise NoReverseMatch(msg)
django.urls.exceptions.NoReverseMatch: Reverse for '' not found. '' is not a valid view function or pattern name.
2017-12-17 16:45:59,148-[INFO]-/ops-data/zp/haha/mysite-11/opsweb/resources/idc/__init__.py-[line:63]-IDC 模型对象id: 1 查询成功并返回给前端
2017-12-17 16:46:03,765-[INFO]-/ops-data/zp/haha/mysite-11/opsweb/resources/idc/__init__.py-[line:63]-IDC 模型对象id: 2 查询成功并返回给前端
2017-12-17 16:46:06,660-[INFO]-/ops-data/zp/haha/mysite-11/opsweb/resources/idc/__init__.py-[line:63]-IDC 模型对象id: 3 查询成功并返回给前端
2017-12-17 16:46:09,516-[INFO]-/ops-data/zp/haha/mysite-11/opsweb/resources/idc/__init__.py-[line:63]-IDC 模型对象id: 2 查询成功并返回给前端
2017-12-17 16:46:12,176-[INFO]-/ops-data/zp/haha/mysite-11/opsweb/resources/idc/__init__.py-[line:63]-IDC 模型对象id: 1 查询成功并返回给前端
2017-12-17 16:46:16,196-[INFO]-/ops-data/zp/haha/mysite-11/opsweb/resources/idc/__init__.py-[line:63]-IDC 模型对象id: 3 查询成功并返回给前端
2017-12-17 16:46:19,599-[INFO]-/ops-data/zp/haha/mysite-11/opsweb/resources/idc/__init__.py-[line:63]-IDC 模型对象id: 2 查询成功并返回给前端
2017-12-17 16:46:53,589-[INFO]-/ops-data/zp/haha/mysite-11/opsweb/resources/idc/__init__.py-[line:63]-IDC 模型对象id: 1 查询成功并返回给前端
2017-12-17 16:46:56,136-[INFO]-/ops-data/zp/haha/mysite-11/opsweb/resources/idc/__init__.py-[line:63]-IDC 模型对象id: 2 查询成功并返回给前端
2017-12-17 16:47:01,903-[INFO]-/ops-data/zp/haha/mysite-11/opsweb/resources/idc/__init__.py-[line:63]-IDC 模型对象id: 3 查询成功并返回给前端
2017-12-17 16:49:53,175-[INFO]-/ops-data/zp/haha/mysite-11/opsweb/resources/idc/__init__.py-[line:63]-IDC 模型对象id: 8 查询成功并返回给前端
2017-12-17 16:52:22,890-[INFO]-/ops-data/zp/haha/mysite-11/opsweb/resources/idc/__init__.py-[line:63]-IDC 模型对象id: 8 查询成功并返回给前端
2017-12-17 16:52:44,500-[INFO]-/ops-data/zp/haha/mysite-11/opsweb/resources/idc/__init__.py-[line:63]-IDC 模型对象id: 3 查询成功并返回给前端
2017-12-17 16:52:46,523-[INFO]-/ops-data/zp/haha/mysite-11/opsweb/resources/idc/__init__.py-[line:63]-IDC 模型对象id: 2 查询成功并返回给前端
2017-12-17 17:04:37,053-[ERROR]-/ops-data/zp/haha/mysite-11/lib/python3.6/site-packages/django/core/handlers/exception.py-[line:135]-Internal Server Error: /resources/idc/change/
Traceback (most recent call last):
  File "/ops-data/zp/haha/mysite-11/lib/python3.6/site-packages/django/core/handlers/exception.py", line 41, in inner
    response = get_response(request)
  File "/ops-data/zp/haha/mysite-11/lib/python3.6/site-packages/django/core/handlers/base.py", line 249, in _legacy_get_response
    response = self._get_response(request)
  File "/ops-data/zp/haha/mysite-11/lib/python3.6/site-packages/django/core/handlers/base.py", line 172, in _get_response
    resolver_match = resolver.resolve(request.path_info)
  File "/ops-data/zp/haha/mysite-11/lib/python3.6/site-packages/django/urls/resolvers.py", line 362, in resolve
    for pattern in self.url_patterns:
  File "/ops-data/zp/haha/mysite-11/lib/python3.6/site-packages/django/utils/functional.py", line 35, in __get__
    res = instance.__dict__[self.name] = self.func(instance)
  File "/ops-data/zp/haha/mysite-11/lib/python3.6/site-packages/django/urls/resolvers.py", line 405, in url_patterns
    patterns = getattr(self.urlconf_module, "urlpatterns", self.urlconf_module)
  File "/ops-data/zp/haha/mysite-11/lib/python3.6/site-packages/django/utils/functional.py", line 35, in __get__
    res = instance.__dict__[self.name] = self.func(instance)
  File "/ops-data/zp/haha/mysite-11/lib/python3.6/site-packages/django/urls/resolvers.py", line 398, in urlconf_module
    return import_module(self.urlconf_name)
  File "/ops-data/zp/haha/mysite-11/lib/python3.6/importlib/__init__.py", line 126, in import_module
    return _bootstrap._gcd_import(name[level:], package, level)
  File "<frozen importlib._bootstrap>", line 994, in _gcd_import
  File "<frozen importlib._bootstrap>", line 971, in _find_and_load
  File "<frozen importlib._bootstrap>", line 955, in _find_and_load_unlocked
  File "<frozen importlib._bootstrap>", line 665, in _load_unlocked
  File "<frozen importlib._bootstrap_external>", line 678, in exec_module
  File "<frozen importlib._bootstrap>", line 219, in _call_with_frames_removed
  File "/ops-data/zp/haha/mysite-11/opsweb/opsweb/urls.py", line 29, in <module>
    url(r'^resources/', include("resources.urls")),
  File "/ops-data/zp/haha/mysite-11/lib/python3.6/site-packages/django/conf/urls/__init__.py", line 50, in include
    urlconf_module = import_module(urlconf_module)
  File "/ops-data/zp/haha/mysite-11/lib/python3.6/importlib/__init__.py", line 126, in import_module
    return _bootstrap._gcd_import(name[level:], package, level)
  File "<frozen importlib._bootstrap>", line 994, in _gcd_import
  File "<frozen importlib._bootstrap>", line 971, in _find_and_load
  File "<frozen importlib._bootstrap>", line 955, in _find_and_load_unlocked
  File "<frozen importlib._bootstrap>", line 665, in _load_unlocked
  File "<frozen importlib._bootstrap_external>", line 678, in exec_module
  File "<frozen importlib._bootstrap>", line 219, in _call_with_frames_removed
  File "/ops-data/zp/haha/mysite-11/opsweb/resources/urls.py", line 4, in <module>
    from . import views,server,idc
  File "/ops-data/zp/haha/mysite-11/opsweb/resources/idc/__init__.py", line 9, in <module>
    from resources.forms import IdcAddForm
ImportError: cannot import name 'IdcAddForm'
2017-12-17 17:04:37,725-[ERROR]-/ops-data/zp/haha/mysite-11/lib/python3.6/site-packages/django/core/handlers/exception.py-[line:135]-Internal Server Error: /resources/idc/change/
Traceback (most recent call last):
  File "/ops-data/zp/haha/mysite-11/lib/python3.6/site-packages/django/core/handlers/exception.py", line 41, in inner
    response = get_response(request)
  File "/ops-data/zp/haha/mysite-11/lib/python3.6/site-packages/django/core/handlers/base.py", line 249, in _legacy_get_response
    response = self._get_response(request)
  File "/ops-data/zp/haha/mysite-11/lib/python3.6/site-packages/django/core/handlers/base.py", line 172, in _get_response
    resolver_match = resolver.resolve(request.path_info)
  File "/ops-data/zp/haha/mysite-11/lib/python3.6/site-packages/django/urls/resolvers.py", line 362, in resolve
    for pattern in self.url_patterns:
  File "/ops-data/zp/haha/mysite-11/lib/python3.6/site-packages/django/utils/functional.py", line 35, in __get__
    res = instance.__dict__[self.name] = self.func(instance)
  File "/ops-data/zp/haha/mysite-11/lib/python3.6/site-packages/django/urls/resolvers.py", line 405, in url_patterns
    patterns = getattr(self.urlconf_module, "urlpatterns", self.urlconf_module)
  File "/ops-data/zp/haha/mysite-11/lib/python3.6/site-packages/django/utils/functional.py", line 35, in __get__
    res = instance.__dict__[self.name] = self.func(instance)
  File "/ops-data/zp/haha/mysite-11/lib/python3.6/site-packages/django/urls/resolvers.py", line 398, in urlconf_module
    return import_module(self.urlconf_name)
  File "/ops-data/zp/haha/mysite-11/lib/python3.6/importlib/__init__.py", line 126, in import_module
    return _bootstrap._gcd_import(name[level:], package, level)
  File "<frozen importlib._bootstrap>", line 994, in _gcd_import
  File "<frozen importlib._bootstrap>", line 971, in _find_and_load
  File "<frozen importlib._bootstrap>", line 955, in _find_and_load_unlocked
  File "<frozen importlib._bootstrap>", line 665, in _load_unlocked
  File "<frozen importlib._bootstrap_external>", line 678, in exec_module
  File "<frozen importlib._bootstrap>", line 219, in _call_with_frames_removed
  File "/ops-data/zp/haha/mysite-11/opsweb/opsweb/urls.py", line 29, in <module>
    url(r'^resources/', include("resources.urls")),
  File "/ops-data/zp/haha/mysite-11/lib/python3.6/site-packages/django/conf/urls/__init__.py", line 50, in include
    urlconf_module = import_module(urlconf_module)
  File "/ops-data/zp/haha/mysite-11/lib/python3.6/importlib/__init__.py", line 126, in import_module
    return _bootstrap._gcd_import(name[level:], package, level)
  File "<frozen importlib._bootstrap>", line 994, in _gcd_import
  File "<frozen importlib._bootstrap>", line 971, in _find_and_load
  File "<frozen importlib._bootstrap>", line 955, in _find_and_load_unlocked
  File "<frozen importlib._bootstrap>", line 665, in _load_unlocked
  File "<frozen importlib._bootstrap_external>", line 678, in exec_module
  File "<frozen importlib._bootstrap>", line 219, in _call_with_frames_removed
  File "/ops-data/zp/haha/mysite-11/opsweb/resources/urls.py", line 4, in <module>
    from . import views,server,idc
  File "/ops-data/zp/haha/mysite-11/opsweb/resources/idc/__init__.py", line 9, in <module>
    from resources.forms import IdcAddForm
ImportError: cannot import name 'IdcAddForm'
2017-12-17 17:04:38,456-[ERROR]-/ops-data/zp/haha/mysite-11/lib/python3.6/site-packages/django/core/handlers/exception.py-[line:135]-Internal Server Error: /resources/idc/change/
Traceback (most recent call last):
  File "/ops-data/zp/haha/mysite-11/lib/python3.6/site-packages/django/core/handlers/exception.py", line 41, in inner
    response = get_response(request)
  File "/ops-data/zp/haha/mysite-11/lib/python3.6/site-packages/django/core/handlers/base.py", line 249, in _legacy_get_response
    response = self._get_response(request)
  File "/ops-data/zp/haha/mysite-11/lib/python3.6/site-packages/django/core/handlers/base.py", line 172, in _get_response
    resolver_match = resolver.resolve(request.path_info)
  File "/ops-data/zp/haha/mysite-11/lib/python3.6/site-packages/django/urls/resolvers.py", line 362, in resolve
    for pattern in self.url_patterns:
  File "/ops-data/zp/haha/mysite-11/lib/python3.6/site-packages/django/utils/functional.py", line 35, in __get__
    res = instance.__dict__[self.name] = self.func(instance)
  File "/ops-data/zp/haha/mysite-11/lib/python3.6/site-packages/django/urls/resolvers.py", line 405, in url_patterns
    patterns = getattr(self.urlconf_module, "urlpatterns", self.urlconf_module)
  File "/ops-data/zp/haha/mysite-11/lib/python3.6/site-packages/django/utils/functional.py", line 35, in __get__
    res = instance.__dict__[self.name] = self.func(instance)
  File "/ops-data/zp/haha/mysite-11/lib/python3.6/site-packages/django/urls/resolvers.py", line 398, in urlconf_module
    return import_module(self.urlconf_name)
  File "/ops-data/zp/haha/mysite-11/lib/python3.6/importlib/__init__.py", line 126, in import_module
    return _bootstrap._gcd_import(name[level:], package, level)
  File "<frozen importlib._bootstrap>", line 994, in _gcd_import
  File "<frozen importlib._bootstrap>", line 971, in _find_and_load
  File "<frozen importlib._bootstrap>", line 955, in _find_and_load_unlocked
  File "<frozen importlib._bootstrap>", line 665, in _load_unlocked
  File "<frozen importlib._bootstrap_external>", line 678, in exec_module
  File "<frozen importlib._bootstrap>", line 219, in _call_with_frames_removed
  File "/ops-data/zp/haha/mysite-11/opsweb/opsweb/urls.py", line 29, in <module>
    url(r'^resources/', include("resources.urls")),
  File "/ops-data/zp/haha/mysite-11/lib/python3.6/site-packages/django/conf/urls/__init__.py", line 50, in include
    urlconf_module = import_module(urlconf_module)
  File "/ops-data/zp/haha/mysite-11/lib/python3.6/importlib/__init__.py", line 126, in import_module
    return _bootstrap._gcd_import(name[level:], package, level)
  File "<frozen importlib._bootstrap>", line 994, in _gcd_import
  File "<frozen importlib._bootstrap>", line 971, in _find_and_load
  File "<frozen importlib._bootstrap>", line 955, in _find_and_load_unlocked
  File "<frozen importlib._bootstrap>", line 665, in _load_unlocked
  File "<frozen importlib._bootstrap_external>", line 678, in exec_module
  File "<frozen importlib._bootstrap>", line 219, in _call_with_frames_removed
  File "/ops-data/zp/haha/mysite-11/opsweb/resources/urls.py", line 4, in <module>
    from . import views,server,idc
  File "/ops-data/zp/haha/mysite-11/opsweb/resources/idc/__init__.py", line 9, in <module>
    from resources.forms import IdcAddForm
ImportError: cannot import name 'IdcAddForm'
2017-12-17 17:04:40,676-[ERROR]-/ops-data/zp/haha/mysite-11/lib/python3.6/site-packages/django/core/handlers/exception.py-[line:135]-Internal Server Error: /resources/idc/change/
Traceback (most recent call last):
  File "/ops-data/zp/haha/mysite-11/lib/python3.6/site-packages/django/core/handlers/exception.py", line 41, in inner
    response = get_response(request)
  File "/ops-data/zp/haha/mysite-11/lib/python3.6/site-packages/django/core/handlers/base.py", line 249, in _legacy_get_response
    response = self._get_response(request)
  File "/ops-data/zp/haha/mysite-11/lib/python3.6/site-packages/django/core/handlers/base.py", line 172, in _get_response
    resolver_match = resolver.resolve(request.path_info)
  File "/ops-data/zp/haha/mysite-11/lib/python3.6/site-packages/django/urls/resolvers.py", line 362, in resolve
    for pattern in self.url_patterns:
  File "/ops-data/zp/haha/mysite-11/lib/python3.6/site-packages/django/utils/functional.py", line 35, in __get__
    res = instance.__dict__[self.name] = self.func(instance)
  File "/ops-data/zp/haha/mysite-11/lib/python3.6/site-packages/django/urls/resolvers.py", line 405, in url_patterns
    patterns = getattr(self.urlconf_module, "urlpatterns", self.urlconf_module)
  File "/ops-data/zp/haha/mysite-11/lib/python3.6/site-packages/django/utils/functional.py", line 35, in __get__
    res = instance.__dict__[self.name] = self.func(instance)
  File "/ops-data/zp/haha/mysite-11/lib/python3.6/site-packages/django/urls/resolvers.py", line 398, in urlconf_module
    return import_module(self.urlconf_name)
  File "/ops-data/zp/haha/mysite-11/lib/python3.6/importlib/__init__.py", line 126, in import_module
    return _bootstrap._gcd_import(name[level:], package, level)
  File "<frozen importlib._bootstrap>", line 994, in _gcd_import
  File "<frozen importlib._bootstrap>", line 971, in _find_and_load
  File "<frozen importlib._bootstrap>", line 955, in _find_and_load_unlocked
  File "<frozen importlib._bootstrap>", line 665, in _load_unlocked
  File "<frozen importlib._bootstrap_external>", line 678, in exec_module
  File "<frozen importlib._bootstrap>", line 219, in _call_with_frames_removed
  File "/ops-data/zp/haha/mysite-11/opsweb/opsweb/urls.py", line 29, in <module>
    url(r'^resources/', include("resources.urls")),
  File "/ops-data/zp/haha/mysite-11/lib/python3.6/site-packages/django/conf/urls/__init__.py", line 50, in include
    urlconf_module = import_module(urlconf_module)
  File "/ops-data/zp/haha/mysite-11/lib/python3.6/importlib/__init__.py", line 126, in import_module
    return _bootstrap._gcd_import(name[level:], package, level)
  File "<frozen importlib._bootstrap>", line 994, in _gcd_import
  File "<frozen importlib._bootstrap>", line 971, in _find_and_load
  File "<frozen importlib._bootstrap>", line 955, in _find_and_load_unlocked
  File "<frozen importlib._bootstrap>", line 665, in _load_unlocked
  File "<frozen importlib._bootstrap_external>", line 678, in exec_module
  File "<frozen importlib._bootstrap>", line 219, in _call_with_frames_removed
  File "/ops-data/zp/haha/mysite-11/opsweb/resources/urls.py", line 4, in <module>
    from . import views,server,idc
  File "/ops-data/zp/haha/mysite-11/opsweb/resources/idc/__init__.py", line 9, in <module>
    from resources.forms import IdcAddForm
ImportError: cannot import name 'IdcAddForm'
2017-12-17 17:04:40,864-[ERROR]-/ops-data/zp/haha/mysite-11/lib/python3.6/site-packages/django/core/handlers/exception.py-[line:135]-Internal Server Error: /resources/idc/change/
Traceback (most recent call last):
  File "/ops-data/zp/haha/mysite-11/lib/python3.6/site-packages/django/core/handlers/exception.py", line 41, in inner
    response = get_response(request)
  File "/ops-data/zp/haha/mysite-11/lib/python3.6/site-packages/django/core/handlers/base.py", line 249, in _legacy_get_response
    response = self._get_response(request)
  File "/ops-data/zp/haha/mysite-11/lib/python3.6/site-packages/django/core/handlers/base.py", line 172, in _get_response
    resolver_match = resolver.resolve(request.path_info)
  File "/ops-data/zp/haha/mysite-11/lib/python3.6/site-packages/django/urls/resolvers.py", line 362, in resolve
    for pattern in self.url_patterns:
  File "/ops-data/zp/haha/mysite-11/lib/python3.6/site-packages/django/utils/functional.py", line 35, in __get__
    res = instance.__dict__[self.name] = self.func(instance)
  File "/ops-data/zp/haha/mysite-11/lib/python3.6/site-packages/django/urls/resolvers.py", line 405, in url_patterns
    patterns = getattr(self.urlconf_module, "urlpatterns", self.urlconf_module)
  File "/ops-data/zp/haha/mysite-11/lib/python3.6/site-packages/django/utils/functional.py", line 35, in __get__
    res = instance.__dict__[self.name] = self.func(instance)
  File "/ops-data/zp/haha/mysite-11/lib/python3.6/site-packages/django/urls/resolvers.py", line 398, in urlconf_module
    return import_module(self.urlconf_name)
  File "/ops-data/zp/haha/mysite-11/lib/python3.6/importlib/__init__.py", line 126, in import_module
    return _bootstrap._gcd_import(name[level:], package, level)
  File "<frozen importlib._bootstrap>", line 994, in _gcd_import
  File "<frozen importlib._bootstrap>", line 971, in _find_and_load
  File "<frozen importlib._bootstrap>", line 955, in _find_and_load_unlocked
  File "<frozen importlib._bootstrap>", line 665, in _load_unlocked
  File "<frozen importlib._bootstrap_external>", line 678, in exec_module
  File "<frozen importlib._bootstrap>", line 219, in _call_with_frames_removed
  File "/ops-data/zp/haha/mysite-11/opsweb/opsweb/urls.py", line 29, in <module>
    url(r'^resources/', include("resources.urls")),
  File "/ops-data/zp/haha/mysite-11/lib/python3.6/site-packages/django/conf/urls/__init__.py", line 50, in include
    urlconf_module = import_module(urlconf_module)
  File "/ops-data/zp/haha/mysite-11/lib/python3.6/importlib/__init__.py", line 126, in import_module
    return _bootstrap._gcd_import(name[level:], package, level)
  File "<frozen importlib._bootstrap>", line 994, in _gcd_import
  File "<frozen importlib._bootstrap>", line 971, in _find_and_load
  File "<frozen importlib._bootstrap>", line 955, in _find_and_load_unlocked
  File "<frozen importlib._bootstrap>", line 665, in _load_unlocked
  File "<frozen importlib._bootstrap_external>", line 678, in exec_module
  File "<frozen importlib._bootstrap>", line 219, in _call_with_frames_removed
  File "/ops-data/zp/haha/mysite-11/opsweb/resources/urls.py", line 4, in <module>
    from . import views,server,idc
  File "/ops-data/zp/haha/mysite-11/opsweb/resources/idc/__init__.py", line 9, in <module>
    from resources.forms import IdcAddForm
ImportError: cannot import name 'IdcAddForm'
2017-12-17 17:04:40,932-[ERROR]-/ops-data/zp/haha/mysite-11/lib/python3.6/site-packages/django/core/handlers/exception.py-[line:135]-Internal Server Error: /resources/idc/change/
Traceback (most recent call last):
  File "/ops-data/zp/haha/mysite-11/lib/python3.6/site-packages/django/core/handlers/exception.py", line 41, in inner
    response = get_response(request)
  File "/ops-data/zp/haha/mysite-11/lib/python3.6/site-packages/django/core/handlers/base.py", line 249, in _legacy_get_response
    response = self._get_response(request)
  File "/ops-data/zp/haha/mysite-11/lib/python3.6/site-packages/django/core/handlers/base.py", line 172, in _get_response
    resolver_match = resolver.resolve(request.path_info)
  File "/ops-data/zp/haha/mysite-11/lib/python3.6/site-packages/django/urls/resolvers.py", line 362, in resolve
    for pattern in self.url_patterns:
  File "/ops-data/zp/haha/mysite-11/lib/python3.6/site-packages/django/utils/functional.py", line 35, in __get__
    res = instance.__dict__[self.name] = self.func(instance)
  File "/ops-data/zp/haha/mysite-11/lib/python3.6/site-packages/django/urls/resolvers.py", line 405, in url_patterns
    patterns = getattr(self.urlconf_module, "urlpatterns", self.urlconf_module)
  File "/ops-data/zp/haha/mysite-11/lib/python3.6/site-packages/django/utils/functional.py", line 35, in __get__
    res = instance.__dict__[self.name] = self.func(instance)
  File "/ops-data/zp/haha/mysite-11/lib/python3.6/site-packages/django/urls/resolvers.py", line 398, in urlconf_module
    return import_module(self.urlconf_name)
  File "/ops-data/zp/haha/mysite-11/lib/python3.6/importlib/__init__.py", line 126, in import_module
    return _bootstrap._gcd_import(name[level:], package, level)
  File "<frozen importlib._bootstrap>", line 994, in _gcd_import
  File "<frozen importlib._bootstrap>", line 971, in _find_and_load
  File "<frozen importlib._bootstrap>", line 955, in _find_and_load_unlocked
  File "<frozen importlib._bootstrap>", line 665, in _load_unlocked
  File "<frozen importlib._bootstrap_external>", line 678, in exec_module
  File "<frozen importlib._bootstrap>", line 219, in _call_with_frames_removed
  File "/ops-data/zp/haha/mysite-11/opsweb/opsweb/urls.py", line 29, in <module>
    url(r'^resources/', include("resources.urls")),
  File "/ops-data/zp/haha/mysite-11/lib/python3.6/site-packages/django/conf/urls/__init__.py", line 50, in include
    urlconf_module = import_module(urlconf_module)
  File "/ops-data/zp/haha/mysite-11/lib/python3.6/importlib/__init__.py", line 126, in import_module
    return _bootstrap._gcd_import(name[level:], package, level)
  File "<frozen importlib._bootstrap>", line 994, in _gcd_import
  File "<frozen importlib._bootstrap>", line 971, in _find_and_load
  File "<frozen importlib._bootstrap>", line 955, in _find_and_load_unlocked
  File "<frozen importlib._bootstrap>", line 665, in _load_unlocked
  File "<frozen importlib._bootstrap_external>", line 678, in exec_module
  File "<frozen importlib._bootstrap>", line 219, in _call_with_frames_removed
  File "/ops-data/zp/haha/mysite-11/opsweb/resources/urls.py", line 4, in <module>
    from . import views,server,idc
  File "/ops-data/zp/haha/mysite-11/opsweb/resources/idc/__init__.py", line 9, in <module>
    from resources.forms import IdcAddForm
ImportError: cannot import name 'IdcAddForm'
2017-12-17 17:04:41,002-[ERROR]-/ops-data/zp/haha/mysite-11/lib/python3.6/site-packages/django/core/handlers/exception.py-[line:135]-Internal Server Error: /resources/idc/change/
Traceback (most recent call last):
  File "/ops-data/zp/haha/mysite-11/lib/python3.6/site-packages/django/core/handlers/exception.py", line 41, in inner
    response = get_response(request)
  File "/ops-data/zp/haha/mysite-11/lib/python3.6/site-packages/django/core/handlers/base.py", line 249, in _legacy_get_response
    response = self._get_response(request)
  File "/ops-data/zp/haha/mysite-11/lib/python3.6/site-packages/django/core/handlers/base.py", line 172, in _get_response
    resolver_match = resolver.resolve(request.path_info)
  File "/ops-data/zp/haha/mysite-11/lib/python3.6/site-packages/django/urls/resolvers.py", line 362, in resolve
    for pattern in self.url_patterns:
  File "/ops-data/zp/haha/mysite-11/lib/python3.6/site-packages/django/utils/functional.py", line 35, in __get__
    res = instance.__dict__[self.name] = self.func(instance)
  File "/ops-data/zp/haha/mysite-11/lib/python3.6/site-packages/django/urls/resolvers.py", line 405, in url_patterns
    patterns = getattr(self.urlconf_module, "urlpatterns", self.urlconf_module)
  File "/ops-data/zp/haha/mysite-11/lib/python3.6/site-packages/django/utils/functional.py", line 35, in __get__
    res = instance.__dict__[self.name] = self.func(instance)
  File "/ops-data/zp/haha/mysite-11/lib/python3.6/site-packages/django/urls/resolvers.py", line 398, in urlconf_module
    return import_module(self.urlconf_name)
  File "/ops-data/zp/haha/mysite-11/lib/python3.6/importlib/__init__.py", line 126, in import_module
    return _bootstrap._gcd_import(name[level:], package, level)
  File "<frozen importlib._bootstrap>", line 994, in _gcd_import
  File "<frozen importlib._bootstrap>", line 971, in _find_and_load
  File "<frozen importlib._bootstrap>", line 955, in _find_and_load_unlocked
  File "<frozen importlib._bootstrap>", line 665, in _load_unlocked
  File "<frozen importlib._bootstrap_external>", line 678, in exec_module
  File "<frozen importlib._bootstrap>", line 219, in _call_with_frames_removed
  File "/ops-data/zp/haha/mysite-11/opsweb/opsweb/urls.py", line 29, in <module>
    url(r'^resources/', include("resources.urls")),
  File "/ops-data/zp/haha/mysite-11/lib/python3.6/site-packages/django/conf/urls/__init__.py", line 50, in include
    urlconf_module = import_module(urlconf_module)
  File "/ops-data/zp/haha/mysite-11/lib/python3.6/importlib/__init__.py", line 126, in import_module
    return _bootstrap._gcd_import(name[level:], package, level)
  File "<frozen importlib._bootstrap>", line 994, in _gcd_import
  File "<frozen importlib._bootstrap>", line 971, in _find_and_load
  File "<frozen importlib._bootstrap>", line 955, in _find_and_load_unlocked
  File "<frozen importlib._bootstrap>", line 665, in _load_unlocked
  File "<frozen importlib._bootstrap_external>", line 678, in exec_module
  File "<frozen importlib._bootstrap>", line 219, in _call_with_frames_removed
  File "/ops-data/zp/haha/mysite-11/opsweb/resources/urls.py", line 4, in <module>
    from . import views,server,idc
  File "/ops-data/zp/haha/mysite-11/opsweb/resources/idc/__init__.py", line 9, in <module>
    from resources.forms import IdcAddForm
ImportError: cannot import name 'IdcAddForm'
2017-12-17 17:04:41,073-[ERROR]-/ops-data/zp/haha/mysite-11/lib/python3.6/site-packages/django/core/handlers/exception.py-[line:135]-Internal Server Error: /resources/idc/change/
Traceback (most recent call last):
  File "/ops-data/zp/haha/mysite-11/lib/python3.6/site-packages/django/core/handlers/exception.py", line 41, in inner
    response = get_response(request)
  File "/ops-data/zp/haha/mysite-11/lib/python3.6/site-packages/django/core/handlers/base.py", line 249, in _legacy_get_response
    response = self._get_response(request)
  File "/ops-data/zp/haha/mysite-11/lib/python3.6/site-packages/django/core/handlers/base.py", line 172, in _get_response
    resolver_match = resolver.resolve(request.path_info)
  File "/ops-data/zp/haha/mysite-11/lib/python3.6/site-packages/django/urls/resolvers.py", line 362, in resolve
    for pattern in self.url_patterns:
  File "/ops-data/zp/haha/mysite-11/lib/python3.6/site-packages/django/utils/functional.py", line 35, in __get__
    res = instance.__dict__[self.name] = self.func(instance)
  File "/ops-data/zp/haha/mysite-11/lib/python3.6/site-packages/django/urls/resolvers.py", line 405, in url_patterns
    patterns = getattr(self.urlconf_module, "urlpatterns", self.urlconf_module)
  File "/ops-data/zp/haha/mysite-11/lib/python3.6/site-packages/django/utils/functional.py", line 35, in __get__
    res = instance.__dict__[self.name] = self.func(instance)
  File "/ops-data/zp/haha/mysite-11/lib/python3.6/site-packages/django/urls/resolvers.py", line 398, in urlconf_module
    return import_module(self.urlconf_name)
  File "/ops-data/zp/haha/mysite-11/lib/python3.6/importlib/__init__.py", line 126, in import_module
    return _bootstrap._gcd_import(name[level:], package, level)
  File "<frozen importlib._bootstrap>", line 994, in _gcd_import
  File "<frozen importlib._bootstrap>", line 971, in _find_and_load
  File "<frozen importlib._bootstrap>", line 955, in _find_and_load_unlocked
  File "<frozen importlib._bootstrap>", line 665, in _load_unlocked
  File "<frozen importlib._bootstrap_external>", line 678, in exec_module
  File "<frozen importlib._bootstrap>", line 219, in _call_with_frames_removed
  File "/ops-data/zp/haha/mysite-11/opsweb/opsweb/urls.py", line 29, in <module>
    url(r'^resources/', include("resources.urls")),
  File "/ops-data/zp/haha/mysite-11/lib/python3.6/site-packages/django/conf/urls/__init__.py", line 50, in include
    urlconf_module = import_module(urlconf_module)
  File "/ops-data/zp/haha/mysite-11/lib/python3.6/importlib/__init__.py", line 126, in import_module
    return _bootstrap._gcd_import(name[level:], package, level)
  File "<frozen importlib._bootstrap>", line 994, in _gcd_import
  File "<frozen importlib._bootstrap>", line 971, in _find_and_load
  File "<frozen importlib._bootstrap>", line 955, in _find_and_load_unlocked
  File "<frozen importlib._bootstrap>", line 665, in _load_unlocked
  File "<frozen importlib._bootstrap_external>", line 678, in exec_module
  File "<frozen importlib._bootstrap>", line 219, in _call_with_frames_removed
  File "/ops-data/zp/haha/mysite-11/opsweb/resources/urls.py", line 4, in <module>
    from . import views,server,idc
  File "/ops-data/zp/haha/mysite-11/opsweb/resources/idc/__init__.py", line 9, in <module>
    from resources.forms import IdcAddForm
ImportError: cannot import name 'IdcAddForm'
2017-12-17 17:04:41,214-[ERROR]-/ops-data/zp/haha/mysite-11/lib/python3.6/site-packages/django/core/handlers/exception.py-[line:135]-Internal Server Error: /resources/idc/change/
Traceback (most recent call last):
  File "/ops-data/zp/haha/mysite-11/lib/python3.6/site-packages/django/core/handlers/exception.py", line 41, in inner
    response = get_response(request)
  File "/ops-data/zp/haha/mysite-11/lib/python3.6/site-packages/django/core/handlers/base.py", line 249, in _legacy_get_response
    response = self._get_response(request)
  File "/ops-data/zp/haha/mysite-11/lib/python3.6/site-packages/django/core/handlers/base.py", line 172, in _get_response
    resolver_match = resolver.resolve(request.path_info)
  File "/ops-data/zp/haha/mysite-11/lib/python3.6/site-packages/django/urls/resolvers.py", line 362, in resolve
    for pattern in self.url_patterns:
  File "/ops-data/zp/haha/mysite-11/lib/python3.6/site-packages/django/utils/functional.py", line 35, in __get__
    res = instance.__dict__[self.name] = self.func(instance)
  File "/ops-data/zp/haha/mysite-11/lib/python3.6/site-packages/django/urls/resolvers.py", line 405, in url_patterns
    patterns = getattr(self.urlconf_module, "urlpatterns", self.urlconf_module)
  File "/ops-data/zp/haha/mysite-11/lib/python3.6/site-packages/django/utils/functional.py", line 35, in __get__
    res = instance.__dict__[self.name] = self.func(instance)
  File "/ops-data/zp/haha/mysite-11/lib/python3.6/site-packages/django/urls/resolvers.py", line 398, in urlconf_module
    return import_module(self.urlconf_name)
  File "/ops-data/zp/haha/mysite-11/lib/python3.6/importlib/__init__.py", line 126, in import_module
    return _bootstrap._gcd_import(name[level:], package, level)
  File "<frozen importlib._bootstrap>", line 994, in _gcd_import
  File "<frozen importlib._bootstrap>", line 971, in _find_and_load
  File "<frozen importlib._bootstrap>", line 955, in _find_and_load_unlocked
  File "<frozen importlib._bootstrap>", line 665, in _load_unlocked
  File "<frozen importlib._bootstrap_external>", line 678, in exec_module
  File "<frozen importlib._bootstrap>", line 219, in _call_with_frames_removed
  File "/ops-data/zp/haha/mysite-11/opsweb/opsweb/urls.py", line 29, in <module>
    url(r'^resources/', include("resources.urls")),
  File "/ops-data/zp/haha/mysite-11/lib/python3.6/site-packages/django/conf/urls/__init__.py", line 50, in include
    urlconf_module = import_module(urlconf_module)
  File "/ops-data/zp/haha/mysite-11/lib/python3.6/importlib/__init__.py", line 126, in import_module
    return _bootstrap._gcd_import(name[level:], package, level)
  File "<frozen importlib._bootstrap>", line 994, in _gcd_import
  File "<frozen importlib._bootstrap>", line 971, in _find_and_load
  File "<frozen importlib._bootstrap>", line 955, in _find_and_load_unlocked
  File "<frozen importlib._bootstrap>", line 665, in _load_unlocked
  File "<frozen importlib._bootstrap_external>", line 678, in exec_module
  File "<frozen importlib._bootstrap>", line 219, in _call_with_frames_removed
  File "/ops-data/zp/haha/mysite-11/opsweb/resources/urls.py", line 4, in <module>
    from . import views,server,idc
  File "/ops-data/zp/haha/mysite-11/opsweb/resources/idc/__init__.py", line 9, in <module>
    from resources.forms import IdcAddForm
ImportError: cannot import name 'IdcAddForm'
2017-12-17 17:04:41,398-[ERROR]-/ops-data/zp/haha/mysite-11/lib/python3.6/site-packages/django/core/handlers/exception.py-[line:135]-Internal Server Error: /resources/idc/change/
Traceback (most recent call last):
  File "/ops-data/zp/haha/mysite-11/lib/python3.6/site-packages/django/core/handlers/exception.py", line 41, in inner
    response = get_response(request)
  File "/ops-data/zp/haha/mysite-11/lib/python3.6/site-packages/django/core/handlers/base.py", line 249, in _legacy_get_response
    response = self._get_response(request)
  File "/ops-data/zp/haha/mysite-11/lib/python3.6/site-packages/django/core/handlers/base.py", line 172, in _get_response
    resolver_match = resolver.resolve(request.path_info)
  File "/ops-data/zp/haha/mysite-11/lib/python3.6/site-packages/django/urls/resolvers.py", line 362, in resolve
    for pattern in self.url_patterns:
  File "/ops-data/zp/haha/mysite-11/lib/python3.6/site-packages/django/utils/functional.py", line 35, in __get__
    res = instance.__dict__[self.name] = self.func(instance)
  File "/ops-data/zp/haha/mysite-11/lib/python3.6/site-packages/django/urls/resolvers.py", line 405, in url_patterns
    patterns = getattr(self.urlconf_module, "urlpatterns", self.urlconf_module)
  File "/ops-data/zp/haha/mysite-11/lib/python3.6/site-packages/django/utils/functional.py", line 35, in __get__
    res = instance.__dict__[self.name] = self.func(instance)
  File "/ops-data/zp/haha/mysite-11/lib/python3.6/site-packages/django/urls/resolvers.py", line 398, in urlconf_module
    return import_module(self.urlconf_name)
  File "/ops-data/zp/haha/mysite-11/lib/python3.6/importlib/__init__.py", line 126, in import_module
    return _bootstrap._gcd_import(name[level:], package, level)
  File "<frozen importlib._bootstrap>", line 994, in _gcd_import
  File "<frozen importlib._bootstrap>", line 971, in _find_and_load
  File "<frozen importlib._bootstrap>", line 955, in _find_and_load_unlocked
  File "<frozen importlib._bootstrap>", line 665, in _load_unlocked
  File "<frozen importlib._bootstrap_external>", line 678, in exec_module
  File "<frozen importlib._bootstrap>", line 219, in _call_with_frames_removed
  File "/ops-data/zp/haha/mysite-11/opsweb/opsweb/urls.py", line 29, in <module>
    url(r'^resources/', include("resources.urls")),
  File "/ops-data/zp/haha/mysite-11/lib/python3.6/site-packages/django/conf/urls/__init__.py", line 50, in include
    urlconf_module = import_module(urlconf_module)
  File "/ops-data/zp/haha/mysite-11/lib/python3.6/importlib/__init__.py", line 126, in import_module
    return _bootstrap._gcd_import(name[level:], package, level)
  File "<frozen importlib._bootstrap>", line 994, in _gcd_import
  File "<frozen importlib._bootstrap>", line 971, in _find_and_load
  File "<frozen importlib._bootstrap>", line 955, in _find_and_load_unlocked
  File "<frozen importlib._bootstrap>", line 665, in _load_unlocked
  File "<frozen importlib._bootstrap_external>", line 678, in exec_module
  File "<frozen importlib._bootstrap>", line 219, in _call_with_frames_removed
  File "/ops-data/zp/haha/mysite-11/opsweb/resources/urls.py", line 4, in <module>
    from . import views,server,idc
  File "/ops-data/zp/haha/mysite-11/opsweb/resources/idc/__init__.py", line 9, in <module>
    from resources.forms import IdcAddForm
ImportError: cannot import name 'IdcAddForm'
2017-12-17 17:04:41,567-[ERROR]-/ops-data/zp/haha/mysite-11/lib/python3.6/site-packages/django/core/handlers/exception.py-[line:135]-Internal Server Error: /resources/idc/change/
Traceback (most recent call last):
  File "/ops-data/zp/haha/mysite-11/lib/python3.6/site-packages/django/core/handlers/exception.py", line 41, in inner
    response = get_response(request)
  File "/ops-data/zp/haha/mysite-11/lib/python3.6/site-packages/django/core/handlers/base.py", line 249, in _legacy_get_response
    response = self._get_response(request)
  File "/ops-data/zp/haha/mysite-11/lib/python3.6/site-packages/django/core/handlers/base.py", line 172, in _get_response
    resolver_match = resolver.resolve(request.path_info)
  File "/ops-data/zp/haha/mysite-11/lib/python3.6/site-packages/django/urls/resolvers.py", line 362, in resolve
    for pattern in self.url_patterns:
  File "/ops-data/zp/haha/mysite-11/lib/python3.6/site-packages/django/utils/functional.py", line 35, in __get__
    res = instance.__dict__[self.name] = self.func(instance)
  File "/ops-data/zp/haha/mysite-11/lib/python3.6/site-packages/django/urls/resolvers.py", line 405, in url_patterns
    patterns = getattr(self.urlconf_module, "urlpatterns", self.urlconf_module)
  File "/ops-data/zp/haha/mysite-11/lib/python3.6/site-packages/django/utils/functional.py", line 35, in __get__
    res = instance.__dict__[self.name] = self.func(instance)
  File "/ops-data/zp/haha/mysite-11/lib/python3.6/site-packages/django/urls/resolvers.py", line 398, in urlconf_module
    return import_module(self.urlconf_name)
  File "/ops-data/zp/haha/mysite-11/lib/python3.6/importlib/__init__.py", line 126, in import_module
    return _bootstrap._gcd_import(name[level:], package, level)
  File "<frozen importlib._bootstrap>", line 994, in _gcd_import
  File "<frozen importlib._bootstrap>", line 971, in _find_and_load
  File "<frozen importlib._bootstrap>", line 955, in _find_and_load_unlocked
  File "<frozen importlib._bootstrap>", line 665, in _load_unlocked
  File "<frozen importlib._bootstrap_external>", line 678, in exec_module
  File "<frozen importlib._bootstrap>", line 219, in _call_with_frames_removed
  File "/ops-data/zp/haha/mysite-11/opsweb/opsweb/urls.py", line 29, in <module>
    url(r'^resources/', include("resources.urls")),
  File "/ops-data/zp/haha/mysite-11/lib/python3.6/site-packages/django/conf/urls/__init__.py", line 50, in include
    urlconf_module = import_module(urlconf_module)
  File "/ops-data/zp/haha/mysite-11/lib/python3.6/importlib/__init__.py", line 126, in import_module
    return _bootstrap._gcd_import(name[level:], package, level)
  File "<frozen importlib._bootstrap>", line 994, in _gcd_import
  File "<frozen importlib._bootstrap>", line 971, in _find_and_load
  File "<frozen importlib._bootstrap>", line 955, in _find_and_load_unlocked
  File "<frozen importlib._bootstrap>", line 665, in _load_unlocked
  File "<frozen importlib._bootstrap_external>", line 678, in exec_module
  File "<frozen importlib._bootstrap>", line 219, in _call_with_frames_removed
  File "/ops-data/zp/haha/mysite-11/opsweb/resources/urls.py", line 4, in <module>
    from . import views,server,idc
  File "/ops-data/zp/haha/mysite-11/opsweb/resources/idc/__init__.py", line 9, in <module>
    from resources.forms import IdcAddForm
ImportError: cannot import name 'IdcAddForm'
2017-12-17 17:04:41,719-[ERROR]-/ops-data/zp/haha/mysite-11/lib/python3.6/site-packages/django/core/handlers/exception.py-[line:135]-Internal Server Error: /resources/idc/change/
Traceback (most recent call last):
  File "/ops-data/zp/haha/mysite-11/lib/python3.6/site-packages/django/core/handlers/exception.py", line 41, in inner
    response = get_response(request)
  File "/ops-data/zp/haha/mysite-11/lib/python3.6/site-packages/django/core/handlers/base.py", line 249, in _legacy_get_response
    response = self._get_response(request)
  File "/ops-data/zp/haha/mysite-11/lib/python3.6/site-packages/django/core/handlers/base.py", line 172, in _get_response
    resolver_match = resolver.resolve(request.path_info)
  File "/ops-data/zp/haha/mysite-11/lib/python3.6/site-packages/django/urls/resolvers.py", line 362, in resolve
    for pattern in self.url_patterns:
  File "/ops-data/zp/haha/mysite-11/lib/python3.6/site-packages/django/utils/functional.py", line 35, in __get__
    res = instance.__dict__[self.name] = self.func(instance)
  File "/ops-data/zp/haha/mysite-11/lib/python3.6/site-packages/django/urls/resolvers.py", line 405, in url_patterns
    patterns = getattr(self.urlconf_module, "urlpatterns", self.urlconf_module)
  File "/ops-data/zp/haha/mysite-11/lib/python3.6/site-packages/django/utils/functional.py", line 35, in __get__
    res = instance.__dict__[self.name] = self.func(instance)
  File "/ops-data/zp/haha/mysite-11/lib/python3.6/site-packages/django/urls/resolvers.py", line 398, in urlconf_module
    return import_module(self.urlconf_name)
  File "/ops-data/zp/haha/mysite-11/lib/python3.6/importlib/__init__.py", line 126, in import_module
    return _bootstrap._gcd_import(name[level:], package, level)
  File "<frozen importlib._bootstrap>", line 994, in _gcd_import
  File "<frozen importlib._bootstrap>", line 971, in _find_and_load
  File "<frozen importlib._bootstrap>", line 955, in _find_and_load_unlocked
  File "<frozen importlib._bootstrap>", line 665, in _load_unlocked
  File "<frozen importlib._bootstrap_external>", line 678, in exec_module
  File "<frozen importlib._bootstrap>", line 219, in _call_with_frames_removed
  File "/ops-data/zp/haha/mysite-11/opsweb/opsweb/urls.py", line 29, in <module>
    url(r'^resources/', include("resources.urls")),
  File "/ops-data/zp/haha/mysite-11/lib/python3.6/site-packages/django/conf/urls/__init__.py", line 50, in include
    urlconf_module = import_module(urlconf_module)
  File "/ops-data/zp/haha/mysite-11/lib/python3.6/importlib/__init__.py", line 126, in import_module
    return _bootstrap._gcd_import(name[level:], package, level)
  File "<frozen importlib._bootstrap>", line 994, in _gcd_import
  File "<frozen importlib._bootstrap>", line 971, in _find_and_load
  File "<frozen importlib._bootstrap>", line 955, in _find_and_load_unlocked
  File "<frozen importlib._bootstrap>", line 665, in _load_unlocked
  File "<frozen importlib._bootstrap_external>", line 678, in exec_module
  File "<frozen importlib._bootstrap>", line 219, in _call_with_frames_removed
  File "/ops-data/zp/haha/mysite-11/opsweb/resources/urls.py", line 4, in <module>
    from . import views,server,idc
  File "/ops-data/zp/haha/mysite-11/opsweb/resources/idc/__init__.py", line 9, in <module>
    from resources.forms import IdcAddForm
ImportError: cannot import name 'IdcAddForm'
2017-12-17 17:04:41,888-[ERROR]-/ops-data/zp/haha/mysite-11/lib/python3.6/site-packages/django/core/handlers/exception.py-[line:135]-Internal Server Error: /resources/idc/change/
Traceback (most recent call last):
  File "/ops-data/zp/haha/mysite-11/lib/python3.6/site-packages/django/core/handlers/exception.py", line 41, in inner
    response = get_response(request)
  File "/ops-data/zp/haha/mysite-11/lib/python3.6/site-packages/django/core/handlers/base.py", line 249, in _legacy_get_response
    response = self._get_response(request)
  File "/ops-data/zp/haha/mysite-11/lib/python3.6/site-packages/django/core/handlers/base.py", line 172, in _get_response
    resolver_match = resolver.resolve(request.path_info)
  File "/ops-data/zp/haha/mysite-11/lib/python3.6/site-packages/django/urls/resolvers.py", line 362, in resolve
    for pattern in self.url_patterns:
  File "/ops-data/zp/haha/mysite-11/lib/python3.6/site-packages/django/utils/functional.py", line 35, in __get__
    res = instance.__dict__[self.name] = self.func(instance)
  File "/ops-data/zp/haha/mysite-11/lib/python3.6/site-packages/django/urls/resolvers.py", line 405, in url_patterns
    patterns = getattr(self.urlconf_module, "urlpatterns", self.urlconf_module)
  File "/ops-data/zp/haha/mysite-11/lib/python3.6/site-packages/django/utils/functional.py", line 35, in __get__
    res = instance.__dict__[self.name] = self.func(instance)
  File "/ops-data/zp/haha/mysite-11/lib/python3.6/site-packages/django/urls/resolvers.py", line 398, in urlconf_module
    return import_module(self.urlconf_name)
  File "/ops-data/zp/haha/mysite-11/lib/python3.6/importlib/__init__.py", line 126, in import_module
    return _bootstrap._gcd_import(name[level:], package, level)
  File "<frozen importlib._bootstrap>", line 994, in _gcd_import
  File "<frozen importlib._bootstrap>", line 971, in _find_and_load
  File "<frozen importlib._bootstrap>", line 955, in _find_and_load_unlocked
  File "<frozen importlib._bootstrap>", line 665, in _load_unlocked
  File "<frozen importlib._bootstrap_external>", line 678, in exec_module
  File "<frozen importlib._bootstrap>", line 219, in _call_with_frames_removed
  File "/ops-data/zp/haha/mysite-11/opsweb/opsweb/urls.py", line 29, in <module>
    url(r'^resources/', include("resources.urls")),
  File "/ops-data/zp/haha/mysite-11/lib/python3.6/site-packages/django/conf/urls/__init__.py", line 50, in include
    urlconf_module = import_module(urlconf_module)
  File "/ops-data/zp/haha/mysite-11/lib/python3.6/importlib/__init__.py", line 126, in import_module
    return _bootstrap._gcd_import(name[level:], package, level)
  File "<frozen importlib._bootstrap>", line 994, in _gcd_import
  File "<frozen importlib._bootstrap>", line 971, in _find_and_load
  File "<frozen importlib._bootstrap>", line 955, in _find_and_load_unlocked
  File "<frozen importlib._bootstrap>", line 665, in _load_unlocked
  File "<frozen importlib._bootstrap_external>", line 678, in exec_module
  File "<frozen importlib._bootstrap>", line 219, in _call_with_frames_removed
  File "/ops-data/zp/haha/mysite-11/opsweb/resources/urls.py", line 4, in <module>
    from . import views,server,idc
  File "/ops-data/zp/haha/mysite-11/opsweb/resources/idc/__init__.py", line 9, in <module>
    from resources.forms import IdcAddForm
ImportError: cannot import name 'IdcAddForm'
2017-12-17 17:04:42,039-[ERROR]-/ops-data/zp/haha/mysite-11/lib/python3.6/site-packages/django/core/handlers/exception.py-[line:135]-Internal Server Error: /resources/idc/change/
Traceback (most recent call last):
  File "/ops-data/zp/haha/mysite-11/lib/python3.6/site-packages/django/core/handlers/exception.py", line 41, in inner
    response = get_response(request)
  File "/ops-data/zp/haha/mysite-11/lib/python3.6/site-packages/django/core/handlers/base.py", line 249, in _legacy_get_response
    response = self._get_response(request)
  File "/ops-data/zp/haha/mysite-11/lib/python3.6/site-packages/django/core/handlers/base.py", line 172, in _get_response
    resolver_match = resolver.resolve(request.path_info)
  File "/ops-data/zp/haha/mysite-11/lib/python3.6/site-packages/django/urls/resolvers.py", line 362, in resolve
    for pattern in self.url_patterns:
  File "/ops-data/zp/haha/mysite-11/lib/python3.6/site-packages/django/utils/functional.py", line 35, in __get__
    res = instance.__dict__[self.name] = self.func(instance)
  File "/ops-data/zp/haha/mysite-11/lib/python3.6/site-packages/django/urls/resolvers.py", line 405, in url_patterns
    patterns = getattr(self.urlconf_module, "urlpatterns", self.urlconf_module)
  File "/ops-data/zp/haha/mysite-11/lib/python3.6/site-packages/django/utils/functional.py", line 35, in __get__
    res = instance.__dict__[self.name] = self.func(instance)
  File "/ops-data/zp/haha/mysite-11/lib/python3.6/site-packages/django/urls/resolvers.py", line 398, in urlconf_module
    return import_module(self.urlconf_name)
  File "/ops-data/zp/haha/mysite-11/lib/python3.6/importlib/__init__.py", line 126, in import_module
    return _bootstrap._gcd_import(name[level:], package, level)
  File "<frozen importlib._bootstrap>", line 994, in _gcd_import
  File "<frozen importlib._bootstrap>", line 971, in _find_and_load
  File "<frozen importlib._bootstrap>", line 955, in _find_and_load_unlocked
  File "<frozen importlib._bootstrap>", line 665, in _load_unlocked
  File "<frozen importlib._bootstrap_external>", line 678, in exec_module
  File "<frozen importlib._bootstrap>", line 219, in _call_with_frames_removed
  File "/ops-data/zp/haha/mysite-11/opsweb/opsweb/urls.py", line 29, in <module>
    url(r'^resources/', include("resources.urls")),
  File "/ops-data/zp/haha/mysite-11/lib/python3.6/site-packages/django/conf/urls/__init__.py", line 50, in include
    urlconf_module = import_module(urlconf_module)
  File "/ops-data/zp/haha/mysite-11/lib/python3.6/importlib/__init__.py", line 126, in import_module
    return _bootstrap._gcd_import(name[level:], package, level)
  File "<frozen importlib._bootstrap>", line 994, in _gcd_import
  File "<frozen importlib._bootstrap>", line 971, in _find_and_load
  File "<frozen importlib._bootstrap>", line 955, in _find_and_load_unlocked
  File "<frozen importlib._bootstrap>", line 665, in _load_unlocked
  File "<frozen importlib._bootstrap_external>", line 678, in exec_module
  File "<frozen importlib._bootstrap>", line 219, in _call_with_frames_removed
  File "/ops-data/zp/haha/mysite-11/opsweb/resources/urls.py", line 4, in <module>
    from . import views,server,idc
  File "/ops-data/zp/haha/mysite-11/opsweb/resources/idc/__init__.py", line 9, in <module>
    from resources.forms import IdcAddForm
ImportError: cannot import name 'IdcAddForm'
2017-12-17 17:04:42,199-[ERROR]-/ops-data/zp/haha/mysite-11/lib/python3.6/site-packages/django/core/handlers/exception.py-[line:135]-Internal Server Error: /resources/idc/change/
Traceback (most recent call last):
  File "/ops-data/zp/haha/mysite-11/lib/python3.6/site-packages/django/core/handlers/exception.py", line 41, in inner
    response = get_response(request)
  File "/ops-data/zp/haha/mysite-11/lib/python3.6/site-packages/django/core/handlers/base.py", line 249, in _legacy_get_response
    response = self._get_response(request)
  File "/ops-data/zp/haha/mysite-11/lib/python3.6/site-packages/django/core/handlers/base.py", line 172, in _get_response
    resolver_match = resolver.resolve(request.path_info)
  File "/ops-data/zp/haha/mysite-11/lib/python3.6/site-packages/django/urls/resolvers.py", line 362, in resolve
    for pattern in self.url_patterns:
  File "/ops-data/zp/haha/mysite-11/lib/python3.6/site-packages/django/utils/functional.py", line 35, in __get__
    res = instance.__dict__[self.name] = self.func(instance)
  File "/ops-data/zp/haha/mysite-11/lib/python3.6/site-packages/django/urls/resolvers.py", line 405, in url_patterns
    patterns = getattr(self.urlconf_module, "urlpatterns", self.urlconf_module)
  File "/ops-data/zp/haha/mysite-11/lib/python3.6/site-packages/django/utils/functional.py", line 35, in __get__
    res = instance.__dict__[self.name] = self.func(instance)
  File "/ops-data/zp/haha/mysite-11/lib/python3.6/site-packages/django/urls/resolvers.py", line 398, in urlconf_module
    return import_module(self.urlconf_name)
  File "/ops-data/zp/haha/mysite-11/lib/python3.6/importlib/__init__.py", line 126, in import_module
    return _bootstrap._gcd_import(name[level:], package, level)
  File "<frozen importlib._bootstrap>", line 994, in _gcd_import
  File "<frozen importlib._bootstrap>", line 971, in _find_and_load
  File "<frozen importlib._bootstrap>", line 955, in _find_and_load_unlocked
  File "<frozen importlib._bootstrap>", line 665, in _load_unlocked
  File "<frozen importlib._bootstrap_external>", line 678, in exec_module
  File "<frozen importlib._bootstrap>", line 219, in _call_with_frames_removed
  File "/ops-data/zp/haha/mysite-11/opsweb/opsweb/urls.py", line 29, in <module>
    url(r'^resources/', include("resources.urls")),
  File "/ops-data/zp/haha/mysite-11/lib/python3.6/site-packages/django/conf/urls/__init__.py", line 50, in include
    urlconf_module = import_module(urlconf_module)
  File "/ops-data/zp/haha/mysite-11/lib/python3.6/importlib/__init__.py", line 126, in import_module
    return _bootstrap._gcd_import(name[level:], package, level)
  File "<frozen importlib._bootstrap>", line 994, in _gcd_import
  File "<frozen importlib._bootstrap>", line 971, in _find_and_load
  File "<frozen importlib._bootstrap>", line 955, in _find_and_load_unlocked
  File "<frozen importlib._bootstrap>", line 665, in _load_unlocked
  File "<frozen importlib._bootstrap_external>", line 678, in exec_module
  File "<frozen importlib._bootstrap>", line 219, in _call_with_frames_removed
  File "/ops-data/zp/haha/mysite-11/opsweb/resources/urls.py", line 4, in <module>
    from . import views,server,idc
  File "/ops-data/zp/haha/mysite-11/opsweb/resources/idc/__init__.py", line 9, in <module>
    from resources.forms import IdcAddForm
ImportError: cannot import name 'IdcAddForm'
2017-12-17 17:04:42,350-[ERROR]-/ops-data/zp/haha/mysite-11/lib/python3.6/site-packages/django/core/handlers/exception.py-[line:135]-Internal Server Error: /resources/idc/change/
Traceback (most recent call last):
  File "/ops-data/zp/haha/mysite-11/lib/python3.6/site-packages/django/core/handlers/exception.py", line 41, in inner
    response = get_response(request)
  File "/ops-data/zp/haha/mysite-11/lib/python3.6/site-packages/django/core/handlers/base.py", line 249, in _legacy_get_response
    response = self._get_response(request)
  File "/ops-data/zp/haha/mysite-11/lib/python3.6/site-packages/django/core/handlers/base.py", line 172, in _get_response
    resolver_match = resolver.resolve(request.path_info)
  File "/ops-data/zp/haha/mysite-11/lib/python3.6/site-packages/django/urls/resolvers.py", line 362, in resolve
    for pattern in self.url_patterns:
  File "/ops-data/zp/haha/mysite-11/lib/python3.6/site-packages/django/utils/functional.py", line 35, in __get__
    res = instance.__dict__[self.name] = self.func(instance)
  File "/ops-data/zp/haha/mysite-11/lib/python3.6/site-packages/django/urls/resolvers.py", line 405, in url_patterns
    patterns = getattr(self.urlconf_module, "urlpatterns", self.urlconf_module)
  File "/ops-data/zp/haha/mysite-11/lib/python3.6/site-packages/django/utils/functional.py", line 35, in __get__
    res = instance.__dict__[self.name] = self.func(instance)
  File "/ops-data/zp/haha/mysite-11/lib/python3.6/site-packages/django/urls/resolvers.py", line 398, in urlconf_module
    return import_module(self.urlconf_name)
  File "/ops-data/zp/haha/mysite-11/lib/python3.6/importlib/__init__.py", line 126, in import_module
    return _bootstrap._gcd_import(name[level:], package, level)
  File "<frozen importlib._bootstrap>", line 994, in _gcd_import
  File "<frozen importlib._bootstrap>", line 971, in _find_and_load
  File "<frozen importlib._bootstrap>", line 955, in _find_and_load_unlocked
  File "<frozen importlib._bootstrap>", line 665, in _load_unlocked
  File "<frozen importlib._bootstrap_external>", line 678, in exec_module
  File "<frozen importlib._bootstrap>", line 219, in _call_with_frames_removed
  File "/ops-data/zp/haha/mysite-11/opsweb/opsweb/urls.py", line 29, in <module>
    url(r'^resources/', include("resources.urls")),
  File "/ops-data/zp/haha/mysite-11/lib/python3.6/site-packages/django/conf/urls/__init__.py", line 50, in include
    urlconf_module = import_module(urlconf_module)
  File "/ops-data/zp/haha/mysite-11/lib/python3.6/importlib/__init__.py", line 126, in import_module
    return _bootstrap._gcd_import(name[level:], package, level)
  File "<frozen importlib._bootstrap>", line 994, in _gcd_import
  File "<frozen importlib._bootstrap>", line 971, in _find_and_load
  File "<frozen importlib._bootstrap>", line 955, in _find_and_load_unlocked
  File "<frozen importlib._bootstrap>", line 665, in _load_unlocked
  File "<frozen importlib._bootstrap_external>", line 678, in exec_module
  File "<frozen importlib._bootstrap>", line 219, in _call_with_frames_removed
  File "/ops-data/zp/haha/mysite-11/opsweb/resources/urls.py", line 4, in <module>
    from . import views,server,idc
  File "/ops-data/zp/haha/mysite-11/opsweb/resources/idc/__init__.py", line 9, in <module>
    from resources.forms import IdcAddForm
ImportError: cannot import name 'IdcAddForm'
2017-12-17 17:04:42,510-[ERROR]-/ops-data/zp/haha/mysite-11/lib/python3.6/site-packages/django/core/handlers/exception.py-[line:135]-Internal Server Error: /resources/idc/change/
Traceback (most recent call last):
  File "/ops-data/zp/haha/mysite-11/lib/python3.6/site-packages/django/core/handlers/exception.py", line 41, in inner
    response = get_response(request)
  File "/ops-data/zp/haha/mysite-11/lib/python3.6/site-packages/django/core/handlers/base.py", line 249, in _legacy_get_response
    response = self._get_response(request)
  File "/ops-data/zp/haha/mysite-11/lib/python3.6/site-packages/django/core/handlers/base.py", line 172, in _get_response
    resolver_match = resolver.resolve(request.path_info)
  File "/ops-data/zp/haha/mysite-11/lib/python3.6/site-packages/django/urls/resolvers.py", line 362, in resolve
    for pattern in self.url_patterns:
  File "/ops-data/zp/haha/mysite-11/lib/python3.6/site-packages/django/utils/functional.py", line 35, in __get__
    res = instance.__dict__[self.name] = self.func(instance)
  File "/ops-data/zp/haha/mysite-11/lib/python3.6/site-packages/django/urls/resolvers.py", line 405, in url_patterns
    patterns = getattr(self.urlconf_module, "urlpatterns", self.urlconf_module)
  File "/ops-data/zp/haha/mysite-11/lib/python3.6/site-packages/django/utils/functional.py", line 35, in __get__
    res = instance.__dict__[self.name] = self.func(instance)
  File "/ops-data/zp/haha/mysite-11/lib/python3.6/site-packages/django/urls/resolvers.py", line 398, in urlconf_module
    return import_module(self.urlconf_name)
  File "/ops-data/zp/haha/mysite-11/lib/python3.6/importlib/__init__.py", line 126, in import_module
    return _bootstrap._gcd_import(name[level:], package, level)
  File "<frozen importlib._bootstrap>", line 994, in _gcd_import
  File "<frozen importlib._bootstrap>", line 971, in _find_and_load
  File "<frozen importlib._bootstrap>", line 955, in _find_and_load_unlocked
  File "<frozen importlib._bootstrap>", line 665, in _load_unlocked
  File "<frozen importlib._bootstrap_external>", line 678, in exec_module
  File "<frozen importlib._bootstrap>", line 219, in _call_with_frames_removed
  File "/ops-data/zp/haha/mysite-11/opsweb/opsweb/urls.py", line 29, in <module>
    url(r'^resources/', include("resources.urls")),
  File "/ops-data/zp/haha/mysite-11/lib/python3.6/site-packages/django/conf/urls/__init__.py", line 50, in include
    urlconf_module = import_module(urlconf_module)
  File "/ops-data/zp/haha/mysite-11/lib/python3.6/importlib/__init__.py", line 126, in import_module
    return _bootstrap._gcd_import(name[level:], package, level)
  File "<frozen importlib._bootstrap>", line 994, in _gcd_import
  File "<frozen importlib._bootstrap>", line 971, in _find_and_load
  File "<frozen importlib._bootstrap>", line 955, in _find_and_load_unlocked
  File "<frozen importlib._bootstrap>", line 665, in _load_unlocked
  File "<frozen importlib._bootstrap_external>", line 678, in exec_module
  File "<frozen importlib._bootstrap>", line 219, in _call_with_frames_removed
  File "/ops-data/zp/haha/mysite-11/opsweb/resources/urls.py", line 4, in <module>
    from . import views,server,idc
  File "/ops-data/zp/haha/mysite-11/opsweb/resources/idc/__init__.py", line 9, in <module>
    from resources.forms import IdcAddForm
ImportError: cannot import name 'IdcAddForm'
2017-12-17 17:04:42,808-[ERROR]-/ops-data/zp/haha/mysite-11/lib/python3.6/site-packages/django/core/handlers/exception.py-[line:135]-Internal Server Error: /resources/idc/change/
Traceback (most recent call last):
  File "/ops-data/zp/haha/mysite-11/lib/python3.6/site-packages/django/core/handlers/exception.py", line 41, in inner
    response = get_response(request)
  File "/ops-data/zp/haha/mysite-11/lib/python3.6/site-packages/django/core/handlers/base.py", line 249, in _legacy_get_response
    response = self._get_response(request)
  File "/ops-data/zp/haha/mysite-11/lib/python3.6/site-packages/django/core/handlers/base.py", line 172, in _get_response
    resolver_match = resolver.resolve(request.path_info)
  File "/ops-data/zp/haha/mysite-11/lib/python3.6/site-packages/django/urls/resolvers.py", line 362, in resolve
    for pattern in self.url_patterns:
  File "/ops-data/zp/haha/mysite-11/lib/python3.6/site-packages/django/utils/functional.py", line 35, in __get__
    res = instance.__dict__[self.name] = self.func(instance)
  File "/ops-data/zp/haha/mysite-11/lib/python3.6/site-packages/django/urls/resolvers.py", line 405, in url_patterns
    patterns = getattr(self.urlconf_module, "urlpatterns", self.urlconf_module)
  File "/ops-data/zp/haha/mysite-11/lib/python3.6/site-packages/django/utils/functional.py", line 35, in __get__
    res = instance.__dict__[self.name] = self.func(instance)
  File "/ops-data/zp/haha/mysite-11/lib/python3.6/site-packages/django/urls/resolvers.py", line 398, in urlconf_module
    return import_module(self.urlconf_name)
  File "/ops-data/zp/haha/mysite-11/lib/python3.6/importlib/__init__.py", line 126, in import_module
    return _bootstrap._gcd_import(name[level:], package, level)
  File "<frozen importlib._bootstrap>", line 994, in _gcd_import
  File "<frozen importlib._bootstrap>", line 971, in _find_and_load
  File "<frozen importlib._bootstrap>", line 955, in _find_and_load_unlocked
  File "<frozen importlib._bootstrap>", line 665, in _load_unlocked
  File "<frozen importlib._bootstrap_external>", line 678, in exec_module
  File "<frozen importlib._bootstrap>", line 219, in _call_with_frames_removed
  File "/ops-data/zp/haha/mysite-11/opsweb/opsweb/urls.py", line 29, in <module>
    url(r'^resources/', include("resources.urls")),
  File "/ops-data/zp/haha/mysite-11/lib/python3.6/site-packages/django/conf/urls/__init__.py", line 50, in include
    urlconf_module = import_module(urlconf_module)
  File "/ops-data/zp/haha/mysite-11/lib/python3.6/importlib/__init__.py", line 126, in import_module
    return _bootstrap._gcd_import(name[level:], package, level)
  File "<frozen importlib._bootstrap>", line 994, in _gcd_import
  File "<frozen importlib._bootstrap>", line 971, in _find_and_load
  File "<frozen importlib._bootstrap>", line 955, in _find_and_load_unlocked
  File "<frozen importlib._bootstrap>", line 665, in _load_unlocked
  File "<frozen importlib._bootstrap_external>", line 678, in exec_module
  File "<frozen importlib._bootstrap>", line 219, in _call_with_frames_removed
  File "/ops-data/zp/haha/mysite-11/opsweb/resources/urls.py", line 4, in <module>
    from . import views,server,idc
  File "/ops-data/zp/haha/mysite-11/opsweb/resources/idc/__init__.py", line 9, in <module>
    from resources.forms import IdcAddForm
ImportError: cannot import name 'IdcAddForm'
2017-12-17 17:04:42,968-[ERROR]-/ops-data/zp/haha/mysite-11/lib/python3.6/site-packages/django/core/handlers/exception.py-[line:135]-Internal Server Error: /resources/idc/change/
Traceback (most recent call last):
  File "/ops-data/zp/haha/mysite-11/lib/python3.6/site-packages/django/core/handlers/exception.py", line 41, in inner
    response = get_response(request)
  File "/ops-data/zp/haha/mysite-11/lib/python3.6/site-packages/django/core/handlers/base.py", line 249, in _legacy_get_response
    response = self._get_response(request)
  File "/ops-data/zp/haha/mysite-11/lib/python3.6/site-packages/django/core/handlers/base.py", line 172, in _get_response
    resolver_match = resolver.resolve(request.path_info)
  File "/ops-data/zp/haha/mysite-11/lib/python3.6/site-packages/django/urls/resolvers.py", line 362, in resolve
    for pattern in self.url_patterns:
  File "/ops-data/zp/haha/mysite-11/lib/python3.6/site-packages/django/utils/functional.py", line 35, in __get__
    res = instance.__dict__[self.name] = self.func(instance)
  File "/ops-data/zp/haha/mysite-11/lib/python3.6/site-packages/django/urls/resolvers.py", line 405, in url_patterns
    patterns = getattr(self.urlconf_module, "urlpatterns", self.urlconf_module)
  File "/ops-data/zp/haha/mysite-11/lib/python3.6/site-packages/django/utils/functional.py", line 35, in __get__
    res = instance.__dict__[self.name] = self.func(instance)
  File "/ops-data/zp/haha/mysite-11/lib/python3.6/site-packages/django/urls/resolvers.py", line 398, in urlconf_module
    return import_module(self.urlconf_name)
  File "/ops-data/zp/haha/mysite-11/lib/python3.6/importlib/__init__.py", line 126, in import_module
    return _bootstrap._gcd_import(name[level:], package, level)
  File "<frozen importlib._bootstrap>", line 994, in _gcd_import
  File "<frozen importlib._bootstrap>", line 971, in _find_and_load
  File "<frozen importlib._bootstrap>", line 955, in _find_and_load_unlocked
  File "<frozen importlib._bootstrap>", line 665, in _load_unlocked
  File "<frozen importlib._bootstrap_external>", line 678, in exec_module
  File "<frozen importlib._bootstrap>", line 219, in _call_with_frames_removed
  File "/ops-data/zp/haha/mysite-11/opsweb/opsweb/urls.py", line 29, in <module>
    url(r'^resources/', include("resources.urls")),
  File "/ops-data/zp/haha/mysite-11/lib/python3.6/site-packages/django/conf/urls/__init__.py", line 50, in include
    urlconf_module = import_module(urlconf_module)
  File "/ops-data/zp/haha/mysite-11/lib/python3.6/importlib/__init__.py", line 126, in import_module
    return _bootstrap._gcd_import(name[level:], package, level)
  File "<frozen importlib._bootstrap>", line 994, in _gcd_import
  File "<frozen importlib._bootstrap>", line 971, in _find_and_load
  File "<frozen importlib._bootstrap>", line 955, in _find_and_load_unlocked
  File "<frozen importlib._bootstrap>", line 665, in _load_unlocked
  File "<frozen importlib._bootstrap_external>", line 678, in exec_module
  File "<frozen importlib._bootstrap>", line 219, in _call_with_frames_removed
  File "/ops-data/zp/haha/mysite-11/opsweb/resources/urls.py", line 4, in <module>
    from . import views,server,idc
  File "/ops-data/zp/haha/mysite-11/opsweb/resources/idc/__init__.py", line 9, in <module>
    from resources.forms import IdcAddForm
ImportError: cannot import name 'IdcAddForm'
2017-12-17 17:04:43,120-[ERROR]-/ops-data/zp/haha/mysite-11/lib/python3.6/site-packages/django/core/handlers/exception.py-[line:135]-Internal Server Error: /resources/idc/change/
Traceback (most recent call last):
  File "/ops-data/zp/haha/mysite-11/lib/python3.6/site-packages/django/core/handlers/exception.py", line 41, in inner
    response = get_response(request)
  File "/ops-data/zp/haha/mysite-11/lib/python3.6/site-packages/django/core/handlers/base.py", line 249, in _legacy_get_response
    response = self._get_response(request)
  File "/ops-data/zp/haha/mysite-11/lib/python3.6/site-packages/django/core/handlers/base.py", line 172, in _get_response
    resolver_match = resolver.resolve(request.path_info)
  File "/ops-data/zp/haha/mysite-11/lib/python3.6/site-packages/django/urls/resolvers.py", line 362, in resolve
    for pattern in self.url_patterns:
  File "/ops-data/zp/haha/mysite-11/lib/python3.6/site-packages/django/utils/functional.py", line 35, in __get__
    res = instance.__dict__[self.name] = self.func(instance)
  File "/ops-data/zp/haha/mysite-11/lib/python3.6/site-packages/django/urls/resolvers.py", line 405, in url_patterns
    patterns = getattr(self.urlconf_module, "urlpatterns", self.urlconf_module)
  File "/ops-data/zp/haha/mysite-11/lib/python3.6/site-packages/django/utils/functional.py", line 35, in __get__
    res = instance.__dict__[self.name] = self.func(instance)
  File "/ops-data/zp/haha/mysite-11/lib/python3.6/site-packages/django/urls/resolvers.py", line 398, in urlconf_module
    return import_module(self.urlconf_name)
  File "/ops-data/zp/haha/mysite-11/lib/python3.6/importlib/__init__.py", line 126, in import_module
    return _bootstrap._gcd_import(name[level:], package, level)
  File "<frozen importlib._bootstrap>", line 994, in _gcd_import
  File "<frozen importlib._bootstrap>", line 971, in _find_and_load
  File "<frozen importlib._bootstrap>", line 955, in _find_and_load_unlocked
  File "<frozen importlib._bootstrap>", line 665, in _load_unlocked
  File "<frozen importlib._bootstrap_external>", line 678, in exec_module
  File "<frozen importlib._bootstrap>", line 219, in _call_with_frames_removed
  File "/ops-data/zp/haha/mysite-11/opsweb/opsweb/urls.py", line 29, in <module>
    url(r'^resources/', include("resources.urls")),
  File "/ops-data/zp/haha/mysite-11/lib/python3.6/site-packages/django/conf/urls/__init__.py", line 50, in include
    urlconf_module = import_module(urlconf_module)
  File "/ops-data/zp/haha/mysite-11/lib/python3.6/importlib/__init__.py", line 126, in import_module
    return _bootstrap._gcd_import(name[level:], package, level)
  File "<frozen importlib._bootstrap>", line 994, in _gcd_import
  File "<frozen importlib._bootstrap>", line 971, in _find_and_load
  File "<frozen importlib._bootstrap>", line 955, in _find_and_load_unlocked
  File "<frozen importlib._bootstrap>", line 665, in _load_unlocked
  File "<frozen importlib._bootstrap_external>", line 678, in exec_module
  File "<frozen importlib._bootstrap>", line 219, in _call_with_frames_removed
  File "/ops-data/zp/haha/mysite-11/opsweb/resources/urls.py", line 4, in <module>
    from . import views,server,idc
  File "/ops-data/zp/haha/mysite-11/opsweb/resources/idc/__init__.py", line 9, in <module>
    from resources.forms import IdcAddForm
ImportError: cannot import name 'IdcAddForm'
2017-12-17 17:04:43,271-[ERROR]-/ops-data/zp/haha/mysite-11/lib/python3.6/site-packages/django/core/handlers/exception.py-[line:135]-Internal Server Error: /resources/idc/change/
Traceback (most recent call last):
  File "/ops-data/zp/haha/mysite-11/lib/python3.6/site-packages/django/core/handlers/exception.py", line 41, in inner
    response = get_response(request)
  File "/ops-data/zp/haha/mysite-11/lib/python3.6/site-packages/django/core/handlers/base.py", line 249, in _legacy_get_response
    response = self._get_response(request)
  File "/ops-data/zp/haha/mysite-11/lib/python3.6/site-packages/django/core/handlers/base.py", line 172, in _get_response
    resolver_match = resolver.resolve(request.path_info)
  File "/ops-data/zp/haha/mysite-11/lib/python3.6/site-packages/django/urls/resolvers.py", line 362, in resolve
    for pattern in self.url_patterns:
  File "/ops-data/zp/haha/mysite-11/lib/python3.6/site-packages/django/utils/functional.py", line 35, in __get__
    res = instance.__dict__[self.name] = self.func(instance)
  File "/ops-data/zp/haha/mysite-11/lib/python3.6/site-packages/django/urls/resolvers.py", line 405, in url_patterns
    patterns = getattr(self.urlconf_module, "urlpatterns", self.urlconf_module)
  File "/ops-data/zp/haha/mysite-11/lib/python3.6/site-packages/django/utils/functional.py", line 35, in __get__
    res = instance.__dict__[self.name] = self.func(instance)
  File "/ops-data/zp/haha/mysite-11/lib/python3.6/site-packages/django/urls/resolvers.py", line 398, in urlconf_module
    return import_module(self.urlconf_name)
  File "/ops-data/zp/haha/mysite-11/lib/python3.6/importlib/__init__.py", line 126, in import_module
    return _bootstrap._gcd_import(name[level:], package, level)
  File "<frozen importlib._bootstrap>", line 994, in _gcd_import
  File "<frozen importlib._bootstrap>", line 971, in _find_and_load
  File "<frozen importlib._bootstrap>", line 955, in _find_and_load_unlocked
  File "<frozen importlib._bootstrap>", line 665, in _load_unlocked
  File "<frozen importlib._bootstrap_external>", line 678, in exec_module
  File "<frozen importlib._bootstrap>", line 219, in _call_with_frames_removed
  File "/ops-data/zp/haha/mysite-11/opsweb/opsweb/urls.py", line 29, in <module>
    url(r'^resources/', include("resources.urls")),
  File "/ops-data/zp/haha/mysite-11/lib/python3.6/site-packages/django/conf/urls/__init__.py", line 50, in include
    urlconf_module = import_module(urlconf_module)
  File "/ops-data/zp/haha/mysite-11/lib/python3.6/importlib/__init__.py", line 126, in import_module
    return _bootstrap._gcd_import(name[level:], package, level)
  File "<frozen importlib._bootstrap>", line 994, in _gcd_import
  File "<frozen importlib._bootstrap>", line 971, in _find_and_load
  File "<frozen importlib._bootstrap>", line 955, in _find_and_load_unlocked
  File "<frozen importlib._bootstrap>", line 665, in _load_unlocked
  File "<frozen importlib._bootstrap_external>", line 678, in exec_module
  File "<frozen importlib._bootstrap>", line 219, in _call_with_frames_removed
  File "/ops-data/zp/haha/mysite-11/opsweb/resources/urls.py", line 4, in <module>
    from . import views,server,idc
  File "/ops-data/zp/haha/mysite-11/opsweb/resources/idc/__init__.py", line 9, in <module>
    from resources.forms import IdcAddForm
ImportError: cannot import name 'IdcAddForm'
2017-12-17 17:04:43,714-[ERROR]-/ops-data/zp/haha/mysite-11/lib/python3.6/site-packages/django/core/handlers/exception.py-[line:135]-Internal Server Error: /resources/idc/change/
Traceback (most recent call last):
  File "/ops-data/zp/haha/mysite-11/lib/python3.6/site-packages/django/core/handlers/exception.py", line 41, in inner
    response = get_response(request)
  File "/ops-data/zp/haha/mysite-11/lib/python3.6/site-packages/django/core/handlers/base.py", line 249, in _legacy_get_response
    response = self._get_response(request)
  File "/ops-data/zp/haha/mysite-11/lib/python3.6/site-packages/django/core/handlers/base.py", line 172, in _get_response
    resolver_match = resolver.resolve(request.path_info)
  File "/ops-data/zp/haha/mysite-11/lib/python3.6/site-packages/django/urls/resolvers.py", line 362, in resolve
    for pattern in self.url_patterns:
  File "/ops-data/zp/haha/mysite-11/lib/python3.6/site-packages/django/utils/functional.py", line 35, in __get__
    res = instance.__dict__[self.name] = self.func(instance)
  File "/ops-data/zp/haha/mysite-11/lib/python3.6/site-packages/django/urls/resolvers.py", line 405, in url_patterns
    patterns = getattr(self.urlconf_module, "urlpatterns", self.urlconf_module)
  File "/ops-data/zp/haha/mysite-11/lib/python3.6/site-packages/django/utils/functional.py", line 35, in __get__
    res = instance.__dict__[self.name] = self.func(instance)
  File "/ops-data/zp/haha/mysite-11/lib/python3.6/site-packages/django/urls/resolvers.py", line 398, in urlconf_module
    return import_module(self.urlconf_name)
  File "/ops-data/zp/haha/mysite-11/lib/python3.6/importlib/__init__.py", line 126, in import_module
    return _bootstrap._gcd_import(name[level:], package, level)
  File "<frozen importlib._bootstrap>", line 994, in _gcd_import
  File "<frozen importlib._bootstrap>", line 971, in _find_and_load
  File "<frozen importlib._bootstrap>", line 955, in _find_and_load_unlocked
  File "<frozen importlib._bootstrap>", line 665, in _load_unlocked
  File "<frozen importlib._bootstrap_external>", line 678, in exec_module
  File "<frozen importlib._bootstrap>", line 219, in _call_with_frames_removed
  File "/ops-data/zp/haha/mysite-11/opsweb/opsweb/urls.py", line 29, in <module>
    url(r'^resources/', include("resources.urls")),
  File "/ops-data/zp/haha/mysite-11/lib/python3.6/site-packages/django/conf/urls/__init__.py", line 50, in include
    urlconf_module = import_module(urlconf_module)
  File "/ops-data/zp/haha/mysite-11/lib/python3.6/importlib/__init__.py", line 126, in import_module
    return _bootstrap._gcd_import(name[level:], package, level)
  File "<frozen importlib._bootstrap>", line 994, in _gcd_import
  File "<frozen importlib._bootstrap>", line 971, in _find_and_load
  File "<frozen importlib._bootstrap>", line 955, in _find_and_load_unlocked
  File "<frozen importlib._bootstrap>", line 665, in _load_unlocked
  File "<frozen importlib._bootstrap_external>", line 678, in exec_module
  File "<frozen importlib._bootstrap>", line 219, in _call_with_frames_removed
  File "/ops-data/zp/haha/mysite-11/opsweb/resources/urls.py", line 4, in <module>
    from . import views,server,idc
  File "/ops-data/zp/haha/mysite-11/opsweb/resources/idc/__init__.py", line 9, in <module>
    from resources.forms import IdcAddForm
ImportError: cannot import name 'IdcAddForm'
2017-12-17 17:04:43,862-[ERROR]-/ops-data/zp/haha/mysite-11/lib/python3.6/site-packages/django/core/handlers/exception.py-[line:135]-Internal Server Error: /resources/idc/change/
Traceback (most recent call last):
  File "/ops-data/zp/haha/mysite-11/lib/python3.6/site-packages/django/core/handlers/exception.py", line 41, in inner
    response = get_response(request)
  File "/ops-data/zp/haha/mysite-11/lib/python3.6/site-packages/django/core/handlers/base.py", line 249, in _legacy_get_response
    response = self._get_response(request)
  File "/ops-data/zp/haha/mysite-11/lib/python3.6/site-packages/django/core/handlers/base.py", line 172, in _get_response
    resolver_match = resolver.resolve(request.path_info)
  File "/ops-data/zp/haha/mysite-11/lib/python3.6/site-packages/django/urls/resolvers.py", line 362, in resolve
    for pattern in self.url_patterns:
  File "/ops-data/zp/haha/mysite-11/lib/python3.6/site-packages/django/utils/functional.py", line 35, in __get__
    res = instance.__dict__[self.name] = self.func(instance)
  File "/ops-data/zp/haha/mysite-11/lib/python3.6/site-packages/django/urls/resolvers.py", line 405, in url_patterns
    patterns = getattr(self.urlconf_module, "urlpatterns", self.urlconf_module)
  File "/ops-data/zp/haha/mysite-11/lib/python3.6/site-packages/django/utils/functional.py", line 35, in __get__
    res = instance.__dict__[self.name] = self.func(instance)
  File "/ops-data/zp/haha/mysite-11/lib/python3.6/site-packages/django/urls/resolvers.py", line 398, in urlconf_module
    return import_module(self.urlconf_name)
  File "/ops-data/zp/haha/mysite-11/lib/python3.6/importlib/__init__.py", line 126, in import_module
    return _bootstrap._gcd_import(name[level:], package, level)
  File "<frozen importlib._bootstrap>", line 994, in _gcd_import
  File "<frozen importlib._bootstrap>", line 971, in _find_and_load
  File "<frozen importlib._bootstrap>", line 955, in _find_and_load_unlocked
  File "<frozen importlib._bootstrap>", line 665, in _load_unlocked
  File "<frozen importlib._bootstrap_external>", line 678, in exec_module
  File "<frozen importlib._bootstrap>", line 219, in _call_with_frames_removed
  File "/ops-data/zp/haha/mysite-11/opsweb/opsweb/urls.py", line 29, in <module>
    url(r'^resources/', include("resources.urls")),
  File "/ops-data/zp/haha/mysite-11/lib/python3.6/site-packages/django/conf/urls/__init__.py", line 50, in include
    urlconf_module = import_module(urlconf_module)
  File "/ops-data/zp/haha/mysite-11/lib/python3.6/importlib/__init__.py", line 126, in import_module
    return _bootstrap._gcd_import(name[level:], package, level)
  File "<frozen importlib._bootstrap>", line 994, in _gcd_import
  File "<frozen importlib._bootstrap>", line 971, in _find_and_load
  File "<frozen importlib._bootstrap>", line 955, in _find_and_load_unlocked
  File "<frozen importlib._bootstrap>", line 665, in _load_unlocked
  File "<frozen importlib._bootstrap_external>", line 678, in exec_module
  File "<frozen importlib._bootstrap>", line 219, in _call_with_frames_removed
  File "/ops-data/zp/haha/mysite-11/opsweb/resources/urls.py", line 4, in <module>
    from . import views,server,idc
  File "/ops-data/zp/haha/mysite-11/opsweb/resources/idc/__init__.py", line 9, in <module>
    from resources.forms import IdcAddForm
ImportError: cannot import name 'IdcAddForm'
2017-12-17 17:04:44,023-[ERROR]-/ops-data/zp/haha/mysite-11/lib/python3.6/site-packages/django/core/handlers/exception.py-[line:135]-Internal Server Error: /resources/idc/change/
Traceback (most recent call last):
  File "/ops-data/zp/haha/mysite-11/lib/python3.6/site-packages/django/core/handlers/exception.py", line 41, in inner
    response = get_response(request)
  File "/ops-data/zp/haha/mysite-11/lib/python3.6/site-packages/django/core/handlers/base.py", line 249, in _legacy_get_response
    response = self._get_response(request)
  File "/ops-data/zp/haha/mysite-11/lib/python3.6/site-packages/django/core/handlers/base.py", line 172, in _get_response
    resolver_match = resolver.resolve(request.path_info)
  File "/ops-data/zp/haha/mysite-11/lib/python3.6/site-packages/django/urls/resolvers.py", line 362, in resolve
    for pattern in self.url_patterns:
  File "/ops-data/zp/haha/mysite-11/lib/python3.6/site-packages/django/utils/functional.py", line 35, in __get__
    res = instance.__dict__[self.name] = self.func(instance)
  File "/ops-data/zp/haha/mysite-11/lib/python3.6/site-packages/django/urls/resolvers.py", line 405, in url_patterns
    patterns = getattr(self.urlconf_module, "urlpatterns", self.urlconf_module)
  File "/ops-data/zp/haha/mysite-11/lib/python3.6/site-packages/django/utils/functional.py", line 35, in __get__
    res = instance.__dict__[self.name] = self.func(instance)
  File "/ops-data/zp/haha/mysite-11/lib/python3.6/site-packages/django/urls/resolvers.py", line 398, in urlconf_module
    return import_module(self.urlconf_name)
  File "/ops-data/zp/haha/mysite-11/lib/python3.6/importlib/__init__.py", line 126, in import_module
    return _bootstrap._gcd_import(name[level:], package, level)
  File "<frozen importlib._bootstrap>", line 994, in _gcd_import
  File "<frozen importlib._bootstrap>", line 971, in _find_and_load
  File "<frozen importlib._bootstrap>", line 955, in _find_and_load_unlocked
  File "<frozen importlib._bootstrap>", line 665, in _load_unlocked
  File "<frozen importlib._bootstrap_external>", line 678, in exec_module
  File "<frozen importlib._bootstrap>", line 219, in _call_with_frames_removed
  File "/ops-data/zp/haha/mysite-11/opsweb/opsweb/urls.py", line 29, in <module>
    url(r'^resources/', include("resources.urls")),
  File "/ops-data/zp/haha/mysite-11/lib/python3.6/site-packages/django/conf/urls/__init__.py", line 50, in include
    urlconf_module = import_module(urlconf_module)
  File "/ops-data/zp/haha/mysite-11/lib/python3.6/importlib/__init__.py", line 126, in import_module
    return _bootstrap._gcd_import(name[level:], package, level)
  File "<frozen importlib._bootstrap>", line 994, in _gcd_import
  File "<frozen importlib._bootstrap>", line 971, in _find_and_load
  File "<frozen importlib._bootstrap>", line 955, in _find_and_load_unlocked
  File "<frozen importlib._bootstrap>", line 665, in _load_unlocked
  File "<frozen importlib._bootstrap_external>", line 678, in exec_module
  File "<frozen importlib._bootstrap>", line 219, in _call_with_frames_removed
  File "/ops-data/zp/haha/mysite-11/opsweb/resources/urls.py", line 4, in <module>
    from . import views,server,idc
  File "/ops-data/zp/haha/mysite-11/opsweb/resources/idc/__init__.py", line 9, in <module>
    from resources.forms import IdcAddForm
ImportError: cannot import name 'IdcAddForm'
2017-12-17 17:04:44,200-[ERROR]-/ops-data/zp/haha/mysite-11/lib/python3.6/site-packages/django/core/handlers/exception.py-[line:135]-Internal Server Error: /resources/idc/change/
Traceback (most recent call last):
  File "/ops-data/zp/haha/mysite-11/lib/python3.6/site-packages/django/core/handlers/exception.py", line 41, in inner
    response = get_response(request)
  File "/ops-data/zp/haha/mysite-11/lib/python3.6/site-packages/django/core/handlers/base.py", line 249, in _legacy_get_response
    response = self._get_response(request)
  File "/ops-data/zp/haha/mysite-11/lib/python3.6/site-packages/django/core/handlers/base.py", line 172, in _get_response
    resolver_match = resolver.resolve(request.path_info)
  File "/ops-data/zp/haha/mysite-11/lib/python3.6/site-packages/django/urls/resolvers.py", line 362, in resolve
    for pattern in self.url_patterns:
  File "/ops-data/zp/haha/mysite-11/lib/python3.6/site-packages/django/utils/functional.py", line 35, in __get__
    res = instance.__dict__[self.name] = self.func(instance)
  File "/ops-data/zp/haha/mysite-11/lib/python3.6/site-packages/django/urls/resolvers.py", line 405, in url_patterns
    patterns = getattr(self.urlconf_module, "urlpatterns", self.urlconf_module)
  File "/ops-data/zp/haha/mysite-11/lib/python3.6/site-packages/django/utils/functional.py", line 35, in __get__
    res = instance.__dict__[self.name] = self.func(instance)
  File "/ops-data/zp/haha/mysite-11/lib/python3.6/site-packages/django/urls/resolvers.py", line 398, in urlconf_module
    return import_module(self.urlconf_name)
  File "/ops-data/zp/haha/mysite-11/lib/python3.6/importlib/__init__.py", line 126, in import_module
    return _bootstrap._gcd_import(name[level:], package, level)
  File "<frozen importlib._bootstrap>", line 994, in _gcd_import
  File "<frozen importlib._bootstrap>", line 971, in _find_and_load
  File "<frozen importlib._bootstrap>", line 955, in _find_and_load_unlocked
  File "<frozen importlib._bootstrap>", line 665, in _load_unlocked
  File "<frozen importlib._bootstrap_external>", line 678, in exec_module
  File "<frozen importlib._bootstrap>", line 219, in _call_with_frames_removed
  File "/ops-data/zp/haha/mysite-11/opsweb/opsweb/urls.py", line 29, in <module>
    url(r'^resources/', include("resources.urls")),
  File "/ops-data/zp/haha/mysite-11/lib/python3.6/site-packages/django/conf/urls/__init__.py", line 50, in include
    urlconf_module = import_module(urlconf_module)
  File "/ops-data/zp/haha/mysite-11/lib/python3.6/importlib/__init__.py", line 126, in import_module
    return _bootstrap._gcd_import(name[level:], package, level)
  File "<frozen importlib._bootstrap>", line 994, in _gcd_import
  File "<frozen importlib._bootstrap>", line 971, in _find_and_load
  File "<frozen importlib._bootstrap>", line 955, in _find_and_load_unlocked
  File "<frozen importlib._bootstrap>", line 665, in _load_unlocked
  File "<frozen importlib._bootstrap_external>", line 678, in exec_module
  File "<frozen importlib._bootstrap>", line 219, in _call_with_frames_removed
  File "/ops-data/zp/haha/mysite-11/opsweb/resources/urls.py", line 4, in <module>
    from . import views,server,idc
  File "/ops-data/zp/haha/mysite-11/opsweb/resources/idc/__init__.py", line 9, in <module>
    from resources.forms import IdcAddForm
ImportError: cannot import name 'IdcAddForm'
2017-12-17 17:04:44,487-[ERROR]-/ops-data/zp/haha/mysite-11/lib/python3.6/site-packages/django/core/handlers/exception.py-[line:135]-Internal Server Error: /resources/idc/change/
Traceback (most recent call last):
  File "/ops-data/zp/haha/mysite-11/lib/python3.6/site-packages/django/core/handlers/exception.py", line 41, in inner
    response = get_response(request)
  File "/ops-data/zp/haha/mysite-11/lib/python3.6/site-packages/django/core/handlers/base.py", line 249, in _legacy_get_response
    response = self._get_response(request)
  File "/ops-data/zp/haha/mysite-11/lib/python3.6/site-packages/django/core/handlers/base.py", line 172, in _get_response
    resolver_match = resolver.resolve(request.path_info)
  File "/ops-data/zp/haha/mysite-11/lib/python3.6/site-packages/django/urls/resolvers.py", line 362, in resolve
    for pattern in self.url_patterns:
  File "/ops-data/zp/haha/mysite-11/lib/python3.6/site-packages/django/utils/functional.py", line 35, in __get__
    res = instance.__dict__[self.name] = self.func(instance)
  File "/ops-data/zp/haha/mysite-11/lib/python3.6/site-packages/django/urls/resolvers.py", line 405, in url_patterns
    patterns = getattr(self.urlconf_module, "urlpatterns", self.urlconf_module)
  File "/ops-data/zp/haha/mysite-11/lib/python3.6/site-packages/django/utils/functional.py", line 35, in __get__
    res = instance.__dict__[self.name] = self.func(instance)
  File "/ops-data/zp/haha/mysite-11/lib/python3.6/site-packages/django/urls/resolvers.py", line 398, in urlconf_module
    return import_module(self.urlconf_name)
  File "/ops-data/zp/haha/mysite-11/lib/python3.6/importlib/__init__.py", line 126, in import_module
    return _bootstrap._gcd_import(name[level:], package, level)
  File "<frozen importlib._bootstrap>", line 994, in _gcd_import
  File "<frozen importlib._bootstrap>", line 971, in _find_and_load
  File "<frozen importlib._bootstrap>", line 955, in _find_and_load_unlocked
  File "<frozen importlib._bootstrap>", line 665, in _load_unlocked
  File "<frozen importlib._bootstrap_external>", line 678, in exec_module
  File "<frozen importlib._bootstrap>", line 219, in _call_with_frames_removed
  File "/ops-data/zp/haha/mysite-11/opsweb/opsweb/urls.py", line 29, in <module>
    url(r'^resources/', include("resources.urls")),
  File "/ops-data/zp/haha/mysite-11/lib/python3.6/site-packages/django/conf/urls/__init__.py", line 50, in include
    urlconf_module = import_module(urlconf_module)
  File "/ops-data/zp/haha/mysite-11/lib/python3.6/importlib/__init__.py", line 126, in import_module
    return _bootstrap._gcd_import(name[level:], package, level)
  File "<frozen importlib._bootstrap>", line 994, in _gcd_import
  File "<frozen importlib._bootstrap>", line 971, in _find_and_load
  File "<frozen importlib._bootstrap>", line 955, in _find_and_load_unlocked
  File "<frozen importlib._bootstrap>", line 665, in _load_unlocked
  File "<frozen importlib._bootstrap_external>", line 678, in exec_module
  File "<frozen importlib._bootstrap>", line 219, in _call_with_frames_removed
  File "/ops-data/zp/haha/mysite-11/opsweb/resources/urls.py", line 4, in <module>
    from . import views,server,idc
  File "/ops-data/zp/haha/mysite-11/opsweb/resources/idc/__init__.py", line 9, in <module>
    from resources.forms import IdcAddForm
ImportError: cannot import name 'IdcAddForm'
2017-12-17 17:04:44,656-[ERROR]-/ops-data/zp/haha/mysite-11/lib/python3.6/site-packages/django/core/handlers/exception.py-[line:135]-Internal Server Error: /resources/idc/change/
Traceback (most recent call last):
  File "/ops-data/zp/haha/mysite-11/lib/python3.6/site-packages/django/core/handlers/exception.py", line 41, in inner
    response = get_response(request)
  File "/ops-data/zp/haha/mysite-11/lib/python3.6/site-packages/django/core/handlers/base.py", line 249, in _legacy_get_response
    response = self._get_response(request)
  File "/ops-data/zp/haha/mysite-11/lib/python3.6/site-packages/django/core/handlers/base.py", line 172, in _get_response
    resolver_match = resolver.resolve(request.path_info)
  File "/ops-data/zp/haha/mysite-11/lib/python3.6/site-packages/django/urls/resolvers.py", line 362, in resolve
    for pattern in self.url_patterns:
  File "/ops-data/zp/haha/mysite-11/lib/python3.6/site-packages/django/utils/functional.py", line 35, in __get__
    res = instance.__dict__[self.name] = self.func(instance)
  File "/ops-data/zp/haha/mysite-11/lib/python3.6/site-packages/django/urls/resolvers.py", line 405, in url_patterns
    patterns = getattr(self.urlconf_module, "urlpatterns", self.urlconf_module)
  File "/ops-data/zp/haha/mysite-11/lib/python3.6/site-packages/django/utils/functional.py", line 35, in __get__
    res = instance.__dict__[self.name] = self.func(instance)
  File "/ops-data/zp/haha/mysite-11/lib/python3.6/site-packages/django/urls/resolvers.py", line 398, in urlconf_module
    return import_module(self.urlconf_name)
  File "/ops-data/zp/haha/mysite-11/lib/python3.6/importlib/__init__.py", line 126, in import_module
    return _bootstrap._gcd_import(name[level:], package, level)
  File "<frozen importlib._bootstrap>", line 994, in _gcd_import
  File "<frozen importlib._bootstrap>", line 971, in _find_and_load
  File "<frozen importlib._bootstrap>", line 955, in _find_and_load_unlocked
  File "<frozen importlib._bootstrap>", line 665, in _load_unlocked
  File "<frozen importlib._bootstrap_external>", line 678, in exec_module
  File "<frozen importlib._bootstrap>", line 219, in _call_with_frames_removed
  File "/ops-data/zp/haha/mysite-11/opsweb/opsweb/urls.py", line 29, in <module>
    url(r'^resources/', include("resources.urls")),
  File "/ops-data/zp/haha/mysite-11/lib/python3.6/site-packages/django/conf/urls/__init__.py", line 50, in include
    urlconf_module = import_module(urlconf_module)
  File "/ops-data/zp/haha/mysite-11/lib/python3.6/importlib/__init__.py", line 126, in import_module
    return _bootstrap._gcd_import(name[level:], package, level)
  File "<frozen importlib._bootstrap>", line 994, in _gcd_import
  File "<frozen importlib._bootstrap>", line 971, in _find_and_load
  File "<frozen importlib._bootstrap>", line 955, in _find_and_load_unlocked
  File "<frozen importlib._bootstrap>", line 665, in _load_unlocked
  File "<frozen importlib._bootstrap_external>", line 678, in exec_module
  File "<frozen importlib._bootstrap>", line 219, in _call_with_frames_removed
  File "/ops-data/zp/haha/mysite-11/opsweb/resources/urls.py", line 4, in <module>
    from . import views,server,idc
  File "/ops-data/zp/haha/mysite-11/opsweb/resources/idc/__init__.py", line 9, in <module>
    from resources.forms import IdcAddForm
ImportError: cannot import name 'IdcAddForm'
2017-12-17 17:04:45,119-[ERROR]-/ops-data/zp/haha/mysite-11/lib/python3.6/site-packages/django/core/handlers/exception.py-[line:135]-Internal Server Error: /resources/idc/change/
Traceback (most recent call last):
  File "/ops-data/zp/haha/mysite-11/lib/python3.6/site-packages/django/core/handlers/exception.py", line 41, in inner
    response = get_response(request)
  File "/ops-data/zp/haha/mysite-11/lib/python3.6/site-packages/django/core/handlers/base.py", line 249, in _legacy_get_response
    response = self._get_response(request)
  File "/ops-data/zp/haha/mysite-11/lib/python3.6/site-packages/django/core/handlers/base.py", line 172, in _get_response
    resolver_match = resolver.resolve(request.path_info)
  File "/ops-data/zp/haha/mysite-11/lib/python3.6/site-packages/django/urls/resolvers.py", line 362, in resolve
    for pattern in self.url_patterns:
  File "/ops-data/zp/haha/mysite-11/lib/python3.6/site-packages/django/utils/functional.py", line 35, in __get__
    res = instance.__dict__[self.name] = self.func(instance)
  File "/ops-data/zp/haha/mysite-11/lib/python3.6/site-packages/django/urls/resolvers.py", line 405, in url_patterns
    patterns = getattr(self.urlconf_module, "urlpatterns", self.urlconf_module)
  File "/ops-data/zp/haha/mysite-11/lib/python3.6/site-packages/django/utils/functional.py", line 35, in __get__
    res = instance.__dict__[self.name] = self.func(instance)
  File "/ops-data/zp/haha/mysite-11/lib/python3.6/site-packages/django/urls/resolvers.py", line 398, in urlconf_module
    return import_module(self.urlconf_name)
  File "/ops-data/zp/haha/mysite-11/lib/python3.6/importlib/__init__.py", line 126, in import_module
    return _bootstrap._gcd_import(name[level:], package, level)
  File "<frozen importlib._bootstrap>", line 994, in _gcd_import
  File "<frozen importlib._bootstrap>", line 971, in _find_and_load
  File "<frozen importlib._bootstrap>", line 955, in _find_and_load_unlocked
  File "<frozen importlib._bootstrap>", line 665, in _load_unlocked
  File "<frozen importlib._bootstrap_external>", line 678, in exec_module
  File "<frozen importlib._bootstrap>", line 219, in _call_with_frames_removed
  File "/ops-data/zp/haha/mysite-11/opsweb/opsweb/urls.py", line 29, in <module>
    url(r'^resources/', include("resources.urls")),
  File "/ops-data/zp/haha/mysite-11/lib/python3.6/site-packages/django/conf/urls/__init__.py", line 50, in include
    urlconf_module = import_module(urlconf_module)
  File "/ops-data/zp/haha/mysite-11/lib/python3.6/importlib/__init__.py", line 126, in import_module
    return _bootstrap._gcd_import(name[level:], package, level)
  File "<frozen importlib._bootstrap>", line 994, in _gcd_import
  File "<frozen importlib._bootstrap>", line 971, in _find_and_load
  File "<frozen importlib._bootstrap>", line 955, in _find_and_load_unlocked
  File "<frozen importlib._bootstrap>", line 665, in _load_unlocked
  File "<frozen importlib._bootstrap_external>", line 678, in exec_module
  File "<frozen importlib._bootstrap>", line 219, in _call_with_frames_removed
  File "/ops-data/zp/haha/mysite-11/opsweb/resources/urls.py", line 4, in <module>
    from . import views,server,idc
  File "/ops-data/zp/haha/mysite-11/opsweb/resources/idc/__init__.py", line 9, in <module>
    from resources.forms import IdcAddForm
ImportError: cannot import name 'IdcAddForm'
2017-12-17 17:04:45,278-[ERROR]-/ops-data/zp/haha/mysite-11/lib/python3.6/site-packages/django/core/handlers/exception.py-[line:135]-Internal Server Error: /resources/idc/change/
Traceback (most recent call last):
  File "/ops-data/zp/haha/mysite-11/lib/python3.6/site-packages/django/core/handlers/exception.py", line 41, in inner
    response = get_response(request)
  File "/ops-data/zp/haha/mysite-11/lib/python3.6/site-packages/django/core/handlers/base.py", line 249, in _legacy_get_response
    response = self._get_response(request)
  File "/ops-data/zp/haha/mysite-11/lib/python3.6/site-packages/django/core/handlers/base.py", line 172, in _get_response
    resolver_match = resolver.resolve(request.path_info)
  File "/ops-data/zp/haha/mysite-11/lib/python3.6/site-packages/django/urls/resolvers.py", line 362, in resolve
    for pattern in self.url_patterns:
  File "/ops-data/zp/haha/mysite-11/lib/python3.6/site-packages/django/utils/functional.py", line 35, in __get__
    res = instance.__dict__[self.name] = self.func(instance)
  File "/ops-data/zp/haha/mysite-11/lib/python3.6/site-packages/django/urls/resolvers.py", line 405, in url_patterns
    patterns = getattr(self.urlconf_module, "urlpatterns", self.urlconf_module)
  File "/ops-data/zp/haha/mysite-11/lib/python3.6/site-packages/django/utils/functional.py", line 35, in __get__
    res = instance.__dict__[self.name] = self.func(instance)
  File "/ops-data/zp/haha/mysite-11/lib/python3.6/site-packages/django/urls/resolvers.py", line 398, in urlconf_module
    return import_module(self.urlconf_name)
  File "/ops-data/zp/haha/mysite-11/lib/python3.6/importlib/__init__.py", line 126, in import_module
    return _bootstrap._gcd_import(name[level:], package, level)
  File "<frozen importlib._bootstrap>", line 994, in _gcd_import
  File "<frozen importlib._bootstrap>", line 971, in _find_and_load
  File "<frozen importlib._bootstrap>", line 955, in _find_and_load_unlocked
  File "<frozen importlib._bootstrap>", line 665, in _load_unlocked
  File "<frozen importlib._bootstrap_external>", line 678, in exec_module
  File "<frozen importlib._bootstrap>", line 219, in _call_with_frames_removed
  File "/ops-data/zp/haha/mysite-11/opsweb/opsweb/urls.py", line 29, in <module>
    url(r'^resources/', include("resources.urls")),
  File "/ops-data/zp/haha/mysite-11/lib/python3.6/site-packages/django/conf/urls/__init__.py", line 50, in include
    urlconf_module = import_module(urlconf_module)
  File "/ops-data/zp/haha/mysite-11/lib/python3.6/importlib/__init__.py", line 126, in import_module
    return _bootstrap._gcd_import(name[level:], package, level)
  File "<frozen importlib._bootstrap>", line 994, in _gcd_import
  File "<frozen importlib._bootstrap>", line 971, in _find_and_load
  File "<frozen importlib._bootstrap>", line 955, in _find_and_load_unlocked
  File "<frozen importlib._bootstrap>", line 665, in _load_unlocked
  File "<frozen importlib._bootstrap_external>", line 678, in exec_module
  File "<frozen importlib._bootstrap>", line 219, in _call_with_frames_removed
  File "/ops-data/zp/haha/mysite-11/opsweb/resources/urls.py", line 4, in <module>
    from . import views,server,idc
  File "/ops-data/zp/haha/mysite-11/opsweb/resources/idc/__init__.py", line 9, in <module>
    from resources.forms import IdcAddForm
ImportError: cannot import name 'IdcAddForm'
2017-12-17 17:04:45,721-[ERROR]-/ops-data/zp/haha/mysite-11/lib/python3.6/site-packages/django/core/handlers/exception.py-[line:135]-Internal Server Error: /resources/idc/change/
Traceback (most recent call last):
  File "/ops-data/zp/haha/mysite-11/lib/python3.6/site-packages/django/core/handlers/exception.py", line 41, in inner
    response = get_response(request)
  File "/ops-data/zp/haha/mysite-11/lib/python3.6/site-packages/django/core/handlers/base.py", line 249, in _legacy_get_response
    response = self._get_response(request)
  File "/ops-data/zp/haha/mysite-11/lib/python3.6/site-packages/django/core/handlers/base.py", line 172, in _get_response
    resolver_match = resolver.resolve(request.path_info)
  File "/ops-data/zp/haha/mysite-11/lib/python3.6/site-packages/django/urls/resolvers.py", line 362, in resolve
    for pattern in self.url_patterns:
  File "/ops-data/zp/haha/mysite-11/lib/python3.6/site-packages/django/utils/functional.py", line 35, in __get__
    res = instance.__dict__[self.name] = self.func(instance)
  File "/ops-data/zp/haha/mysite-11/lib/python3.6/site-packages/django/urls/resolvers.py", line 405, in url_patterns
    patterns = getattr(self.urlconf_module, "urlpatterns", self.urlconf_module)
  File "/ops-data/zp/haha/mysite-11/lib/python3.6/site-packages/django/utils/functional.py", line 35, in __get__
    res = instance.__dict__[self.name] = self.func(instance)
  File "/ops-data/zp/haha/mysite-11/lib/python3.6/site-packages/django/urls/resolvers.py", line 398, in urlconf_module
    return import_module(self.urlconf_name)
  File "/ops-data/zp/haha/mysite-11/lib/python3.6/importlib/__init__.py", line 126, in import_module
    return _bootstrap._gcd_import(name[level:], package, level)
  File "<frozen importlib._bootstrap>", line 994, in _gcd_import
  File "<frozen importlib._bootstrap>", line 971, in _find_and_load
  File "<frozen importlib._bootstrap>", line 955, in _find_and_load_unlocked
  File "<frozen importlib._bootstrap>", line 665, in _load_unlocked
  File "<frozen importlib._bootstrap_external>", line 678, in exec_module
  File "<frozen importlib._bootstrap>", line 219, in _call_with_frames_removed
  File "/ops-data/zp/haha/mysite-11/opsweb/opsweb/urls.py", line 29, in <module>
    url(r'^resources/', include("resources.urls")),
  File "/ops-data/zp/haha/mysite-11/lib/python3.6/site-packages/django/conf/urls/__init__.py", line 50, in include
    urlconf_module = import_module(urlconf_module)
  File "/ops-data/zp/haha/mysite-11/lib/python3.6/importlib/__init__.py", line 126, in import_module
    return _bootstrap._gcd_import(name[level:], package, level)
  File "<frozen importlib._bootstrap>", line 994, in _gcd_import
  File "<frozen importlib._bootstrap>", line 971, in _find_and_load
  File "<frozen importlib._bootstrap>", line 955, in _find_and_load_unlocked
  File "<frozen importlib._bootstrap>", line 665, in _load_unlocked
  File "<frozen importlib._bootstrap_external>", line 678, in exec_module
  File "<frozen importlib._bootstrap>", line 219, in _call_with_frames_removed
  File "/ops-data/zp/haha/mysite-11/opsweb/resources/urls.py", line 4, in <module>
    from . import views,server,idc
  File "/ops-data/zp/haha/mysite-11/opsweb/resources/idc/__init__.py", line 9, in <module>
    from resources.forms import IdcAddForm
ImportError: cannot import name 'IdcAddForm'
2017-12-17 17:04:45,889-[ERROR]-/ops-data/zp/haha/mysite-11/lib/python3.6/site-packages/django/core/handlers/exception.py-[line:135]-Internal Server Error: /resources/idc/change/
Traceback (most recent call last):
  File "/ops-data/zp/haha/mysite-11/lib/python3.6/site-packages/django/core/handlers/exception.py", line 41, in inner
    response = get_response(request)
  File "/ops-data/zp/haha/mysite-11/lib/python3.6/site-packages/django/core/handlers/base.py", line 249, in _legacy_get_response
    response = self._get_response(request)
  File "/ops-data/zp/haha/mysite-11/lib/python3.6/site-packages/django/core/handlers/base.py", line 172, in _get_response
    resolver_match = resolver.resolve(request.path_info)
  File "/ops-data/zp/haha/mysite-11/lib/python3.6/site-packages/django/urls/resolvers.py", line 362, in resolve
    for pattern in self.url_patterns:
  File "/ops-data/zp/haha/mysite-11/lib/python3.6/site-packages/django/utils/functional.py", line 35, in __get__
    res = instance.__dict__[self.name] = self.func(instance)
  File "/ops-data/zp/haha/mysite-11/lib/python3.6/site-packages/django/urls/resolvers.py", line 405, in url_patterns
    patterns = getattr(self.urlconf_module, "urlpatterns", self.urlconf_module)
  File "/ops-data/zp/haha/mysite-11/lib/python3.6/site-packages/django/utils/functional.py", line 35, in __get__
    res = instance.__dict__[self.name] = self.func(instance)
  File "/ops-data/zp/haha/mysite-11/lib/python3.6/site-packages/django/urls/resolvers.py", line 398, in urlconf_module
    return import_module(self.urlconf_name)
  File "/ops-data/zp/haha/mysite-11/lib/python3.6/importlib/__init__.py", line 126, in import_module
    return _bootstrap._gcd_import(name[level:], package, level)
  File "<frozen importlib._bootstrap>", line 994, in _gcd_import
  File "<frozen importlib._bootstrap>", line 971, in _find_and_load
  File "<frozen importlib._bootstrap>", line 955, in _find_and_load_unlocked
  File "<frozen importlib._bootstrap>", line 665, in _load_unlocked
  File "<frozen importlib._bootstrap_external>", line 678, in exec_module
  File "<frozen importlib._bootstrap>", line 219, in _call_with_frames_removed
  File "/ops-data/zp/haha/mysite-11/opsweb/opsweb/urls.py", line 29, in <module>
    url(r'^resources/', include("resources.urls")),
  File "/ops-data/zp/haha/mysite-11/lib/python3.6/site-packages/django/conf/urls/__init__.py", line 50, in include
    urlconf_module = import_module(urlconf_module)
  File "/ops-data/zp/haha/mysite-11/lib/python3.6/importlib/__init__.py", line 126, in import_module
    return _bootstrap._gcd_import(name[level:], package, level)
  File "<frozen importlib._bootstrap>", line 994, in _gcd_import
  File "<frozen importlib._bootstrap>", line 971, in _find_and_load
  File "<frozen importlib._bootstrap>", line 955, in _find_and_load_unlocked
  File "<frozen importlib._bootstrap>", line 665, in _load_unlocked
  File "<frozen importlib._bootstrap_external>", line 678, in exec_module
  File "<frozen importlib._bootstrap>", line 219, in _call_with_frames_removed
  File "/ops-data/zp/haha/mysite-11/opsweb/resources/urls.py", line 4, in <module>
    from . import views,server,idc
  File "/ops-data/zp/haha/mysite-11/opsweb/resources/idc/__init__.py", line 9, in <module>
    from resources.forms import IdcAddForm
ImportError: cannot import name 'IdcAddForm'
2017-12-17 17:12:45,549-[INFO]-/ops-data/zp/haha/mysite-11/opsweb/resources/idc/__init__.py-[line:64]-IDC 模型对象id: 1 查询成功并返回给前端
2017-12-17 17:21:14,510-[INFO]-/ops-data/zp/haha/mysite-11/opsweb/resources/idc/__init__.py-[line:64]-IDC 模型对象id: 1 查询成功并返回给前端
2017-12-17 17:21:21,596-[ERROR]-/ops-data/zp/haha/mysite-11/lib/python3.6/site-packages/django/core/handlers/exception.py-[line:135]-Internal Server Error: /resources/idc/change/
Traceback (most recent call last):
  File "/ops-data/zp/haha/mysite-11/opsweb/resources/idc/__init__.py", line 94, in post
    idc_obj.save(update_fields=["user","email","phone","address","last_change_time"])
  File "/ops-data/zp/haha/mysite-11/lib/python3.6/site-packages/django/db/models/base.py", line 794, in save
    % ', '.join(non_model_fields))
ValueError: The following fields do not exist in this model or are m2m fields: last_change_time

During handling of the above exception, another exception occurred:

Traceback (most recent call last):
  File "/ops-data/zp/haha/mysite-11/lib/python3.6/site-packages/django/core/handlers/exception.py", line 41, in inner
    response = get_response(request)
  File "/ops-data/zp/haha/mysite-11/lib/python3.6/site-packages/django/core/handlers/base.py", line 249, in _legacy_get_response
    response = self._get_response(request)
  File "/ops-data/zp/haha/mysite-11/lib/python3.6/site-packages/django/core/handlers/base.py", line 187, in _get_response
    response = self.process_exception_by_middleware(e, request)
  File "/ops-data/zp/haha/mysite-11/lib/python3.6/site-packages/django/core/handlers/base.py", line 185, in _get_response
    response = wrapped_callback(request, *callback_args, **callback_kwargs)
  File "/ops-data/zp/haha/mysite-11/lib/python3.6/site-packages/django/views/generic/base.py", line 68, in view
    return self.dispatch(request, *args, **kwargs)
  File "/ops-data/zp/haha/mysite-11/lib/python3.6/site-packages/django/views/generic/base.py", line 88, in dispatch
    return handler(request, *args, **kwargs)
  File "/ops-data/zp/haha/mysite-11/opsweb/resources/idc/__init__.py", line 98, in post
    wslog_error().error("IDC: %s 保存修改信息失败,错误信息: %s" %(idc_id,e.args))
NameError: name 'e' is not defined
2017-12-17 17:29:14,413-[INFO]-/ops-data/zp/haha/mysite-11/opsweb/resources/idc/__init__.py-[line:64]-IDC 模型对象id: 1 查询成功并返回给前端
2017-12-17 17:30:22,029-[INFO]-/ops-data/zp/haha/mysite-11/opsweb/resources/idc/__init__.py-[line:101]-IDC: 1 更改信息成功
2017-12-17 17:30:29,352-[INFO]-/ops-data/zp/haha/mysite-11/opsweb/resources/idc/__init__.py-[line:64]-IDC 模型对象id: 3 查询成功并返回给前端
2017-12-17 17:30:37,628-[INFO]-/ops-data/zp/haha/mysite-11/opsweb/resources/idc/__init__.py-[line:101]-IDC: 3 更改信息成功
2017-12-17 17:30:42,802-[INFO]-/ops-data/zp/haha/mysite-11/opsweb/resources/idc/__init__.py-[line:64]-IDC 模型对象id: 2 查询成功并返回给前端
2017-12-17 17:30:51,429-[INFO]-/ops-data/zp/haha/mysite-11/opsweb/resources/idc/__init__.py-[line:101]-IDC: 2 更改信息成功
2017-12-17 17:32:23,224-[INFO]-/ops-data/zp/haha/mysite-11/opsweb/resources/idc/__init__.py-[line:64]-IDC 模型对象id: 2 查询成功并返回给前端
2017-12-17 17:32:29,868-[INFO]-/ops-data/zp/haha/mysite-11/opsweb/resources/idc/__init__.py-[line:101]-IDC: id-2 更改信息成功
2017-12-17 17:32:35,578-[INFO]-/ops-data/zp/haha/mysite-11/opsweb/resources/idc/__init__.py-[line:64]-IDC 模型对象id: 1 查询成功并返回给前端
2017-12-17 17:32:41,522-[INFO]-/ops-data/zp/haha/mysite-11/opsweb/resources/idc/__init__.py-[line:101]-IDC: id-1 更改信息成功
2017-12-17 17:32:48,607-[INFO]-/ops-data/zp/haha/mysite-11/opsweb/resources/idc/__init__.py-[line:64]-IDC 模型对象id: 3 查询成功并返回给前端
2017-12-17 17:32:54,197-[INFO]-/ops-data/zp/haha/mysite-11/opsweb/resources/idc/__init__.py-[line:101]-IDC: id-3 更改信息成功
2017-12-17 17:46:18,604-[INFO]-/ops-data/zp/haha/mysite-11/opsweb/resources/idc/__init__.py-[line:64]-IDC 模型对象id: 1 查询成功并返回给前端
2017-12-17 22:25:26,468-[ERROR]-/ops-data/zp/haha/mysite-11/lib/python3.6/site-packages/django/core/handlers/exception.py-[line:135]-Internal Server Error: /resources/idc/list/
Traceback (most recent call last):
  File "/ops-data/zp/haha/mysite-11/lib/python3.6/site-packages/django/core/handlers/exception.py", line 41, in inner
    response = get_response(request)
  File "/ops-data/zp/haha/mysite-11/lib/python3.6/site-packages/django/core/handlers/base.py", line 249, in _legacy_get_response
    response = self._get_response(request)
  File "/ops-data/zp/haha/mysite-11/lib/python3.6/site-packages/django/core/handlers/base.py", line 187, in _get_response
    response = self.process_exception_by_middleware(e, request)
  File "/ops-data/zp/haha/mysite-11/lib/python3.6/site-packages/django/core/handlers/base.py", line 185, in _get_response
    response = wrapped_callback(request, *callback_args, **callback_kwargs)
  File "/ops-data/zp/haha/mysite-11/lib/python3.6/site-packages/django/views/generic/base.py", line 68, in view
    return self.dispatch(request, *args, **kwargs)
  File "/ops-data/zp/haha/mysite-11/opsweb/accounts/permission/permission_required_mixin.py", line 11, in dispatch
    return redirect(self.permission_redirect_url)
  File "/ops-data/zp/haha/mysite-11/lib/python3.6/site-packages/django/shortcuts.py", line 56, in redirect
    return redirect_class(resolve_url(to, *args, **kwargs))
  File "/ops-data/zp/haha/mysite-11/lib/python3.6/site-packages/django/shortcuts.py", line 147, in resolve_url
    return reverse(to, args=args, kwargs=kwargs)
  File "/ops-data/zp/haha/mysite-11/lib/python3.6/site-packages/django/urls/base.py", line 91, in reverse
    return force_text(iri_to_uri(resolver._reverse_with_prefix(view, prefix, *args, **kwargs)))
  File "/ops-data/zp/haha/mysite-11/lib/python3.6/site-packages/django/urls/resolvers.py", line 497, in _reverse_with_prefix
    raise NoReverseMatch(msg)
django.urls.exceptions.NoReverseMatch: Reverse for 'user_list' not found. 'user_list' is not a valid view function or pattern name.
2017-12-17 22:25:54,785-[ERROR]-/ops-data/zp/haha/mysite-11/lib/python3.6/site-packages/django/core/handlers/exception.py-[line:135]-Internal Server Error: /resources/idc/list/
Traceback (most recent call last):
  File "/ops-data/zp/haha/mysite-11/lib/python3.6/site-packages/django/core/handlers/exception.py", line 41, in inner
    response = get_response(request)
  File "/ops-data/zp/haha/mysite-11/lib/python3.6/site-packages/django/core/handlers/base.py", line 249, in _legacy_get_response
    response = self._get_response(request)
  File "/ops-data/zp/haha/mysite-11/lib/python3.6/site-packages/django/core/handlers/base.py", line 187, in _get_response
    response = self.process_exception_by_middleware(e, request)
  File "/ops-data/zp/haha/mysite-11/lib/python3.6/site-packages/django/core/handlers/base.py", line 185, in _get_response
    response = wrapped_callback(request, *callback_args, **callback_kwargs)
  File "/ops-data/zp/haha/mysite-11/lib/python3.6/site-packages/django/views/generic/base.py", line 68, in view
    return self.dispatch(request, *args, **kwargs)
  File "/ops-data/zp/haha/mysite-11/opsweb/accounts/permission/permission_required_mixin.py", line 11, in dispatch
    return redirect(self.permission_redirect_url)
  File "/ops-data/zp/haha/mysite-11/lib/python3.6/site-packages/django/shortcuts.py", line 56, in redirect
    return redirect_class(resolve_url(to, *args, **kwargs))
  File "/ops-data/zp/haha/mysite-11/lib/python3.6/site-packages/django/shortcuts.py", line 147, in resolve_url
    return reverse(to, args=args, kwargs=kwargs)
  File "/ops-data/zp/haha/mysite-11/lib/python3.6/site-packages/django/urls/base.py", line 91, in reverse
    return force_text(iri_to_uri(resolver._reverse_with_prefix(view, prefix, *args, **kwargs)))
  File "/ops-data/zp/haha/mysite-11/lib/python3.6/site-packages/django/urls/resolvers.py", line 497, in _reverse_with_prefix
    raise NoReverseMatch(msg)
django.urls.exceptions.NoReverseMatch: Reverse for 'user_list' not found. 'user_list' is not a valid view function or pattern name.
2017-12-17 22:27:41,290-[ERROR]-/ops-data/zp/haha/mysite-11/lib/python3.6/site-packages/django/core/handlers/exception.py-[line:135]-Internal Server Error: /resources/idc/list/
Traceback (most recent call last):
  File "/ops-data/zp/haha/mysite-11/lib/python3.6/site-packages/django/core/handlers/exception.py", line 41, in inner
    response = get_response(request)
  File "/ops-data/zp/haha/mysite-11/lib/python3.6/site-packages/django/core/handlers/base.py", line 249, in _legacy_get_response
    response = self._get_response(request)
  File "/ops-data/zp/haha/mysite-11/lib/python3.6/site-packages/django/core/handlers/base.py", line 187, in _get_response
    response = self.process_exception_by_middleware(e, request)
  File "/ops-data/zp/haha/mysite-11/lib/python3.6/site-packages/django/core/handlers/base.py", line 185, in _get_response
    response = wrapped_callback(request, *callback_args, **callback_kwargs)
  File "/ops-data/zp/haha/mysite-11/lib/python3.6/site-packages/django/views/generic/base.py", line 68, in view
    return self.dispatch(request, *args, **kwargs)
  File "/ops-data/zp/haha/mysite-11/opsweb/accounts/permission/permission_required_mixin.py", line 11, in dispatch
    return redirect(self.permission_redirect_url)
  File "/ops-data/zp/haha/mysite-11/lib/python3.6/site-packages/django/shortcuts.py", line 56, in redirect
    return redirect_class(resolve_url(to, *args, **kwargs))
  File "/ops-data/zp/haha/mysite-11/lib/python3.6/site-packages/django/shortcuts.py", line 147, in resolve_url
    return reverse(to, args=args, kwargs=kwargs)
  File "/ops-data/zp/haha/mysite-11/lib/python3.6/site-packages/django/urls/base.py", line 91, in reverse
    return force_text(iri_to_uri(resolver._reverse_with_prefix(view, prefix, *args, **kwargs)))
  File "/ops-data/zp/haha/mysite-11/lib/python3.6/site-packages/django/urls/resolvers.py", line 497, in _reverse_with_prefix
    raise NoReverseMatch(msg)
django.urls.exceptions.NoReverseMatch: Reverse for 'user_list' not found. 'user_list' is not a valid view function or pattern name.
2017-12-17 22:27:44,038-[ERROR]-/ops-data/zp/haha/mysite-11/lib/python3.6/site-packages/django/core/handlers/exception.py-[line:135]-Internal Server Error: /resources/idc/list/
Traceback (most recent call last):
  File "/ops-data/zp/haha/mysite-11/lib/python3.6/site-packages/django/core/handlers/exception.py", line 41, in inner
    response = get_response(request)
  File "/ops-data/zp/haha/mysite-11/lib/python3.6/site-packages/django/core/handlers/base.py", line 249, in _legacy_get_response
    response = self._get_response(request)
  File "/ops-data/zp/haha/mysite-11/lib/python3.6/site-packages/django/core/handlers/base.py", line 187, in _get_response
    response = self.process_exception_by_middleware(e, request)
  File "/ops-data/zp/haha/mysite-11/lib/python3.6/site-packages/django/core/handlers/base.py", line 185, in _get_response
    response = wrapped_callback(request, *callback_args, **callback_kwargs)
  File "/ops-data/zp/haha/mysite-11/lib/python3.6/site-packages/django/views/generic/base.py", line 68, in view
    return self.dispatch(request, *args, **kwargs)
  File "/ops-data/zp/haha/mysite-11/opsweb/accounts/permission/permission_required_mixin.py", line 11, in dispatch
    return redirect(self.permission_redirect_url)
  File "/ops-data/zp/haha/mysite-11/lib/python3.6/site-packages/django/shortcuts.py", line 56, in redirect
    return redirect_class(resolve_url(to, *args, **kwargs))
  File "/ops-data/zp/haha/mysite-11/lib/python3.6/site-packages/django/shortcuts.py", line 147, in resolve_url
    return reverse(to, args=args, kwargs=kwargs)
  File "/ops-data/zp/haha/mysite-11/lib/python3.6/site-packages/django/urls/base.py", line 91, in reverse
    return force_text(iri_to_uri(resolver._reverse_with_prefix(view, prefix, *args, **kwargs)))
  File "/ops-data/zp/haha/mysite-11/lib/python3.6/site-packages/django/urls/resolvers.py", line 497, in _reverse_with_prefix
    raise NoReverseMatch(msg)
django.urls.exceptions.NoReverseMatch: Reverse for 'user_list' not found. 'user_list' is not a valid view function or pattern name.
2017-12-17 22:27:45,982-[ERROR]-/ops-data/zp/haha/mysite-11/lib/python3.6/site-packages/django/core/handlers/exception.py-[line:135]-Internal Server Error: /resources/idc/list/
Traceback (most recent call last):
  File "/ops-data/zp/haha/mysite-11/lib/python3.6/site-packages/django/core/handlers/exception.py", line 41, in inner
    response = get_response(request)
  File "/ops-data/zp/haha/mysite-11/lib/python3.6/site-packages/django/core/handlers/base.py", line 249, in _legacy_get_response
    response = self._get_response(request)
  File "/ops-data/zp/haha/mysite-11/lib/python3.6/site-packages/django/core/handlers/base.py", line 187, in _get_response
    response = self.process_exception_by_middleware(e, request)
  File "/ops-data/zp/haha/mysite-11/lib/python3.6/site-packages/django/core/handlers/base.py", line 185, in _get_response
    response = wrapped_callback(request, *callback_args, **callback_kwargs)
  File "/ops-data/zp/haha/mysite-11/lib/python3.6/site-packages/django/views/generic/base.py", line 68, in view
    return self.dispatch(request, *args, **kwargs)
  File "/ops-data/zp/haha/mysite-11/opsweb/accounts/permission/permission_required_mixin.py", line 11, in dispatch
    return redirect(self.permission_redirect_url)
  File "/ops-data/zp/haha/mysite-11/lib/python3.6/site-packages/django/shortcuts.py", line 56, in redirect
    return redirect_class(resolve_url(to, *args, **kwargs))
  File "/ops-data/zp/haha/mysite-11/lib/python3.6/site-packages/django/shortcuts.py", line 147, in resolve_url
    return reverse(to, args=args, kwargs=kwargs)
  File "/ops-data/zp/haha/mysite-11/lib/python3.6/site-packages/django/urls/base.py", line 91, in reverse
    return force_text(iri_to_uri(resolver._reverse_with_prefix(view, prefix, *args, **kwargs)))
  File "/ops-data/zp/haha/mysite-11/lib/python3.6/site-packages/django/urls/resolvers.py", line 497, in _reverse_with_prefix
    raise NoReverseMatch(msg)
django.urls.exceptions.NoReverseMatch: Reverse for 'user_list' not found. 'user_list' is not a valid view function or pattern name.
2017-12-17 22:29:22,996-[ERROR]-/ops-data/zp/haha/mysite-11/lib/python3.6/site-packages/django/core/handlers/exception.py-[line:135]-Internal Server Error: /resources/idc/list/
Traceback (most recent call last):
  File "/ops-data/zp/haha/mysite-11/lib/python3.6/site-packages/django/core/handlers/exception.py", line 41, in inner
    response = get_response(request)
  File "/ops-data/zp/haha/mysite-11/lib/python3.6/site-packages/django/core/handlers/base.py", line 249, in _legacy_get_response
    response = self._get_response(request)
  File "/ops-data/zp/haha/mysite-11/lib/python3.6/site-packages/django/core/handlers/base.py", line 187, in _get_response
    response = self.process_exception_by_middleware(e, request)
  File "/ops-data/zp/haha/mysite-11/lib/python3.6/site-packages/django/core/handlers/base.py", line 185, in _get_response
    response = wrapped_callback(request, *callback_args, **callback_kwargs)
  File "/ops-data/zp/haha/mysite-11/lib/python3.6/site-packages/django/views/generic/base.py", line 68, in view
    return self.dispatch(request, *args, **kwargs)
  File "/ops-data/zp/haha/mysite-11/opsweb/accounts/permission/permission_required_mixin.py", line 11, in dispatch
    return redirect(self.permission_redirect_url)
  File "/ops-data/zp/haha/mysite-11/lib/python3.6/site-packages/django/shortcuts.py", line 56, in redirect
    return redirect_class(resolve_url(to, *args, **kwargs))
  File "/ops-data/zp/haha/mysite-11/lib/python3.6/site-packages/django/shortcuts.py", line 147, in resolve_url
    return reverse(to, args=args, kwargs=kwargs)
  File "/ops-data/zp/haha/mysite-11/lib/python3.6/site-packages/django/urls/base.py", line 91, in reverse
    return force_text(iri_to_uri(resolver._reverse_with_prefix(view, prefix, *args, **kwargs)))
  File "/ops-data/zp/haha/mysite-11/lib/python3.6/site-packages/django/urls/resolvers.py", line 497, in _reverse_with_prefix
    raise NoReverseMatch(msg)
django.urls.exceptions.NoReverseMatch: Reverse for 'user_list' not found. 'user_list' is not a valid view function or pattern name.
2017-12-17 22:29:24,855-[ERROR]-/ops-data/zp/haha/mysite-11/lib/python3.6/site-packages/django/core/handlers/exception.py-[line:135]-Internal Server Error: /resources/idc/list/
Traceback (most recent call last):
  File "/ops-data/zp/haha/mysite-11/lib/python3.6/site-packages/django/core/handlers/exception.py", line 41, in inner
    response = get_response(request)
  File "/ops-data/zp/haha/mysite-11/lib/python3.6/site-packages/django/core/handlers/base.py", line 249, in _legacy_get_response
    response = self._get_response(request)
  File "/ops-data/zp/haha/mysite-11/lib/python3.6/site-packages/django/core/handlers/base.py", line 187, in _get_response
    response = self.process_exception_by_middleware(e, request)
  File "/ops-data/zp/haha/mysite-11/lib/python3.6/site-packages/django/core/handlers/base.py", line 185, in _get_response
    response = wrapped_callback(request, *callback_args, **callback_kwargs)
  File "/ops-data/zp/haha/mysite-11/lib/python3.6/site-packages/django/views/generic/base.py", line 68, in view
    return self.dispatch(request, *args, **kwargs)
  File "/ops-data/zp/haha/mysite-11/opsweb/accounts/permission/permission_required_mixin.py", line 11, in dispatch
    return redirect(self.permission_redirect_url)
  File "/ops-data/zp/haha/mysite-11/lib/python3.6/site-packages/django/shortcuts.py", line 56, in redirect
    return redirect_class(resolve_url(to, *args, **kwargs))
  File "/ops-data/zp/haha/mysite-11/lib/python3.6/site-packages/django/shortcuts.py", line 147, in resolve_url
    return reverse(to, args=args, kwargs=kwargs)
  File "/ops-data/zp/haha/mysite-11/lib/python3.6/site-packages/django/urls/base.py", line 91, in reverse
    return force_text(iri_to_uri(resolver._reverse_with_prefix(view, prefix, *args, **kwargs)))
  File "/ops-data/zp/haha/mysite-11/lib/python3.6/site-packages/django/urls/resolvers.py", line 497, in _reverse_with_prefix
    raise NoReverseMatch(msg)
django.urls.exceptions.NoReverseMatch: Reverse for 'user_list' not found. 'user_list' is not a valid view function or pattern name.
